package scmc.worldgen.structure;

import java.util.Random;

import net.minecraft.block.Block;
import net.minecraft.block.material.Material;
import net.minecraft.init.Blocks;
import net.minecraft.util.math.BlockPos;
import net.minecraft.world.World;
import net.minecraft.world.gen.feature.WorldGenerator;
import scmc.blocks.ModBlocks;
import scmc.blocks.metablocks.ModMetaBlocks;

public class StructureZergSpire extends WorldGenerator {

	protected Block[] GetValidSpawnBlocks() {
		return new Block[] { ModBlocks.ZERG_CREEP };
	}

	public boolean LocationIsValidSpawn(World world, BlockPos pos) {
		
		Block checkBlock = world.getBlockState(pos).getBlock();
		Material m = checkBlock.getDefaultState().getMaterial();
		Block blockAbove = world.getBlockState(pos.up()).getBlock();
		Block blockBelow = world.getBlockState(pos.down()).getBlock();

		for (Block i : GetValidSpawnBlocks()) {
			if (blockAbove != Blocks.AIR) {
				return false;
			}
			if (checkBlock == i) {
				return true;
			} else if (m == Material.PLANTS && blockBelow == i) {
				world.getBlockState(pos).getMaterial();
				return true;
			}
		}
		return false;
	}

	public boolean generate(World world, Random rand, BlockPos pos) {
		if (rand.nextInt(1) == 0) {
			generate_r0(world, rand, pos);
		}

		return true;
	}

	public boolean generate_r0(World world, Random rand, BlockPos pos) {
		if (!LocationIsValidSpawn(world, pos) || !LocationIsValidSpawn(world, pos.add(23, 0, 0))
				|| !LocationIsValidSpawn(world, pos.add(23, 0, 25))
				|| !LocationIsValidSpawn(world, pos.add(0, 0, 25))
				|| !LocationIsValidSpawn(world, pos.add(11, 0, 12))) {
			return false;
		}

		world.setBlockState(pos.add(14, 0, 3), ModBlocks.KERATIN_CHUNK.getDefaultState(), 2);
		world.setBlockState(pos.add(15, 0, 3), ModBlocks.KERATIN_CHUNK.getDefaultState(), 2);
		world.setBlockState(pos.add(12, 0, 4), ModBlocks.KERATIN_CHUNK.getDefaultState(), 2);
		world.setBlockState(pos.add(14, 0, 4), ModMetaBlocks.ZERG_CARAPACE.getDefaultState(), 2);
		world.setBlockState(pos.add(15, 0, 4), ModMetaBlocks.ZERG_CARAPACE.getDefaultState(), 2);
		world.setBlockState(pos.add(4, 0, 5), ModBlocks.KERATIN_CHUNK.getDefaultState(), 2);
		world.setBlockState(pos.add(13, 0, 5), ModBlocks.KERATIN_CHUNK.getDefaultState(), 2);
		world.setBlockState(pos.add(14, 0, 5), ModMetaBlocks.ZERG_CARAPACE.getDefaultState(), 2);
		world.setBlockState(pos.add(15, 0, 5), ModMetaBlocks.ZERG_CARAPACE.getDefaultState(), 2);
		world.setBlockState(pos.add(16, 0, 5), ModMetaBlocks.ZERG_CARAPACE.getDefaultState(), 2);
		world.setBlockState(pos.add(18, 0, 5), ModBlocks.KERATIN_CHUNK.getDefaultState(), 2);
		world.setBlockState(pos.add(5, 0, 6), ModBlocks.KERATIN_CHUNK.getDefaultState(), 2);
		world.setBlockState(pos.add(6, 0, 6), ModMetaBlocks.ZERG_CARAPACE.getDefaultState(), 2);
		world.setBlockState(pos.add(10, 0, 6), ModMetaBlocks.ZERG_FLESH.getDefaultState(), 2);
		world.setBlockState(pos.add(11, 0, 6), ModMetaBlocks.ZERG_FLESH.getDefaultState(), 2);
		world.setBlockState(pos.add(12, 0, 6), ModMetaBlocks.ZERG_FLESH.getDefaultState(), 2);
		world.setBlockState(pos.add(13, 0, 6), ModMetaBlocks.ZERG_FLESH.getDefaultState(), 2);
		world.setBlockState(pos.add(14, 0, 6), ModMetaBlocks.ZERG_FLESH.getDefaultState(), 2);
		world.setBlockState(pos.add(15, 0, 6), ModMetaBlocks.ZERG_FLESH.getDefaultState(), 2);
		world.setBlockState(pos.add(16, 0, 6), ModMetaBlocks.ZERG_CARAPACE.getDefaultState(), 2);
		world.setBlockState(pos.add(17, 0, 6), ModBlocks.KERATIN_CHUNK.getDefaultState(), 2);
		world.setBlockState(pos.add(4, 0, 7), ModMetaBlocks.ZERG_CARAPACE.getDefaultState(), 2);
		world.setBlockState(pos.add(5, 0, 7), ModMetaBlocks.ZERG_CARAPACE.getDefaultState(), 2);
		world.setBlockState(pos.add(6, 0, 7), ModMetaBlocks.ZERG_CARAPACE.getDefaultState(), 2);
		world.setBlockState(pos.add(7, 0, 7), ModMetaBlocks.ZERG_CARAPACE.getDefaultState(), 2);
		world.setBlockState(pos.add(9, 0, 7), ModMetaBlocks.ZERG_FLESH.getDefaultState(), 2);
		world.setBlockState(pos.add(10, 0, 7), ModMetaBlocks.ZERG_FLESH.getDefaultState(), 2);
		world.setBlockState(pos.add(11, 0, 7), ModMetaBlocks.ZERG_FLESH.getDefaultState(), 2);
		world.setBlockState(pos.add(12, 0, 7), ModMetaBlocks.ZERG_FLESH.getDefaultState(), 2);
		world.setBlockState(pos.add(13, 0, 7), ModMetaBlocks.ZERG_FLESH.getDefaultState(), 2);
		world.setBlockState(pos.add(14, 0, 7), ModMetaBlocks.ZERG_FLESH.getDefaultState(), 2);
		world.setBlockState(pos.add(15, 0, 7), ModMetaBlocks.ZERG_FLESH.getDefaultState(), 2);
		world.setBlockState(pos.add(16, 0, 7), ModMetaBlocks.ZERG_CARAPACE.getDefaultState(), 2);
		world.setBlockState(pos.add(17, 0, 7), ModMetaBlocks.ZERG_CARAPACE.getDefaultState(), 2);
		world.setBlockState(pos.add(3, 0, 8), ModBlocks.KERATIN_CHUNK.getDefaultState(), 2);
		world.setBlockState(pos.add(4, 0, 8), ModMetaBlocks.ZERG_CARAPACE.getDefaultState(), 2);
		world.setBlockState(pos.add(5, 0, 8), ModMetaBlocks.ZERG_CARAPACE.getDefaultState(), 2);
		world.setBlockState(pos.add(6, 0, 8), ModMetaBlocks.ZERG_CARAPACE.getDefaultState(), 2);
		world.setBlockState(pos.add(7, 0, 8), ModMetaBlocks.ZERG_CARAPACE.getDefaultState(), 2);
		world.setBlockState(pos.add(8, 0, 8), ModMetaBlocks.ZERG_FLESH.getDefaultState(), 2);
		world.setBlockState(pos.add(9, 0, 8), ModMetaBlocks.ZERG_FLESH.getDefaultState(), 2);
		world.setBlockState(pos.add(10, 0, 8), ModMetaBlocks.ZERG_FLESH.getDefaultState(), 2);
		world.setBlockState(pos.add(11, 0, 8), ModMetaBlocks.ZERG_FLESH.getDefaultState(), 2);
		world.setBlockState(pos.add(12, 0, 8), ModMetaBlocks.ZERG_FLESH.getDefaultState(), 2);
		world.setBlockState(pos.add(13, 0, 8), ModMetaBlocks.ZERG_FLESH.getDefaultState(), 2);
		world.setBlockState(pos.add(14, 0, 8), ModMetaBlocks.ZERG_FLESH.getDefaultState(), 2);
		world.setBlockState(pos.add(15, 0, 8), ModMetaBlocks.ZERG_FLESH.getDefaultState(), 2);
		world.setBlockState(pos.add(16, 0, 8), ModMetaBlocks.ZERG_FLESH.getDefaultState(), 2);
		world.setBlockState(pos.add(3, 0, 9), ModBlocks.KERATIN_CHUNK.getDefaultState(), 2);
		world.setBlockState(pos.add(4, 0, 9), ModMetaBlocks.ZERG_CARAPACE.getDefaultState(), 2);
		world.setBlockState(pos.add(5, 0, 9), ModMetaBlocks.ZERG_CARAPACE.getDefaultState(), 2);
		world.setBlockState(pos.add(6, 0, 9), ModMetaBlocks.ZERG_CARAPACE.getDefaultState(), 2);
		world.setBlockState(pos.add(7, 0, 9), ModMetaBlocks.ZERG_FLESH.getDefaultState(), 2);
		world.setBlockState(pos.add(8, 0, 9), ModMetaBlocks.ZERG_FLESH.getDefaultState(), 2);
		world.setBlockState(pos.add(9, 0, 9), ModMetaBlocks.ZERG_FLESH.getDefaultState(), 2);
		world.setBlockState(pos.add(10, 0, 9), ModMetaBlocks.ZERG_FLESH.getDefaultState(), 2);
		world.setBlockState(pos.add(11, 0, 9), ModMetaBlocks.ZERG_FLESH.getDefaultState(), 2);
		world.setBlockState(pos.add(12, 0, 9), ModMetaBlocks.ZERG_FLESH.getDefaultState(), 2);
		world.setBlockState(pos.add(13, 0, 9), ModMetaBlocks.ZERG_FLESH.getDefaultState(), 2);
		world.setBlockState(pos.add(14, 0, 9), ModMetaBlocks.ZERG_FLESH.getDefaultState(), 2);
		world.setBlockState(pos.add(15, 0, 9), ModMetaBlocks.ZERG_FLESH.getDefaultState(), 2);
		world.setBlockState(pos.add(16, 0, 9), ModMetaBlocks.ZERG_FLESH.getDefaultState(), 2);
		world.setBlockState(pos.add(17, 0, 9), ModMetaBlocks.ZERG_FLESH.getDefaultState(), 2);
		world.setBlockState(pos.add(4, 0, 10), ModMetaBlocks.ZERG_CARAPACE.getDefaultState(), 2);
		world.setBlockState(pos.add(5, 0, 10), ModMetaBlocks.ZERG_CARAPACE.getDefaultState(), 2);
		world.setBlockState(pos.add(6, 0, 10), ModMetaBlocks.ZERG_FLESH.getDefaultState(), 2);
		world.setBlockState(pos.add(7, 0, 10), ModMetaBlocks.ZERG_FLESH.getDefaultState(), 2);
		world.setBlockState(pos.add(8, 0, 10), ModMetaBlocks.ZERG_FLESH.getDefaultState(), 2);
		world.setBlockState(pos.add(9, 0, 10), ModMetaBlocks.ZERG_FLESH.getDefaultState(), 2);
		world.setBlockState(pos.add(10, 0, 10), ModMetaBlocks.ZERG_FLESH.getDefaultState(), 2);
		world.setBlockState(pos.add(11, 0, 10), ModMetaBlocks.ZERG_FLESH.getDefaultState(), 2);
		world.setBlockState(pos.add(12, 0, 10), ModMetaBlocks.ZERG_FLESH.getDefaultState(), 2);
		world.setBlockState(pos.add(13, 0, 10), ModMetaBlocks.ZERG_FLESH.getDefaultState(), 2);
		world.setBlockState(pos.add(14, 0, 10), ModMetaBlocks.ZERG_FLESH.getDefaultState(), 2);
		world.setBlockState(pos.add(15, 0, 10), ModMetaBlocks.ZERG_FLESH.getDefaultState(), 2);
		world.setBlockState(pos.add(16, 0, 10), ModMetaBlocks.ZERG_FLESH.getDefaultState(), 2);
		world.setBlockState(pos.add(17, 0, 10), ModMetaBlocks.ZERG_FLESH.getDefaultState(), 2);
		world.setBlockState(pos.add(18, 0, 10), ModMetaBlocks.ZERG_FLESH.getDefaultState(), 2);
		world.setBlockState(pos.add(19, 0, 10), ModMetaBlocks.ZERG_CARAPACE.getDefaultState(), 2);
		world.setBlockState(pos.add(20, 0, 10), ModBlocks.KERATIN_CHUNK.getDefaultState(), 2);
		world.setBlockState(pos.add(2, 0, 11), ModBlocks.KERATIN_CHUNK.getDefaultState(), 2);
		world.setBlockState(pos.add(3, 0, 11), ModMetaBlocks.ZERG_CARAPACE.getDefaultState(), 2);
		world.setBlockState(pos.add(4, 0, 11), ModMetaBlocks.ZERG_CARAPACE.getDefaultState(), 2);
		world.setBlockState(pos.add(5, 0, 11), ModMetaBlocks.ZERG_CARAPACE.getDefaultState(), 2);
		world.setBlockState(pos.add(6, 0, 11), ModMetaBlocks.ZERG_FLESH.getDefaultState(), 2);
		world.setBlockState(pos.add(7, 0, 11), ModMetaBlocks.ZERG_FLESH.getDefaultState(), 2);
		world.setBlockState(pos.add(8, 0, 11), ModMetaBlocks.ZERG_FLESH.getDefaultState(), 2);
		world.setBlockState(pos.add(9, 0, 11), ModMetaBlocks.ZERG_FLESH.getDefaultState(), 2);
		world.setBlockState(pos.add(10, 0, 11), ModMetaBlocks.ZERG_FLESH.getDefaultState(), 2);
		world.setBlockState(pos.add(11, 0, 11), ModMetaBlocks.ZERG_FLESH.getDefaultState(), 2);
		world.setBlockState(pos.add(12, 0, 11), ModMetaBlocks.ZERG_FLESH.getDefaultState(), 2);
		world.setBlockState(pos.add(13, 0, 11), ModMetaBlocks.ZERG_FLESH.getDefaultState(), 2);
		world.setBlockState(pos.add(14, 0, 11), ModMetaBlocks.ZERG_FLESH.getDefaultState(), 2);
		world.setBlockState(pos.add(15, 0, 11), ModMetaBlocks.ZERG_FLESH.getDefaultState(), 2);
		world.setBlockState(pos.add(16, 0, 11), ModMetaBlocks.ZERG_FLESH.getDefaultState(), 2);
		world.setBlockState(pos.add(17, 0, 11), ModMetaBlocks.ZERG_FLESH.getDefaultState(), 2);
		world.setBlockState(pos.add(18, 0, 11), ModMetaBlocks.ZERG_FLESH.getDefaultState(), 2);
		world.setBlockState(pos.add(19, 0, 11), ModMetaBlocks.ZERG_CARAPACE.getDefaultState(), 2);
		world.setBlockState(pos.add(20, 0, 11), ModMetaBlocks.ZERG_CARAPACE.getDefaultState(), 2);
		world.setBlockState(pos.add(3, 0, 12), ModMetaBlocks.ZERG_CARAPACE.getDefaultState(), 2);
		world.setBlockState(pos.add(4, 0, 12), ModMetaBlocks.ZERG_CARAPACE.getDefaultState(), 2);
		world.setBlockState(pos.add(5, 0, 12), ModMetaBlocks.ZERG_CARAPACE.getDefaultState(), 2);
		world.setBlockState(pos.add(6, 0, 12), ModMetaBlocks.ZERG_FLESH.getDefaultState(), 2);
		world.setBlockState(pos.add(7, 0, 12), ModMetaBlocks.ZERG_FLESH.getDefaultState(), 2);
		world.setBlockState(pos.add(8, 0, 12), ModMetaBlocks.ZERG_FLESH.getDefaultState(), 2);
		world.setBlockState(pos.add(9, 0, 12), ModMetaBlocks.ZERG_FLESH.getDefaultState(), 2);
		world.setBlockState(pos.add(10, 0, 12), ModMetaBlocks.ZERG_FLESH.getDefaultState(), 2);
		world.setBlockState(pos.add(11, 0, 12), ModMetaBlocks.ZERG_FLESH.getDefaultState(), 2);
		world.setBlockState(pos.add(12, 0, 12), ModMetaBlocks.ZERG_FLESH.getDefaultState(), 2);
		world.setBlockState(pos.add(13, 0, 12), ModMetaBlocks.ZERG_FLESH.getDefaultState(), 2);
		world.setBlockState(pos.add(14, 0, 12), ModMetaBlocks.ZERG_FLESH.getDefaultState(), 2);
		world.setBlockState(pos.add(15, 0, 12), ModMetaBlocks.ZERG_FLESH.getDefaultState(), 2);
		world.setBlockState(pos.add(16, 0, 12), ModMetaBlocks.ZERG_FLESH.getDefaultState(), 2);
		world.setBlockState(pos.add(17, 0, 12), ModMetaBlocks.ZERG_FLESH.getDefaultState(), 2);
		world.setBlockState(pos.add(18, 0, 12), ModMetaBlocks.ZERG_FLESH.getDefaultState(), 2);
		world.setBlockState(pos.add(19, 0, 12), ModMetaBlocks.ZERG_FLESH.getDefaultState(), 2);
		world.setBlockState(pos.add(20, 0, 12), ModMetaBlocks.ZERG_CARAPACE.getDefaultState(), 2);
		world.setBlockState(pos.add(21, 0, 12), ModMetaBlocks.ZERG_CARAPACE.getDefaultState(), 2);
		world.setBlockState(pos.add(22, 0, 12), ModBlocks.KERATIN_CHUNK.getDefaultState(), 2);
		world.setBlockState(pos.add(2, 0, 13), ModBlocks.KERATIN_CHUNK.getDefaultState(), 2);
		world.setBlockState(pos.add(3, 0, 13), ModMetaBlocks.ZERG_CARAPACE.getDefaultState(), 2);
		world.setBlockState(pos.add(4, 0, 13), ModMetaBlocks.ZERG_CARAPACE.getDefaultState(), 2);
		world.setBlockState(pos.add(5, 0, 13), ModMetaBlocks.ZERG_CARAPACE.getDefaultState(), 2);
		world.setBlockState(pos.add(6, 0, 13), ModMetaBlocks.ZERG_FLESH.getDefaultState(), 2);
		world.setBlockState(pos.add(7, 0, 13), ModMetaBlocks.ZERG_FLESH.getDefaultState(), 2);
		world.setBlockState(pos.add(8, 0, 13), ModMetaBlocks.ZERG_FLESH.getDefaultState(), 2);
		world.setBlockState(pos.add(9, 0, 13), ModMetaBlocks.ZERG_FLESH.getDefaultState(), 2);
		world.setBlockState(pos.add(10, 0, 13), ModMetaBlocks.ZERG_FLESH.getDefaultState(), 2);
		world.setBlockState(pos.add(11, 0, 13), ModMetaBlocks.ZERG_FLESH.getDefaultState(), 2);
		world.setBlockState(pos.add(12, 0, 13), ModMetaBlocks.ZERG_FLESH.getDefaultState(), 2);
		world.setBlockState(pos.add(13, 0, 13), ModMetaBlocks.ZERG_FLESH.getDefaultState(), 2);
		world.setBlockState(pos.add(14, 0, 13), ModMetaBlocks.ZERG_FLESH.getDefaultState(), 2);
		world.setBlockState(pos.add(15, 0, 13), ModMetaBlocks.ZERG_FLESH.getDefaultState(), 2);
		world.setBlockState(pos.add(16, 0, 13), ModMetaBlocks.ZERG_FLESH.getDefaultState(), 2);
		world.setBlockState(pos.add(17, 0, 13), ModMetaBlocks.ZERG_FLESH.getDefaultState(), 2);
		world.setBlockState(pos.add(18, 0, 13), ModMetaBlocks.ZERG_FLESH.getDefaultState(), 2);
		world.setBlockState(pos.add(19, 0, 13), ModMetaBlocks.ZERG_FLESH.getDefaultState(), 2);
		world.setBlockState(pos.add(20, 0, 13), ModMetaBlocks.ZERG_CARAPACE.getDefaultState(), 2);
		world.setBlockState(pos.add(21, 0, 13), ModMetaBlocks.ZERG_CARAPACE.getDefaultState(), 2);
		world.setBlockState(pos.add(22, 0, 13), ModBlocks.KERATIN_CHUNK.getDefaultState(), 2);
		world.setBlockState(pos.add(4, 0, 14), ModBlocks.KERATIN_CHUNK.getDefaultState(), 2);
		world.setBlockState(pos.add(5, 0, 14), ModMetaBlocks.ZERG_CARAPACE.getDefaultState(), 2);
		world.setBlockState(pos.add(6, 0, 14), ModMetaBlocks.ZERG_FLESH.getDefaultState(), 2);
		world.setBlockState(pos.add(7, 0, 14), ModMetaBlocks.ZERG_FLESH.getDefaultState(), 2);
		world.setBlockState(pos.add(8, 0, 14), ModMetaBlocks.ZERG_FLESH.getDefaultState(), 2);
		world.setBlockState(pos.add(9, 0, 14), ModMetaBlocks.ZERG_FLESH.getDefaultState(), 2);
		world.setBlockState(pos.add(10, 0, 14), ModMetaBlocks.ZERG_FLESH.getDefaultState(), 2);
		world.setBlockState(pos.add(11, 0, 14), ModMetaBlocks.ZERG_FLESH.getDefaultState(), 2);
		world.setBlockState(pos.add(12, 0, 14), ModMetaBlocks.ZERG_FLESH.getDefaultState(), 2);
		world.setBlockState(pos.add(13, 0, 14), ModMetaBlocks.ZERG_FLESH.getDefaultState(), 2);
		world.setBlockState(pos.add(14, 0, 14), ModMetaBlocks.ZERG_FLESH.getDefaultState(), 2);
		world.setBlockState(pos.add(15, 0, 14), ModMetaBlocks.ZERG_FLESH.getDefaultState(), 2);
		world.setBlockState(pos.add(16, 0, 14), ModMetaBlocks.ZERG_FLESH.getDefaultState(), 2);
		world.setBlockState(pos.add(17, 0, 14), ModMetaBlocks.ZERG_FLESH.getDefaultState(), 2);
		world.setBlockState(pos.add(18, 0, 14), ModMetaBlocks.ZERG_FLESH.getDefaultState(), 2);
		world.setBlockState(pos.add(19, 0, 14), ModMetaBlocks.ZERG_CARAPACE.getDefaultState(), 2);
		world.setBlockState(pos.add(20, 0, 14), ModBlocks.KERATIN_CHUNK.getDefaultState(), 2);
		world.setBlockState(pos.add(3, 0, 15), ModBlocks.KERATIN_CHUNK.getDefaultState(), 2);
		world.setBlockState(pos.add(7, 0, 15), ModMetaBlocks.ZERG_FLESH.getDefaultState(), 2);
		world.setBlockState(pos.add(8, 0, 15), ModMetaBlocks.ZERG_FLESH.getDefaultState(), 2);
		world.setBlockState(pos.add(9, 0, 15), ModMetaBlocks.ZERG_FLESH.getDefaultState(), 2);
		world.setBlockState(pos.add(10, 0, 15), ModMetaBlocks.ZERG_FLESH.getDefaultState(), 2);
		world.setBlockState(pos.add(11, 0, 15), ModMetaBlocks.ZERG_FLESH.getDefaultState(), 2);
		world.setBlockState(pos.add(12, 0, 15), ModMetaBlocks.ZERG_FLESH.getDefaultState(), 2);
		world.setBlockState(pos.add(13, 0, 15), ModMetaBlocks.ZERG_FLESH.getDefaultState(), 2);
		world.setBlockState(pos.add(14, 0, 15), ModMetaBlocks.ZERG_FLESH.getDefaultState(), 2);
		world.setBlockState(pos.add(15, 0, 15), ModMetaBlocks.ZERG_FLESH.getDefaultState(), 2);
		world.setBlockState(pos.add(16, 0, 15), ModMetaBlocks.ZERG_FLESH.getDefaultState(), 2);
		world.setBlockState(pos.add(17, 0, 15), ModMetaBlocks.ZERG_FLESH.getDefaultState(), 2);
		world.setBlockState(pos.add(18, 0, 15), ModMetaBlocks.ZERG_CARAPACE.getDefaultState(), 2);
		world.setBlockState(pos.add(19, 0, 15), ModMetaBlocks.ZERG_CARAPACE.getDefaultState(), 2);
		world.setBlockState(pos.add(21, 0, 15), ModBlocks.KERATIN_CHUNK.getDefaultState(), 2);
		world.setBlockState(pos.add(7, 0, 16), ModMetaBlocks.ZERG_CARAPACE.getDefaultState(), 2);
		world.setBlockState(pos.add(8, 0, 16), ModMetaBlocks.ZERG_FLESH.getDefaultState(), 2);
		world.setBlockState(pos.add(9, 0, 16), ModMetaBlocks.ZERG_FLESH.getDefaultState(), 2);
		world.setBlockState(pos.add(10, 0, 16), ModMetaBlocks.ZERG_FLESH.getDefaultState(), 2);
		world.setBlockState(pos.add(11, 0, 16), ModMetaBlocks.ZERG_FLESH.getDefaultState(), 2);
		world.setBlockState(pos.add(12, 0, 16), ModMetaBlocks.ZERG_FLESH.getDefaultState(), 2);
		world.setBlockState(pos.add(13, 0, 16), ModMetaBlocks.ZERG_FLESH.getDefaultState(), 2);
		world.setBlockState(pos.add(14, 0, 16), ModMetaBlocks.ZERG_FLESH.getDefaultState(), 2);
		world.setBlockState(pos.add(15, 0, 16), ModMetaBlocks.ZERG_FLESH.getDefaultState(), 2);
		world.setBlockState(pos.add(16, 0, 16), ModMetaBlocks.ZERG_FLESH.getDefaultState(), 2);
		world.setBlockState(pos.add(6, 0, 17), ModMetaBlocks.ZERG_CARAPACE.getDefaultState(), 2);
		world.setBlockState(pos.add(7, 0, 17), ModMetaBlocks.ZERG_CARAPACE.getDefaultState(), 2);
		world.setBlockState(pos.add(8, 0, 17), ModMetaBlocks.ZERG_FLESH.getDefaultState(), 2);
		world.setBlockState(pos.add(9, 0, 17), ModMetaBlocks.ZERG_FLESH.getDefaultState(), 2);
		world.setBlockState(pos.add(10, 0, 17), ModMetaBlocks.ZERG_FLESH.getDefaultState(), 2);
		world.setBlockState(pos.add(11, 0, 17), ModMetaBlocks.ZERG_FLESH.getDefaultState(), 2);
		world.setBlockState(pos.add(12, 0, 17), ModMetaBlocks.ZERG_FLESH.getDefaultState(), 2);
		world.setBlockState(pos.add(13, 0, 17), ModMetaBlocks.ZERG_FLESH.getDefaultState(), 2);
		world.setBlockState(pos.add(14, 0, 17), ModMetaBlocks.ZERG_FLESH.getDefaultState(), 2);
		world.setBlockState(pos.add(15, 0, 17), ModMetaBlocks.ZERG_FLESH.getDefaultState(), 2);
		world.setBlockState(pos.add(16, 0, 17), ModMetaBlocks.ZERG_CARAPACE.getDefaultState(), 2);
		world.setBlockState(pos.add(6, 0, 18), ModMetaBlocks.ZERG_CARAPACE.getDefaultState(), 2);
		world.setBlockState(pos.add(7, 0, 18), ModMetaBlocks.ZERG_CARAPACE.getDefaultState(), 2);
		world.setBlockState(pos.add(8, 0, 18), ModMetaBlocks.ZERG_FLESH.getDefaultState(), 2);
		world.setBlockState(pos.add(9, 0, 18), ModMetaBlocks.ZERG_FLESH.getDefaultState(), 2);
		world.setBlockState(pos.add(10, 0, 18), ModMetaBlocks.ZERG_CARAPACE.getDefaultState(), 2);
		world.setBlockState(pos.add(11, 0, 18), ModMetaBlocks.ZERG_FLESH.getDefaultState(), 2);
		world.setBlockState(pos.add(12, 0, 18), ModMetaBlocks.ZERG_FLESH.getDefaultState(), 2);
		world.setBlockState(pos.add(13, 0, 18), ModMetaBlocks.ZERG_FLESH.getDefaultState(), 2);
		world.setBlockState(pos.add(14, 0, 18), ModMetaBlocks.ZERG_FLESH.getDefaultState(), 2);
		world.setBlockState(pos.add(15, 0, 18), ModMetaBlocks.ZERG_CARAPACE.getDefaultState(), 2);
		world.setBlockState(pos.add(16, 0, 18), ModMetaBlocks.ZERG_CARAPACE.getDefaultState(), 2);
		world.setBlockState(pos.add(6, 0, 19), ModBlocks.KERATIN_CHUNK.getDefaultState(), 2);
		world.setBlockState(pos.add(7, 0, 19), ModMetaBlocks.ZERG_CARAPACE.getDefaultState(), 2);
		world.setBlockState(pos.add(8, 0, 19), ModMetaBlocks.ZERG_CARAPACE.getDefaultState(), 2);
		world.setBlockState(pos.add(9, 0, 19), ModMetaBlocks.ZERG_CARAPACE.getDefaultState(), 2);
		world.setBlockState(pos.add(10, 0, 19), ModMetaBlocks.ZERG_CARAPACE.getDefaultState(), 2);
		world.setBlockState(pos.add(12, 0, 19), ModBlocks.KERATIN_CHUNK.getDefaultState(), 2);
		world.setBlockState(pos.add(13, 0, 19), ModMetaBlocks.ZERG_CARAPACE.getDefaultState(), 2);
		world.setBlockState(pos.add(14, 0, 19), ModMetaBlocks.ZERG_CARAPACE.getDefaultState(), 2);
		world.setBlockState(pos.add(15, 0, 19), ModBlocks.KERATIN_CHUNK.getDefaultState(), 2);
		world.setBlockState(pos.add(5, 0, 20), ModBlocks.KERATIN_CHUNK.getDefaultState(), 2);
		world.setBlockState(pos.add(7, 0, 20), ModMetaBlocks.ZERG_CARAPACE.getDefaultState(), 2);
		world.setBlockState(pos.add(8, 0, 20), ModMetaBlocks.ZERG_CARAPACE.getDefaultState(), 2);
		world.setBlockState(pos.add(9, 0, 20), ModMetaBlocks.ZERG_CARAPACE.getDefaultState(), 2);
		world.setBlockState(pos.add(11, 0, 20), ModBlocks.KERATIN_CHUNK.getDefaultState(), 2);
		world.setBlockState(pos.add(13, 0, 20), ModMetaBlocks.ZERG_CARAPACE.getDefaultState(), 2);
		world.setBlockState(pos.add(14, 0, 20), ModMetaBlocks.ZERG_CARAPACE.getDefaultState(), 2);
		world.setBlockState(pos.add(16, 0, 20), ModBlocks.KERATIN_CHUNK.getDefaultState(), 2);
		world.setBlockState(pos.add(8, 0, 21), ModBlocks.KERATIN_CHUNK.getDefaultState(), 2);
		world.setBlockState(pos.add(9, 0, 21), ModBlocks.KERATIN_CHUNK.getDefaultState(), 2);
		world.setBlockState(pos.add(13, 0, 21), ModBlocks.KERATIN_CHUNK.getDefaultState(), 2);
		world.setBlockState(pos.add(14, 0, 21), ModBlocks.KERATIN_CHUNK.getDefaultState(), 2);
		world.setBlockState(pos.add(14, 1, 4), ModBlocks.KERATIN_CHUNK.getDefaultState(), 2);
		world.setBlockState(pos.add(15, 1, 4), ModBlocks.KERATIN_CHUNK.getDefaultState(), 2);
		world.setBlockState(pos.add(13, 1, 5), ModBlocks.KERATIN_CHUNK.getDefaultState(), 2);
		world.setBlockState(pos.add(14, 1, 5), ModMetaBlocks.ZERG_CARAPACE.getDefaultState(), 2);
		world.setBlockState(pos.add(15, 1, 5), ModMetaBlocks.ZERG_CARAPACE.getDefaultState(), 2);
		world.setBlockState(pos.add(16, 1, 5), ModMetaBlocks.ZERG_CARAPACE.getDefaultState(), 2);
		world.setBlockState(pos.add(5, 1, 6), ModBlocks.KERATIN_CHUNK.getDefaultState(), 2);
		world.setBlockState(pos.add(6, 1, 6), ModMetaBlocks.ZERG_CARAPACE.getDefaultState(), 2);
		world.setBlockState(pos.add(10, 1, 6), ModMetaBlocks.ZERG_FLESH.getDefaultState(), 2);
		world.setBlockState(pos.add(11, 1, 6), ModMetaBlocks.ZERG_FLESH.getDefaultState(), 2);
		world.setBlockState(pos.add(13, 1, 6), ModMetaBlocks.ZERG_CARAPACE.getDefaultState(), 2);
		world.setBlockState(pos.add(14, 1, 6), ModMetaBlocks.ZERG_FLESH.getDefaultState(), 2);
		world.setBlockState(pos.add(15, 1, 6), ModMetaBlocks.ZERG_FLESH.getDefaultState(), 2);
		world.setBlockState(pos.add(16, 1, 6), ModMetaBlocks.ZERG_CARAPACE.getDefaultState(), 2);
		world.setBlockState(pos.add(17, 1, 6), ModBlocks.KERATIN_CHUNK.getDefaultState(), 2);
		world.setBlockState(pos.add(4, 1, 7), ModMetaBlocks.ZERG_CARAPACE.getDefaultState(), 2);
		world.setBlockState(pos.add(5, 1, 7), ModMetaBlocks.ZERG_CARAPACE.getDefaultState(), 2);
		world.setBlockState(pos.add(6, 1, 7), ModMetaBlocks.ZERG_CARAPACE.getDefaultState(), 2);
		world.setBlockState(pos.add(10, 1, 7), ModMetaBlocks.ZERG_FLESH.getDefaultState(), 2);
		world.setBlockState(pos.add(11, 1, 7), ModMetaBlocks.ZERG_FLESH.getDefaultState(), 2);
		world.setBlockState(pos.add(12, 1, 7), ModMetaBlocks.ZERG_FLESH.getDefaultState(), 2);
		world.setBlockState(pos.add(13, 1, 7), ModMetaBlocks.ZERG_FLESH.getDefaultState(), 2);
		world.setBlockState(pos.add(14, 1, 7), ModMetaBlocks.ZERG_FLESH.getDefaultState(), 2);
		world.setBlockState(pos.add(15, 1, 7), ModMetaBlocks.ZERG_FLESH.getDefaultState(), 2);
		world.setBlockState(pos.add(16, 1, 7), ModMetaBlocks.ZERG_CARAPACE.getDefaultState(), 2);
		world.setBlockState(pos.add(17, 1, 7), ModMetaBlocks.ZERG_CARAPACE.getDefaultState(), 2);
		world.setBlockState(pos.add(4, 1, 8), ModBlocks.KERATIN_CHUNK.getDefaultState(), 2);
		world.setBlockState(pos.add(5, 1, 8), ModMetaBlocks.ZERG_CARAPACE.getDefaultState(), 2);
		world.setBlockState(pos.add(6, 1, 8), ModMetaBlocks.ZERG_FLESH.getDefaultState(), 2);
		world.setBlockState(pos.add(7, 1, 8), ModMetaBlocks.ZERG_FLESH.getDefaultState(), 2);
		world.setBlockState(pos.add(15, 1, 8), ModMetaBlocks.ZERG_FLESH.getDefaultState(), 2);
		world.setBlockState(pos.add(4, 1, 9), ModBlocks.KERATIN_CHUNK.getDefaultState(), 2);
		world.setBlockState(pos.add(5, 1, 9), ModMetaBlocks.ZERG_CARAPACE.getDefaultState(), 2);
		world.setBlockState(pos.add(6, 1, 9), ModMetaBlocks.ZERG_FLESH.getDefaultState(), 2);
		world.setBlockState(pos.add(7, 1, 9), ModMetaBlocks.ZERG_FLESH.getDefaultState(), 2);
		world.setBlockState(pos.add(11, 1, 9), ModMetaBlocks.ZERG_FLESH.getDefaultState(), 2);
		world.setBlockState(pos.add(12, 1, 9), ModMetaBlocks.ZERG_FLESH.getDefaultState(), 2);
		world.setBlockState(pos.add(13, 1, 9), ModMetaBlocks.ZERG_FLESH.getDefaultState(), 2);
		world.setBlockState(pos.add(16, 1, 9), ModMetaBlocks.ZERG_FLESH.getDefaultState(), 2);
		world.setBlockState(pos.add(5, 1, 10), ModMetaBlocks.ZERG_CARAPACE.getDefaultState(), 2);
		world.setBlockState(pos.add(6, 1, 10), ModMetaBlocks.ZERG_CARAPACE.getDefaultState(), 2);
		world.setBlockState(pos.add(10, 1, 10), ModMetaBlocks.ZERG_FLESH.getDefaultState(), 2);

		generate_r02(world, rand, pos);
		return true;

	}

	public boolean generate_r02(World world, Random rand, BlockPos pos) {

		world.setBlockState(pos.add(14, 1, 10), ModMetaBlocks.ZERG_FLESH.getDefaultState(), 2);
		world.setBlockState(pos.add(17, 1, 10), ModMetaBlocks.ZERG_FLESH.getDefaultState(), 2);
		world.setBlockState(pos.add(18, 1, 10), ModMetaBlocks.ZERG_CARAPACE.getDefaultState(), 2);
		world.setBlockState(pos.add(19, 1, 10), ModBlocks.KERATIN_CHUNK.getDefaultState(), 2);
		world.setBlockState(pos.add(3, 1, 11), ModBlocks.KERATIN_CHUNK.getDefaultState(), 2);
		world.setBlockState(pos.add(4, 1, 11), ModMetaBlocks.ZERG_CARAPACE.getDefaultState(), 2);
		world.setBlockState(pos.add(5, 1, 11), ModMetaBlocks.ZERG_CARAPACE.getDefaultState(), 2);
		world.setBlockState(pos.add(6, 1, 11), ModMetaBlocks.ZERG_CARAPACE.getDefaultState(), 2);
		world.setBlockState(pos.add(7, 1, 11), ModMetaBlocks.ZERG_FLESH.getDefaultState(), 2);
		world.setBlockState(pos.add(9, 1, 11), ModMetaBlocks.ZERG_FLESH.getDefaultState(), 2);
		world.setBlockState(pos.add(15, 1, 11), ModMetaBlocks.ZERG_FLESH.getDefaultState(), 2);
		world.setBlockState(pos.add(17, 1, 11), ModMetaBlocks.ZERG_FLESH.getDefaultState(), 2);
		world.setBlockState(pos.add(18, 1, 11), ModMetaBlocks.ZERG_CARAPACE.getDefaultState(), 2);
		world.setBlockState(pos.add(19, 1, 11), ModMetaBlocks.ZERG_CARAPACE.getDefaultState(), 2);
		world.setBlockState(pos.add(20, 1, 11), ModMetaBlocks.ZERG_CARAPACE.getDefaultState(), 2);
		world.setBlockState(pos.add(3, 1, 12), ModMetaBlocks.ZERG_CARAPACE.getDefaultState(), 2);
		world.setBlockState(pos.add(4, 1, 12), ModMetaBlocks.ZERG_CARAPACE.getDefaultState(), 2);
		world.setBlockState(pos.add(5, 1, 12), ModMetaBlocks.ZERG_FLESH.getDefaultState(), 2);
		world.setBlockState(pos.add(6, 1, 12), ModMetaBlocks.ZERG_FLESH.getDefaultState(), 2);
		world.setBlockState(pos.add(7, 1, 12), ModMetaBlocks.ZERG_FLESH.getDefaultState(), 2);
		world.setBlockState(pos.add(9, 1, 12), ModMetaBlocks.ZERG_FLESH.getDefaultState(), 2);
		world.setBlockState(pos.add(15, 1, 12), ModMetaBlocks.ZERG_FLESH.getDefaultState(), 2);
		world.setBlockState(pos.add(17, 1, 12), ModMetaBlocks.ZERG_FLESH.getDefaultState(), 2);
		world.setBlockState(pos.add(18, 1, 12), ModMetaBlocks.ZERG_FLESH.getDefaultState(), 2);
		world.setBlockState(pos.add(19, 1, 12), ModMetaBlocks.ZERG_FLESH.getDefaultState(), 2);
		world.setBlockState(pos.add(20, 1, 12), ModMetaBlocks.ZERG_CARAPACE.getDefaultState(), 2);
		world.setBlockState(pos.add(21, 1, 12), ModBlocks.KERATIN_CHUNK.getDefaultState(), 2);
		world.setBlockState(pos.add(3, 1, 13), ModBlocks.KERATIN_CHUNK.getDefaultState(), 2);
		world.setBlockState(pos.add(4, 1, 13), ModMetaBlocks.ZERG_CARAPACE.getDefaultState(), 2);
		world.setBlockState(pos.add(5, 1, 13), ModMetaBlocks.ZERG_FLESH.getDefaultState(), 2);
		world.setBlockState(pos.add(6, 1, 13), ModMetaBlocks.ZERG_FLESH.getDefaultState(), 2);
		world.setBlockState(pos.add(7, 1, 13), ModMetaBlocks.ZERG_FLESH.getDefaultState(), 2);
		world.setBlockState(pos.add(9, 1, 13), ModMetaBlocks.ZERG_FLESH.getDefaultState(), 2);
		world.setBlockState(pos.add(15, 1, 13), ModMetaBlocks.ZERG_FLESH.getDefaultState(), 2);
		world.setBlockState(pos.add(17, 1, 13), ModMetaBlocks.ZERG_FLESH.getDefaultState(), 2);
		world.setBlockState(pos.add(18, 1, 13), ModMetaBlocks.ZERG_FLESH.getDefaultState(), 2);
		world.setBlockState(pos.add(19, 1, 13), ModMetaBlocks.ZERG_FLESH.getDefaultState(), 2);
		world.setBlockState(pos.add(20, 1, 13), ModMetaBlocks.ZERG_CARAPACE.getDefaultState(), 2);
		world.setBlockState(pos.add(21, 1, 13), ModBlocks.KERATIN_CHUNK.getDefaultState(), 2);
		world.setBlockState(pos.add(4, 1, 14), ModBlocks.KERATIN_CHUNK.getDefaultState(), 2);
		world.setBlockState(pos.add(5, 1, 14), ModMetaBlocks.ZERG_CARAPACE.getDefaultState(), 2);
		world.setBlockState(pos.add(6, 1, 14), ModMetaBlocks.ZERG_CARAPACE.getDefaultState(), 2);
		world.setBlockState(pos.add(7, 1, 14), ModMetaBlocks.ZERG_FLESH.getDefaultState(), 2);
		world.setBlockState(pos.add(10, 1, 14), ModMetaBlocks.ZERG_FLESH.getDefaultState(), 2);
		world.setBlockState(pos.add(14, 1, 14), ModMetaBlocks.ZERG_FLESH.getDefaultState(), 2);
		world.setBlockState(pos.add(17, 1, 14), ModMetaBlocks.ZERG_FLESH.getDefaultState(), 2);
		world.setBlockState(pos.add(18, 1, 14), ModMetaBlocks.ZERG_CARAPACE.getDefaultState(), 2);
		world.setBlockState(pos.add(19, 1, 14), ModMetaBlocks.ZERG_CARAPACE.getDefaultState(), 2);
		world.setBlockState(pos.add(20, 1, 14), ModBlocks.KERATIN_CHUNK.getDefaultState(), 2);
		world.setBlockState(pos.add(8, 1, 15), ModMetaBlocks.ZERG_FLESH.getDefaultState(), 2);
		world.setBlockState(pos.add(11, 1, 15), ModMetaBlocks.ZERG_FLESH.getDefaultState(), 2);
		world.setBlockState(pos.add(12, 1, 15), ModMetaBlocks.ZERG_FLESH.getDefaultState(), 2);
		world.setBlockState(pos.add(13, 1, 15), ModMetaBlocks.ZERG_FLESH.getDefaultState(), 2);
		world.setBlockState(pos.add(16, 1, 15), ModMetaBlocks.ZERG_FLESH.getDefaultState(), 2);
		world.setBlockState(pos.add(18, 1, 15), ModMetaBlocks.ZERG_CARAPACE.getDefaultState(), 2);
		world.setBlockState(pos.add(19, 1, 15), ModMetaBlocks.ZERG_CARAPACE.getDefaultState(), 2);
		world.setBlockState(pos.add(7, 1, 16), ModMetaBlocks.ZERG_CARAPACE.getDefaultState(), 2);
		world.setBlockState(pos.add(8, 1, 16), ModMetaBlocks.ZERG_CARAPACE.getDefaultState(), 2);
		world.setBlockState(pos.add(9, 1, 16), ModMetaBlocks.ZERG_FLESH.getDefaultState(), 2);
		world.setBlockState(pos.add(15, 1, 16), ModMetaBlocks.ZERG_FLESH.getDefaultState(), 2);
		world.setBlockState(pos.add(6, 1, 17), ModMetaBlocks.ZERG_CARAPACE.getDefaultState(), 2);
		world.setBlockState(pos.add(7, 1, 17), ModMetaBlocks.ZERG_CARAPACE.getDefaultState(), 2);
		world.setBlockState(pos.add(8, 1, 17), ModMetaBlocks.ZERG_FLESH.getDefaultState(), 2);
		world.setBlockState(pos.add(9, 1, 17), ModMetaBlocks.ZERG_FLESH.getDefaultState(), 2);
		world.setBlockState(pos.add(10, 1, 17), ModMetaBlocks.ZERG_FLESH.getDefaultState(), 2);
		world.setBlockState(pos.add(11, 1, 17), ModMetaBlocks.ZERG_FLESH.getDefaultState(), 2);
		world.setBlockState(pos.add(12, 1, 17), ModMetaBlocks.ZERG_FLESH.getDefaultState(), 2);
		world.setBlockState(pos.add(13, 1, 17), ModMetaBlocks.ZERG_FLESH.getDefaultState(), 2);
		world.setBlockState(pos.add(14, 1, 17), ModMetaBlocks.ZERG_FLESH.getDefaultState(), 2);
		world.setBlockState(pos.add(15, 1, 17), ModMetaBlocks.ZERG_CARAPACE.getDefaultState(), 2);
		world.setBlockState(pos.add(16, 1, 17), ModMetaBlocks.ZERG_CARAPACE.getDefaultState(), 2);
		world.setBlockState(pos.add(6, 1, 18), ModMetaBlocks.ZERG_CARAPACE.getDefaultState(), 2);
		world.setBlockState(pos.add(7, 1, 18), ModMetaBlocks.ZERG_CARAPACE.getDefaultState(), 2);
		world.setBlockState(pos.add(8, 1, 18), ModMetaBlocks.ZERG_FLESH.getDefaultState(), 2);
		world.setBlockState(pos.add(9, 1, 18), ModMetaBlocks.ZERG_FLESH.getDefaultState(), 2);
		world.setBlockState(pos.add(10, 1, 18), ModMetaBlocks.ZERG_CARAPACE.getDefaultState(), 2);
		world.setBlockState(pos.add(11, 1, 18), ModMetaBlocks.ZERG_CARAPACE.getDefaultState(), 2);
		world.setBlockState(pos.add(12, 1, 18), ModMetaBlocks.ZERG_CARAPACE.getDefaultState(), 2);
		world.setBlockState(pos.add(13, 1, 18), ModMetaBlocks.ZERG_FLESH.getDefaultState(), 2);
		world.setBlockState(pos.add(14, 1, 18), ModMetaBlocks.ZERG_FLESH.getDefaultState(), 2);
		world.setBlockState(pos.add(15, 1, 18), ModMetaBlocks.ZERG_CARAPACE.getDefaultState(), 2);
		world.setBlockState(pos.add(16, 1, 18), ModMetaBlocks.ZERG_CARAPACE.getDefaultState(), 2);
		world.setBlockState(pos.add(6, 1, 19), ModBlocks.KERATIN_CHUNK.getDefaultState(), 2);
		world.setBlockState(pos.add(7, 1, 19), ModMetaBlocks.ZERG_CARAPACE.getDefaultState(), 2);
		world.setBlockState(pos.add(8, 1, 19), ModMetaBlocks.ZERG_CARAPACE.getDefaultState(), 2);
		world.setBlockState(pos.add(9, 1, 19), ModMetaBlocks.ZERG_CARAPACE.getDefaultState(), 2);
		world.setBlockState(pos.add(10, 1, 19), ModMetaBlocks.ZERG_CARAPACE.getDefaultState(), 2);
		world.setBlockState(pos.add(12, 1, 19), ModBlocks.KERATIN_CHUNK.getDefaultState(), 2);
		world.setBlockState(pos.add(13, 1, 19), ModMetaBlocks.ZERG_CARAPACE.getDefaultState(), 2);
		world.setBlockState(pos.add(14, 1, 19), ModMetaBlocks.ZERG_CARAPACE.getDefaultState(), 2);
		world.setBlockState(pos.add(15, 1, 19), ModBlocks.KERATIN_CHUNK.getDefaultState(), 2);
		world.setBlockState(pos.add(7, 1, 20), ModMetaBlocks.ZERG_CARAPACE.getDefaultState(), 2);
		world.setBlockState(pos.add(8, 1, 20), ModBlocks.KERATIN_CHUNK.getDefaultState(), 2);
		world.setBlockState(pos.add(9, 1, 20), ModBlocks.KERATIN_CHUNK.getDefaultState(), 2);
		world.setBlockState(pos.add(13, 1, 20), ModBlocks.KERATIN_CHUNK.getDefaultState(), 2);
		world.setBlockState(pos.add(14, 1, 20), ModBlocks.KERATIN_CHUNK.getDefaultState(), 2);
		world.setBlockState(pos.add(9, 2, 5), ModMetaBlocks.ZERG_FLESH.getDefaultState(), 2);
		world.setBlockState(pos.add(10, 2, 5), ModMetaBlocks.ZERG_FLESH.getDefaultState(), 2);
		world.setBlockState(pos.add(14, 2, 5), ModMetaBlocks.ZERG_CARAPACE.getDefaultState(), 2);
		world.setBlockState(pos.add(15, 2, 5), ModMetaBlocks.ZERG_CARAPACE.getDefaultState(), 2);
		world.setBlockState(pos.add(9, 2, 6), ModMetaBlocks.ZERG_FLESH.getDefaultState(), 2);
		world.setBlockState(pos.add(10, 2, 6), ModMetaBlocks.ZERG_FLESH.getDefaultState(), 2);
		world.setBlockState(pos.add(11, 2, 6), ModMetaBlocks.ZERG_FLESH.getDefaultState(), 2);
		world.setBlockState(pos.add(13, 2, 6), ModMetaBlocks.ZERG_CARAPACE.getDefaultState(), 2);
		world.setBlockState(pos.add(14, 2, 6), ModMetaBlocks.ZERG_FLESH.getDefaultState(), 2);
		world.setBlockState(pos.add(15, 2, 6), ModMetaBlocks.ZERG_FLESH.getDefaultState(), 2);
		world.setBlockState(pos.add(16, 2, 6), ModMetaBlocks.ZERG_CARAPACE.getDefaultState(), 2);
		world.setBlockState(pos.add(6, 2, 7), ModMetaBlocks.ZERG_CARAPACE.getDefaultState(), 2);
		world.setBlockState(pos.add(10, 2, 7), ModMetaBlocks.ZERG_FLESH.getDefaultState(), 2);
		world.setBlockState(pos.add(11, 2, 7), ModMetaBlocks.ZERG_FLESH.getDefaultState(), 2);
		world.setBlockState(pos.add(14, 2, 7), ModMetaBlocks.ZERG_FLESH.getDefaultState(), 2);
		world.setBlockState(pos.add(15, 2, 7), ModMetaBlocks.ZERG_FLESH.getDefaultState(), 2);
		world.setBlockState(pos.add(16, 2, 7), ModMetaBlocks.ZERG_CARAPACE.getDefaultState(), 2);
		world.setBlockState(pos.add(5, 2, 8), ModMetaBlocks.ZERG_CARAPACE.getDefaultState(), 2);
		world.setBlockState(pos.add(6, 2, 8), ModMetaBlocks.ZERG_FLESH.getDefaultState(), 2);
		world.setBlockState(pos.add(7, 2, 8), ModMetaBlocks.ZERG_FLESH.getDefaultState(), 2);
		world.setBlockState(pos.add(5, 2, 9), ModMetaBlocks.ZERG_CARAPACE.getDefaultState(), 2);
		world.setBlockState(pos.add(6, 2, 9), ModMetaBlocks.ZERG_FLESH.getDefaultState(), 2);
		world.setBlockState(pos.add(7, 2, 9), ModMetaBlocks.ZERG_FLESH.getDefaultState(), 2);
		world.setBlockState(pos.add(4, 2, 11), ModMetaBlocks.ZERG_CARAPACE.getDefaultState(), 2);
		world.setBlockState(pos.add(5, 2, 11), ModMetaBlocks.ZERG_CARAPACE.getDefaultState(), 2);
		world.setBlockState(pos.add(6, 2, 11), ModMetaBlocks.ZERG_CARAPACE.getDefaultState(), 2);
		world.setBlockState(pos.add(18, 2, 11), ModMetaBlocks.ZERG_CARAPACE.getDefaultState(), 2);
		world.setBlockState(pos.add(19, 2, 11), ModMetaBlocks.ZERG_CARAPACE.getDefaultState(), 2);
		world.setBlockState(pos.add(4, 2, 12), ModMetaBlocks.ZERG_CARAPACE.getDefaultState(), 2);
		world.setBlockState(pos.add(5, 2, 12), ModMetaBlocks.ZERG_FLESH.getDefaultState(), 2);
		world.setBlockState(pos.add(6, 2, 12), ModMetaBlocks.ZERG_FLESH.getDefaultState(), 2);
		world.setBlockState(pos.add(18, 2, 12), ModMetaBlocks.ZERG_FLESH.getDefaultState(), 2);
		world.setBlockState(pos.add(19, 2, 12), ModMetaBlocks.ZERG_FLESH.getDefaultState(), 2);
		world.setBlockState(pos.add(20, 2, 12), ModMetaBlocks.ZERG_CARAPACE.getDefaultState(), 2);
		world.setBlockState(pos.add(4, 2, 13), ModMetaBlocks.ZERG_CARAPACE.getDefaultState(), 2);
		world.setBlockState(pos.add(5, 2, 13), ModMetaBlocks.ZERG_FLESH.getDefaultState(), 2);
		world.setBlockState(pos.add(6, 2, 13), ModMetaBlocks.ZERG_FLESH.getDefaultState(), 2);
		world.setBlockState(pos.add(18, 2, 13), ModMetaBlocks.ZERG_FLESH.getDefaultState(), 2);
		world.setBlockState(pos.add(19, 2, 13), ModMetaBlocks.ZERG_FLESH.getDefaultState(), 2);
		world.setBlockState(pos.add(20, 2, 13), ModMetaBlocks.ZERG_CARAPACE.getDefaultState(), 2);
		world.setBlockState(pos.add(5, 2, 14), ModMetaBlocks.ZERG_CARAPACE.getDefaultState(), 2);
		world.setBlockState(pos.add(6, 2, 14), ModMetaBlocks.ZERG_CARAPACE.getDefaultState(), 2);
		world.setBlockState(pos.add(18, 2, 14), ModMetaBlocks.ZERG_CARAPACE.getDefaultState(), 2);
		world.setBlockState(pos.add(19, 2, 14), ModMetaBlocks.ZERG_CARAPACE.getDefaultState(), 2);
		world.setBlockState(pos.add(7, 2, 17), ModMetaBlocks.ZERG_CARAPACE.getDefaultState(), 2);
		world.setBlockState(pos.add(8, 2, 17), ModMetaBlocks.ZERG_FLESH.getDefaultState(), 2);
		world.setBlockState(pos.add(9, 2, 17), ModMetaBlocks.ZERG_FLESH.getDefaultState(), 2);
		world.setBlockState(pos.add(10, 2, 17), ModMetaBlocks.ZERG_CARAPACE.getDefaultState(), 2);
		world.setBlockState(pos.add(13, 2, 17), ModMetaBlocks.ZERG_FLESH.getDefaultState(), 2);
		world.setBlockState(pos.add(14, 2, 17), ModMetaBlocks.ZERG_FLESH.getDefaultState(), 2);
		world.setBlockState(pos.add(15, 2, 17), ModMetaBlocks.ZERG_CARAPACE.getDefaultState(), 2);
		world.setBlockState(pos.add(7, 2, 18), ModMetaBlocks.ZERG_CARAPACE.getDefaultState(), 2);
		world.setBlockState(pos.add(8, 2, 18), ModMetaBlocks.ZERG_FLESH.getDefaultState(), 2);
		world.setBlockState(pos.add(9, 2, 18), ModMetaBlocks.ZERG_FLESH.getDefaultState(), 2);
		world.setBlockState(pos.add(10, 2, 18), ModMetaBlocks.ZERG_CARAPACE.getDefaultState(), 2);
		world.setBlockState(pos.add(12, 2, 18), ModMetaBlocks.ZERG_CARAPACE.getDefaultState(), 2);
		world.setBlockState(pos.add(13, 2, 18), ModMetaBlocks.ZERG_FLESH.getDefaultState(), 2);
		world.setBlockState(pos.add(14, 2, 18), ModMetaBlocks.ZERG_FLESH.getDefaultState(), 2);
		world.setBlockState(pos.add(15, 2, 18), ModMetaBlocks.ZERG_CARAPACE.getDefaultState(), 2);
		world.setBlockState(pos.add(8, 2, 19), ModMetaBlocks.ZERG_CARAPACE.getDefaultState(), 2);
		world.setBlockState(pos.add(9, 2, 19), ModMetaBlocks.ZERG_CARAPACE.getDefaultState(), 2);
		world.setBlockState(pos.add(13, 2, 19), ModMetaBlocks.ZERG_CARAPACE.getDefaultState(), 2);
		world.setBlockState(pos.add(14, 2, 19), ModMetaBlocks.ZERG_CARAPACE.getDefaultState(), 2);
		world.setBlockState(pos.add(9, 3, 5), ModMetaBlocks.ZERG_FLESH.getDefaultState(), 2);
		world.setBlockState(pos.add(10, 3, 5), ModMetaBlocks.ZERG_FLESH.getDefaultState(), 2);
		world.setBlockState(pos.add(9, 3, 6), ModMetaBlocks.ZERG_FLESH.getDefaultState(), 2);
		world.setBlockState(pos.add(10, 3, 6), ModMetaBlocks.ZERG_FLESH.getDefaultState(), 2);
		world.setBlockState(pos.add(11, 3, 6), ModMetaBlocks.ZERG_FLESH.getDefaultState(), 2);
		world.setBlockState(pos.add(14, 3, 6), ModMetaBlocks.ZERG_FLESH.getDefaultState(), 2);
		world.setBlockState(pos.add(15, 3, 6), ModMetaBlocks.ZERG_FLESH.getDefaultState(), 2);
		world.setBlockState(pos.add(10, 3, 7), ModMetaBlocks.ZERG_FLESH.getDefaultState(), 2);
		world.setBlockState(pos.add(11, 3, 7), ModMetaBlocks.ZERG_FLESH.getDefaultState(), 2);
		world.setBlockState(pos.add(14, 3, 7), ModMetaBlocks.ZERG_FLESH.getDefaultState(), 2);
		world.setBlockState(pos.add(15, 3, 7), ModMetaBlocks.ZERG_FLESH.getDefaultState(), 2);
		world.setBlockState(pos.add(6, 3, 8), ModMetaBlocks.ZERG_FLESH.getDefaultState(), 2);
		world.setBlockState(pos.add(7, 3, 8), ModMetaBlocks.ZERG_FLESH.getDefaultState(), 2);
		world.setBlockState(pos.add(6, 3, 9), ModMetaBlocks.ZERG_FLESH.getDefaultState(), 2);
		world.setBlockState(pos.add(7, 3, 9), ModMetaBlocks.ZERG_FLESH.getDefaultState(), 2);
		world.setBlockState(pos.add(4, 3, 12), ModMetaBlocks.ZERG_CARAPACE.getDefaultState(), 2);
		world.setBlockState(pos.add(5, 3, 12), ModMetaBlocks.ZERG_FLESH.getDefaultState(), 2);
		world.setBlockState(pos.add(6, 3, 12), ModMetaBlocks.ZERG_FLESH.getDefaultState(), 2);
		world.setBlockState(pos.add(18, 3, 12), ModMetaBlocks.ZERG_FLESH.getDefaultState(), 2);
		world.setBlockState(pos.add(19, 3, 12), ModMetaBlocks.ZERG_FLESH.getDefaultState(), 2);
		world.setBlockState(pos.add(4, 3, 13), ModMetaBlocks.ZERG_CARAPACE.getDefaultState(), 2);
		world.setBlockState(pos.add(5, 3, 13), ModMetaBlocks.ZERG_FLESH.getDefaultState(), 2);
		world.setBlockState(pos.add(6, 3, 13), ModMetaBlocks.ZERG_FLESH.getDefaultState(), 2);
		world.setBlockState(pos.add(18, 3, 13), ModMetaBlocks.ZERG_FLESH.getDefaultState(), 2);
		world.setBlockState(pos.add(19, 3, 13), ModMetaBlocks.ZERG_FLESH.getDefaultState(), 2);
		world.setBlockState(pos.add(5, 3, 14), ModMetaBlocks.ZERG_CARAPACE.getDefaultState(), 2);
		world.setBlockState(pos.add(6, 3, 14), ModMetaBlocks.ZERG_CARAPACE.getDefaultState(), 2);
		world.setBlockState(pos.add(8, 3, 17), ModMetaBlocks.ZERG_FLESH.getDefaultState(), 2);
		world.setBlockState(pos.add(9, 3, 17), ModMetaBlocks.ZERG_FLESH.getDefaultState(), 2);
		world.setBlockState(pos.add(13, 3, 17), ModMetaBlocks.ZERG_FLESH.getDefaultState(), 2);
		world.setBlockState(pos.add(14, 3, 17), ModMetaBlocks.ZERG_FLESH.getDefaultState(), 2);
		world.setBlockState(pos.add(8, 3, 18), ModMetaBlocks.ZERG_FLESH.getDefaultState(), 2);
		world.setBlockState(pos.add(9, 3, 18), ModMetaBlocks.ZERG_FLESH.getDefaultState(), 2);
		world.setBlockState(pos.add(13, 3, 18), ModMetaBlocks.ZERG_FLESH.getDefaultState(), 2);
		world.setBlockState(pos.add(14, 3, 18), ModMetaBlocks.ZERG_FLESH.getDefaultState(), 2);

		generate_r03(world, rand, pos);
		return true;

	}

	public boolean generate_r03(World world, Random rand, BlockPos pos) {

		world.setBlockState(pos.add(9, 4, 5), ModMetaBlocks.ZERG_FLESH.getDefaultState(), 2);
		world.setBlockState(pos.add(10, 4, 5), ModMetaBlocks.ZERG_FLESH.getDefaultState(), 2);
		world.setBlockState(pos.add(9, 4, 6), ModMetaBlocks.ZERG_FLESH.getDefaultState(), 2);
		world.setBlockState(pos.add(10, 4, 6), ModMetaBlocks.ZERG_FLESH.getDefaultState(), 2);
		world.setBlockState(pos.add(14, 4, 6), ModMetaBlocks.ZERG_FLESH.getDefaultState(), 2);
		world.setBlockState(pos.add(15, 4, 6), ModMetaBlocks.ZERG_FLESH.getDefaultState(), 2);
		world.setBlockState(pos.add(14, 4, 7), ModMetaBlocks.ZERG_FLESH.getDefaultState(), 2);
		world.setBlockState(pos.add(15, 4, 7), ModMetaBlocks.ZERG_FLESH.getDefaultState(), 2);
		world.setBlockState(pos.add(6, 4, 8), ModMetaBlocks.ZERG_FLESH.getDefaultState(), 2);
		world.setBlockState(pos.add(7, 4, 8), ModMetaBlocks.ZERG_FLESH.getDefaultState(), 2);
		world.setBlockState(pos.add(6, 4, 9), ModMetaBlocks.ZERG_FLESH.getDefaultState(), 2);
		world.setBlockState(pos.add(7, 4, 9), ModMetaBlocks.ZERG_FLESH.getDefaultState(), 2);
		world.setBlockState(pos.add(5, 4, 12), ModMetaBlocks.ZERG_FLESH.getDefaultState(), 2);
		world.setBlockState(pos.add(6, 4, 12), ModMetaBlocks.ZERG_FLESH.getDefaultState(), 2);
		world.setBlockState(pos.add(18, 4, 12), ModMetaBlocks.ZERG_FLESH.getDefaultState(), 2);
		world.setBlockState(pos.add(19, 4, 12), ModMetaBlocks.ZERG_FLESH.getDefaultState(), 2);
		world.setBlockState(pos.add(4, 4, 13), ModMetaBlocks.ZERG_CARAPACE.getDefaultState(), 2);
		world.setBlockState(pos.add(5, 4, 13), ModMetaBlocks.ZERG_FLESH.getDefaultState(), 2);
		world.setBlockState(pos.add(6, 4, 13), ModMetaBlocks.ZERG_FLESH.getDefaultState(), 2);
		world.setBlockState(pos.add(18, 4, 13), ModMetaBlocks.ZERG_FLESH.getDefaultState(), 2);
		world.setBlockState(pos.add(19, 4, 13), ModMetaBlocks.ZERG_FLESH.getDefaultState(), 2);
		world.setBlockState(pos.add(5, 4, 14), ModMetaBlocks.ZERG_CARAPACE.getDefaultState(), 2);
		world.setBlockState(pos.add(8, 4, 17), ModMetaBlocks.ZERG_FLESH.getDefaultState(), 2);
		world.setBlockState(pos.add(9, 4, 17), ModMetaBlocks.ZERG_FLESH.getDefaultState(), 2);
		world.setBlockState(pos.add(13, 4, 17), ModMetaBlocks.ZERG_FLESH.getDefaultState(), 2);
		world.setBlockState(pos.add(14, 4, 17), ModMetaBlocks.ZERG_FLESH.getDefaultState(), 2);
		world.setBlockState(pos.add(8, 4, 18), ModMetaBlocks.ZERG_FLESH.getDefaultState(), 2);
		world.setBlockState(pos.add(9, 4, 18), ModMetaBlocks.ZERG_FLESH.getDefaultState(), 2);
		world.setBlockState(pos.add(13, 4, 18), ModMetaBlocks.ZERG_FLESH.getDefaultState(), 2);
		world.setBlockState(pos.add(14, 4, 18), ModMetaBlocks.ZERG_FLESH.getDefaultState(), 2);
		world.setBlockState(pos.add(8, 5, 4), ModMetaBlocks.ZERG_FLESH.getDefaultState(), 2);
		world.setBlockState(pos.add(9, 5, 4), ModMetaBlocks.ZERG_FLESH.getDefaultState(), 2);
		world.setBlockState(pos.add(8, 5, 5), ModMetaBlocks.ZERG_FLESH.getDefaultState(), 2);
		world.setBlockState(pos.add(9, 5, 5), ModMetaBlocks.ZERG_FLESH.getDefaultState(), 2);
		world.setBlockState(pos.add(10, 5, 5), ModMetaBlocks.ZERG_FLESH.getDefaultState(), 2);
		world.setBlockState(pos.add(9, 5, 6), ModMetaBlocks.ZERG_FLESH.getDefaultState(), 2);
		world.setBlockState(pos.add(10, 5, 6), ModMetaBlocks.ZERG_FLESH.getDefaultState(), 2);
		world.setBlockState(pos.add(14, 5, 6), ModMetaBlocks.ZERG_FLESH.getDefaultState(), 2);
		world.setBlockState(pos.add(15, 5, 6), ModMetaBlocks.ZERG_FLESH.getDefaultState(), 2);
		world.setBlockState(pos.add(14, 5, 7), ModMetaBlocks.ZERG_FLESH.getDefaultState(), 2);
		world.setBlockState(pos.add(15, 5, 7), ModMetaBlocks.ZERG_FLESH.getDefaultState(), 2);
		world.setBlockState(pos.add(6, 5, 8), ModMetaBlocks.ZERG_FLESH.getDefaultState(), 2);
		world.setBlockState(pos.add(7, 5, 8), ModMetaBlocks.ZERG_FLESH.getDefaultState(), 2);
		world.setBlockState(pos.add(6, 5, 9), ModMetaBlocks.ZERG_FLESH.getDefaultState(), 2);
		world.setBlockState(pos.add(7, 5, 9), ModMetaBlocks.ZERG_FLESH.getDefaultState(), 2);
		world.setBlockState(pos.add(5, 5, 12), ModMetaBlocks.ZERG_FLESH.getDefaultState(), 2);
		world.setBlockState(pos.add(6, 5, 12), ModMetaBlocks.ZERG_FLESH.getDefaultState(), 2);
		world.setBlockState(pos.add(18, 5, 12), ModMetaBlocks.ZERG_FLESH.getDefaultState(), 2);
		world.setBlockState(pos.add(19, 5, 12), ModMetaBlocks.ZERG_FLESH.getDefaultState(), 2);
		world.setBlockState(pos.add(5, 5, 13), ModMetaBlocks.ZERG_FLESH.getDefaultState(), 2);
		world.setBlockState(pos.add(6, 5, 13), ModMetaBlocks.ZERG_FLESH.getDefaultState(), 2);
		world.setBlockState(pos.add(18, 5, 13), ModMetaBlocks.ZERG_FLESH.getDefaultState(), 2);
		world.setBlockState(pos.add(19, 5, 13), ModMetaBlocks.ZERG_FLESH.getDefaultState(), 2);
		world.setBlockState(pos.add(8, 5, 17), ModMetaBlocks.ZERG_FLESH.getDefaultState(), 2);
		world.setBlockState(pos.add(9, 5, 17), ModMetaBlocks.ZERG_FLESH.getDefaultState(), 2);
		world.setBlockState(pos.add(13, 5, 17), ModMetaBlocks.ZERG_FLESH.getDefaultState(), 2);
		world.setBlockState(pos.add(14, 5, 17), ModMetaBlocks.ZERG_FLESH.getDefaultState(), 2);
		world.setBlockState(pos.add(8, 5, 18), ModMetaBlocks.ZERG_FLESH.getDefaultState(), 2);
		world.setBlockState(pos.add(9, 5, 18), ModMetaBlocks.ZERG_FLESH.getDefaultState(), 2);
		world.setBlockState(pos.add(13, 5, 18), ModMetaBlocks.ZERG_FLESH.getDefaultState(), 2);
		world.setBlockState(pos.add(14, 5, 18), ModMetaBlocks.ZERG_FLESH.getDefaultState(), 2);
		world.setBlockState(pos.add(8, 6, 4), ModMetaBlocks.ZERG_FLESH.getDefaultState(), 2);
		world.setBlockState(pos.add(9, 6, 4), ModMetaBlocks.ZERG_FLESH.getDefaultState(), 2);
		world.setBlockState(pos.add(8, 6, 5), ModMetaBlocks.ZERG_FLESH.getDefaultState(), 2);
		world.setBlockState(pos.add(9, 6, 5), ModMetaBlocks.ZERG_FLESH.getDefaultState(), 2);
		world.setBlockState(pos.add(10, 6, 5), ModMetaBlocks.ZERG_FLESH.getDefaultState(), 2);

		generate_r04(world, rand, pos);
		return true;

	}

	public boolean generate_r04(World world, Random rand, BlockPos pos) {

		world.setBlockState(pos.add(9, 6, 6), ModMetaBlocks.ZERG_FLESH.getDefaultState(), 2);
		world.setBlockState(pos.add(10, 6, 6), ModMetaBlocks.ZERG_FLESH.getDefaultState(), 2);
		world.setBlockState(pos.add(14, 6, 6), ModMetaBlocks.ZERG_FLESH.getDefaultState(), 2);
		world.setBlockState(pos.add(15, 6, 6), ModMetaBlocks.ZERG_FLESH.getDefaultState(), 2);
		world.setBlockState(pos.add(14, 6, 7), ModMetaBlocks.ZERG_FLESH.getDefaultState(), 2);
		world.setBlockState(pos.add(15, 6, 7), ModMetaBlocks.ZERG_FLESH.getDefaultState(), 2);
		world.setBlockState(pos.add(6, 6, 8), ModMetaBlocks.ZERG_FLESH.getDefaultState(), 2);
		world.setBlockState(pos.add(7, 6, 8), ModMetaBlocks.ZERG_FLESH.getDefaultState(), 2);
		world.setBlockState(pos.add(6, 6, 9), ModMetaBlocks.ZERG_FLESH.getDefaultState(), 2);
		world.setBlockState(pos.add(7, 6, 9), ModMetaBlocks.ZERG_FLESH.getDefaultState(), 2);
		world.setBlockState(pos.add(5, 6, 12), ModMetaBlocks.ZERG_FLESH.getDefaultState(), 2);
		world.setBlockState(pos.add(6, 6, 12), ModMetaBlocks.ZERG_FLESH.getDefaultState(), 2);
		world.setBlockState(pos.add(18, 6, 12), ModMetaBlocks.ZERG_FLESH.getDefaultState(), 2);
		world.setBlockState(pos.add(19, 6, 12), ModMetaBlocks.ZERG_FLESH.getDefaultState(), 2);
		world.setBlockState(pos.add(5, 6, 13), ModMetaBlocks.ZERG_FLESH.getDefaultState(), 2);
		world.setBlockState(pos.add(6, 6, 13), ModMetaBlocks.ZERG_FLESH.getDefaultState(), 2);
		world.setBlockState(pos.add(18, 6, 13), ModMetaBlocks.ZERG_FLESH.getDefaultState(), 2);
		world.setBlockState(pos.add(19, 6, 13), ModMetaBlocks.ZERG_FLESH.getDefaultState(), 2);
		world.setBlockState(pos.add(8, 6, 17), ModMetaBlocks.ZERG_FLESH.getDefaultState(), 2);
		world.setBlockState(pos.add(9, 6, 17), ModMetaBlocks.ZERG_FLESH.getDefaultState(), 2);
		world.setBlockState(pos.add(13, 6, 17), ModMetaBlocks.ZERG_FLESH.getDefaultState(), 2);
		world.setBlockState(pos.add(14, 6, 17), ModMetaBlocks.ZERG_FLESH.getDefaultState(), 2);
		world.setBlockState(pos.add(8, 6, 18), ModMetaBlocks.ZERG_FLESH.getDefaultState(), 2);
		world.setBlockState(pos.add(9, 6, 18), ModMetaBlocks.ZERG_FLESH.getDefaultState(), 2);
		world.setBlockState(pos.add(13, 6, 18), ModMetaBlocks.ZERG_FLESH.getDefaultState(), 2);
		world.setBlockState(pos.add(14, 6, 18), ModMetaBlocks.ZERG_FLESH.getDefaultState(), 2);
		world.setBlockState(pos.add(8, 7, 4), ModMetaBlocks.ZERG_FLESH.getDefaultState(), 2);
		world.setBlockState(pos.add(9, 7, 4), ModMetaBlocks.ZERG_FLESH.getDefaultState(), 2);
		world.setBlockState(pos.add(8, 7, 5), ModMetaBlocks.ZERG_FLESH.getDefaultState(), 2);
		world.setBlockState(pos.add(9, 7, 5), ModMetaBlocks.ZERG_FLESH.getDefaultState(), 2);
		world.setBlockState(pos.add(10, 7, 5), ModMetaBlocks.ZERG_FLESH.getDefaultState(), 2);
		world.setBlockState(pos.add(9, 7, 6), ModMetaBlocks.ZERG_FLESH.getDefaultState(), 2);
		world.setBlockState(pos.add(10, 7, 6), ModMetaBlocks.ZERG_FLESH.getDefaultState(), 2);
		world.setBlockState(pos.add(14, 7, 6), ModMetaBlocks.ZERG_FLESH.getDefaultState(), 2);
		world.setBlockState(pos.add(15, 7, 6), ModMetaBlocks.ZERG_FLESH.getDefaultState(), 2);
		world.setBlockState(pos.add(14, 7, 7), ModMetaBlocks.ZERG_FLESH.getDefaultState(), 2);
		world.setBlockState(pos.add(15, 7, 7), ModMetaBlocks.ZERG_FLESH.getDefaultState(), 2);
		world.setBlockState(pos.add(6, 7, 8), ModMetaBlocks.ZERG_FLESH.getDefaultState(), 2);
		world.setBlockState(pos.add(7, 7, 8), ModMetaBlocks.ZERG_FLESH.getDefaultState(), 2);
		world.setBlockState(pos.add(6, 7, 9), ModMetaBlocks.ZERG_FLESH.getDefaultState(), 2);
		world.setBlockState(pos.add(7, 7, 9), ModMetaBlocks.ZERG_FLESH.getDefaultState(), 2);
		world.setBlockState(pos.add(5, 7, 12), ModMetaBlocks.ZERG_FLESH.getDefaultState(), 2);
		world.setBlockState(pos.add(6, 7, 12), ModMetaBlocks.ZERG_FLESH.getDefaultState(), 2);
		world.setBlockState(pos.add(18, 7, 12), ModMetaBlocks.ZERG_FLESH.getDefaultState(), 2);
		world.setBlockState(pos.add(19, 7, 12), ModMetaBlocks.ZERG_FLESH.getDefaultState(), 2);
		world.setBlockState(pos.add(5, 7, 13), ModMetaBlocks.ZERG_FLESH.getDefaultState(), 2);
		world.setBlockState(pos.add(6, 7, 13), ModMetaBlocks.ZERG_FLESH.getDefaultState(), 2);
		world.setBlockState(pos.add(18, 7, 13), ModMetaBlocks.ZERG_FLESH.getDefaultState(), 2);
		world.setBlockState(pos.add(19, 7, 13), ModMetaBlocks.ZERG_FLESH.getDefaultState(), 2);
		world.setBlockState(pos.add(8, 7, 17), ModMetaBlocks.ZERG_FLESH.getDefaultState(), 2);
		world.setBlockState(pos.add(9, 7, 17), ModMetaBlocks.ZERG_FLESH.getDefaultState(), 2);
		world.setBlockState(pos.add(13, 7, 17), ModMetaBlocks.ZERG_FLESH.getDefaultState(), 2);
		world.setBlockState(pos.add(14, 7, 17), ModMetaBlocks.ZERG_FLESH.getDefaultState(), 2);
		world.setBlockState(pos.add(8, 7, 18), ModMetaBlocks.ZERG_FLESH.getDefaultState(), 2);
		world.setBlockState(pos.add(9, 7, 18), ModMetaBlocks.ZERG_FLESH.getDefaultState(), 2);
		world.setBlockState(pos.add(13, 7, 18), ModMetaBlocks.ZERG_FLESH.getDefaultState(), 2);
		world.setBlockState(pos.add(14, 7, 18), ModMetaBlocks.ZERG_FLESH.getDefaultState(), 2);
		world.setBlockState(pos.add(8, 8, 4), ModMetaBlocks.ZERG_FLESH.getDefaultState(), 2);
		world.setBlockState(pos.add(9, 8, 4), ModMetaBlocks.ZERG_FLESH.getDefaultState(), 2);
		world.setBlockState(pos.add(8, 8, 5), ModMetaBlocks.ZERG_FLESH.getDefaultState(), 2);
		world.setBlockState(pos.add(9, 8, 5), ModMetaBlocks.ZERG_FLESH.getDefaultState(), 2);
		world.setBlockState(pos.add(10, 8, 5), ModMetaBlocks.ZERG_FLESH.getDefaultState(), 2);
		world.setBlockState(pos.add(9, 8, 6), ModMetaBlocks.ZERG_FLESH.getDefaultState(), 2);
		world.setBlockState(pos.add(10, 8, 6), ModMetaBlocks.ZERG_FLESH.getDefaultState(), 2);
		world.setBlockState(pos.add(14, 8, 6), ModMetaBlocks.ZERG_FLESH.getDefaultState(), 2);
		world.setBlockState(pos.add(15, 8, 6), ModMetaBlocks.ZERG_FLESH.getDefaultState(), 2);
		world.setBlockState(pos.add(14, 8, 7), ModMetaBlocks.ZERG_FLESH.getDefaultState(), 2);
		world.setBlockState(pos.add(15, 8, 7), ModMetaBlocks.ZERG_FLESH.getDefaultState(), 2);
		world.setBlockState(pos.add(6, 8, 8), ModMetaBlocks.ZERG_FLESH.getDefaultState(), 2);
		world.setBlockState(pos.add(7, 8, 8), ModMetaBlocks.ZERG_FLESH.getDefaultState(), 2);
		world.setBlockState(pos.add(6, 8, 9), ModMetaBlocks.ZERG_FLESH.getDefaultState(), 2);
		world.setBlockState(pos.add(7, 8, 9), ModMetaBlocks.ZERG_FLESH.getDefaultState(), 2);
		world.setBlockState(pos.add(5, 8, 12), ModMetaBlocks.ZERG_FLESH.getDefaultState(), 2);
		world.setBlockState(pos.add(6, 8, 12), ModMetaBlocks.ZERG_FLESH.getDefaultState(), 2);
		world.setBlockState(pos.add(18, 8, 12), ModMetaBlocks.ZERG_FLESH.getDefaultState(), 2);
		world.setBlockState(pos.add(19, 8, 12), ModMetaBlocks.ZERG_FLESH.getDefaultState(), 2);
		world.setBlockState(pos.add(5, 8, 13), ModMetaBlocks.ZERG_FLESH.getDefaultState(), 2);
		world.setBlockState(pos.add(6, 8, 13), ModMetaBlocks.ZERG_FLESH.getDefaultState(), 2);
		world.setBlockState(pos.add(18, 8, 13), ModMetaBlocks.ZERG_FLESH.getDefaultState(), 2);
		world.setBlockState(pos.add(19, 8, 13), ModMetaBlocks.ZERG_FLESH.getDefaultState(), 2);

		generate_r05(world, rand, pos);
		return true;

	}

	public boolean generate_r05(World world, Random rand, BlockPos pos) {

		world.setBlockState(pos.add(8, 8, 17), ModMetaBlocks.ZERG_FLESH.getDefaultState(), 2);
		world.setBlockState(pos.add(9, 8, 17), ModMetaBlocks.ZERG_FLESH.getDefaultState(), 2);
		world.setBlockState(pos.add(13, 8, 17), ModMetaBlocks.ZERG_FLESH.getDefaultState(), 2);
		world.setBlockState(pos.add(14, 8, 17), ModMetaBlocks.ZERG_FLESH.getDefaultState(), 2);
		world.setBlockState(pos.add(8, 8, 18), ModMetaBlocks.ZERG_FLESH.getDefaultState(), 2);
		world.setBlockState(pos.add(9, 8, 18), ModMetaBlocks.ZERG_FLESH.getDefaultState(), 2);
		world.setBlockState(pos.add(13, 8, 18), ModMetaBlocks.ZERG_FLESH.getDefaultState(), 2);
		world.setBlockState(pos.add(14, 8, 18), ModMetaBlocks.ZERG_FLESH.getDefaultState(), 2);
		world.setBlockState(pos.add(8, 9, 4), ModMetaBlocks.ZERG_FLESH.getDefaultState(), 2);
		world.setBlockState(pos.add(9, 9, 4), ModMetaBlocks.ZERG_FLESH.getDefaultState(), 2);
		world.setBlockState(pos.add(8, 9, 5), ModMetaBlocks.ZERG_FLESH.getDefaultState(), 2);
		world.setBlockState(pos.add(9, 9, 5), ModMetaBlocks.ZERG_FLESH.getDefaultState(), 2);
		world.setBlockState(pos.add(10, 9, 5), ModMetaBlocks.ZERG_FLESH.getDefaultState(), 2);
		world.setBlockState(pos.add(9, 9, 6), ModMetaBlocks.ZERG_FLESH.getDefaultState(), 2);
		world.setBlockState(pos.add(10, 9, 6), ModMetaBlocks.ZERG_FLESH.getDefaultState(), 2);
		world.setBlockState(pos.add(14, 9, 6), ModMetaBlocks.ZERG_FLESH.getDefaultState(), 2);
		world.setBlockState(pos.add(15, 9, 6), ModMetaBlocks.ZERG_FLESH.getDefaultState(), 2);
		world.setBlockState(pos.add(14, 9, 7), ModMetaBlocks.ZERG_FLESH.getDefaultState(), 2);
		world.setBlockState(pos.add(15, 9, 7), ModMetaBlocks.ZERG_FLESH.getDefaultState(), 2);
		world.setBlockState(pos.add(6, 9, 8), ModMetaBlocks.ZERG_FLESH.getDefaultState(), 2);
		world.setBlockState(pos.add(7, 9, 8), ModMetaBlocks.ZERG_FLESH.getDefaultState(), 2);
		world.setBlockState(pos.add(6, 9, 9), ModMetaBlocks.ZERG_FLESH.getDefaultState(), 2);
		world.setBlockState(pos.add(7, 9, 9), ModMetaBlocks.ZERG_FLESH.getDefaultState(), 2);
		world.setBlockState(pos.add(18, 9, 11), ModMetaBlocks.ZERG_FLESH.getDefaultState(), 2);
		world.setBlockState(pos.add(5, 9, 12), ModMetaBlocks.ZERG_FLESH.getDefaultState(), 2);
		world.setBlockState(pos.add(6, 9, 12), ModMetaBlocks.ZERG_FLESH.getDefaultState(), 2);
		world.setBlockState(pos.add(17, 9, 12), ModMetaBlocks.ZERG_FLESH.getDefaultState(), 2);
		world.setBlockState(pos.add(18, 9, 12), ModMetaBlocks.ZERG_FLESH.getDefaultState(), 2);
		world.setBlockState(pos.add(19, 9, 12), ModMetaBlocks.ZERG_FLESH.getDefaultState(), 2);
		world.setBlockState(pos.add(5, 9, 13), ModMetaBlocks.ZERG_FLESH.getDefaultState(), 2);
		world.setBlockState(pos.add(6, 9, 13), ModMetaBlocks.ZERG_FLESH.getDefaultState(), 2);
		world.setBlockState(pos.add(18, 9, 13), ModMetaBlocks.ZERG_FLESH.getDefaultState(), 2);
		world.setBlockState(pos.add(19, 9, 13), ModMetaBlocks.ZERG_FLESH.getDefaultState(), 2);
		world.setBlockState(pos.add(8, 9, 17), ModMetaBlocks.ZERG_FLESH.getDefaultState(), 2);
		world.setBlockState(pos.add(9, 9, 17), ModMetaBlocks.ZERG_FLESH.getDefaultState(), 2);
		world.setBlockState(pos.add(13, 9, 17), ModMetaBlocks.ZERG_FLESH.getDefaultState(), 2);
		world.setBlockState(pos.add(14, 9, 17), ModMetaBlocks.ZERG_FLESH.getDefaultState(), 2);
		world.setBlockState(pos.add(8, 9, 18), ModMetaBlocks.ZERG_FLESH.getDefaultState(), 2);
		world.setBlockState(pos.add(9, 9, 18), ModMetaBlocks.ZERG_FLESH.getDefaultState(), 2);
		world.setBlockState(pos.add(13, 9, 18), ModMetaBlocks.ZERG_FLESH.getDefaultState(), 2);
		world.setBlockState(pos.add(14, 9, 18), ModMetaBlocks.ZERG_FLESH.getDefaultState(), 2);
		world.setBlockState(pos.add(8, 10, 4), ModMetaBlocks.ZERG_FLESH.getDefaultState(), 2);
		world.setBlockState(pos.add(9, 10, 4), ModMetaBlocks.ZERG_FLESH.getDefaultState(), 2);
		world.setBlockState(pos.add(8, 10, 5), ModMetaBlocks.ZERG_FLESH.getDefaultState(), 2);
		world.setBlockState(pos.add(9, 10, 5), ModMetaBlocks.ZERG_FLESH.getDefaultState(), 2);
		world.setBlockState(pos.add(14, 10, 6), ModMetaBlocks.ZERG_FLESH.getDefaultState(), 2);
		world.setBlockState(pos.add(15, 10, 6), ModMetaBlocks.ZERG_FLESH.getDefaultState(), 2);
		world.setBlockState(pos.add(14, 10, 7), ModMetaBlocks.ZERG_FLESH.getDefaultState(), 2);
		world.setBlockState(pos.add(15, 10, 7), ModMetaBlocks.ZERG_FLESH.getDefaultState(), 2);
		world.setBlockState(pos.add(6, 10, 8), ModMetaBlocks.ZERG_FLESH.getDefaultState(), 2);
		world.setBlockState(pos.add(7, 10, 8), ModMetaBlocks.ZERG_FLESH.getDefaultState(), 2);
		world.setBlockState(pos.add(6, 10, 9), ModMetaBlocks.ZERG_FLESH.getDefaultState(), 2);
		world.setBlockState(pos.add(7, 10, 9), ModMetaBlocks.ZERG_FLESH.getDefaultState(), 2);
		world.setBlockState(pos.add(17, 10, 11), ModMetaBlocks.ZERG_FLESH.getDefaultState(), 2);
		world.setBlockState(pos.add(18, 10, 11), ModMetaBlocks.ZERG_FLESH.getDefaultState(), 2);
		world.setBlockState(pos.add(5, 10, 12), ModMetaBlocks.ZERG_FLESH.getDefaultState(), 2);
		world.setBlockState(pos.add(6, 10, 12), ModMetaBlocks.ZERG_FLESH.getDefaultState(), 2);
		world.setBlockState(pos.add(17, 10, 12), ModMetaBlocks.ZERG_FLESH.getDefaultState(), 2);
		world.setBlockState(pos.add(18, 10, 12), ModMetaBlocks.ZERG_FLESH.getDefaultState(), 2);
		world.setBlockState(pos.add(19, 10, 12), ModMetaBlocks.ZERG_FLESH.getDefaultState(), 2);
		world.setBlockState(pos.add(5, 10, 13), ModMetaBlocks.ZERG_FLESH.getDefaultState(), 2);
		world.setBlockState(pos.add(6, 10, 13), ModMetaBlocks.ZERG_FLESH.getDefaultState(), 2);
		world.setBlockState(pos.add(18, 10, 13), ModMetaBlocks.ZERG_FLESH.getDefaultState(), 2);
		world.setBlockState(pos.add(19, 10, 13), ModMetaBlocks.ZERG_FLESH.getDefaultState(), 2);
		world.setBlockState(pos.add(8, 10, 17), ModMetaBlocks.ZERG_FLESH.getDefaultState(), 2);
		world.setBlockState(pos.add(9, 10, 17), ModMetaBlocks.ZERG_FLESH.getDefaultState(), 2);
		world.setBlockState(pos.add(13, 10, 17), ModMetaBlocks.ZERG_FLESH.getDefaultState(), 2);
		world.setBlockState(pos.add(14, 10, 17), ModMetaBlocks.ZERG_FLESH.getDefaultState(), 2);
		world.setBlockState(pos.add(8, 10, 18), ModMetaBlocks.ZERG_FLESH.getDefaultState(), 2);
		world.setBlockState(pos.add(9, 10, 18), ModMetaBlocks.ZERG_FLESH.getDefaultState(), 2);
		world.setBlockState(pos.add(13, 10, 18), ModMetaBlocks.ZERG_FLESH.getDefaultState(), 2);
		world.setBlockState(pos.add(14, 10, 18), ModMetaBlocks.ZERG_FLESH.getDefaultState(), 2);

		generate_r06(world, rand, pos);
		return true;

	}

	public boolean generate_r06(World world, Random rand, BlockPos pos) {

		world.setBlockState(pos.add(8, 11, 4), ModMetaBlocks.ZERG_FLESH.getDefaultState(), 2);
		world.setBlockState(pos.add(9, 11, 4), ModMetaBlocks.ZERG_FLESH.getDefaultState(), 2);
		world.setBlockState(pos.add(8, 11, 5), ModMetaBlocks.ZERG_FLESH.getDefaultState(), 2);
		world.setBlockState(pos.add(9, 11, 5), ModMetaBlocks.ZERG_FLESH.getDefaultState(), 2);
		world.setBlockState(pos.add(14, 11, 6), ModMetaBlocks.ZERG_FLESH.getDefaultState(), 2);
		world.setBlockState(pos.add(15, 11, 6), ModMetaBlocks.ZERG_FLESH.getDefaultState(), 2);
		world.setBlockState(pos.add(14, 11, 7), ModMetaBlocks.ZERG_FLESH.getDefaultState(), 2);
		world.setBlockState(pos.add(15, 11, 7), ModMetaBlocks.ZERG_FLESH.getDefaultState(), 2);
		world.setBlockState(pos.add(6, 11, 8), ModMetaBlocks.ZERG_FLESH.getDefaultState(), 2);
		world.setBlockState(pos.add(7, 11, 8), ModMetaBlocks.ZERG_FLESH.getDefaultState(), 2);
		world.setBlockState(pos.add(6, 11, 9), ModMetaBlocks.ZERG_FLESH.getDefaultState(), 2);
		world.setBlockState(pos.add(7, 11, 9), ModMetaBlocks.ZERG_FLESH.getDefaultState(), 2);
		world.setBlockState(pos.add(17, 11, 11), ModMetaBlocks.ZERG_FLESH.getDefaultState(), 2);
		world.setBlockState(pos.add(18, 11, 11), ModMetaBlocks.ZERG_FLESH.getDefaultState(), 2);
		world.setBlockState(pos.add(5, 11, 12), ModMetaBlocks.ZERG_FLESH.getDefaultState(), 2);
		world.setBlockState(pos.add(6, 11, 12), ModMetaBlocks.ZERG_FLESH.getDefaultState(), 2);
		world.setBlockState(pos.add(17, 11, 12), ModMetaBlocks.ZERG_FLESH.getDefaultState(), 2);
		world.setBlockState(pos.add(18, 11, 12), ModMetaBlocks.ZERG_FLESH.getDefaultState(), 2);
		world.setBlockState(pos.add(19, 11, 12), ModMetaBlocks.ZERG_FLESH.getDefaultState(), 2);
		world.setBlockState(pos.add(5, 11, 13), ModMetaBlocks.ZERG_FLESH.getDefaultState(), 2);
		world.setBlockState(pos.add(6, 11, 13), ModMetaBlocks.ZERG_FLESH.getDefaultState(), 2);
		world.setBlockState(pos.add(18, 11, 13), ModMetaBlocks.ZERG_FLESH.getDefaultState(), 2);
		world.setBlockState(pos.add(19, 11, 13), ModMetaBlocks.ZERG_FLESH.getDefaultState(), 2);
		world.setBlockState(pos.add(8, 11, 17), ModMetaBlocks.ZERG_FLESH.getDefaultState(), 2);
		world.setBlockState(pos.add(9, 11, 17), ModMetaBlocks.ZERG_FLESH.getDefaultState(), 2);
		world.setBlockState(pos.add(13, 11, 17), ModMetaBlocks.ZERG_FLESH.getDefaultState(), 2);
		world.setBlockState(pos.add(14, 11, 17), ModMetaBlocks.ZERG_FLESH.getDefaultState(), 2);
		world.setBlockState(pos.add(8, 11, 18), ModMetaBlocks.ZERG_FLESH.getDefaultState(), 2);
		world.setBlockState(pos.add(9, 11, 18), ModMetaBlocks.ZERG_FLESH.getDefaultState(), 2);
		world.setBlockState(pos.add(13, 11, 18), ModMetaBlocks.ZERG_FLESH.getDefaultState(), 2);
		world.setBlockState(pos.add(14, 11, 18), ModMetaBlocks.ZERG_FLESH.getDefaultState(), 2);
		world.setBlockState(pos.add(8, 12, 4), ModMetaBlocks.ZERG_FLESH.getDefaultState(), 2);
		world.setBlockState(pos.add(9, 12, 4), ModMetaBlocks.ZERG_FLESH.getDefaultState(), 2);
		world.setBlockState(pos.add(8, 12, 5), ModMetaBlocks.ZERG_FLESH.getDefaultState(), 2);
		world.setBlockState(pos.add(9, 12, 5), ModMetaBlocks.ZERG_FLESH.getDefaultState(), 2);
		world.setBlockState(pos.add(14, 12, 6), ModMetaBlocks.ZERG_FLESH.getDefaultState(), 2);
		world.setBlockState(pos.add(15, 12, 6), ModMetaBlocks.ZERG_FLESH.getDefaultState(), 2);
		world.setBlockState(pos.add(14, 12, 7), ModMetaBlocks.ZERG_FLESH.getDefaultState(), 2);
		world.setBlockState(pos.add(15, 12, 7), ModMetaBlocks.ZERG_FLESH.getDefaultState(), 2);
		world.setBlockState(pos.add(6, 12, 8), ModMetaBlocks.ZERG_FLESH.getDefaultState(), 2);
		world.setBlockState(pos.add(7, 12, 8), ModMetaBlocks.ZERG_FLESH.getDefaultState(), 2);
		world.setBlockState(pos.add(6, 12, 9), ModMetaBlocks.ZERG_FLESH.getDefaultState(), 2);
		world.setBlockState(pos.add(7, 12, 9), ModMetaBlocks.ZERG_FLESH.getDefaultState(), 2);
		world.setBlockState(pos.add(17, 12, 11), ModMetaBlocks.ZERG_FLESH.getDefaultState(), 2);
		world.setBlockState(pos.add(18, 12, 11), ModMetaBlocks.ZERG_FLESH.getDefaultState(), 2);
		world.setBlockState(pos.add(5, 12, 12), ModMetaBlocks.ZERG_FLESH.getDefaultState(), 2);
		world.setBlockState(pos.add(6, 12, 12), ModMetaBlocks.ZERG_FLESH.getDefaultState(), 2);
		world.setBlockState(pos.add(17, 12, 12), ModMetaBlocks.ZERG_FLESH.getDefaultState(), 2);
		world.setBlockState(pos.add(18, 12, 12), ModMetaBlocks.ZERG_FLESH.getDefaultState(), 2);
		world.setBlockState(pos.add(19, 12, 12), ModMetaBlocks.ZERG_FLESH.getDefaultState(), 2);
		world.setBlockState(pos.add(5, 12, 13), ModMetaBlocks.ZERG_FLESH.getDefaultState(), 2);
		world.setBlockState(pos.add(6, 12, 13), ModMetaBlocks.ZERG_FLESH.getDefaultState(), 2);
		world.setBlockState(pos.add(18, 12, 13), ModMetaBlocks.ZERG_FLESH.getDefaultState(), 2);
		world.setBlockState(pos.add(8, 12, 17), ModMetaBlocks.ZERG_FLESH.getDefaultState(), 2);
		world.setBlockState(pos.add(9, 12, 17), ModMetaBlocks.ZERG_FLESH.getDefaultState(), 2);
		world.setBlockState(pos.add(13, 12, 17), ModMetaBlocks.ZERG_FLESH.getDefaultState(), 2);
		world.setBlockState(pos.add(14, 12, 17), ModMetaBlocks.ZERG_FLESH.getDefaultState(), 2);
		world.setBlockState(pos.add(8, 12, 18), ModMetaBlocks.ZERG_FLESH.getDefaultState(), 2);
		world.setBlockState(pos.add(9, 12, 18), ModMetaBlocks.ZERG_FLESH.getDefaultState(), 2);
		world.setBlockState(pos.add(13, 12, 18), ModMetaBlocks.ZERG_FLESH.getDefaultState(), 2);
		world.setBlockState(pos.add(14, 12, 18), ModMetaBlocks.ZERG_FLESH.getDefaultState(), 2);
		world.setBlockState(pos.add(8, 13, 4), ModMetaBlocks.ZERG_FLESH.getDefaultState(), 2);
		world.setBlockState(pos.add(9, 13, 4), ModMetaBlocks.ZERG_FLESH.getDefaultState(), 2);
		world.setBlockState(pos.add(8, 13, 5), ModMetaBlocks.ZERG_FLESH.getDefaultState(), 2);
		world.setBlockState(pos.add(9, 13, 5), ModMetaBlocks.ZERG_FLESH.getDefaultState(), 2);
		world.setBlockState(pos.add(14, 13, 6), ModMetaBlocks.ZERG_FLESH.getDefaultState(), 2);
		world.setBlockState(pos.add(15, 13, 6), ModMetaBlocks.ZERG_FLESH.getDefaultState(), 2);
		world.setBlockState(pos.add(14, 13, 7), ModMetaBlocks.ZERG_FLESH.getDefaultState(), 2);
		world.setBlockState(pos.add(15, 13, 7), ModMetaBlocks.ZERG_FLESH.getDefaultState(), 2);
		world.setBlockState(pos.add(6, 13, 8), ModMetaBlocks.ZERG_FLESH.getDefaultState(), 2);
		world.setBlockState(pos.add(7, 13, 8), ModMetaBlocks.ZERG_FLESH.getDefaultState(), 2);
		world.setBlockState(pos.add(6, 13, 9), ModMetaBlocks.ZERG_FLESH.getDefaultState(), 2);
		world.setBlockState(pos.add(7, 13, 9), ModMetaBlocks.ZERG_FLESH.getDefaultState(), 2);

		generate_r07(world, rand, pos);
		return true;

	}

	public boolean generate_r07(World world, Random rand, BlockPos pos) {

		world.setBlockState(pos.add(17, 13, 11), ModMetaBlocks.ZERG_FLESH.getDefaultState(), 2);
		world.setBlockState(pos.add(18, 13, 11), ModMetaBlocks.ZERG_FLESH.getDefaultState(), 2);
		world.setBlockState(pos.add(5, 13, 12), ModMetaBlocks.ZERG_FLESH.getDefaultState(), 2);
		world.setBlockState(pos.add(6, 13, 12), ModMetaBlocks.ZERG_FLESH.getDefaultState(), 2);
		world.setBlockState(pos.add(17, 13, 12), ModMetaBlocks.ZERG_FLESH.getDefaultState(), 2);
		world.setBlockState(pos.add(18, 13, 12), ModMetaBlocks.ZERG_FLESH.getDefaultState(), 2);
		world.setBlockState(pos.add(5, 13, 13), ModMetaBlocks.ZERG_FLESH.getDefaultState(), 2);
		world.setBlockState(pos.add(6, 13, 13), ModMetaBlocks.ZERG_FLESH.getDefaultState(), 2);
		world.setBlockState(pos.add(8, 13, 17), ModMetaBlocks.ZERG_FLESH.getDefaultState(), 2);
		world.setBlockState(pos.add(9, 13, 17), ModMetaBlocks.ZERG_FLESH.getDefaultState(), 2);
		world.setBlockState(pos.add(13, 13, 17), ModMetaBlocks.ZERG_FLESH.getDefaultState(), 2);
		world.setBlockState(pos.add(14, 13, 17), ModMetaBlocks.ZERG_FLESH.getDefaultState(), 2);
		world.setBlockState(pos.add(8, 13, 18), ModMetaBlocks.ZERG_FLESH.getDefaultState(), 2);
		world.setBlockState(pos.add(9, 13, 18), ModMetaBlocks.ZERG_FLESH.getDefaultState(), 2);
		world.setBlockState(pos.add(13, 13, 18), ModMetaBlocks.ZERG_FLESH.getDefaultState(), 2);
		world.setBlockState(pos.add(14, 13, 18), ModMetaBlocks.ZERG_FLESH.getDefaultState(), 2);
		world.setBlockState(pos.add(8, 14, 4), ModMetaBlocks.ZERG_FLESH.getDefaultState(), 2);
		world.setBlockState(pos.add(9, 14, 4), ModMetaBlocks.ZERG_FLESH.getDefaultState(), 2);
		world.setBlockState(pos.add(8, 14, 5), ModMetaBlocks.ZERG_FLESH.getDefaultState(), 2);
		world.setBlockState(pos.add(9, 14, 5), ModMetaBlocks.ZERG_FLESH.getDefaultState(), 2);
		world.setBlockState(pos.add(14, 14, 6), ModMetaBlocks.ZERG_FLESH.getDefaultState(), 2);
		world.setBlockState(pos.add(15, 14, 6), ModMetaBlocks.ZERG_FLESH.getDefaultState(), 2);
		world.setBlockState(pos.add(14, 14, 7), ModMetaBlocks.ZERG_FLESH.getDefaultState(), 2);
		world.setBlockState(pos.add(15, 14, 7), ModMetaBlocks.ZERG_FLESH.getDefaultState(), 2);
		world.setBlockState(pos.add(6, 14, 8), ModMetaBlocks.ZERG_FLESH.getDefaultState(), 2);
		world.setBlockState(pos.add(7, 14, 8), ModMetaBlocks.ZERG_FLESH.getDefaultState(), 2);
		world.setBlockState(pos.add(6, 14, 9), ModMetaBlocks.ZERG_FLESH.getDefaultState(), 2);
		world.setBlockState(pos.add(7, 14, 9), ModMetaBlocks.ZERG_FLESH.getDefaultState(), 2);
		world.setBlockState(pos.add(17, 14, 11), ModMetaBlocks.ZERG_FLESH.getDefaultState(), 2);
		world.setBlockState(pos.add(18, 14, 11), ModMetaBlocks.ZERG_FLESH.getDefaultState(), 2);
		world.setBlockState(pos.add(5, 14, 12), ModMetaBlocks.ZERG_FLESH.getDefaultState(), 2);
		world.setBlockState(pos.add(6, 14, 12), ModMetaBlocks.ZERG_FLESH.getDefaultState(), 2);
		world.setBlockState(pos.add(17, 14, 12), ModMetaBlocks.ZERG_FLESH.getDefaultState(), 2);
		world.setBlockState(pos.add(18, 14, 12), ModMetaBlocks.ZERG_FLESH.getDefaultState(), 2);
		world.setBlockState(pos.add(5, 14, 13), ModMetaBlocks.ZERG_FLESH.getDefaultState(), 2);
		world.setBlockState(pos.add(6, 14, 13), ModMetaBlocks.ZERG_FLESH.getDefaultState(), 2);
		world.setBlockState(pos.add(8, 14, 16), ModMetaBlocks.ZERG_FLESH.getDefaultState(), 2);
		world.setBlockState(pos.add(9, 14, 16), ModMetaBlocks.ZERG_FLESH.getDefaultState(), 2);
		world.setBlockState(pos.add(8, 14, 17), ModMetaBlocks.ZERG_FLESH.getDefaultState(), 2);
		world.setBlockState(pos.add(9, 14, 17), ModMetaBlocks.ZERG_FLESH.getDefaultState(), 2);
		world.setBlockState(pos.add(13, 14, 17), ModMetaBlocks.ZERG_FLESH.getDefaultState(), 2);
		world.setBlockState(pos.add(14, 14, 17), ModMetaBlocks.ZERG_FLESH.getDefaultState(), 2);
		world.setBlockState(pos.add(8, 14, 18), ModMetaBlocks.ZERG_FLESH.getDefaultState(), 2);
		world.setBlockState(pos.add(9, 14, 18), ModMetaBlocks.ZERG_FLESH.getDefaultState(), 2);
		world.setBlockState(pos.add(13, 14, 18), ModMetaBlocks.ZERG_FLESH.getDefaultState(), 2);
		world.setBlockState(pos.add(14, 14, 18), ModMetaBlocks.ZERG_FLESH.getDefaultState(), 2);
		world.setBlockState(pos.add(8, 15, 4), ModMetaBlocks.ZERG_FLESH.getDefaultState(), 2);
		world.setBlockState(pos.add(9, 15, 4), ModMetaBlocks.ZERG_FLESH.getDefaultState(), 2);
		world.setBlockState(pos.add(8, 15, 5), ModMetaBlocks.ZERG_FLESH.getDefaultState(), 2);
		world.setBlockState(pos.add(9, 15, 5), ModMetaBlocks.ZERG_FLESH.getDefaultState(), 2);
		world.setBlockState(pos.add(15, 15, 5), ModMetaBlocks.ZERG_FLESH.getDefaultState(), 2);
		world.setBlockState(pos.add(14, 15, 6), ModMetaBlocks.ZERG_FLESH.getDefaultState(), 2);
		world.setBlockState(pos.add(15, 15, 6), ModMetaBlocks.ZERG_FLESH.getDefaultState(), 2);
		world.setBlockState(pos.add(16, 15, 6), ModMetaBlocks.ZERG_FLESH.getDefaultState(), 2);
		world.setBlockState(pos.add(14, 15, 7), ModMetaBlocks.ZERG_FLESH.getDefaultState(), 2);
		world.setBlockState(pos.add(15, 15, 7), ModMetaBlocks.ZERG_FLESH.getDefaultState(), 2);
		world.setBlockState(pos.add(6, 15, 8), ModMetaBlocks.ZERG_FLESH.getDefaultState(), 2);
		world.setBlockState(pos.add(7, 15, 8), ModMetaBlocks.ZERG_FLESH.getDefaultState(), 2);
		world.setBlockState(pos.add(6, 15, 9), ModMetaBlocks.ZERG_FLESH.getDefaultState(), 2);
		world.setBlockState(pos.add(7, 15, 9), ModMetaBlocks.ZERG_FLESH.getDefaultState(), 2);
		world.setBlockState(pos.add(14, 15, 11), ModBlocks.KERATIN_CHUNK.getDefaultState(), 2);
		world.setBlockState(pos.add(15, 15, 11), ModBlocks.KERATIN_CHUNK.getDefaultState(), 2);
		world.setBlockState(pos.add(17, 15, 11), ModMetaBlocks.ZERG_FLESH.getDefaultState(), 2);
		world.setBlockState(pos.add(18, 15, 11), ModMetaBlocks.ZERG_FLESH.getDefaultState(), 2);
		world.setBlockState(pos.add(5, 15, 12), ModMetaBlocks.ZERG_FLESH.getDefaultState(), 2);
		world.setBlockState(pos.add(6, 15, 12), ModMetaBlocks.ZERG_FLESH.getDefaultState(), 2);
		world.setBlockState(pos.add(17, 15, 12), ModMetaBlocks.ZERG_FLESH.getDefaultState(), 2);
		world.setBlockState(pos.add(18, 15, 12), ModMetaBlocks.ZERG_FLESH.getDefaultState(), 2);
		world.setBlockState(pos.add(5, 15, 13), ModMetaBlocks.ZERG_FLESH.getDefaultState(), 2);
		world.setBlockState(pos.add(6, 15, 13), ModMetaBlocks.ZERG_FLESH.getDefaultState(), 2);
		world.setBlockState(pos.add(10, 15, 13), ModBlocks.KERATIN_CHUNK.getDefaultState(), 2);
		world.setBlockState(pos.add(8, 15, 16), ModMetaBlocks.ZERG_FLESH.getDefaultState(), 2);
		world.setBlockState(pos.add(9, 15, 16), ModMetaBlocks.ZERG_FLESH.getDefaultState(), 2);
		world.setBlockState(pos.add(8, 15, 17), ModMetaBlocks.ZERG_FLESH.getDefaultState(), 2);
		world.setBlockState(pos.add(9, 15, 17), ModMetaBlocks.ZERG_FLESH.getDefaultState(), 2);
		world.setBlockState(pos.add(13, 15, 17), ModMetaBlocks.ZERG_FLESH.getDefaultState(), 2);
		world.setBlockState(pos.add(14, 15, 17), ModMetaBlocks.ZERG_FLESH.getDefaultState(), 2);
		world.setBlockState(pos.add(8, 15, 18), ModMetaBlocks.ZERG_FLESH.getDefaultState(), 2);
		world.setBlockState(pos.add(9, 15, 18), ModMetaBlocks.ZERG_FLESH.getDefaultState(), 2);
		world.setBlockState(pos.add(13, 15, 18), ModMetaBlocks.ZERG_FLESH.getDefaultState(), 2);
		world.setBlockState(pos.add(14, 15, 18), ModMetaBlocks.ZERG_FLESH.getDefaultState(), 2);

		generate_r08(world, rand, pos);
		return true;

	}

	public boolean generate_r08(World world, Random rand, BlockPos pos) {

		world.setBlockState(pos.add(8, 16, 4), ModMetaBlocks.ZERG_FLESH.getDefaultState(), 2);
		world.setBlockState(pos.add(9, 16, 4), ModMetaBlocks.ZERG_FLESH.getDefaultState(), 2);
		world.setBlockState(pos.add(8, 16, 5), ModMetaBlocks.ZERG_FLESH.getDefaultState(), 2);
		world.setBlockState(pos.add(9, 16, 5), ModMetaBlocks.ZERG_FLESH.getDefaultState(), 2);
		world.setBlockState(pos.add(15, 16, 5), ModMetaBlocks.ZERG_FLESH.getDefaultState(), 2);
		world.setBlockState(pos.add(16, 16, 5), ModMetaBlocks.ZERG_FLESH.getDefaultState(), 2);
		world.setBlockState(pos.add(14, 16, 6), ModMetaBlocks.ZERG_FLESH.getDefaultState(), 2);
		world.setBlockState(pos.add(15, 16, 6), ModMetaBlocks.ZERG_FLESH.getDefaultState(), 2);
		world.setBlockState(pos.add(16, 16, 6), ModMetaBlocks.ZERG_FLESH.getDefaultState(), 2);
		world.setBlockState(pos.add(14, 16, 7), ModMetaBlocks.ZERG_FLESH.getDefaultState(), 2);
		world.setBlockState(pos.add(15, 16, 7), ModMetaBlocks.ZERG_FLESH.getDefaultState(), 2);
		world.setBlockState(pos.add(6, 16, 8), ModMetaBlocks.ZERG_FLESH.getDefaultState(), 2);
		world.setBlockState(pos.add(7, 16, 8), ModMetaBlocks.ZERG_FLESH.getDefaultState(), 2);
		world.setBlockState(pos.add(6, 16, 9), ModMetaBlocks.ZERG_FLESH.getDefaultState(), 2);
		world.setBlockState(pos.add(7, 16, 9), ModMetaBlocks.ZERG_FLESH.getDefaultState(), 2);
		world.setBlockState(pos.add(14, 16, 11), ModBlocks.KERATIN_CHUNK.getDefaultState(), 2);
		world.setBlockState(pos.add(15, 16, 11), ModBlocks.KERATIN_CHUNK.getDefaultState(), 2);
		world.setBlockState(pos.add(17, 16, 11), ModMetaBlocks.ZERG_FLESH.getDefaultState(), 2);
		world.setBlockState(pos.add(18, 16, 11), ModMetaBlocks.ZERG_FLESH.getDefaultState(), 2);
		world.setBlockState(pos.add(5, 16, 12), ModMetaBlocks.ZERG_FLESH.getDefaultState(), 2);
		world.setBlockState(pos.add(6, 16, 12), ModMetaBlocks.ZERG_FLESH.getDefaultState(), 2);
		world.setBlockState(pos.add(10, 16, 12), ModBlocks.KERATIN_CHUNK.getDefaultState(), 2);
		world.setBlockState(pos.add(14, 16, 12), ModBlocks.KERATIN_CHUNK.getDefaultState(), 2);
		world.setBlockState(pos.add(17, 16, 12), ModMetaBlocks.ZERG_FLESH.getDefaultState(), 2);
		world.setBlockState(pos.add(18, 16, 12), ModMetaBlocks.ZERG_FLESH.getDefaultState(), 2);
		world.setBlockState(pos.add(5, 16, 13), ModMetaBlocks.ZERG_FLESH.getDefaultState(), 2);
		world.setBlockState(pos.add(6, 16, 13), ModMetaBlocks.ZERG_FLESH.getDefaultState(), 2);
		world.setBlockState(pos.add(10, 16, 13), ModBlocks.KERATIN_CHUNK.getDefaultState(), 2);
		world.setBlockState(pos.add(8, 16, 16), ModMetaBlocks.ZERG_FLESH.getDefaultState(), 2);
		world.setBlockState(pos.add(9, 16, 16), ModMetaBlocks.ZERG_FLESH.getDefaultState(), 2);
		world.setBlockState(pos.add(13, 16, 16), ModMetaBlocks.ZERG_FLESH.getDefaultState(), 2);
		world.setBlockState(pos.add(14, 16, 16), ModMetaBlocks.ZERG_FLESH.getDefaultState(), 2);
		world.setBlockState(pos.add(8, 16, 17), ModMetaBlocks.ZERG_FLESH.getDefaultState(), 2);
		world.setBlockState(pos.add(9, 16, 17), ModMetaBlocks.ZERG_FLESH.getDefaultState(), 2);
		world.setBlockState(pos.add(13, 16, 17), ModMetaBlocks.ZERG_FLESH.getDefaultState(), 2);
		world.setBlockState(pos.add(14, 16, 17), ModMetaBlocks.ZERG_FLESH.getDefaultState(), 2);
		world.setBlockState(pos.add(8, 16, 18), ModMetaBlocks.ZERG_FLESH.getDefaultState(), 2);
		world.setBlockState(pos.add(9, 16, 18), ModMetaBlocks.ZERG_FLESH.getDefaultState(), 2);
		world.setBlockState(pos.add(13, 16, 18), ModMetaBlocks.ZERG_FLESH.getDefaultState(), 2);
		world.setBlockState(pos.add(14, 16, 18), ModMetaBlocks.ZERG_FLESH.getDefaultState(), 2);
		world.setBlockState(pos.add(8, 17, 4), ModMetaBlocks.ZERG_FLESH.getDefaultState(), 2);
		world.setBlockState(pos.add(9, 17, 4), ModMetaBlocks.ZERG_FLESH.getDefaultState(), 2);
		world.setBlockState(pos.add(8, 17, 5), ModMetaBlocks.ZERG_FLESH.getDefaultState(), 2);
		world.setBlockState(pos.add(9, 17, 5), ModMetaBlocks.ZERG_FLESH.getDefaultState(), 2);
		world.setBlockState(pos.add(15, 17, 5), ModMetaBlocks.ZERG_FLESH.getDefaultState(), 2);
		world.setBlockState(pos.add(16, 17, 5), ModMetaBlocks.ZERG_FLESH.getDefaultState(), 2);
		world.setBlockState(pos.add(14, 17, 6), ModMetaBlocks.ZERG_FLESH.getDefaultState(), 2);
		world.setBlockState(pos.add(15, 17, 6), ModMetaBlocks.ZERG_FLESH.getDefaultState(), 2);
		world.setBlockState(pos.add(16, 17, 6), ModMetaBlocks.ZERG_FLESH.getDefaultState(), 2);
		world.setBlockState(pos.add(15, 17, 7), ModMetaBlocks.ZERG_FLESH.getDefaultState(), 2);
		world.setBlockState(pos.add(6, 17, 8), ModMetaBlocks.ZERG_FLESH.getDefaultState(), 2);
		world.setBlockState(pos.add(7, 17, 8), ModMetaBlocks.ZERG_FLESH.getDefaultState(), 2);
		world.setBlockState(pos.add(6, 17, 9), ModMetaBlocks.ZERG_FLESH.getDefaultState(), 2);
		world.setBlockState(pos.add(7, 17, 9), ModMetaBlocks.ZERG_FLESH.getDefaultState(), 2);
		world.setBlockState(pos.add(13, 17, 11), ModBlocks.KERATIN_CHUNK.getDefaultState(), 2);
		world.setBlockState(pos.add(14, 17, 11), ModBlocks.KERATIN_CHUNK.getDefaultState(), 2);
		world.setBlockState(pos.add(15, 17, 11), ModBlocks.KERATIN_CHUNK.getDefaultState(), 2);
		world.setBlockState(pos.add(17, 17, 11), ModMetaBlocks.ZERG_FLESH.getDefaultState(), 2);
		world.setBlockState(pos.add(18, 17, 11), ModMetaBlocks.ZERG_FLESH.getDefaultState(), 2);
		world.setBlockState(pos.add(5, 17, 12), ModMetaBlocks.ZERG_FLESH.getDefaultState(), 2);
		world.setBlockState(pos.add(6, 17, 12), ModMetaBlocks.ZERG_FLESH.getDefaultState(), 2);
		world.setBlockState(pos.add(10, 17, 12), ModBlocks.KERATIN_CHUNK.getDefaultState(), 2);
		world.setBlockState(pos.add(13, 17, 12), ModBlocks.KERATIN_CHUNK.getDefaultState(), 2);
		world.setBlockState(pos.add(14, 17, 12), ModBlocks.KERATIN_CHUNK.getDefaultState(), 2);
		world.setBlockState(pos.add(17, 17, 12), ModMetaBlocks.ZERG_FLESH.getDefaultState(), 2);
		world.setBlockState(pos.add(18, 17, 12), ModMetaBlocks.ZERG_FLESH.getDefaultState(), 2);
		world.setBlockState(pos.add(5, 17, 13), ModMetaBlocks.ZERG_FLESH.getDefaultState(), 2);
		world.setBlockState(pos.add(6, 17, 13), ModMetaBlocks.ZERG_FLESH.getDefaultState(), 2);
		world.setBlockState(pos.add(10, 17, 13), ModBlocks.KERATIN_CHUNK.getDefaultState(), 2);
		world.setBlockState(pos.add(11, 17, 13), ModBlocks.KERATIN_CHUNK.getDefaultState(), 2);
		world.setBlockState(pos.add(8, 17, 16), ModMetaBlocks.ZERG_FLESH.getDefaultState(), 2);
		world.setBlockState(pos.add(9, 17, 16), ModMetaBlocks.ZERG_FLESH.getDefaultState(), 2);
		world.setBlockState(pos.add(13, 17, 16), ModMetaBlocks.ZERG_FLESH.getDefaultState(), 2);
		world.setBlockState(pos.add(14, 17, 16), ModMetaBlocks.ZERG_FLESH.getDefaultState(), 2);
		world.setBlockState(pos.add(8, 17, 17), ModMetaBlocks.ZERG_FLESH.getDefaultState(), 2);
		world.setBlockState(pos.add(9, 17, 17), ModMetaBlocks.ZERG_FLESH.getDefaultState(), 2);
		world.setBlockState(pos.add(13, 17, 17), ModMetaBlocks.ZERG_FLESH.getDefaultState(), 2);
		world.setBlockState(pos.add(14, 17, 17), ModMetaBlocks.ZERG_FLESH.getDefaultState(), 2);
		world.setBlockState(pos.add(8, 17, 18), ModMetaBlocks.ZERG_FLESH.getDefaultState(), 2);
		world.setBlockState(pos.add(9, 17, 18), ModMetaBlocks.ZERG_FLESH.getDefaultState(), 2);
		world.setBlockState(pos.add(13, 17, 18), ModMetaBlocks.ZERG_FLESH.getDefaultState(), 2);
		world.setBlockState(pos.add(14, 17, 18), ModMetaBlocks.ZERG_FLESH.getDefaultState(), 2);
		world.setBlockState(pos.add(8, 18, 4), ModMetaBlocks.ZERG_FLESH.getDefaultState(), 2);
		world.setBlockState(pos.add(9, 18, 4), ModMetaBlocks.ZERG_FLESH.getDefaultState(), 2);
		world.setBlockState(pos.add(8, 18, 5), ModMetaBlocks.ZERG_FLESH.getDefaultState(), 2);
		world.setBlockState(pos.add(9, 18, 5), ModMetaBlocks.ZERG_FLESH.getDefaultState(), 2);
		world.setBlockState(pos.add(10, 18, 5), ModMetaBlocks.ZERG_FLESH.getDefaultState(), 2);
		world.setBlockState(pos.add(15, 18, 5), ModMetaBlocks.ZERG_FLESH.getDefaultState(), 2);
		world.setBlockState(pos.add(16, 18, 5), ModMetaBlocks.ZERG_FLESH.getDefaultState(), 2);

		generate_r09(world, rand, pos);
		return true;

	}

	public boolean generate_r09(World world, Random rand, BlockPos pos) {

		world.setBlockState(pos.add(9, 18, 6), ModMetaBlocks.ZERG_FLESH.getDefaultState(), 2);
		world.setBlockState(pos.add(10, 18, 6), ModMetaBlocks.ZERG_FLESH.getDefaultState(), 2);
		world.setBlockState(pos.add(15, 18, 6), ModMetaBlocks.ZERG_FLESH.getDefaultState(), 2);
		world.setBlockState(pos.add(16, 18, 6), ModMetaBlocks.ZERG_FLESH.getDefaultState(), 2);
		world.setBlockState(pos.add(6, 18, 8), ModMetaBlocks.ZERG_FLESH.getDefaultState(), 2);
		world.setBlockState(pos.add(7, 18, 8), ModMetaBlocks.ZERG_FLESH.getDefaultState(), 2);
		world.setBlockState(pos.add(6, 18, 9), ModMetaBlocks.ZERG_FLESH.getDefaultState(), 2);
		world.setBlockState(pos.add(7, 18, 9), ModMetaBlocks.ZERG_FLESH.getDefaultState(), 2);
		world.setBlockState(pos.add(11, 18, 11), ModBlocks.KERATIN_CHUNK.getDefaultState(), 2);
		world.setBlockState(pos.add(13, 18, 11), ModBlocks.KERATIN_CHUNK.getDefaultState(), 2);
		world.setBlockState(pos.add(14, 18, 11), ModBlocks.KERATIN_CHUNK.getDefaultState(), 2);
		world.setBlockState(pos.add(15, 18, 11), ModBlocks.KERATIN_CHUNK.getDefaultState(), 2);
		world.setBlockState(pos.add(17, 18, 11), ModMetaBlocks.ZERG_FLESH.getDefaultState(), 2);
		world.setBlockState(pos.add(18, 18, 11), ModMetaBlocks.ZERG_FLESH.getDefaultState(), 2);
		world.setBlockState(pos.add(5, 18, 12), ModMetaBlocks.ZERG_FLESH.getDefaultState(), 2);
		world.setBlockState(pos.add(6, 18, 12), ModMetaBlocks.ZERG_FLESH.getDefaultState(), 2);
		world.setBlockState(pos.add(10, 18, 12), ModBlocks.KERATIN_CHUNK.getDefaultState(), 2);
		world.setBlockState(pos.add(11, 18, 12), ModBlocks.KERATIN_CHUNK.getDefaultState(), 2);
		world.setBlockState(pos.add(12, 18, 12), ModBlocks.KERATIN_CHUNK.getDefaultState(), 2);
		world.setBlockState(pos.add(13, 18, 12), ModBlocks.KERATIN_CHUNK.getDefaultState(), 2);
		world.setBlockState(pos.add(14, 18, 12), ModBlocks.KERATIN_CHUNK.getDefaultState(), 2);
		world.setBlockState(pos.add(17, 18, 12), ModMetaBlocks.ZERG_FLESH.getDefaultState(), 2);
		world.setBlockState(pos.add(18, 18, 12), ModMetaBlocks.ZERG_FLESH.getDefaultState(), 2);
		world.setBlockState(pos.add(5, 18, 13), ModMetaBlocks.ZERG_FLESH.getDefaultState(), 2);
		world.setBlockState(pos.add(6, 18, 13), ModMetaBlocks.ZERG_FLESH.getDefaultState(), 2);
		world.setBlockState(pos.add(10, 18, 13), ModBlocks.KERATIN_CHUNK.getDefaultState(), 2);
		world.setBlockState(pos.add(11, 18, 13), ModBlocks.KERATIN_CHUNK.getDefaultState(), 2);
		world.setBlockState(pos.add(8, 18, 16), ModMetaBlocks.ZERG_FLESH.getDefaultState(), 2);
		world.setBlockState(pos.add(9, 18, 16), ModMetaBlocks.ZERG_FLESH.getDefaultState(), 2);
		world.setBlockState(pos.add(13, 18, 16), ModMetaBlocks.ZERG_FLESH.getDefaultState(), 2);
		world.setBlockState(pos.add(14, 18, 16), ModMetaBlocks.ZERG_FLESH.getDefaultState(), 2);
		world.setBlockState(pos.add(8, 18, 17), ModMetaBlocks.ZERG_FLESH.getDefaultState(), 2);
		world.setBlockState(pos.add(9, 18, 17), ModMetaBlocks.ZERG_FLESH.getDefaultState(), 2);
		world.setBlockState(pos.add(13, 18, 17), ModMetaBlocks.ZERG_FLESH.getDefaultState(), 2);
		world.setBlockState(pos.add(14, 18, 17), ModMetaBlocks.ZERG_FLESH.getDefaultState(), 2);
		world.setBlockState(pos.add(13, 18, 18), ModMetaBlocks.ZERG_FLESH.getDefaultState(), 2);
		world.setBlockState(pos.add(14, 18, 18), ModMetaBlocks.ZERG_FLESH.getDefaultState(), 2);
		world.setBlockState(pos.add(8, 19, 4), ModMetaBlocks.ZERG_FLESH.getDefaultState(), 2);
		world.setBlockState(pos.add(9, 19, 4), ModMetaBlocks.ZERG_FLESH.getDefaultState(), 2);
		world.setBlockState(pos.add(8, 19, 5), ModMetaBlocks.ZERG_FLESH.getDefaultState(), 2);
		world.setBlockState(pos.add(9, 19, 5), ModMetaBlocks.ZERG_FLESH.getDefaultState(), 2);
		world.setBlockState(pos.add(10, 19, 5), ModMetaBlocks.ZERG_FLESH.getDefaultState(), 2);
		world.setBlockState(pos.add(15, 19, 5), ModMetaBlocks.ZERG_FLESH.getDefaultState(), 2);
		world.setBlockState(pos.add(16, 19, 5), ModMetaBlocks.ZERG_FLESH.getDefaultState(), 2);
		world.setBlockState(pos.add(9, 19, 6), ModMetaBlocks.ZERG_FLESH.getDefaultState(), 2);
		world.setBlockState(pos.add(10, 19, 6), ModMetaBlocks.ZERG_FLESH.getDefaultState(), 2);
		world.setBlockState(pos.add(15, 19, 6), ModMetaBlocks.ZERG_FLESH.getDefaultState(), 2);
		world.setBlockState(pos.add(16, 19, 6), ModMetaBlocks.ZERG_FLESH.getDefaultState(), 2);
		world.setBlockState(pos.add(6, 19, 8), ModMetaBlocks.ZERG_FLESH.getDefaultState(), 2);
		world.setBlockState(pos.add(7, 19, 8), ModMetaBlocks.ZERG_FLESH.getDefaultState(), 2);
		world.setBlockState(pos.add(6, 19, 9), ModMetaBlocks.ZERG_FLESH.getDefaultState(), 2);
		world.setBlockState(pos.add(7, 19, 9), ModMetaBlocks.ZERG_FLESH.getDefaultState(), 2);
		world.setBlockState(pos.add(11, 19, 11), ModBlocks.KERATIN_CHUNK.getDefaultState(), 2);
		world.setBlockState(pos.add(12, 19, 11), ModBlocks.KERATIN_CHUNK.getDefaultState(), 2);
		world.setBlockState(pos.add(13, 19, 11), ModBlocks.KERATIN_CHUNK.getDefaultState(), 2);
		world.setBlockState(pos.add(14, 19, 11), ModBlocks.KERATIN_CHUNK.getDefaultState(), 2);
		world.setBlockState(pos.add(17, 19, 11), ModMetaBlocks.ZERG_FLESH.getDefaultState(), 2);
		world.setBlockState(pos.add(18, 19, 11), ModMetaBlocks.ZERG_FLESH.getDefaultState(), 2);
		world.setBlockState(pos.add(5, 19, 12), ModMetaBlocks.ZERG_FLESH.getDefaultState(), 2);
		world.setBlockState(pos.add(6, 19, 12), ModMetaBlocks.ZERG_FLESH.getDefaultState(), 2);
		world.setBlockState(pos.add(10, 19, 12), ModBlocks.KERATIN_CHUNK.getDefaultState(), 2);
		world.setBlockState(pos.add(11, 19, 12), ModBlocks.KERATIN_CHUNK.getDefaultState(), 2);
		world.setBlockState(pos.add(12, 19, 12), ModBlocks.KERATIN_CHUNK.getDefaultState(), 2);
		world.setBlockState(pos.add(13, 19, 12), ModBlocks.KERATIN_CHUNK.getDefaultState(), 2);
		world.setBlockState(pos.add(14, 19, 12), ModBlocks.KERATIN_CHUNK.getDefaultState(), 2);
		world.setBlockState(pos.add(17, 19, 12), ModMetaBlocks.ZERG_FLESH.getDefaultState(), 2);
		world.setBlockState(pos.add(18, 19, 12), ModMetaBlocks.ZERG_FLESH.getDefaultState(), 2);
		world.setBlockState(pos.add(5, 19, 13), ModMetaBlocks.ZERG_FLESH.getDefaultState(), 2);
		world.setBlockState(pos.add(6, 19, 13), ModMetaBlocks.ZERG_FLESH.getDefaultState(), 2);
		world.setBlockState(pos.add(11, 19, 13), ModBlocks.KERATIN_CHUNK.getDefaultState(), 2);
		world.setBlockState(pos.add(12, 19, 13), ModBlocks.KERATIN_CHUNK.getDefaultState(), 2);
		world.setBlockState(pos.add(8, 19, 16), ModMetaBlocks.ZERG_FLESH.getDefaultState(), 2);
		world.setBlockState(pos.add(9, 19, 16), ModMetaBlocks.ZERG_FLESH.getDefaultState(), 2);
		world.setBlockState(pos.add(13, 19, 16), ModMetaBlocks.ZERG_FLESH.getDefaultState(), 2);
		world.setBlockState(pos.add(14, 19, 16), ModMetaBlocks.ZERG_FLESH.getDefaultState(), 2);
		world.setBlockState(pos.add(8, 19, 17), ModMetaBlocks.ZERG_FLESH.getDefaultState(), 2);
		world.setBlockState(pos.add(9, 19, 17), ModMetaBlocks.ZERG_FLESH.getDefaultState(), 2);
		world.setBlockState(pos.add(13, 19, 17), ModMetaBlocks.ZERG_FLESH.getDefaultState(), 2);
		world.setBlockState(pos.add(14, 19, 17), ModMetaBlocks.ZERG_FLESH.getDefaultState(), 2);
		world.setBlockState(pos.add(13, 19, 18), ModMetaBlocks.ZERG_FLESH.getDefaultState(), 2);
		world.setBlockState(pos.add(14, 19, 18), ModMetaBlocks.ZERG_FLESH.getDefaultState(), 2);
		world.setBlockState(pos.add(8, 20, 4), ModMetaBlocks.ZERG_FLESH.getDefaultState(), 2);
		world.setBlockState(pos.add(9, 20, 4), ModMetaBlocks.ZERG_FLESH.getDefaultState(), 2);
		world.setBlockState(pos.add(8, 20, 5), ModMetaBlocks.ZERG_FLESH.getDefaultState(), 2);
		world.setBlockState(pos.add(9, 20, 5), ModMetaBlocks.ZERG_FLESH.getDefaultState(), 2);
		world.setBlockState(pos.add(10, 20, 5), ModMetaBlocks.ZERG_FLESH.getDefaultState(), 2);
		world.setBlockState(pos.add(15, 20, 5), ModMetaBlocks.ZERG_FLESH.getDefaultState(), 2);
		world.setBlockState(pos.add(16, 20, 5), ModMetaBlocks.ZERG_FLESH.getDefaultState(), 2);
		world.setBlockState(pos.add(9, 20, 6), ModMetaBlocks.ZERG_FLESH.getDefaultState(), 2);
		world.setBlockState(pos.add(10, 20, 6), ModMetaBlocks.ZERG_FLESH.getDefaultState(), 2);
		world.setBlockState(pos.add(15, 20, 6), ModMetaBlocks.ZERG_FLESH.getDefaultState(), 2);
		world.setBlockState(pos.add(16, 20, 6), ModMetaBlocks.ZERG_FLESH.getDefaultState(), 2);
		world.setBlockState(pos.add(6, 20, 8), ModMetaBlocks.ZERG_FLESH.getDefaultState(), 2);
		world.setBlockState(pos.add(7, 20, 8), ModMetaBlocks.ZERG_FLESH.getDefaultState(), 2);
		world.setBlockState(pos.add(6, 20, 9), ModMetaBlocks.ZERG_FLESH.getDefaultState(), 2);
		world.setBlockState(pos.add(7, 20, 9), ModMetaBlocks.ZERG_FLESH.getDefaultState(), 2);
		world.setBlockState(pos.add(11, 20, 11), ModBlocks.KERATIN_CHUNK.getDefaultState(), 2);
		world.setBlockState(pos.add(12, 20, 11), ModBlocks.KERATIN_CHUNK.getDefaultState(), 2);
		world.setBlockState(pos.add(13, 20, 11), ModBlocks.KERATIN_CHUNK.getDefaultState(), 2);
		world.setBlockState(pos.add(14, 20, 11), ModBlocks.KERATIN_CHUNK.getDefaultState(), 2);
		world.setBlockState(pos.add(17, 20, 11), ModMetaBlocks.ZERG_FLESH.getDefaultState(), 2);
		world.setBlockState(pos.add(18, 20, 11), ModMetaBlocks.ZERG_FLESH.getDefaultState(), 2);
		world.setBlockState(pos.add(5, 20, 12), ModMetaBlocks.ZERG_FLESH.getDefaultState(), 2);
		world.setBlockState(pos.add(6, 20, 12), ModMetaBlocks.ZERG_FLESH.getDefaultState(), 2);
		world.setBlockState(pos.add(10, 20, 12), ModBlocks.KERATIN_CHUNK.getDefaultState(), 2);
		world.setBlockState(pos.add(11, 20, 12), ModBlocks.KERATIN_CHUNK.getDefaultState(), 2);
		world.setBlockState(pos.add(12, 20, 12), ModBlocks.KERATIN_CHUNK.getDefaultState(), 2);
		world.setBlockState(pos.add(13, 20, 12), ModBlocks.KERATIN_CHUNK.getDefaultState(), 2);
		world.setBlockState(pos.add(14, 20, 12), ModBlocks.KERATIN_CHUNK.getDefaultState(), 2);
		world.setBlockState(pos.add(17, 20, 12), ModMetaBlocks.ZERG_FLESH.getDefaultState(), 2);
		world.setBlockState(pos.add(18, 20, 12), ModMetaBlocks.ZERG_FLESH.getDefaultState(), 2);
		world.setBlockState(pos.add(5, 20, 13), ModMetaBlocks.ZERG_FLESH.getDefaultState(), 2);
		world.setBlockState(pos.add(6, 20, 13), ModMetaBlocks.ZERG_FLESH.getDefaultState(), 2);
		world.setBlockState(pos.add(11, 20, 13), ModBlocks.KERATIN_CHUNK.getDefaultState(), 2);
		world.setBlockState(pos.add(12, 20, 13), ModBlocks.KERATIN_CHUNK.getDefaultState(), 2);
		world.setBlockState(pos.add(8, 20, 16), ModMetaBlocks.ZERG_FLESH.getDefaultState(), 2);
		world.setBlockState(pos.add(9, 20, 16), ModMetaBlocks.ZERG_FLESH.getDefaultState(), 2);

		generate_r010(world, rand, pos);
		return true;

	}

	public boolean generate_r010(World world, Random rand, BlockPos pos) {

		world.setBlockState(pos.add(13, 20, 16), ModMetaBlocks.ZERG_FLESH.getDefaultState(), 2);
		world.setBlockState(pos.add(14, 20, 16), ModMetaBlocks.ZERG_FLESH.getDefaultState(), 2);
		world.setBlockState(pos.add(8, 20, 17), ModMetaBlocks.ZERG_FLESH.getDefaultState(), 2);
		world.setBlockState(pos.add(9, 20, 17), ModMetaBlocks.ZERG_FLESH.getDefaultState(), 2);
		world.setBlockState(pos.add(13, 20, 17), ModMetaBlocks.ZERG_FLESH.getDefaultState(), 2);
		world.setBlockState(pos.add(14, 20, 17), ModMetaBlocks.ZERG_FLESH.getDefaultState(), 2);
		world.setBlockState(pos.add(9, 21, 5), ModMetaBlocks.ZERG_FLESH.getDefaultState(), 2);
		world.setBlockState(pos.add(10, 21, 5), ModMetaBlocks.ZERG_FLESH.getDefaultState(), 2);
		world.setBlockState(pos.add(15, 21, 5), ModMetaBlocks.ZERG_FLESH.getDefaultState(), 2);
		world.setBlockState(pos.add(16, 21, 5), ModMetaBlocks.ZERG_FLESH.getDefaultState(), 2);
		world.setBlockState(pos.add(9, 21, 6), ModMetaBlocks.ZERG_FLESH.getDefaultState(), 2);
		world.setBlockState(pos.add(10, 21, 6), ModMetaBlocks.ZERG_FLESH.getDefaultState(), 2);
		world.setBlockState(pos.add(15, 21, 6), ModMetaBlocks.ZERG_FLESH.getDefaultState(), 2);
		world.setBlockState(pos.add(16, 21, 6), ModMetaBlocks.ZERG_FLESH.getDefaultState(), 2);
		world.setBlockState(pos.add(6, 21, 8), ModMetaBlocks.ZERG_FLESH.getDefaultState(), 2);
		world.setBlockState(pos.add(7, 21, 8), ModMetaBlocks.ZERG_FLESH.getDefaultState(), 2);
		world.setBlockState(pos.add(6, 21, 9), ModMetaBlocks.ZERG_FLESH.getDefaultState(), 2);
		world.setBlockState(pos.add(7, 21, 9), ModMetaBlocks.ZERG_FLESH.getDefaultState(), 2);
		world.setBlockState(pos.add(10, 21, 10), ModBlocks.KERATIN_CHUNK.getDefaultState(), 2);
		world.setBlockState(pos.add(11, 21, 10), ModBlocks.KERATIN_CHUNK.getDefaultState(), 2);
		world.setBlockState(pos.add(12, 21, 10), ModBlocks.KERATIN_CHUNK.getDefaultState(), 2);
		world.setBlockState(pos.add(13, 21, 10), ModBlocks.KERATIN_CHUNK.getDefaultState(), 2);
		world.setBlockState(pos.add(10, 21, 11), ModBlocks.KERATIN_CHUNK.getDefaultState(), 2);
		world.setBlockState(pos.add(11, 21, 11), ModBlocks.KERATIN_CHUNK.getDefaultState(), 2);
		world.setBlockState(pos.add(12, 21, 11), ModBlocks.KERATIN_CHUNK.getDefaultState(), 2);
		world.setBlockState(pos.add(13, 21, 11), ModBlocks.KERATIN_CHUNK.getDefaultState(), 2);
		world.setBlockState(pos.add(14, 21, 11), ModBlocks.KERATIN_CHUNK.getDefaultState(), 2);
		world.setBlockState(pos.add(17, 21, 11), ModMetaBlocks.ZERG_FLESH.getDefaultState(), 2);
