//Schematic to java Structure by jajo_11 | inspired by "MITHION'S .SCHEMATIC TO JAVA CONVERTINGTOOL"

package scmc.worldgen.structure;

import java.util.Random;

import net.minecraft.block.Block;
import net.minecraft.block.material.Material;
import net.minecraft.init.Blocks;
import net.minecraft.util.math.BlockPos;
import net.minecraft.world.World;
import net.minecraft.world.gen.feature.WorldGenerator;
import scmc.blocks.ModBlocks;
import scmc.blocks.metablocks.ModMetaBlocks;

public class StructureZergSpawningPool extends WorldGenerator {
	protected Block[] GetValidSpawnBlocks() {
		return new Block[] { ModBlocks.ZERG_CREEP };
	}

	public boolean LocationIsValidSpawn(World world, BlockPos pos) {
		
		Block checkBlock = world.getBlockState(pos).getBlock();
		Material m = checkBlock.getDefaultState().getMaterial();
		Block blockAbove = world.getBlockState(pos.up()).getBlock();
		Block blockBelow = world.getBlockState(pos.down()).getBlock();

		for (Block i : GetValidSpawnBlocks()) {
			if (blockAbove != Blocks.AIR) {
				return false;
			}
			if (checkBlock == i) {
				return true;
			} else if (m == Material.PLANTS && blockBelow == i) {
				return true;
			}
		}
		return false;
	}
	
	public boolean generate(World world, Random rand, BlockPos pos) {
		if (rand.nextInt(1) == 0) {
			generate_r0(world, rand, pos);
		}

		return true;
	}

	public void generate_r0(World world, Random rand, BlockPos pos) {
		if (!LocationIsValidSpawn(world, pos) || !LocationIsValidSpawn(world, pos.add(18, 0, 0))
				|| !LocationIsValidSpawn(world, pos.add(18, 0, 20)) || !LocationIsValidSpawn(world, pos.add(0, 0, 20))) {
			return;
		}
		
//		LogHelper.logger.log(Level.WARN, "Generating pool.");
		
		//First level
		world.setBlockState(pos.add(8, 0, 1), ModMetaBlocks.ZERG_FLESH.getDefaultState(), 2);
		world.setBlockState(pos.add(9, 0, 2), ModMetaBlocks.ZERG_FLESH.getDefaultState(), 2);
		world.setBlockState(pos.add(1, 0, 3), ModMetaBlocks.ZERG_FLESH.getDefaultState(), 2);
		world.setBlockState(pos.add(8, 0, 3), ModMetaBlocks.ZERG_FLESH.getDefaultState(), 2);
		world.setBlockState(pos.add(9, 0, 3), ModMetaBlocks.ZERG_FLESH.getDefaultState(), 2);
		world.setBlockState(pos.add(2, 0, 4), ModMetaBlocks.ZERG_FLESH.getDefaultState(), 2);
		world.setBlockState(pos.add(3, 0, 4), ModMetaBlocks.ZERG_FLESH.getDefaultState(), 2);
		world.setBlockState(pos.add(5, 0, 4), ModMetaBlocks.ZERG_FLESH.getDefaultState(), 2);
		world.setBlockState(pos.add(6, 0, 4), ModMetaBlocks.ZERG_FLESH.getDefaultState(), 2);
		world.setBlockState(pos.add(7, 0, 4), ModMetaBlocks.ZERG_FLESH.getDefaultState(), 2);
		world.setBlockState(pos.add(8, 0, 4), ModMetaBlocks.ZERG_FLESH.getDefaultState(), 2);
		world.setBlockState(pos.add(9, 0, 4), ModMetaBlocks.ZERG_FLESH.getDefaultState(), 2);
		world.setBlockState(pos.add(10, 0, 4), ModMetaBlocks.ZERG_FLESH.getDefaultState(), 2);
		world.setBlockState(pos.add(11, 0, 4), ModMetaBlocks.ZERG_FLESH.getDefaultState(), 2);
		world.setBlockState(pos.add(14, 0, 4), ModMetaBlocks.ZERG_FLESH.getDefaultState(), 2);
		world.setBlockState(pos.add(15, 0, 4), ModMetaBlocks.ZERG_FLESH.getDefaultState(), 2);
		world.setBlockState(pos.add(4, 0, 5), ModMetaBlocks.ZERG_FLESH.getDefaultState(), 2);
		world.setBlockState(pos.add(5, 0, 5), ModMetaBlocks.ZERG_FLESH.getDefaultState(), 2);
		world.setBlockState(pos.add(6, 0, 5), ModMetaBlocks.ZERG_FLESH.getDefaultState(), 2);
		world.setBlockState(pos.add(7, 0, 5), ModMetaBlocks.ZERG_FLESH.getDefaultState(), 2);
		world.setBlockState(pos.add(8, 0, 5), ModMetaBlocks.ZERG_FLESH.getDefaultState(), 2);
		world.setBlockState(pos.add(9, 0, 5), ModMetaBlocks.ZERG_FLESH.getDefaultState(), 2);
		world.setBlockState(pos.add(10, 0, 5), ModMetaBlocks.ZERG_FLESH.getDefaultState(), 2);
		world.setBlockState(pos.add(11, 0, 5), ModMetaBlocks.ZERG_FLESH.getDefaultState(), 2);
		world.setBlockState(pos.add(12, 0, 5), ModMetaBlocks.ZERG_FLESH.getDefaultState(), 2);
		world.setBlockState(pos.add(13, 0, 5), ModMetaBlocks.ZERG_FLESH.getDefaultState(), 2);
		world.setBlockState(pos.add(14, 0, 5), ModMetaBlocks.ZERG_FLESH.getDefaultState(), 2);
		world.setBlockState(pos.add(4, 0, 6), ModMetaBlocks.ZERG_FLESH.getDefaultState(), 2);
		world.setBlockState(pos.add(5, 0, 6), ModMetaBlocks.ZERG_FLESH.getDefaultState(), 2);
		world.setBlockState(pos.add(6, 0, 6), ModMetaBlocks.ZERG_FLESH.getDefaultState(), 2);
		world.setBlockState(pos.add(7, 0, 6), ModMetaBlocks.ZERG_FLESH.getDefaultState(), 2);
		world.setBlockState(pos.add(8, 0, 6), ModMetaBlocks.ZERG_FLESH.getDefaultState(), 2);
		world.setBlockState(pos.add(9, 0, 6), ModMetaBlocks.ZERG_FLESH.getDefaultState(), 2);
		world.setBlockState(pos.add(10, 0, 6), ModMetaBlocks.ZERG_FLESH.getDefaultState(), 2);
		world.setBlockState(pos.add(11, 0, 6), ModMetaBlocks.ZERG_FLESH.getDefaultState(), 2);
		world.setBlockState(pos.add(12, 0, 6), ModMetaBlocks.ZERG_FLESH.getDefaultState(), 2);
		world.setBlockState(pos.add(13, 0, 6), ModMetaBlocks.ZERG_FLESH.getDefaultState(), 2);
		world.setBlockState(pos.add(4, 0, 7), ModMetaBlocks.ZERG_FLESH.getDefaultState(), 2);
		world.setBlockState(pos.add(5, 0, 7), ModMetaBlocks.ZERG_FLESH.getDefaultState(), 2);
		world.setBlockState(pos.add(6, 0, 7), ModMetaBlocks.ZERG_FLESH.getDefaultState(), 2);
		world.setBlockState(pos.add(7, 0, 7), ModMetaBlocks.ZERG_FLESH.getDefaultState(), 2);
		world.setBlockState(pos.add(8, 0, 7), ModMetaBlocks.ZERG_FLESH.getDefaultState(), 2);
		world.setBlockState(pos.add(9, 0, 7), ModMetaBlocks.ZERG_FLESH.getDefaultState(), 2);
		world.setBlockState(pos.add(10, 0, 7), ModMetaBlocks.ZERG_FLESH.getDefaultState(), 2);
		world.setBlockState(pos.add(11, 0, 7), ModMetaBlocks.ZERG_FLESH.getDefaultState(), 2);
		world.setBlockState(pos.add(12, 0, 7), ModMetaBlocks.ZERG_FLESH.getDefaultState(), 2);
		world.setBlockState(pos.add(13, 0, 7), ModMetaBlocks.ZERG_FLESH.getDefaultState(), 2);
		world.setBlockState(pos.add(14, 0, 7), ModMetaBlocks.ZERG_FLESH.getDefaultState(), 2);
		world.setBlockState(pos.add(3, 0, 8), ModMetaBlocks.ZERG_FLESH.getDefaultState(), 2);
		world.setBlockState(pos.add(4, 0, 8), ModMetaBlocks.ZERG_FLESH.getDefaultState(), 2);
		world.setBlockState(pos.add(5, 0, 8), ModMetaBlocks.ZERG_FLESH.getDefaultState(), 2);
		world.setBlockState(pos.add(6, 0, 8), ModMetaBlocks.ZERG_FLESH.getDefaultState(), 2);
		world.setBlockState(pos.add(7, 0, 8), ModMetaBlocks.ZERG_FLESH.getDefaultState(), 2);
		world.setBlockState(pos.add(8, 0, 8), ModMetaBlocks.ZERG_FLESH.getDefaultState(), 2);
		world.setBlockState(pos.add(9, 0, 8), ModMetaBlocks.ZERG_FLESH.getDefaultState(), 2);
		world.setBlockState(pos.add(10, 0, 8), ModMetaBlocks.ZERG_FLESH.getDefaultState(), 2);
		world.setBlockState(pos.add(11, 0, 8), ModMetaBlocks.ZERG_FLESH.getDefaultState(), 2);
		world.setBlockState(pos.add(12, 0, 8), ModMetaBlocks.ZERG_FLESH.getDefaultState(), 2);
		world.setBlockState(pos.add(13, 0, 8), ModMetaBlocks.ZERG_FLESH.getDefaultState(), 2);
		world.setBlockState(pos.add(14, 0, 8), ModMetaBlocks.ZERG_FLESH.getDefaultState(), 2);
		world.setBlockState(pos.add(15, 0, 8), ModMetaBlocks.ZERG_FLESH.getDefaultState(), 2);
		world.setBlockState(pos.add(3, 0, 9), ModMetaBlocks.ZERG_FLESH.getDefaultState(), 2);
		world.setBlockState(pos.add(4, 0, 9), ModMetaBlocks.ZERG_FLESH.getDefaultState(), 2);
		world.setBlockState(pos.add(5, 0, 9), ModMetaBlocks.ZERG_FLESH.getDefaultState(), 2);
		world.setBlockState(pos.add(6, 0, 9), ModMetaBlocks.ZERG_FLESH.getDefaultState(), 2);
		world.setBlockState(pos.add(7, 0, 9), ModMetaBlocks.ZERG_FLESH.getDefaultState(), 2);
		world.setBlockState(pos.add(8, 0, 9), ModMetaBlocks.ZERG_FLESH.getDefaultState(), 2);
		world.setBlockState(pos.add(9, 0, 9), ModMetaBlocks.ZERG_FLESH.getDefaultState(), 2);
		world.setBlockState(pos.add(10, 0, 9), ModMetaBlocks.ZERG_FLESH.getDefaultState(), 2);
		world.setBlockState(pos.add(11, 0, 9), ModMetaBlocks.ZERG_FLESH.getDefaultState(), 2);
		world.setBlockState(pos.add(12, 0, 9), ModMetaBlocks.ZERG_FLESH.getDefaultState(), 2);
		world.setBlockState(pos.add(13, 0, 9), ModMetaBlocks.ZERG_FLESH.getDefaultState(), 2);
		world.setBlockState(pos.add(14, 0, 9), ModMetaBlocks.ZERG_FLESH.getDefaultState(), 2);
		world.setBlockState(pos.add(15, 0, 9), ModMetaBlocks.ZERG_FLESH.getDefaultState(), 2);
		world.setBlockState(pos.add(3, 0, 10), ModMetaBlocks.ZERG_FLESH.getDefaultState(), 2);
		world.setBlockState(pos.add(4, 0, 10), ModMetaBlocks.ZERG_FLESH.getDefaultState(), 2);
		world.setBlockState(pos.add(5, 0, 10), ModMetaBlocks.ZERG_FLESH.getDefaultState(), 2);
		world.setBlockState(pos.add(6, 0, 10), ModMetaBlocks.ZERG_FLESH.getDefaultState(), 2);
		world.setBlockState(pos.add(7, 0, 10), ModMetaBlocks.ZERG_FLESH.getDefaultState(), 2);
		world.setBlockState(pos.add(8, 0, 10), ModMetaBlocks.ZERG_FLESH.getDefaultState(), 2);
		world.setBlockState(pos.add(9, 0, 10), ModMetaBlocks.ZERG_FLESH.getDefaultState(), 2);
		world.setBlockState(pos.add(10, 0, 10), ModMetaBlocks.ZERG_FLESH.getDefaultState(), 2);
		world.setBlockState(pos.add(11, 0, 10), ModMetaBlocks.ZERG_FLESH.getDefaultState(), 2);
		world.setBlockState(pos.add(12, 0, 10), ModMetaBlocks.ZERG_FLESH.getDefaultState(), 2);
		world.setBlockState(pos.add(13, 0, 10), ModMetaBlocks.ZERG_FLESH.getDefaultState(), 2);
		world.setBlockState(pos.add(14, 0, 10), ModMetaBlocks.ZERG_FLESH.getDefaultState(), 2);
		world.setBlockState(pos.add(15, 0, 10), ModMetaBlocks.ZERG_FLESH.getDefaultState(), 2);
		world.setBlockState(pos.add(3, 0, 11), ModMetaBlocks.ZERG_FLESH.getDefaultState(), 2);
		world.setBlockState(pos.add(4, 0, 11), ModMetaBlocks.ZERG_FLESH.getDefaultState(), 2);
		world.setBlockState(pos.add(5, 0, 11), ModMetaBlocks.ZERG_FLESH.getDefaultState(), 2);
		world.setBlockState(pos.add(6, 0, 11), ModMetaBlocks.ZERG_FLESH.getDefaultState(), 2);
		world.setBlockState(pos.add(7, 0, 11), ModMetaBlocks.ZERG_FLESH.getDefaultState(), 2);
		world.setBlockState(pos.add(8, 0, 11), ModMetaBlocks.ZERG_FLESH.getDefaultState(), 2);
		world.setBlockState(pos.add(9, 0, 11), ModMetaBlocks.ZERG_FLESH.getDefaultState(), 2);
		world.setBlockState(pos.add(10, 0, 11), ModMetaBlocks.ZERG_FLESH.getDefaultState(), 2);
		world.setBlockState(pos.add(11, 0, 11), ModMetaBlocks.ZERG_FLESH.getDefaultState(), 2);
		world.setBlockState(pos.add(12, 0, 11), ModMetaBlocks.ZERG_FLESH.getDefaultState(), 2);
		world.setBlockState(pos.add(13, 0, 11), ModMetaBlocks.ZERG_FLESH.getDefaultState(), 2);
		world.setBlockState(pos.add(14, 0, 11), ModMetaBlocks.ZERG_FLESH.getDefaultState(), 2);
		world.setBlockState(pos.add(15, 0, 11), ModMetaBlocks.ZERG_FLESH.getDefaultState(), 2);
		world.setBlockState(pos.add(3, 0, 12), ModMetaBlocks.ZERG_FLESH.getDefaultState(), 2);
		world.setBlockState(pos.add(4, 0, 12), ModMetaBlocks.ZERG_FLESH.getDefaultState(), 2);
		world.setBlockState(pos.add(5, 0, 12), ModMetaBlocks.ZERG_FLESH.getDefaultState(), 2);
		world.setBlockState(pos.add(6, 0, 12), ModMetaBlocks.ZERG_FLESH.getDefaultState(), 2);
		world.setBlockState(pos.add(7, 0, 12), ModMetaBlocks.ZERG_FLESH.getDefaultState(), 2);
		world.setBlockState(pos.add(8, 0, 12), ModMetaBlocks.ZERG_FLESH.getDefaultState(), 2);
		world.setBlockState(pos.add(9, 0, 12), ModMetaBlocks.ZERG_FLESH.getDefaultState(), 2);
		world.setBlockState(pos.add(10, 0, 12), ModMetaBlocks.ZERG_FLESH.getDefaultState(), 2);
		world.setBlockState(pos.add(11, 0, 12), ModMetaBlocks.ZERG_FLESH.getDefaultState(), 2);
		world.setBlockState(pos.add(12, 0, 12), ModMetaBlocks.ZERG_FLESH.getDefaultState(), 2);
		world.setBlockState(pos.add(13, 0, 12), ModMetaBlocks.ZERG_FLESH.getDefaultState(), 2);
		world.setBlockState(pos.add(14, 0, 12), ModMetaBlocks.ZERG_FLESH.getDefaultState(), 2);
		world.setBlockState(pos.add(15, 0, 12), ModMetaBlocks.ZERG_FLESH.getDefaultState(), 2);
		world.setBlockState(pos.add(3, 0, 13), ModMetaBlocks.ZERG_FLESH.getDefaultState(), 2);
		world.setBlockState(pos.add(4, 0, 13), ModMetaBlocks.ZERG_FLESH.getDefaultState(), 2);
		world.setBlockState(pos.add(5, 0, 13), ModMetaBlocks.ZERG_FLESH.getDefaultState(), 2);
		world.setBlockState(pos.add(6, 0, 13), ModMetaBlocks.ZERG_FLESH.getDefaultState(), 2);
		world.setBlockState(pos.add(7, 0, 13), ModMetaBlocks.ZERG_FLESH.getDefaultState(), 2);
		world.setBlockState(pos.add(8, 0, 13), ModMetaBlocks.ZERG_FLESH.getDefaultState(), 2);
		world.setBlockState(pos.add(9, 0, 13), ModMetaBlocks.ZERG_FLESH.getDefaultState(), 2);
		world.setBlockState(pos.add(10, 0, 13), ModMetaBlocks.ZERG_FLESH.getDefaultState(), 2);
		world.setBlockState(pos.add(11, 0, 13), ModMetaBlocks.ZERG_FLESH.getDefaultState(), 2);
		world.setBlockState(pos.add(12, 0, 13), ModMetaBlocks.ZERG_FLESH.getDefaultState(), 2);
		world.setBlockState(pos.add(13, 0, 13), ModMetaBlocks.ZERG_FLESH.getDefaultState(), 2);
		world.setBlockState(pos.add(14, 0, 13), ModMetaBlocks.ZERG_FLESH.getDefaultState(), 2);
		world.setBlockState(pos.add(15, 0, 13), ModMetaBlocks.ZERG_FLESH.getDefaultState(), 2);
		world.setBlockState(pos.add(3, 0, 14), ModMetaBlocks.ZERG_FLESH.getDefaultState(), 2);
		world.setBlockState(pos.add(4, 0, 14), ModMetaBlocks.ZERG_FLESH.getDefaultState(), 2);
		world.setBlockState(pos.add(5, 0, 14), ModMetaBlocks.ZERG_FLESH.getDefaultState(), 2);
		world.setBlockState(pos.add(6, 0, 14), ModMetaBlocks.ZERG_FLESH.getDefaultState(), 2);
		world.setBlockState(pos.add(7, 0, 14), ModMetaBlocks.ZERG_FLESH.getDefaultState(), 2);
		world.setBlockState(pos.add(8, 0, 14), ModMetaBlocks.ZERG_FLESH.getDefaultState(), 2);
		world.setBlockState(pos.add(9, 0, 14), ModMetaBlocks.ZERG_FLESH.getDefaultState(), 2);
		world.setBlockState(pos.add(10, 0, 14), ModMetaBlocks.ZERG_FLESH.getDefaultState(), 2);
		world.setBlockState(pos.add(11, 0, 14), ModMetaBlocks.ZERG_FLESH.getDefaultState(), 2);
		world.setBlockState(pos.add(12, 0, 14), ModMetaBlocks.ZERG_FLESH.getDefaultState(), 2);
		world.setBlockState(pos.add(13, 0, 14), ModMetaBlocks.ZERG_FLESH.getDefaultState(), 2);
		world.setBlockState(pos.add(14, 0, 14), ModMetaBlocks.ZERG_FLESH.getDefaultState(), 2);
		world.setBlockState(pos.add(15, 0, 14), ModMetaBlocks.ZERG_FLESH.getDefaultState(), 2);
		world.setBlockState(pos.add(3, 0, 15), ModMetaBlocks.ZERG_FLESH.getDefaultState(), 2);
		world.setBlockState(pos.add(4, 0, 15), ModMetaBlocks.ZERG_FLESH.getDefaultState(), 2);
		world.setBlockState(pos.add(5, 0, 15), ModMetaBlocks.ZERG_FLESH.getDefaultState(), 2);
		world.setBlockState(pos.add(6, 0, 15), ModMetaBlocks.ZERG_FLESH.getDefaultState(), 2);
		world.setBlockState(pos.add(7, 0, 15), ModMetaBlocks.ZERG_FLESH.getDefaultState(), 2);
		world.setBlockState(pos.add(8, 0, 15), ModMetaBlocks.ZERG_FLESH.getDefaultState(), 2);
		world.setBlockState(pos.add(9, 0, 15), ModMetaBlocks.ZERG_FLESH.getDefaultState(), 2);
		world.setBlockState(pos.add(10, 0, 15), ModMetaBlocks.ZERG_FLESH.getDefaultState(), 2);
		world.setBlockState(pos.add(11, 0, 15), ModMetaBlocks.ZERG_FLESH.getDefaultState(), 2);
		world.setBlockState(pos.add(12, 0, 15), ModMetaBlocks.ZERG_FLESH.getDefaultState(), 2);
		world.setBlockState(pos.add(13, 0, 15), ModMetaBlocks.ZERG_FLESH.getDefaultState(), 2);
		world.setBlockState(pos.add(14, 0, 15), ModMetaBlocks.ZERG_FLESH.getDefaultState(), 2);
		world.setBlockState(pos.add(15, 0, 15), ModMetaBlocks.ZERG_FLESH.getDefaultState(), 2);
		world.setBlockState(pos.add(16, 0, 15), ModMetaBlocks.ZERG_FLESH.getDefaultState(), 2);
		world.setBlockState(pos.add(18, 0, 15), ModMetaBlocks.ZERG_FLESH.getDefaultState(), 2);
		world.setBlockState(pos.add(2, 0, 16), ModMetaBlocks.ZERG_FLESH.getDefaultState(), 2);
		world.setBlockState(pos.add(3, 0, 16), ModMetaBlocks.ZERG_FLESH.getDefaultState(), 2);
		world.setBlockState(pos.add(4, 0, 16), ModMetaBlocks.ZERG_FLESH.getDefaultState(), 2);
		world.setBlockState(pos.add(5, 0, 16), ModMetaBlocks.ZERG_FLESH.getDefaultState(), 2);
		world.setBlockState(pos.add(6, 0, 16), ModMetaBlocks.ZERG_FLESH.getDefaultState(), 2);
		world.setBlockState(pos.add(7, 0, 16), ModMetaBlocks.ZERG_FLESH.getDefaultState(), 2);
		world.setBlockState(pos.add(8, 0, 16), ModMetaBlocks.ZERG_FLESH.getDefaultState(), 2);
		world.setBlockState(pos.add(9, 0, 16), ModMetaBlocks.ZERG_FLESH.getDefaultState(), 2);
		world.setBlockState(pos.add(10, 0, 16), ModMetaBlocks.ZERG_FLESH.getDefaultState(), 2);
		world.setBlockState(pos.add(11, 0, 16), ModMetaBlocks.ZERG_FLESH.getDefaultState(), 2);
		world.setBlockState(pos.add(12, 0, 16), ModMetaBlocks.ZERG_FLESH.getDefaultState(), 2);
		world.setBlockState(pos.add(13, 0, 16), ModMetaBlocks.ZERG_FLESH.getDefaultState(), 2);
		world.setBlockState(pos.add(14, 0, 16), ModMetaBlocks.ZERG_FLESH.getDefaultState(), 2);
		world.setBlockState(pos.add(16, 0, 16), ModMetaBlocks.ZERG_FLESH.getDefaultState(), 2);
		world.setBlockState(pos.add(17, 0, 16), ModMetaBlocks.ZERG_FLESH.getDefaultState(), 2);
		world.setBlockState(pos.add(0, 0, 17), ModMetaBlocks.ZERG_FLESH.getDefaultState(), 2);
		world.setBlockState(pos.add(1, 0, 17), ModMetaBlocks.ZERG_FLESH.getDefaultState(), 2);
		world.setBlockState(pos.add(3, 0, 17), ModMetaBlocks.ZERG_FLESH.getDefaultState(), 2);
		world.setBlockState(pos.add(14, 0, 17), ModMetaBlocks.ZERG_FLESH.getDefaultState(), 2);
		world.setBlockState(pos.add(3, 0, 18), ModMetaBlocks.ZERG_FLESH.getDefaultState(), 2);
		world.setBlockState(pos.add(13, 0, 18), ModMetaBlocks.ZERG_FLESH.getDefaultState(), 2);
		world.setBlockState(pos.add(4, 0, 19), ModMetaBlocks.ZERG_FLESH.getDefaultState(), 2);
		world.setBlockState(pos.add(14, 0, 19), ModMetaBlocks.ZERG_FLESH.getDefaultState(), 2);
		
		//Second Level
		world.setBlockState(pos.add(8, 1, 4), ModMetaBlocks.ZERG_FLESH.getDefaultState(), 2);
		world.setBlockState(pos.add(6, 1, 5), ModMetaBlocks.ZERG_FLESH.getDefaultState(), 2);
		world.setBlockState(pos.add(7, 1, 5), ModMetaBlocks.ZERG_FLESH.getDefaultState(), 2);
		world.setBlockState(pos.add(8, 1, 5), ModMetaBlocks.ZERG_FLESH.getDefaultState(), 2);
		world.setBlockState(pos.add(9, 1, 5), ModMetaBlocks.ZERG_FLESH.getDefaultState(), 2);
		world.setBlockState(pos.add(10, 1, 5), ModMetaBlocks.ZERG_FLESH.getDefaultState(), 2);
		world.setBlockState(pos.add(11, 1, 5), ModMetaBlocks.ZERG_FLESH.getDefaultState(), 2);
		world.setBlockState(pos.add(12, 1, 5), ModMetaBlocks.ZERG_FLESH.getDefaultState(), 2);
		world.setBlockState(pos.add(5, 1, 6), ModMetaBlocks.ZERG_FLESH.getDefaultState(), 2);
		world.setBlockState(pos.add(6, 1, 6), ModMetaBlocks.ZERG_FLESH.getDefaultState(), 2);
		world.setBlockState(pos.add(7, 1, 6), ModMetaBlocks.ZERG_FLESH.getDefaultState(), 2);
		world.setBlockState(pos.add(8, 1, 6), ModMetaBlocks.ZERG_FLESH.getDefaultState(), 2);
		world.setBlockState(pos.add(9, 1, 6), ModMetaBlocks.ZERG_FLESH.getDefaultState(), 2);
		world.setBlockState(pos.add(10, 1, 6), ModMetaBlocks.ZERG_FLESH.getDefaultState(), 2);
		world.setBlockState(pos.add(11, 1, 6), ModMetaBlocks.ZERG_FLESH.getDefaultState(), 2);
		world.setBlockState(pos.add(12, 1, 6), ModMetaBlocks.ZERG_FLESH.getDefaultState(), 2);
		world.setBlockState(pos.add(13, 1, 6), ModMetaBlocks.ZERG_FLESH.getDefaultState(), 2);
		world.setBlockState(pos.add(5, 1, 7), ModMetaBlocks.ZERG_FLESH.getDefaultState(), 2);
		world.setBlockState(pos.add(6, 1, 7), ModMetaBlocks.ZERG_FLESH.getDefaultState(), 2);
		world.setBlockState(pos.add(7, 1, 7), ModMetaBlocks.ZERG_FLESH.getDefaultState(), 2);
		world.setBlockState(pos.add(8, 1, 7), ModMetaBlocks.ZERG_FLESH.getDefaultState(), 2);
		world.setBlockState(pos.add(9, 1, 7), ModMetaBlocks.ZERG_FLESH.getDefaultState(), 2);
		world.setBlockState(pos.add(10, 1, 7), ModMetaBlocks.ZERG_FLESH.getDefaultState(), 2);
		world.setBlockState(pos.add(11, 1, 7), ModMetaBlocks.ZERG_FLESH.getDefaultState(), 2);
		world.setBlockState(pos.add(12, 1, 7), ModMetaBlocks.ZERG_FLESH.getDefaultState(), 2);
		world.setBlockState(pos.add(13, 1, 7), ModMetaBlocks.ZERG_FLESH.getDefaultState(), 2);
		world.setBlockState(pos.add(4, 1, 8), ModMetaBlocks.ZERG_FLESH.getDefaultState(), 2);
		world.setBlockState(pos.add(5, 1, 8), ModMetaBlocks.ZERG_FLESH.getDefaultState(), 2);
		world.setBlockState(pos.add(6, 1, 8), ModMetaBlocks.ZERG_FLESH.getDefaultState(), 2);
		world.setBlockState(pos.add(7, 1, 8), ModBlocks.FLUID_ACID.getDefaultState(), 2);
		world.setBlockState(pos.add(8, 1, 8), ModBlocks.FLUID_ACID.getDefaultState(), 2);
		world.setBlockState(pos.add(9, 1, 8), ModBlocks.FLUID_ACID.getDefaultState(), 2);
		world.setBlockState(pos.add(10, 1, 8), ModMetaBlocks.ZERG_FLESH.getDefaultState(), 2);
		world.setBlockState(pos.add(11, 1, 8), ModMetaBlocks.ZERG_FLESH.getDefaultState(), 2);
		world.setBlockState(pos.add(12, 1, 8), ModMetaBlocks.ZERG_FLESH.getDefaultState(), 2);
		world.setBlockState(pos.add(13, 1, 8), ModMetaBlocks.ZERG_FLESH.getDefaultState(), 2);
		world.setBlockState(pos.add(14, 1, 8), ModMetaBlocks.ZERG_FLESH.getDefaultState(), 2);
		world.setBlockState(pos.add(4, 1, 9), ModMetaBlocks.ZERG_FLESH.getDefaultState(), 2);
		world.setBlockState(pos.add(5, 1, 9), ModMetaBlocks.ZERG_FLESH.getDefaultState(), 2);
		world.setBlockState(pos.add(6, 1, 9), ModMetaBlocks.ZERG_FLESH.getDefaultState(), 2);
		world.setBlockState(pos.add(7, 1, 9), ModBlocks.FLUID_ACID.getDefaultState(), 2);
		world.setBlockState(pos.add(8, 1, 9), ModBlocks.FLUID_ACID.getDefaultState(), 2);
		world.setBlockState(pos.add(9, 1, 9), ModBlocks.FLUID_ACID.getDefaultState(), 2);
		world.setBlockState(pos.add(10, 1, 9), ModBlocks.FLUID_ACID.getDefaultState(), 2);
		world.setBlockState(pos.add(11, 1, 9), ModMetaBlocks.ZERG_FLESH.getDefaultState(), 2);
		world.setBlockState(pos.add(12, 1, 9), ModMetaBlocks.ZERG_FLESH.getDefaultState(), 2);
		world.setBlockState(pos.add(13, 1, 9), ModMetaBlocks.ZERG_FLESH.getDefaultState(), 2);
		world.setBlockState(pos.add(14, 1, 9), ModMetaBlocks.ZERG_FLESH.getDefaultState(), 2);
		world.setBlockState(pos.add(4, 1, 10), ModMetaBlocks.ZERG_FLESH.getDefaultState(), 2);
		world.setBlockState(pos.add(5, 1, 10), ModMetaBlocks.ZERG_FLESH.getDefaultState(), 2);
		world.setBlockState(pos.add(6, 1, 10), ModMetaBlocks.ZERG_FLESH.getDefaultState(), 2);
		world.setBlockState(pos.add(7, 1, 10), ModBlocks.FLUID_ACID.getDefaultState(), 2);
		world.setBlockState(pos.add(8, 1, 10), ModBlocks.FLUID_ACID.getDefaultState(), 2);
		world.setBlockState(pos.add(9, 1, 10), ModBlocks.FLUID_ACID.getDefaultState(), 2);
		world.setBlockState(pos.add(10, 1, 10), ModBlocks.FLUID_ACID.getDefaultState(), 2);
		world.setBlockState(pos.add(11, 1, 10), ModBlocks.FLUID_ACID.getDefaultState(), 2);
		world.setBlockState(pos.add(12, 1, 10), ModMetaBlocks.ZERG_FLESH.getDefaultState(), 2);
		world.setBlockState(pos.add(13, 1, 10), ModMetaBlocks.ZERG_FLESH.getDefaultState(), 2);
		world.setBlockState(pos.add(14, 1, 10), ModMetaBlocks.ZERG_FLESH.getDefaultState(), 2);
		world.setBlockState(pos.add(4, 1, 11), ModMetaBlocks.ZERG_FLESH.getDefaultState(), 2);
		world.setBlockState(pos.add(5, 1, 11), ModMetaBlocks.ZERG_FLESH.getDefaultState(), 2);
		world.setBlockState(pos.add(6, 1, 11), ModMetaBlocks.ZERG_FLESH.getDefaultState(), 2);
		world.setBlockState(pos.add(7, 1, 11), ModMetaBlocks.ZERG_FLESH.getDefaultState(), 2);
		world.setBlockState(pos.add(8, 1, 11), ModBlocks.FLUID_ACID.getDefaultState(), 2);
		world.setBlockState(pos.add(9, 1, 11), ModBlocks.FLUID_ACID.getDefaultState(), 2);
		world.setBlockState(pos.add(10, 1, 11), ModBlocks.FLUID_ACID.getDefaultState(), 2);
		world.setBlockState(pos.add(11, 1, 11), ModBlocks.FLUID_ACID.getDefaultState(), 2);
		world.setBlockState(pos.add(12, 1, 11), ModMetaBlocks.ZERG_FLESH.getDefaultState(), 2);
		world.setBlockState(pos.add(13, 1, 11), ModMetaBlocks.ZERG_FLESH.getDefaultState(), 2);
		world.setBlockState(pos.add(14, 1, 11), ModMetaBlocks.ZERG_FLESH.getDefaultState(), 2);
		world.setBlockState(pos.add(4, 1, 12), ModMetaBlocks.ZERG_FLESH.getDefaultState(), 2);
		world.setBlockState(pos.add(5, 1, 12), ModMetaBlocks.ZERG_FLESH.getDefaultState(), 2);
		world.setBlockState(pos.add(6, 1, 12), ModMetaBlocks.ZERG_FLESH.getDefaultState(), 2);
		world.setBlockState(pos.add(7, 1, 12), ModMetaBlocks.ZERG_FLESH.getDefaultState(), 2);
		world.setBlockState(pos.add(8, 1, 12), ModMetaBlocks.ZERG_FLESH.getDefaultState(), 2);
		world.setBlockState(pos.add(9, 1, 12), ModBlocks.FLUID_ACID.getDefaultState(), 2);
		world.setBlockState(pos.add(10, 1, 12), ModBlocks.FLUID_ACID.getDefaultState(), 2);
		world.setBlockState(pos.add(11, 1, 12), ModBlocks.FLUID_ACID.getDefaultState(), 2);
		world.setBlockState(pos.add(12, 1, 12), ModMetaBlocks.ZERG_FLESH.getDefaultState(), 2);
		world.setBlockState(pos.add(13, 1, 12), ModMetaBlocks.ZERG_FLESH.getDefaultState(), 2);
		world.setBlockState(pos.add(14, 1, 12), ModMetaBlocks.ZERG_FLESH.getDefaultState(), 2);
		world.setBlockState(pos.add(4, 1, 13), ModMetaBlocks.ZERG_FLESH.getDefaultState(), 2);
		world.setBlockState(pos.add(5, 1, 13), ModMetaBlocks.ZERG_FLESH.getDefaultState(), 2);
		world.setBlockState(pos.add(6, 1, 13), ModMetaBlocks.ZERG_FLESH.getDefaultState(), 2);
		world.setBlockState(pos.add(7, 1, 13), ModMetaBlocks.ZERG_FLESH.getDefaultState(), 2);
		world.setBlockState(pos.add(8, 1, 13), ModMetaBlocks.ZERG_FLESH.getDefaultState(), 2);
		world.setBlockState(pos.add(9, 1, 13), ModMetaBlocks.ZERG_FLESH.getDefaultState(), 2);
		world.setBlockState(pos.add(10, 1, 13), ModMetaBlocks.ZERG_FLESH.getDefaultState(), 2);
		world.setBlockState(pos.add(11, 1, 13), ModMetaBlocks.ZERG_FLESH.getDefaultState(), 2);
		world.setBlockState(pos.add(12, 1, 13), ModMetaBlocks.ZERG_FLESH.getDefaultState(), 2);
		world.setBlockState(pos.add(13, 1, 13), ModMetaBlocks.ZERG_FLESH.getDefaultState(), 2);
		world.setBlockState(pos.add(14, 1, 13), ModMetaBlocks.ZERG_FLESH.getDefaultState(), 2);
		world.setBlockState(pos.add(4, 1, 14), ModMetaBlocks.ZERG_FLESH.getDefaultState(), 2);
		world.setBlockState(pos.add(5, 1, 14), ModMetaBlocks.ZERG_FLESH.getDefaultState(), 2);
		world.setBlockState(pos.add(6, 1, 14), ModMetaBlocks.ZERG_FLESH.getDefaultState(), 2);
		world.setBlockState(pos.add(7, 1, 14), ModMetaBlocks.ZERG_FLESH.getDefaultState(), 2);
		world.setBlockState(pos.add(8, 1, 14), ModMetaBlocks.ZERG_FLESH.getDefaultState(), 2);
		world.setBlockState(pos.add(9, 1, 14), ModMetaBlocks.ZERG_FLESH.getDefaultState(), 2);
		world.setBlockState(pos.add(10, 1, 14), ModMetaBlocks.ZERG_FLESH.getDefaultState(), 2);
		world.setBlockState(pos.add(11, 1, 14), ModMetaBlocks.ZERG_FLESH.getDefaultState(), 2);
		world.setBlockState(pos.add(12, 1, 14), ModMetaBlocks.ZERG_FLESH.getDefaultState(), 2);
		world.setBlockState(pos.add(13, 1, 14), ModMetaBlocks.ZERG_FLESH.getDefaultState(), 2);
		world.setBlockState(pos.add(14, 1, 14), ModMetaBlocks.ZERG_FLESH.getDefaultState(), 2);
		world.setBlockState(pos.add(4, 1, 15), ModMetaBlocks.ZERG_FLESH.getDefaultState(), 2);
		world.setBlockState(pos.add(5, 1, 15), ModMetaBlocks.ZERG_FLESH.getDefaultState(), 2);
		world.setBlockState(pos.add(6, 1, 15), ModMetaBlocks.ZERG_FLESH.getDefaultState(), 2);
		world.setBlockState(pos.add(7, 1, 15), ModMetaBlocks.ZERG_FLESH.getDefaultState(), 2);
		world.setBlockState(pos.add(8, 1, 15), ModMetaBlocks.ZERG_FLESH.getDefaultState(), 2);
		world.setBlockState(pos.add(9, 1, 15), ModMetaBlocks.ZERG_FLESH.getDefaultState(), 2);
		world.setBlockState(pos.add(10, 1, 15), ModMetaBlocks.ZERG_FLESH.getDefaultState(), 2);
		world.setBlockState(pos.add(11, 1, 15), ModMetaBlocks.ZERG_FLESH.getDefaultState(), 2);
		world.setBlockState(pos.add(12, 1, 15), ModMetaBlocks.ZERG_FLESH.getDefaultState(), 2);
		world.setBlockState(pos.add(13, 1, 15), ModMetaBlocks.ZERG_FLESH.getDefaultState(), 2);
		
		//Third Level
		world.setBlockState(pos.add(7, 2, 5), ModMetaBlocks.ZERG_FLESH.getDefaultState(), 2);
		world.setBlockState(pos.add(8, 2, 5), ModMetaBlocks.ZERG_FLESH.getDefaultState(), 2);
		world.setBlockState(pos.add(9, 2, 5), ModMetaBlocks.ZERG_FLESH.getDefaultState(), 2);
		world.setBlockState(pos.add(10, 2, 5), ModMetaBlocks.ZERG_FLESH.getDefaultState(), 2);
		world.setBlockState(pos.add(11, 2, 5), ModMetaBlocks.ZERG_FLESH.getDefaultState(), 2);
		world.setBlockState(pos.add(5, 2, 6), ModMetaBlocks.ZERG_FLESH.getDefaultState(), 2);
		world.setBlockState(pos.add(6, 2, 6), ModMetaBlocks.ZERG_FLESH.getDefaultState(), 2);
		world.setBlockState(pos.add(7, 2, 6), ModMetaBlocks.ZERG_FLESH.getDefaultState(), 2);
		world.setBlockState(pos.add(8, 2, 6), ModMetaBlocks.ZERG_FLESH.getDefaultState(), 2);
		world.setBlockState(pos.add(9, 2, 6), ModMetaBlocks.ZERG_FLESH.getDefaultState(), 2);
		world.setBlockState(pos.add(10, 2, 6), ModMetaBlocks.ZERG_FLESH.getDefaultState(), 2);
		world.setBlockState(pos.add(11, 2, 6), ModMetaBlocks.ZERG_FLESH.getDefaultState(), 2);
		world.setBlockState(pos.add(12, 2, 6), ModMetaBlocks.ZERG_FLESH.getDefaultState(), 2);
		world.setBlockState(pos.add(5, 2, 7), ModMetaBlocks.ZERG_FLESH.getDefaultState(), 2);
		world.setBlockState(pos.add(6, 2, 7), ModMetaBlocks.ZERG_FLESH.getDefaultState(), 2);
		world.setBlockState(pos.add(7, 2, 7), ModMetaBlocks.ZERG_FLESH.getDefaultState(), 2);
		world.setBlockState(pos.add(8, 2, 7), ModMetaBlocks.ZERG_FLESH.getDefaultState(), 2);
		world.setBlockState(pos.add(9, 2, 7), ModMetaBlocks.ZERG_FLESH.getDefaultState(), 2);
		world.setBlockState(pos.add(10, 2, 7), ModMetaBlocks.ZERG_FLESH.getDefaultState(), 2);
		world.setBlockState(pos.add(11, 2, 7), ModMetaBlocks.ZERG_FLESH.getDefaultState(), 2);
		world.setBlockState(pos.add(12, 2, 7), ModMetaBlocks.ZERG_FLESH.getDefaultState(), 2);
		world.setBlockState(pos.add(13, 2, 7), ModMetaBlocks.ZERG_FLESH.getDefaultState(), 2);
		world.setBlockState(pos.add(4, 2, 8), ModMetaBlocks.ZERG_FLESH.getDefaultState(), 2);
		world.setBlockState(pos.add(5, 2, 8), ModMetaBlocks.ZERG_FLESH.getDefaultState(), 2);
		world.setBlockState(pos.add(6, 2, 8), ModMetaBlocks.ZERG_FLESH.getDefaultState(), 2);
		world.setBlockState(pos.add(7, 2, 8), ModBlocks.FLUID_ACID.getDefaultState(), 2);
		world.setBlockState(pos.add(8, 2, 8), ModBlocks.FLUID_ACID.getDefaultState(), 2);
		world.setBlockState(pos.add(9, 2, 8), ModBlocks.FLUID_ACID.getDefaultState(), 2);
		world.setBlockState(pos.add(10, 2, 8), ModBlocks.FLUID_ACID.getDefaultState(), 2);
		world.setBlockState(pos.add(11, 2, 8), ModMetaBlocks.ZERG_FLESH.getDefaultState(), 2);
		world.setBlockState(pos.add(12, 2, 8), ModMetaBlocks.ZERG_FLESH.getDefaultState(), 2);
		world.setBlockState(pos.add(13, 2, 8), ModMetaBlocks.ZERG_FLESH.getDefaultState(), 2);
		world.setBlockState(pos.add(14, 2, 8), ModMetaBlocks.ZERG_FLESH.getDefaultState(), 2);
		world.setBlockState(pos.add(4, 2, 9), ModMetaBlocks.ZERG_FLESH.getDefaultState(), 2);
		world.setBlockState(pos.add(5, 2, 9), ModMetaBlocks.ZERG_FLESH.getDefaultState(), 2);
		world.setBlockState(pos.add(6, 2, 9), ModMetaBlocks.ZERG_FLESH.getDefaultState(), 2);
		world.setBlockState(pos.add(7, 2, 9), ModBlocks.FLUID_ACID.getDefaultState(), 2);
		world.setBlockState(pos.add(8, 2, 9), ModBlocks.FLUID_ACID.getDefaultState(), 2);
		world.setBlockState(pos.add(9, 2, 9), ModBlocks.FLUID_ACID.getDefaultState(), 2);
		world.setBlockState(pos.add(10, 2, 9), ModBlocks.FLUID_ACID.getDefaultState(), 2);
		world.setBlockState(pos.add(11, 2, 9), ModBlocks.FLUID_ACID.getDefaultState(), 2);
		world.setBlockState(pos.add(12, 2, 9), ModMetaBlocks.ZERG_FLESH.getDefaultState(), 2);
		world.setBlockState(pos.add(13, 2, 9), ModMetaBlocks.ZERG_FLESH.getDefaultState(), 2);
		world.setBlockState(pos.add(14, 2, 9), ModMetaBlocks.ZERG_FLESH.getDefaultState(), 2);
		world.setBlockState(pos.add(4, 2, 10), ModMetaBlocks.ZERG_FLESH.getDefaultState(), 2);
		world.setBlockState(pos.add(5, 2, 10), ModMetaBlocks.ZERG_FLESH.getDefaultState(), 2);
		world.setBlockState(pos.add(6, 2, 10), ModMetaBlocks.ZERG_FLESH.getDefaultState(), 2);
		world.setBlockState(pos.add(7, 2, 10), ModBlocks.FLUID_ACID.getDefaultState(), 2);
		world.setBlockState(pos.add(8, 2, 10), ModBlocks.FLUID_ACID.getDefaultState(), 2);
		world.setBlockState(pos.add(9, 2, 10), ModBlocks.FLUID_ACID.getDefaultState(), 2);
		world.setBlockState(pos.add(10, 2, 10), ModBlocks.FLUID_ACID.getDefaultState(), 2);
		world.setBlockState(pos.add(11, 2, 10), ModBlocks.FLUID_ACID.getDefaultState(), 2);
		world.setBlockState(pos.add(12, 2, 10), ModMetaBlocks.ZERG_FLESH.getDefaultState(), 2);
		world.setBlockState(pos.add(13, 2, 10), ModMetaBlocks.ZERG_FLESH.getDefaultState(), 2);
		world.setBlockState(pos.add(14, 2, 10), ModMetaBlocks.ZERG_FLESH.getDefaultState(), 2);
		world.setBlockState(pos.add(4, 2, 11), ModMetaBlocks.ZERG_FLESH.getDefaultState(), 2);
		world.setBlockState(pos.add(5, 2, 11), ModMetaBlocks.ZERG_FLESH.getDefaultState(), 2);
		world.setBlockState(pos.add(6, 2, 11), ModMetaBlocks.ZERG_FLESH.getDefaultState(), 2);
		world.setBlockState(pos.add(7, 2, 11), ModBlocks.FLUID_ACID.getDefaultState(), 2);
		world.setBlockState(pos.add(8, 2, 11), ModBlocks.FLUID_ACID.getDefaultState(), 2);
		world.setBlockState(pos.add(9, 2, 11), ModBlocks.FLUID_ACID.getDefaultState(), 2);
		world.setBlockState(pos.add(10, 2, 11), ModBlocks.FLUID_ACID.getDefaultState(), 2);
		world.setBlockState(pos.add(11, 2, 11), ModBlocks.FLUID_ACID.getDefaultState(), 2);
		world.setBlockState(pos.add(12, 2, 11), ModMetaBlocks.ZERG_FLESH.getDefaultState(), 2);
		world.setBlockState(pos.add(13, 2, 11), ModMetaBlocks.ZERG_FLESH.getDefaultState(), 2);
		world.setBlockState(pos.add(14, 2, 11), ModMetaBlocks.ZERG_FLESH.getDefaultState(), 2);
		world.setBlockState(pos.add(4, 2, 12), ModMetaBlocks.ZERG_FLESH.getDefaultState(), 2);
		world.setBlockState(pos.add(5, 2, 12), ModMetaBlocks.ZERG_FLESH.getDefaultState(), 2);
		world.setBlockState(pos.add(6, 2, 12), ModMetaBlocks.ZERG_FLESH.getDefaultState(), 2);
		world.setBlockState(pos.add(7, 2, 12), ModMetaBlocks.ZERG_FLESH.getDefaultState(), 2);
		world.setBlockState(pos.add(8, 2, 12), ModBlocks.FLUID_ACID.getDefaultState(), 2);
		world.setBlockState(pos.add(9, 2, 12), ModBlocks.FLUID_ACID.getDefaultState(), 2);
		world.setBlockState(pos.add(10, 2, 12), ModBlocks.FLUID_ACID.getDefaultState(), 2);
		world.setBlockState(pos.add(11, 2, 12), ModBlocks.FLUID_ACID.getDefaultState(), 2);
		world.setBlockState(pos.add(12, 2, 12), ModMetaBlocks.ZERG_FLESH.getDefaultState(), 2);
		world.setBlockState(pos.add(13, 2, 12), ModBlocks.KERATIN_CHUNK.getDefaultState(), 2);
		world.setBlockState(pos.add(14, 2, 12), ModMetaBlocks.ZERG_FLESH.getDefaultState(), 2);
		world.setBlockState(pos.add(4, 2, 13), ModMetaBlocks.ZERG_FLESH.getDefaultState(), 2);
		world.setBlockState(pos.add(5, 2, 13), ModMetaBlocks.ZERG_FLESH.getDefaultState(), 2);
		world.setBlockState(pos.add(6, 2, 13), ModMetaBlocks.ZERG_FLESH.getDefaultState(), 2);
		world.setBlockState(pos.add(7, 2, 13), ModMetaBlocks.ZERG_FLESH.getDefaultState(), 2);
		world.setBlockState(pos.add(8, 2, 13), ModMetaBlocks.ZERG_FLESH.getDefaultState(), 2);
		world.setBlockState(pos.add(9, 2, 13), ModMetaBlocks.ZERG_FLESH.getDefaultState(), 2);
		world.setBlockState(pos.add(10, 2, 13), ModMetaBlocks.ZERG_FLESH.getDefaultState(), 2);
		world.setBlockState(pos.add(11, 2, 13), ModMetaBlocks.ZERG_FLESH.getDefaultState(), 2);
		world.setBlockState(pos.add(12, 2, 13), ModMetaBlocks.ZERG_FLESH.getDefaultState(), 2);
		world.setBlockState(pos.add(13, 2, 13), ModBlocks.KERATIN_CHUNK.getDefaultState(), 2);
		world.setBlockState(pos.add(14, 2, 13), ModMetaBlocks.ZERG_FLESH.getDefaultState(), 2);
		world.setBlockState(pos.add(4, 2, 14), ModMetaBlocks.ZERG_FLESH.getDefaultState(), 2);
		world.setBlockState(pos.add(5, 2, 14), ModMetaBlocks.ZERG_FLESH.getDefaultState(), 2);
		world.setBlockState(pos.add(6, 2, 14), ModMetaBlocks.ZERG_FLESH.getDefaultState(), 2);
		world.setBlockState(pos.add(7, 2, 14), ModMetaBlocks.ZERG_FLESH.getDefaultState(), 2);
		world.setBlockState(pos.add(8, 2, 14), ModMetaBlocks.ZERG_FLESH.getDefaultState(), 2);
		world.setBlockState(pos.add(9, 2, 14), ModMetaBlocks.ZERG_FLESH.getDefaultState(), 2);
		world.setBlockState(pos.add(10, 2, 14), ModMetaBlocks.ZERG_FLESH.getDefaultState(), 2);
		world.setBlockState(pos.add(11, 2, 14), ModMetaBlocks.ZERG_FLESH.getDefaultState(), 2);
		world.setBlockState(pos.add(12, 2, 14), ModBlocks.KERATIN_CHUNK.getDefaultState(), 2);
		world.setBlockState(pos.add(13, 2, 14), ModMetaBlocks.ZERG_FLESH.getDefaultState(), 2);
		world.setBlockState(pos.add(14, 2, 14), ModMetaBlocks.ZERG_FLESH.getDefaultState(), 2);
		world.setBlockState(pos.add(5, 2, 15), ModMetaBlocks.ZERG_FLESH.getDefaultState(), 2);
		world.setBlockState(pos.add(6, 2, 15), ModMetaBlocks.ZERG_FLESH.getDefaultState(), 2);
		world.setBlockState(pos.add(7, 2, 15), ModMetaBlocks.ZERG_FLESH.getDefaultState(), 2);
		world.setBlockState(pos.add(8, 2, 15), ModMetaBlocks.ZERG_FLESH.getDefaultState(), 2);
		world.setBlockState(pos.add(9, 2, 15), ModMetaBlocks.ZERG_FLESH.getDefaultState(), 2);
		world.setBlockState(pos.add(10, 2, 15), ModMetaBlocks.ZERG_FLESH.getDefaultState(), 2);
		world.setBlockState(pos.add(11, 2, 15), ModMetaBlocks.ZERG_FLESH.getDefaultState(), 2);
		world.setBlockState(pos.add(12, 2, 15), ModMetaBlocks.ZERG_FLESH.getDefaultState(), 2);
		world.setBlockState(pos.add(13, 2, 15), ModMetaBlocks.ZERG_FLESH.getDefaultState(), 2);
		
		//Fourth Level
		world.setBlockState(pos.add(5, 3, 6), ModBlocks.KERATIN_CHUNK.getDefaultState(), 2);
		world.setBlockState(pos.add(6, 3, 6), ModBlocks.KERATIN_CHUNK.getDefaultState(), 2);
		world.setBlockState(pos.add(7, 3, 6), ModMetaBlocks.ZERG_FLESH.getStateFromMeta(1), 2);
		world.setBlockState(pos.add(8, 3, 6), ModMetaBlocks.ZERG_FLESH.getStateFromMeta(1), 2);
		world.setBlockState(pos.add(9, 3, 6), ModMetaBlocks.ZERG_FLESH.getStateFromMeta(1), 2);
		world.setBlockState(pos.add(10, 3, 6), ModMetaBlocks.ZERG_FLESH.getStateFromMeta(1), 2);
		world.setBlockState(pos.add(11, 3, 6), ModMetaBlocks.ZERG_FLESH.getStateFromMeta(1), 2);
		world.setBlockState(pos.add(5, 3, 7), ModBlocks.KERATIN_CHUNK.getDefaultState(), 2);
		world.setBlockState(pos.add(6, 3, 7), ModMetaBlocks.ZERG_FLESH.getStateFromMeta(1), 2);
		world.setBlockState(pos.add(12, 3, 7), ModMetaBlocks.ZERG_FLESH.getStateFromMeta(1), 2);
		world.setBlockState(pos.add(13, 3, 7), ModBlocks.KERATIN_CHUNK.getDefaultState(), 2);
		world.setBlockState(pos.add(5, 3, 8), ModMetaBlocks.ZERG_FLESH.getStateFromMeta(1), 2);
		world.setBlockState(pos.add(13, 3, 8), ModMetaBlocks.ZERG_FLESH.getStateFromMeta(1), 2);
		world.setBlockState(pos.add(14, 3, 8), ModMetaBlocks.ZERG_FLESH.getStateFromMeta(1), 2);
		world.setBlockState(pos.add(5, 3, 9), ModMetaBlocks.ZERG_FLESH.getStateFromMeta(1), 2);
		world.setBlockState(pos.add(13, 3, 9), ModMetaBlocks.ZERG_FLESH.getStateFromMeta(1), 2);
		world.setBlockState(pos.add(14, 3, 9), ModMetaBlocks.ZERG_FLESH.getStateFromMeta(1), 2);
		world.setBlockState(pos.add(5, 3, 10), ModMetaBlocks.ZERG_FLESH.getStateFromMeta(1), 2);
		world.setBlockState(pos.add(13, 3, 10), ModMetaBlocks.ZERG_FLESH.getStateFromMeta(1), 2);
		world.setBlockState(pos.add(14, 3, 10), ModBlocks.KERATIN_CHUNK.getDefaultState(), 2);
		world.setBlockState(pos.add(4, 3, 11), ModMetaBlocks.ZERG_FLESH.getStateFromMeta(1), 2);
		world.setBlockState(pos.add(5, 3, 11), ModMetaBlocks.ZERG_FLESH.getStateFromMeta(1), 2);
		world.setBlockState(pos.add(13, 3, 11), ModMetaBlocks.ZERG_FLESH.getStateFromMeta(1), 2);
		world.setBlockState(pos.add(14, 3, 11), ModMetaBlocks.ZERG_FLESH.getStateFromMeta(1), 2);
		world.setBlockState(pos.add(4, 3, 12), ModBlocks.KERATIN_CHUNK.getDefaultState(), 2);
		world.setBlockState(pos.add(5, 3, 12), ModMetaBlocks.ZERG_FLESH.getStateFromMeta(1), 2);
		world.setBlockState(pos.add(13, 3, 12), ModMetaBlocks.ZERG_FLESH.getStateFromMeta(1), 2);
		world.setBlockState(pos.add(4, 3, 13), ModMetaBlocks.ZERG_FLESH.getStateFromMeta(1), 2);
		world.setBlockState(pos.add(5, 3, 13), ModMetaBlocks.ZERG_FLESH.getStateFromMeta(1), 2);
		world.setBlockState(pos.add(12, 3, 13), ModMetaBlocks.ZERG_FLESH.getStateFromMeta(1), 2);
		world.setBlockState(pos.add(13, 3, 13), ModBlocks.KERATIN_CHUNK.getDefaultState(), 2);
		world.setBlockState(pos.add(14, 3, 13), ModMetaBlocks.ZERG_FLESH.getStateFromMeta(1), 2);
		world.setBlockState(pos.add(4, 3, 14), ModMetaBlocks.ZERG_FLESH.getStateFromMeta(1), 2);
		world.setBlockState(pos.add(5, 3, 14), ModBlocks.KERATIN_CHUNK.getDefaultState(), 2);
		world.setBlockState(pos.add(6, 3, 14), ModMetaBlocks.ZERG_FLESH.getStateFromMeta(1), 2);
		world.setBlockState(pos.add(7, 3, 14), ModMetaBlocks.ZERG_FLESH.getStateFromMeta(1), 2);
		world.setBlockState(pos.add(8, 3, 14), ModMetaBlocks.ZERG_FLESH.getStateFromMeta(1), 2);
		world.setBlockState(pos.add(9, 3, 14), ModMetaBlocks.ZERG_FLESH.getStateFromMeta(1), 2);
		world.setBlockState(pos.add(10, 3, 14), ModMetaBlocks.ZERG_FLESH.getStateFromMeta(1), 2);
		world.setBlockState(pos.add(11, 3, 14), ModMetaBlocks.ZERG_FLESH.getStateFromMeta(1), 2);
		world.setBlockState(pos.add(12, 3, 14), ModBlocks.KERATIN_CHUNK.getDefaultState(), 2);
		world.setBlockState(pos.add(13, 3, 14), ModBlocks.KERATIN_CHUNK.getDefaultState(), 2);
		world.setBlockState(pos.add(14, 3, 14), ModMetaBlocks.ZERG_FLESH.getStateFromMeta(1), 2);
		world.setBlockState(pos.add(5, 3, 15), ModMetaBlocks.ZERG_FLESH.getStateFromMeta(1), 2);
		world.setBlockState(pos.add(6, 3, 15), ModMetaBlocks.ZERG_FLESH.getStateFromMeta(1), 2);
		world.setBlockState(pos.add(12, 3, 15), ModMetaBlocks.ZERG_FLESH.getStateFromMeta(1), 2);
		world.setBlockState(pos.add(13, 3, 15), ModMetaBlocks.ZERG_FLESH.getStateFromMeta(1), 2);
		
		//Fifth Level
		world.setBlockState(pos.add(5, 4, 6), ModBlocks.KERATIN_CHUNK.getDefaultState(), 2);
		world.setBlockState(pos.add(13, 4, 7), ModBlocks.KERATIN_CHUNK.getDefaultState(), 2);
		world.setBlockState(pos.add(14, 4, 10), ModBlocks.KERATIN_CHUNK.getDefaultState(), 2);
		world.setBlockState(pos.add(3, 4, 12), ModBlocks.KERATIN_CHUNK.getDefaultState(), 2);
		world.setBlockState(pos.add(5, 4, 14), ModBlocks.KERATIN_CHUNK.getDefaultState(), 2);
		world.setBlockState(pos.add(13, 4, 14), ModBlocks.KERATIN_CHUNK.getDefaultState(), 2);
		
		//Sixth Level
		world.setBlockState(pos.add(6, 5, 7), ModBlocks.KERATIN_CHUNK.getDefaultState(), 2);
		world.setBlockState(pos.add(13, 5, 10), ModBlocks.KERATIN_CHUNK.getDefaultState(), 2);
		world.setBlockState(pos.add(6, 5, 13), ModBlocks.KERATIN_CHUNK.getDefaultState(), 2);
		world.setBlockState(pos.add(12, 5, 13), ModBlocks.KERATIN_CHUNK.getDefaultState(), 2);
	}
}