package scmc.worldgen.structure;

import java.util.Random;

import net.minecraft.block.Block;
import net.minecraft.block.material.Material;
import net.minecraft.init.Blocks;
import net.minecraft.util.math.BlockPos;
import net.minecraft.world.World;
import net.minecraft.world.gen.feature.WorldGenerator;
import scmc.blocks.ModBlocks;
import scmc.blocks.metablocks.ModMetaBlocks;

public class StructureProtossWarpGateTemplate extends WorldGenerator {
	protected Block[] getValidSpawnBlocks() {
		return new Block[] { Blocks.GRASS, Blocks.DIRT, Blocks.STONE, ModBlocks.ASH_CHAR, ModBlocks.STONE_CHAR, ModBlocks.SAND_SHAKURAS, ModBlocks.STONE_SHAKURAS };
	}
	
	public int metaDim;
	public int metaPrimColor;
	public int metaSecColor;
	public Block dimBlock;
	public Block chanBlock;
	public Block stabBlock;

	//TODO: Fix the portal on this
	public boolean LocationIsValidSpawn(World world, BlockPos pos) {
		
		Block checkBlock = world.getBlockState(pos).getBlock();
		Material m = checkBlock.getBlockState().getBaseState().getMaterial();
		Block blockAbove = world.getBlockState(pos.up()).getBlock();
		Block blockBelow = world.getBlockState(pos.down()).getBlock();

		for (Block i : getValidSpawnBlocks()) {
			if (blockAbove != Blocks.AIR) {
				return false;
			}
			if (checkBlock == i) {
				return true;
			} else if (checkBlock == Blocks.SNOW_LAYER && blockBelow == i) {
				return true;
			} else if (m == Material.PLANTS && blockBelow == i) {
				world.getBlockState(pos).getMaterial();
				return true;
			}
		}
		return false;
	}
	
	public boolean generate(World world, Random rand, BlockPos pos) {
		this.metaDim = rand.nextInt(2);
		this.metaPrimColor = 1;
		this.metaSecColor = 2;
		
		if (metaDim == 0) {
//			dimBlock = ModBlocks.WARPGATE_WORMHOLE_OVERWORLD;
			dimBlock = ModBlocks.DIM_PORTAL_OVERWORLD;
		} else if (metaDim == 1) {
//			dimBlock = ModBlocks.WARPGATE_WORMHOLE_CHAR;
			dimBlock = ModBlocks.DIM_PORTAL_CHAR;
		} else if (metaDim == 2) {
//			dimBlock = ModBlocks.WARPGATE_WORMHOLE_SHAKURAS;
			dimBlock = ModBlocks.DIM_PORTAL_SHAKURAS;
		} else {
//			dimBlock = ModBlocks.WARPGATE_WORMHOLE_OVERWORLD;
			dimBlock = ModBlocks.DIM_PORTAL_OVERWORLD;
		}
		
		stabBlock = ModBlocks.PROTOSS_DARK_ENERGY_STABILIZER;
		chanBlock = ModBlocks.PROTOSS_DARK_ENERGY_CHANNEL;

		if (rand.nextInt(1) == 0) {
			generate_r0(world, rand, pos);
		}

		return true;

	}
	
	public boolean generate(int metaDim, int metaPrimColor, int metaSecColor, World world, Random rand, BlockPos pos) {
		this.metaDim = metaDim;
		this.metaPrimColor = metaPrimColor;
		this.metaSecColor = metaSecColor;
		
		if (metaDim == 0) {
//			dimBlock = ModBlocks.WARPGATE_WORMHOLE_OVERWORLD;
			dimBlock = ModBlocks.DIM_PORTAL_OVERWORLD;
		} else if (metaDim == 1) {
//			dimBlock = ModBlocks.WARPGATE_WORMHOLE_CHAR;
			dimBlock = ModBlocks.DIM_PORTAL_CHAR;
		} else if (metaDim == 2) {
//			dimBlock = ModBlocks.WARPGATE_WORMHOLE_SHAKURAS;
			dimBlock = ModBlocks.DIM_PORTAL_SHAKURAS;
		} else {
//			dimBlock = ModBlocks.WARPGATE_WORMHOLE_OVERWORLD;
			dimBlock = ModBlocks.DIM_PORTAL_OVERWORLD;
		}
		
		if(metaPrimColor == 1) {
			stabBlock = ModBlocks.PROTOSS_DARK_ENERGY_STABILIZER;
			chanBlock = ModBlocks.PROTOSS_DARK_ENERGY_CHANNEL;
		}else {
			stabBlock = ModBlocks.PROTOSS_ENERGY_STABILIZER;
			chanBlock = ModBlocks.PROTOSS_ENERGY_CHANNEL;
		}
		
		int i = rand.nextInt(1);
		if (i == 0) {
			generate_r0(world, rand, pos);
		}
		return true;

	}

	public boolean generate_r0(World world, Random rand, BlockPos pos) {
		if (!LocationIsValidSpawn(world, pos) || !LocationIsValidSpawn(world, pos.add(14, 0, 0))
				|| !LocationIsValidSpawn(world, pos.add(14, 0, 14)) || !LocationIsValidSpawn(world, pos.add(0, 0, 14))) {
			return false;
		}

		world.setBlockState(pos.add(0, 1, 0), Blocks.AIR.getDefaultState());
		world.setBlockState(pos.add(1, 1, 0), Blocks.AIR.getDefaultState());
		world.setBlockState(pos.add(2, 1, 0), Blocks.AIR.getDefaultState());
		world.setBlockState(pos.add(3, 1, 0), Blocks.AIR.getDefaultState());
		world.setBlockState(pos.add(4, 1, 0), Blocks.AIR.getDefaultState());
		world.setBlockState(pos.add(5, 1, 0), Blocks.AIR.getDefaultState());
		world.setBlockState(pos.add(6, 1, 0), Blocks.AIR.getDefaultState());
		world.setBlockState(pos.add(7, 1, 0), Blocks.AIR.getDefaultState());
		world.setBlockState(pos.add(8, 1, 0), Blocks.AIR.getDefaultState());
		world.setBlockState(pos.add(9, 1, 0), Blocks.AIR.getDefaultState());
		world.setBlockState(pos.add(10, 1, 0), Blocks.AIR.getDefaultState());
		world.setBlockState(pos.add(11, 1, 0), Blocks.AIR.getDefaultState());
		world.setBlockState(pos.add(12, 1, 0), Blocks.AIR.getDefaultState());
		world.setBlockState(pos.add(13, 1, 0), Blocks.AIR.getDefaultState());
		world.setBlockState(pos.add(14, 1, 0), Blocks.AIR.getDefaultState());
		world.setBlockState(pos.add(0, 1, 1), Blocks.AIR.getDefaultState());
		world.setBlockState(pos.add(1, 1, 1), ModMetaBlocks.PROTOSS_METAL_T1.getStateFromMeta(metaPrimColor));
		world.setBlockState(pos.add(2, 1, 1), ModMetaBlocks.PROTOSS_METAL_T1.getStateFromMeta(metaPrimColor));
		world.setBlockState(pos.add(3, 1, 1), Blocks.AIR.getDefaultState());
		world.setBlockState(pos.add(4, 1, 1), ModMetaBlocks.PROTOSS_METAL_T1.getStateFromMeta(metaPrimColor));
		world.setBlockState(pos.add(5, 1, 1), ModMetaBlocks.PROTOSS_METAL_T1.getStateFromMeta(metaPrimColor));
		world.setBlockState(pos.add(6, 1, 1), Blocks.AIR.getDefaultState());
		world.setBlockState(pos.add(7, 1, 1), ModMetaBlocks.PROTOSS_METAL_T1.getStateFromMeta(metaPrimColor));
		world.setBlockState(pos.add(8, 1, 1), ModMetaBlocks.PROTOSS_METAL_T1.getStateFromMeta(metaPrimColor));
		world.setBlockState(pos.add(9, 1, 1), Blocks.AIR.getDefaultState());
		world.setBlockState(pos.add(10, 1, 1), ModMetaBlocks.PROTOSS_METAL_T1.getStateFromMeta(metaPrimColor));
		world.setBlockState(pos.add(11, 1, 1), ModMetaBlocks.PROTOSS_METAL_T1.getStateFromMeta(metaPrimColor));
		world.setBlockState(pos.add(12, 1, 1), ModMetaBlocks.PROTOSS_METAL_T1.getStateFromMeta(metaPrimColor));
		world.setBlockState(pos.add(13, 1, 1), ModMetaBlocks.PROTOSS_METAL_T1.getStateFromMeta(metaPrimColor));
		world.setBlockState(pos.add(14, 1, 1), Blocks.AIR.getDefaultState());
		world.setBlockState(pos.add(0, 1, 2), Blocks.AIR.getDefaultState());
		world.setBlockState(pos.add(1, 1, 2), ModMetaBlocks.PROTOSS_METAL_T1.getStateFromMeta(metaPrimColor));
		world.setBlockState(pos.add(2, 1, 2), ModMetaBlocks.PROTOSS_METAL_T1.getStateFromMeta(metaPrimColor));
		world.setBlockState(pos.add(3, 1, 2), ModMetaBlocks.PROTOSS_METAL_T1.getStateFromMeta(metaPrimColor));
		world.setBlockState(pos.add(4, 1, 2), ModMetaBlocks.PROTOSS_METAL_T1.getStateFromMeta(metaPrimColor));
		world.setBlockState(pos.add(5, 1, 2), ModMetaBlocks.PROTOSS_METAL_T1.getStateFromMeta(metaPrimColor));
		world.setBlockState(pos.add(6, 1, 2), ModMetaBlocks.PROTOSS_METAL_T1.getStateFromMeta(metaPrimColor));
		world.setBlockState(pos.add(7, 1, 2), ModMetaBlocks.PROTOSS_METAL_T1.getStateFromMeta(metaPrimColor));
		world.setBlockState(pos.add(8, 1, 2), ModMetaBlocks.PROTOSS_METAL_T1.getStateFromMeta(metaPrimColor));
		world.setBlockState(pos.add(9, 1, 2), ModMetaBlocks.PROTOSS_METAL_T1.getStateFromMeta(metaPrimColor));
		world.setBlockState(pos.add(10, 1, 2), ModMetaBlocks.PROTOSS_METAL_T1.getStateFromMeta(metaPrimColor));
		world.setBlockState(pos.add(11, 1, 2), ModMetaBlocks.PROTOSS_METAL_T1.getStateFromMeta(metaPrimColor));
		world.setBlockState(pos.add(12, 1, 2), ModMetaBlocks.PROTOSS_METAL_T1.getStateFromMeta(metaPrimColor));
		world.setBlockState(pos.add(13, 1, 2), ModMetaBlocks.PROTOSS_METAL_T1.getStateFromMeta(metaPrimColor));
		world.setBlockState(pos.add(14, 1, 2), Blocks.AIR.getDefaultState());
		world.setBlockState(pos.add(0, 1, 3), Blocks.AIR.getDefaultState());
		world.setBlockState(pos.add(1, 1, 3), Blocks.AIR.getDefaultState());
		world.setBlockState(pos.add(2, 1, 3), ModMetaBlocks.PROTOSS_METAL_T1.getStateFromMeta(metaPrimColor));
		world.setBlockState(pos.add(3, 1, 3), ModMetaBlocks.PROTOSS_METAL_T1.getStateFromMeta(metaPrimColor));
		world.setBlockState(pos.add(4, 1, 3), ModMetaBlocks.PROTOSS_METAL_T1.getStateFromMeta(metaPrimColor));
		world.setBlockState(pos.add(5, 1, 3), ModMetaBlocks.PROTOSS_METAL_T1.getStateFromMeta(metaPrimColor));
		world.setBlockState(pos.add(6, 1, 3), ModMetaBlocks.PROTOSS_METAL_T1.getStateFromMeta(metaPrimColor));
		world.setBlockState(pos.add(7, 1, 3), ModMetaBlocks.PROTOSS_METAL_T1.getStateFromMeta(metaPrimColor));
		world.setBlockState(pos.add(8, 1, 3), ModMetaBlocks.PROTOSS_METAL_T1.getStateFromMeta(metaPrimColor));
		world.setBlockState(pos.add(9, 1, 3), ModMetaBlocks.PROTOSS_METAL_T1.getStateFromMeta(metaPrimColor));
		world.setBlockState(pos.add(10, 1, 3), ModMetaBlocks.PROTOSS_METAL_T1.getStateFromMeta(metaPrimColor));
		world.setBlockState(pos.add(11, 1, 3), ModMetaBlocks.PROTOSS_METAL_T1.getStateFromMeta(metaPrimColor));
		world.setBlockState(pos.add(12, 1, 3), ModMetaBlocks.PROTOSS_METAL_T1.getStateFromMeta(metaPrimColor));
		world.setBlockState(pos.add(13, 1, 3), ModMetaBlocks.PROTOSS_METAL_T1.getStateFromMeta(metaPrimColor));
		world.setBlockState(pos.add(14, 1, 3), Blocks.AIR.getDefaultState());
		world.setBlockState(pos.add(0, 1, 4), Blocks.AIR.getDefaultState());
		world.setBlockState(pos.add(1, 1, 4), ModMetaBlocks.PROTOSS_METAL_T1.getStateFromMeta(metaPrimColor));
		world.setBlockState(pos.add(2, 1, 4), ModMetaBlocks.PROTOSS_METAL_T1.getStateFromMeta(metaPrimColor));
		world.setBlockState(pos.add(3, 1, 4), ModMetaBlocks.PROTOSS_METAL_T1.getStateFromMeta(metaPrimColor));
		world.setBlockState(pos.add(4, 1, 4), ModMetaBlocks.PROTOSS_METAL_T1.getStateFromMeta(metaPrimColor));
		world.setBlockState(pos.add(5, 1, 4), ModMetaBlocks.PROTOSS_METAL_T1.getStateFromMeta(metaPrimColor));
		world.setBlockState(pos.add(6, 1, 4), ModMetaBlocks.PROTOSS_METAL_T1.getStateFromMeta(metaPrimColor));
		world.setBlockState(pos.add(7, 1, 4), ModMetaBlocks.PROTOSS_METAL_T1.getStateFromMeta(metaPrimColor));
		world.setBlockState(pos.add(8, 1, 4), ModMetaBlocks.PROTOSS_METAL_T1.getStateFromMeta(metaPrimColor));
		world.setBlockState(pos.add(9, 1, 4), ModMetaBlocks.PROTOSS_METAL_T1.getStateFromMeta(metaPrimColor));
		world.setBlockState(pos.add(10, 1, 4), ModMetaBlocks.PROTOSS_METAL_T1.getStateFromMeta(metaPrimColor));
		world.setBlockState(pos.add(11, 1, 4), ModMetaBlocks.PROTOSS_METAL_T1.getStateFromMeta(metaPrimColor));
		world.setBlockState(pos.add(12, 1, 4), ModMetaBlocks.PROTOSS_METAL_T1.getStateFromMeta(metaPrimColor));
		world.setBlockState(pos.add(13, 1, 4), ModMetaBlocks.PROTOSS_METAL_T1.getStateFromMeta(metaPrimColor));
		world.setBlockState(pos.add(14, 1, 4), Blocks.AIR.getDefaultState());
		world.setBlockState(pos.add(0, 1, 5), Blocks.AIR.getDefaultState());
		world.setBlockState(pos.add(1, 1, 5), ModMetaBlocks.PROTOSS_METAL_T1.getStateFromMeta(metaPrimColor));
		world.setBlockState(pos.add(2, 1, 5), ModMetaBlocks.PROTOSS_METAL_T1.getStateFromMeta(metaPrimColor));
		world.setBlockState(pos.add(3, 1, 5), ModMetaBlocks.PROTOSS_METAL_T1.getStateFromMeta(metaPrimColor));
		world.setBlockState(pos.add(4, 1, 5), ModMetaBlocks.PROTOSS_METAL_T1.getStateFromMeta(metaPrimColor));
		world.setBlockState(pos.add(5, 1, 5), ModMetaBlocks.PROTOSS_METAL_T1.getStateFromMeta(metaPrimColor));
		world.setBlockState(pos.add(6, 1, 5), ModMetaBlocks.PROTOSS_METAL_T1.getStateFromMeta(metaPrimColor));
		world.setBlockState(pos.add(7, 1, 5), ModMetaBlocks.PROTOSS_METAL_T1.getStateFromMeta(metaPrimColor));
		world.setBlockState(pos.add(8, 1, 5), ModMetaBlocks.PROTOSS_METAL_T1.getStateFromMeta(metaPrimColor));
		world.setBlockState(pos.add(9, 1, 5), ModMetaBlocks.PROTOSS_METAL_T1.getStateFromMeta(metaPrimColor));
		world.setBlockState(pos.add(10, 1, 5), ModMetaBlocks.PROTOSS_METAL_T1.getStateFromMeta(metaPrimColor));
		world.setBlockState(pos.add(11, 1, 5), ModMetaBlocks.PROTOSS_METAL_T1.getStateFromMeta(metaPrimColor));
		world.setBlockState(pos.add(12, 1, 5), ModMetaBlocks.PROTOSS_METAL_T1.getStateFromMeta(metaPrimColor));
		world.setBlockState(pos.add(13, 1, 5), Blocks.AIR.getDefaultState());
		world.setBlockState(pos.add(14, 1, 5), Blocks.AIR.getDefaultState());
		world.setBlockState(pos.add(0, 1, 6), Blocks.AIR.getDefaultState());
		world.setBlockState(pos.add(1, 1, 6), Blocks.AIR.getDefaultState());
		world.setBlockState(pos.add(2, 1, 6), ModMetaBlocks.PROTOSS_METAL_T1.getStateFromMeta(metaPrimColor));
		world.setBlockState(pos.add(3, 1, 6), ModMetaBlocks.PROTOSS_METAL_T1.getStateFromMeta(metaPrimColor));
		world.setBlockState(pos.add(4, 1, 6), ModMetaBlocks.PROTOSS_METAL_T1.getStateFromMeta(metaPrimColor));
		world.setBlockState(pos.add(5, 1, 6), ModMetaBlocks.PROTOSS_METAL_T1.getStateFromMeta(metaPrimColor));
		world.setBlockState(pos.add(6, 1, 6), ModMetaBlocks.PROTOSS_METAL_T1.getStateFromMeta(metaPrimColor));
		world.setBlockState(pos.add(7, 1, 6), ModMetaBlocks.PROTOSS_METAL_T1.getStateFromMeta(metaPrimColor));
		world.setBlockState(pos.add(8, 1, 6), ModMetaBlocks.PROTOSS_METAL_T1.getStateFromMeta(metaPrimColor));
		world.setBlockState(pos.add(9, 1, 6), ModMetaBlocks.PROTOSS_METAL_T1.getStateFromMeta(metaPrimColor));
		world.setBlockState(pos.add(10, 1, 6), ModMetaBlocks.PROTOSS_METAL_T1.getStateFromMeta(metaPrimColor));
		world.setBlockState(pos.add(11, 1, 6), ModMetaBlocks.PROTOSS_METAL_T1.getStateFromMeta(metaPrimColor));
		world.setBlockState(pos.add(12, 1, 6), ModMetaBlocks.PROTOSS_METAL_T1.getStateFromMeta(metaPrimColor));
		world.setBlockState(pos.add(13, 1, 6), ModMetaBlocks.PROTOSS_METAL_T1.getStateFromMeta(metaPrimColor));
		world.setBlockState(pos.add(14, 1, 6), Blocks.AIR.getDefaultState());
		world.setBlockState(pos.add(0, 1, 7), Blocks.AIR.getDefaultState());
		world.setBlockState(pos.add(1, 1, 7), ModMetaBlocks.PROTOSS_METAL_T1.getStateFromMeta(metaPrimColor));
		world.setBlockState(pos.add(2, 1, 7), ModMetaBlocks.PROTOSS_METAL_T1.getStateFromMeta(metaPrimColor));
		world.setBlockState(pos.add(3, 1, 7), ModMetaBlocks.PROTOSS_METAL_T1.getStateFromMeta(metaPrimColor));
		world.setBlockState(pos.add(4, 1, 7), ModMetaBlocks.PROTOSS_METAL_T1.getStateFromMeta(metaPrimColor));
		world.setBlockState(pos.add(5, 1, 7), ModMetaBlocks.PROTOSS_METAL_T1.getStateFromMeta(metaPrimColor));
		world.setBlockState(pos.add(6, 1, 7), ModMetaBlocks.PROTOSS_METAL_T1.getStateFromMeta(metaPrimColor));
		world.setBlockState(pos.add(7, 1, 7), ModMetaBlocks.PROTOSS_METAL_T1.getStateFromMeta(metaPrimColor));
		world.setBlockState(pos.add(8, 1, 7), ModMetaBlocks.PROTOSS_METAL_T1.getStateFromMeta(metaPrimColor));
		world.setBlockState(pos.add(9, 1, 7), ModMetaBlocks.PROTOSS_METAL_T1.getStateFromMeta(metaPrimColor));
		world.setBlockState(pos.add(10, 1, 7), ModMetaBlocks.PROTOSS_METAL_T1.getStateFromMeta(metaPrimColor));
		world.setBlockState(pos.add(11, 1, 7), ModMetaBlocks.PROTOSS_METAL_T1.getStateFromMeta(metaPrimColor));
		world.setBlockState(pos.add(12, 1, 7), ModMetaBlocks.PROTOSS_METAL_T1.getStateFromMeta(metaPrimColor));
		world.setBlockState(pos.add(13, 1, 7), ModMetaBlocks.PROTOSS_METAL_T1.getStateFromMeta(metaPrimColor));
		world.setBlockState(pos.add(14, 1, 7), Blocks.AIR.getDefaultState());
		world.setBlockState(pos.add(0, 1, 8), Blocks.AIR.getDefaultState());
		world.setBlockState(pos.add(1, 1, 8), ModMetaBlocks.PROTOSS_METAL_T1.getStateFromMeta(metaPrimColor));
		world.setBlockState(pos.add(2, 1, 8), ModMetaBlocks.PROTOSS_METAL_T1.getStateFromMeta(metaPrimColor));
		world.setBlockState(pos.add(3, 1, 8), ModMetaBlocks.PROTOSS_METAL_T1.getStateFromMeta(metaPrimColor));
		world.setBlockState(pos.add(4, 1, 8), ModMetaBlocks.PROTOSS_METAL_T1.getStateFromMeta(metaPrimColor));
		world.setBlockState(pos.add(5, 1, 8), ModMetaBlocks.PROTOSS_METAL_T1.getStateFromMeta(metaPrimColor));
		world.setBlockState(pos.add(6, 1, 8), ModMetaBlocks.PROTOSS_METAL_T1.getStateFromMeta(metaPrimColor));
		world.setBlockState(pos.add(7, 1, 8), ModMetaBlocks.PROTOSS_METAL_T1.getStateFromMeta(metaPrimColor));
		world.setBlockState(pos.add(8, 1, 8), ModMetaBlocks.PROTOSS_METAL_T1.getStateFromMeta(metaPrimColor));
		world.setBlockState(pos.add(9, 1, 8), ModMetaBlocks.PROTOSS_METAL_T1.getStateFromMeta(metaPrimColor));
		world.setBlockState(pos.add(10, 1, 8), ModMetaBlocks.PROTOSS_METAL_T1.getStateFromMeta(metaPrimColor));
		world.setBlockState(pos.add(11, 1, 8), ModMetaBlocks.PROTOSS_METAL_T1.getStateFromMeta(metaPrimColor));
		world.setBlockState(pos.add(12, 1, 8), ModMetaBlocks.PROTOSS_METAL_T1.getStateFromMeta(metaPrimColor));
		world.setBlockState(pos.add(13, 1, 8), Blocks.AIR.getDefaultState());
		world.setBlockState(pos.add(14, 1, 8), Blocks.AIR.getDefaultState());
		world.setBlockState(pos.add(0, 1, 9), Blocks.AIR.getDefaultState());
		world.setBlockState(pos.add(1, 1, 9), Blocks.AIR.getDefaultState());
		world.setBlockState(pos.add(2, 1, 9), ModMetaBlocks.PROTOSS_METAL_T1.getStateFromMeta(metaPrimColor));
		world.setBlockState(pos.add(3, 1, 9), ModMetaBlocks.PROTOSS_METAL_T1.getStateFromMeta(metaPrimColor));
		world.setBlockState(pos.add(4, 1, 9), ModMetaBlocks.PROTOSS_METAL_T1.getStateFromMeta(metaPrimColor));
		world.setBlockState(pos.add(5, 1, 9), ModMetaBlocks.PROTOSS_METAL_T1.getStateFromMeta(metaPrimColor));
		world.setBlockState(pos.add(6, 1, 9), ModMetaBlocks.PROTOSS_METAL_T1.getStateFromMeta(metaPrimColor));
		world.setBlockState(pos.add(7, 1, 9), ModMetaBlocks.PROTOSS_METAL_T1.getStateFromMeta(metaPrimColor));
		world.setBlockState(pos.add(8, 1, 9), ModMetaBlocks.PROTOSS_METAL_T1.getStateFromMeta(metaPrimColor));
		world.setBlockState(pos.add(9, 1, 9), ModMetaBlocks.PROTOSS_METAL_T1.getStateFromMeta(metaPrimColor));
		world.setBlockState(pos.add(10, 1, 9), ModMetaBlocks.PROTOSS_METAL_T1.getStateFromMeta(metaPrimColor));
		world.setBlockState(pos.add(11, 1, 9), ModMetaBlocks.PROTOSS_METAL_T1.getStateFromMeta(metaPrimColor));
		world.setBlockState(pos.add(12, 1, 9), ModMetaBlocks.PROTOSS_METAL_T1.getStateFromMeta(metaPrimColor));
		world.setBlockState(pos.add(13, 1, 9), ModMetaBlocks.PROTOSS_METAL_T1.getStateFromMeta(metaPrimColor));
		world.setBlockState(pos.add(14, 1, 9), Blocks.AIR.getDefaultState());
		world.setBlockState(pos.add(0, 1, 10), Blocks.AIR.getDefaultState());
		world.setBlockState(pos.add(1, 1, 10), ModMetaBlocks.PROTOSS_METAL_T1.getStateFromMeta(metaPrimColor));
		world.setBlockState(pos.add(2, 1, 10), ModMetaBlocks.PROTOSS_METAL_T1.getStateFromMeta(metaPrimColor));
		world.setBlockState(pos.add(3, 1, 10), ModMetaBlocks.PROTOSS_METAL_T1.getStateFromMeta(metaPrimColor));
		world.setBlockState(pos.add(4, 1, 10), ModMetaBlocks.PROTOSS_METAL_T1.getStateFromMeta(metaPrimColor));
		world.setBlockState(pos.add(5, 1, 10), ModMetaBlocks.PROTOSS_METAL_T1.getStateFromMeta(metaPrimColor));
		world.setBlockState(pos.add(6, 1, 10), ModMetaBlocks.PROTOSS_METAL_T1.getStateFromMeta(metaPrimColor));
		world.setBlockState(pos.add(7, 1, 10), ModMetaBlocks.PROTOSS_METAL_T1.getStateFromMeta(metaPrimColor));
		world.setBlockState(pos.add(8, 1, 10), ModMetaBlocks.PROTOSS_METAL_T1.getStateFromMeta(metaPrimColor));
		world.setBlockState(pos.add(9, 1, 10), ModMetaBlocks.PROTOSS_METAL_T1.getStateFromMeta(metaPrimColor));
		world.setBlockState(pos.add(10, 1, 10), ModMetaBlocks.PROTOSS_METAL_T1.getStateFromMeta(metaPrimColor));
		world.setBlockState(pos.add(11, 1, 10), ModMetaBlocks.PROTOSS_METAL_T1.getStateFromMeta(metaPrimColor));
		world.setBlockState(pos.add(12, 1, 10), ModMetaBlocks.PROTOSS_METAL_T1.getStateFromMeta(metaPrimColor));
		world.setBlockState(pos.add(13, 1, 10), ModMetaBlocks.PROTOSS_METAL_T1.getStateFromMeta(metaPrimColor));
		world.setBlockState(pos.add(14, 1, 10), Blocks.AIR.getDefaultState());
		world.setBlockState(pos.add(0, 1, 11), Blocks.AIR.getDefaultState());
		world.setBlockState(pos.add(1, 1, 11), ModMetaBlocks.PROTOSS_METAL_T1.getStateFromMeta(metaPrimColor));
		world.setBlockState(pos.add(2, 1, 11), ModMetaBlocks.PROTOSS_METAL_T1.getStateFromMeta(metaPrimColor));
		world.setBlockState(pos.add(3, 1, 11), ModMetaBlocks.PROTOSS_METAL_T1.getStateFromMeta(metaPrimColor));
		world.setBlockState(pos.add(4, 1, 11), ModMetaBlocks.PROTOSS_METAL_T1.getStateFromMeta(metaPrimColor));
		world.setBlockState(pos.add(5, 1, 11), ModMetaBlocks.PROTOSS_METAL_T1.getStateFromMeta(metaPrimColor));
		world.setBlockState(pos.add(6, 1, 11), ModMetaBlocks.PROTOSS_METAL_T1.getStateFromMeta(metaPrimColor));
		world.setBlockState(pos.add(7, 1, 11), ModMetaBlocks.PROTOSS_METAL_T1.getStateFromMeta(metaPrimColor));
		world.setBlockState(pos.add(8, 1, 11), ModMetaBlocks.PROTOSS_METAL_T1.getStateFromMeta(metaPrimColor));
		world.setBlockState(pos.add(9, 1, 11), ModMetaBlocks.PROTOSS_METAL_T1.getStateFromMeta(metaPrimColor));
		world.setBlockState(pos.add(10, 1, 11), ModMetaBlocks.PROTOSS_METAL_T1.getStateFromMeta(metaPrimColor));
		world.setBlockState(pos.add(11, 1, 11), ModMetaBlocks.PROTOSS_METAL_T1.getStateFromMeta(metaPrimColor));
		world.setBlockState(pos.add(12, 1, 11), ModMetaBlocks.PROTOSS_METAL_T1.getStateFromMeta(metaPrimColor));
		world.setBlockState(pos.add(13, 1, 11), Blocks.AIR.getDefaultState());
		world.setBlockState(pos.add(14, 1, 11), Blocks.AIR.getDefaultState());
		world.setBlockState(pos.add(0, 1, 12), Blocks.AIR.getDefaultState());
		world.setBlockState(pos.add(1, 1, 12), ModMetaBlocks.PROTOSS_METAL_T1.getStateFromMeta(metaPrimColor));
		world.setBlockState(pos.add(2, 1, 12), ModMetaBlocks.PROTOSS_METAL_T1.getStateFromMeta(metaPrimColor));
		world.setBlockState(pos.add(3, 1, 12), ModMetaBlocks.PROTOSS_METAL_T1.getStateFromMeta(metaPrimColor));
		world.setBlockState(pos.add(4, 1, 12), ModMetaBlocks.PROTOSS_METAL_T1.getStateFromMeta(metaPrimColor));
		world.setBlockState(pos.add(5, 1, 12), ModMetaBlocks.PROTOSS_METAL_T1.getStateFromMeta(metaPrimColor));
		world.setBlockState(pos.add(6, 1, 12), ModMetaBlocks.PROTOSS_METAL_T1.getStateFromMeta(metaPrimColor));
		world.setBlockState(pos.add(7, 1, 12), ModMetaBlocks.PROTOSS_METAL_T1.getStateFromMeta(metaPrimColor));
		world.setBlockState(pos.add(8, 1, 12), ModMetaBlocks.PROTOSS_METAL_T1.getStateFromMeta(metaPrimColor));
		world.setBlockState(pos.add(9, 1, 12), ModMetaBlocks.PROTOSS_METAL_T1.getStateFromMeta(metaPrimColor));
		world.setBlockState(pos.add(10, 1, 12), ModMetaBlocks.PROTOSS_METAL_T1.getStateFromMeta(metaPrimColor));
		world.setBlockState(pos.add(11, 1, 12), ModMetaBlocks.PROTOSS_METAL_T1.getStateFromMeta(metaPrimColor));
		world.setBlockState(pos.add(12, 1, 12), ModMetaBlocks.PROTOSS_METAL_T1.getStateFromMeta(metaPrimColor));
		world.setBlockState(pos.add(13, 1, 12), ModMetaBlocks.PROTOSS_METAL_T1.getStateFromMeta(metaPrimColor));
		world.setBlockState(pos.add(14, 1, 12), Blocks.AIR.getDefaultState());
		world.setBlockState(pos.add(0, 1, 13), Blocks.AIR.getDefaultState());
		world.setBlockState(pos.add(1, 1, 13), ModMetaBlocks.PROTOSS_METAL_T1.getStateFromMeta(metaPrimColor));
		world.setBlockState(pos.add(2, 1, 13), ModMetaBlocks.PROTOSS_METAL_T1.getStateFromMeta(metaPrimColor));
		world.setBlockState(pos.add(3, 1, 13), ModMetaBlocks.PROTOSS_METAL_T1.getStateFromMeta(metaPrimColor));
		world.setBlockState(pos.add(4, 1, 13), ModMetaBlocks.PROTOSS_METAL_T1.getStateFromMeta(metaPrimColor));
		world.setBlockState(pos.add(5, 1, 13), Blocks.AIR.getDefaultState());
		world.setBlockState(pos.add(6, 1, 13), ModMetaBlocks.PROTOSS_METAL_T1.getStateFromMeta(metaPrimColor));
		world.setBlockState(pos.add(7, 1, 13), ModMetaBlocks.PROTOSS_METAL_T1.getStateFromMeta(metaPrimColor));
		world.setBlockState(pos.add(8, 1, 13), Blocks.AIR.getDefaultState());
		world.setBlockState(pos.add(9, 1, 13), ModMetaBlocks.PROTOSS_METAL_T1.getStateFromMeta(metaPrimColor));
		world.setBlockState(pos.add(10, 1, 13), ModMetaBlocks.PROTOSS_METAL_T1.getStateFromMeta(metaPrimColor));
		world.setBlockState(pos.add(11, 1, 13), Blocks.AIR.getDefaultState());
		world.setBlockState(pos.add(12, 1, 13), ModMetaBlocks.PROTOSS_METAL_T1.getStateFromMeta(metaPrimColor));
		world.setBlockState(pos.add(13, 1, 13), ModMetaBlocks.PROTOSS_METAL_T1.getStateFromMeta(metaPrimColor));
		world.setBlockState(pos.add(14, 1, 13), Blocks.AIR.getDefaultState());
		world.setBlockState(pos.add(0, 1, 14), Blocks.AIR.getDefaultState());
		world.setBlockState(pos.add(1, 1, 14), Blocks.AIR.getDefaultState());
		world.setBlockState(pos.add(2, 1, 14), Blocks.AIR.getDefaultState());
		world.setBlockState(pos.add(3, 1, 14), Blocks.AIR.getDefaultState());
		world.setBlockState(pos.add(4, 1, 14), Blocks.AIR.getDefaultState());
		world.setBlockState(pos.add(5, 1, 14), Blocks.AIR.getDefaultState());
		world.setBlockState(pos.add(6, 1, 14), Blocks.AIR.getDefaultState());
		world.setBlockState(pos.add(7, 1, 14), Blocks.AIR.getDefaultState());
		world.setBlockState(pos.add(8, 1, 14), Blocks.AIR.getDefaultState());
		world.setBlockState(pos.add(9, 1, 14), Blocks.AIR.getDefaultState());
		world.setBlockState(pos.add(10, 1, 14), Blocks.AIR.getDefaultState());
		world.setBlockState(pos.add(11, 1, 14), Blocks.AIR.getDefaultState());
		world.setBlockState(pos.add(12, 1, 14), Blocks.AIR.getDefaultState());
		world.setBlockState(pos.add(13, 1, 14), Blocks.AIR.getDefaultState());
		world.setBlockState(pos.add(14, 1, 14), Blocks.AIR.getDefaultState());
		world.setBlockState(pos.add(0, 2, 0), Blocks.AIR.getDefaultState());
		world.setBlockState(pos.add(1, 2, 0), Blocks.AIR.getDefaultState());
		world.setBlockState(pos.add(2, 2, 0), Blocks.AIR.getDefaultState());
		world.setBlockState(pos.add(3, 2, 0), Blocks.AIR.getDefaultState());
		world.setBlockState(pos.add(4, 2, 0), Blocks.AIR.getDefaultState());
		world.setBlockState(pos.add(5, 2, 0), Blocks.AIR.getDefaultState());
		world.setBlockState(pos.add(6, 2, 0), Blocks.AIR.getDefaultState());
		world.setBlockState(pos.add(7, 2, 0), Blocks.AIR.getDefaultState());
		world.setBlockState(pos.add(8, 2, 0), Blocks.AIR.getDefaultState());
		world.setBlockState(pos.add(9, 2, 0), Blocks.AIR.getDefaultState());
		world.setBlockState(pos.add(10, 2, 0), Blocks.AIR.getDefaultState());
		world.setBlockState(pos.add(11, 2, 0), Blocks.AIR.getDefaultState());
		world.setBlockState(pos.add(12, 2, 0), Blocks.AIR.getDefaultState());
		world.setBlockState(pos.add(13, 2, 0), Blocks.AIR.getDefaultState());
		world.setBlockState(pos.add(14, 2, 0), Blocks.AIR.getDefaultState());
		world.setBlockState(pos.add(0, 2, 1), Blocks.AIR.getDefaultState());
		world.setBlockState(pos.add(1, 2, 1), ModMetaBlocks.PROTOSS_METAL_T1.getStateFromMeta(metaPrimColor));
		world.setBlockState(pos.add(2, 2, 1), ModMetaBlocks.PROTOSS_METAL_T1.getStateFromMeta(metaPrimColor));
		world.setBlockState(pos.add(3, 2, 1), Blocks.AIR.getDefaultState());
		world.setBlockState(pos.add(4, 2, 1), ModMetaBlocks.PROTOSS_METAL_T1.getStateFromMeta(metaPrimColor));
		world.setBlockState(pos.add(5, 2, 1), ModMetaBlocks.PROTOSS_METAL_T1.getStateFromMeta(metaPrimColor));
		world.setBlockState(pos.add(6, 2, 1), Blocks.AIR.getDefaultState());
		world.setBlockState(pos.add(7, 2, 1), ModMetaBlocks.PROTOSS_METAL_T1.getStateFromMeta(metaPrimColor));
		world.setBlockState(pos.add(8, 2, 1), ModMetaBlocks.PROTOSS_METAL_T1.getStateFromMeta(metaPrimColor));
		world.setBlockState(pos.add(9, 2, 1), Blocks.AIR.getDefaultState());
		world.setBlockState(pos.add(10, 2, 1), ModMetaBlocks.PROTOSS_METAL_T1.getStateFromMeta(metaPrimColor));
		world.setBlockState(pos.add(11, 2, 1), ModMetaBlocks.PROTOSS_METAL_T1.getStateFromMeta(metaSecColor));
		world.setBlockState(pos.add(12, 2, 1), ModMetaBlocks.PROTOSS_METAL_T1.getStateFromMeta(metaSecColor));
		world.setBlockState(pos.add(13, 2, 1), Blocks.AIR.getDefaultState());
		world.setBlockState(pos.add(14, 2, 1), Blocks.AIR.getDefaultState());
		world.setBlockState(pos.add(0, 2, 2), Blocks.AIR.getDefaultState());
		world.setBlockState(pos.add(1, 2, 2), ModMetaBlocks.PROTOSS_METAL_T1.getStateFromMeta(metaPrimColor));
		world.setBlockState(pos.add(2, 2, 2), ModMetaBlocks.PROTOSS_METAL_T1.getStateFromMeta(metaPrimColor));
		world.setBlockState(pos.add(3, 2, 2), ModMetaBlocks.PROTOSS_METAL_T1.getStateFromMeta(metaPrimColor));
		world.setBlockState(pos.add(4, 2, 2), ModMetaBlocks.PROTOSS_METAL_T1.getStateFromMeta(metaPrimColor));
		world.setBlockState(pos.add(5, 2, 2), ModMetaBlocks.PROTOSS_METAL_T1.getStateFromMeta(metaPrimColor));
		world.setBlockState(pos.add(6, 2, 2), ModMetaBlocks.PROTOSS_METAL_T1.getStateFromMeta(metaPrimColor));
		world.setBlockState(pos.add(7, 2, 2), ModMetaBlocks.PROTOSS_METAL_T1.getStateFromMeta(metaPrimColor));
		world.setBlockState(pos.add(8, 2, 2), ModMetaBlocks.PROTOSS_METAL_T1.getStateFromMeta(metaPrimColor));
		world.setBlockState(pos.add(9, 2, 2), ModMetaBlocks.PROTOSS_METAL_T1.getStateFromMeta(metaPrimColor));
		world.setBlockState(pos.add(10, 2, 2), ModMetaBlocks.PROTOSS_METAL_T1.getStateFromMeta(metaPrimColor));
		world.setBlockState(pos.add(11, 2, 2), ModMetaBlocks.PROTOSS_METAL_T1.getStateFromMeta(metaPrimColor));
		world.setBlockState(pos.add(12, 2, 2), ModMetaBlocks.PROTOSS_METAL_T1.getStateFromMeta(metaSecColor));
		world.setBlockState(pos.add(13, 2, 2), ModMetaBlocks.PROTOSS_METAL_T1.getStateFromMeta(metaSecColor));
		world.setBlockState(pos.add(14, 2, 2), Blocks.AIR.getDefaultState());
		world.setBlockState(pos.add(0, 2, 3), Blocks.AIR.getDefaultState());
		world.setBlockState(pos.add(1, 2, 3), Blocks.AIR.getDefaultState());
		world.setBlockState(pos.add(2, 2, 3), ModMetaBlocks.PROTOSS_METAL_T1.getStateFromMeta(metaPrimColor));
		world.setBlockState(pos.add(3, 2, 3), ModMetaBlocks.PROTOSS_METAL_T1.getStateFromMeta(metaPrimColor));
		world.setBlockState(pos.add(4, 2, 3), ModMetaBlocks.PROTOSS_METAL_T1.getStateFromMeta(metaPrimColor));
		world.setBlockState(pos.add(5, 2, 3), ModMetaBlocks.PROTOSS_METAL_T1.getStateFromMeta(metaPrimColor));
		world.setBlockState(pos.add(6, 2, 3), ModMetaBlocks.PROTOSS_METAL_T1.getStateFromMeta(metaPrimColor));
		world.setBlockState(pos.add(7, 2, 3), ModMetaBlocks.PROTOSS_METAL_T1.getStateFromMeta(metaPrimColor));
		world.setBlockState(pos.add(8, 2, 3), ModMetaBlocks.PROTOSS_METAL_T1.getStateFromMeta(metaPrimColor));
		world.setBlockState(pos.add(9, 2, 3), ModMetaBlocks.PROTOSS_METAL_T1.getStateFromMeta(metaPrimColor));
		world.setBlockState(pos.add(10, 2, 3), ModMetaBlocks.PROTOSS_METAL_T1.getStateFromMeta(metaPrimColor));
		world.setBlockState(pos.add(11, 2, 3), ModMetaBlocks.PROTOSS_METAL_T1.getStateFromMeta(metaPrimColor));
		world.setBlockState(pos.add(12, 2, 3), ModMetaBlocks.PROTOSS_METAL_T1.getStateFromMeta(metaPrimColor));
		world.setBlockState(pos.add(13, 2, 3), ModMetaBlocks.PROTOSS_METAL_T1.getStateFromMeta(metaSecColor));
		world.setBlockState(pos.add(14, 2, 3), Blocks.AIR.getDefaultState());
		world.setBlockState(pos.add(0, 2, 4), Blocks.AIR.getDefaultState());
		world.setBlockState(pos.add(1, 2, 4), ModMetaBlocks.PROTOSS_METAL_T1.getStateFromMeta(metaPrimColor));
		world.setBlockState(pos.add(2, 2, 4), ModMetaBlocks.PROTOSS_METAL_T1.getStateFromMeta(metaPrimColor));
		world.setBlockState(pos.add(3, 2, 4), ModMetaBlocks.PROTOSS_METAL_T1.getStateFromMeta(metaPrimColor));
		world.setBlockState(pos.add(4, 2, 4), ModMetaBlocks.PROTOSS_METAL_T1.getStateFromMeta(metaPrimColor));
		world.setBlockState(pos.add(5, 2, 4), ModMetaBlocks.PROTOSS_METAL_T1.getStateFromMeta(metaPrimColor));
		world.setBlockState(pos.add(6, 2, 4), ModMetaBlocks.PROTOSS_METAL_T1.getStateFromMeta(metaPrimColor));
		world.setBlockState(pos.add(7, 2, 4), ModMetaBlocks.PROTOSS_METAL_T1.getStateFromMeta(metaPrimColor));
		world.setBlockState(pos.add(8, 2, 4), ModMetaBlocks.PROTOSS_METAL_T1.getStateFromMeta(metaPrimColor));
		world.setBlockState(pos.add(9, 2, 4), ModMetaBlocks.PROTOSS_METAL_T1.getStateFromMeta(metaPrimColor));
		world.setBlockState(pos.add(10, 2, 4), ModMetaBlocks.PROTOSS_METAL_T1.getStateFromMeta(metaPrimColor));
		world.setBlockState(pos.add(11, 2, 4), ModMetaBlocks.PROTOSS_METAL_T1.getStateFromMeta(metaPrimColor));
		world.setBlockState(pos.add(12, 2, 4), ModMetaBlocks.PROTOSS_METAL_T1.getStateFromMeta(metaPrimColor));
		world.setBlockState(pos.add(13, 2, 4), ModMetaBlocks.PROTOSS_METAL_T1.getStateFromMeta(metaPrimColor));
		world.setBlockState(pos.add(14, 2, 4), Blocks.AIR.getDefaultState());
		world.setBlockState(pos.add(0, 2, 5), Blocks.AIR.getDefaultState());
		world.setBlockState(pos.add(1, 2, 5), ModMetaBlocks.PROTOSS_METAL_T1.getStateFromMeta(metaPrimColor));
		world.setBlockState(pos.add(2, 2, 5), ModMetaBlocks.PROTOSS_METAL_T1.getStateFromMeta(metaPrimColor));
		world.setBlockState(pos.add(3, 2, 5), ModMetaBlocks.PROTOSS_METAL_T1.getStateFromMeta(metaPrimColor));
		world.setBlockState(pos.add(4, 2, 5), ModMetaBlocks.PROTOSS_METAL_T1.getStateFromMeta(metaPrimColor));
		world.setBlockState(pos.add(5, 2, 5), ModMetaBlocks.PROTOSS_METAL_T1.getStateFromMeta(metaPrimColor));
		world.setBlockState(pos.add(6, 2, 5), ModMetaBlocks.PROTOSS_METAL_T1.getStateFromMeta(metaPrimColor));
		world.setBlockState(pos.add(7, 2, 5), ModMetaBlocks.PROTOSS_METAL_T1.getStateFromMeta(metaPrimColor));
		world.setBlockState(pos.add(8, 2, 5), ModMetaBlocks.PROTOSS_METAL_T1.getStateFromMeta(metaPrimColor));
		world.setBlockState(pos.add(9, 2, 5), ModMetaBlocks.PROTOSS_METAL_T1.getStateFromMeta(metaPrimColor));
		world.setBlockState(pos.add(10, 2, 5), ModMetaBlocks.PROTOSS_METAL_T1.getStateFromMeta(metaPrimColor));
		world.setBlockState(pos.add(11, 2, 5), ModMetaBlocks.PROTOSS_METAL_T1.getStateFromMeta(metaPrimColor));
		world.setBlockState(pos.add(12, 2, 5), ModMetaBlocks.PROTOSS_METAL_T1.getStateFromMeta(metaPrimColor));
		world.setBlockState(pos.add(13, 2, 5), Blocks.AIR.getDefaultState());
		world.setBlockState(pos.add(14, 2, 5), Blocks.AIR.getDefaultState());
		world.setBlockState(pos.add(0, 2, 6), Blocks.AIR.getDefaultState());
		world.setBlockState(pos.add(1, 2, 6), Blocks.AIR.getDefaultState());
		world.setBlockState(pos.add(2, 2, 6), ModMetaBlocks.PROTOSS_METAL_T1.getStateFromMeta(metaPrimColor));
		world.setBlockState(pos.add(3, 2, 6), ModMetaBlocks.PROTOSS_METAL_T1.getStateFromMeta(metaPrimColor));
		world.setBlockState(pos.add(4, 2, 6), ModMetaBlocks.PROTOSS_METAL_T1.getStateFromMeta(metaPrimColor));
		world.setBlockState(pos.add(5, 2, 6), ModMetaBlocks.PROTOSS_METAL_T1.getStateFromMeta(metaPrimColor));
		world.setBlockState(pos.add(6, 2, 6), ModMetaBlocks.PROTOSS_METAL_T1.getStateFromMeta(metaPrimColor));
		world.setBlockState(pos.add(7, 2, 6), ModMetaBlocks.PROTOSS_METAL_T1.getStateFromMeta(metaPrimColor));
		world.setBlockState(pos.add(8, 2, 6), ModMetaBlocks.PROTOSS_METAL_T1.getStateFromMeta(metaPrimColor));
		world.setBlockState(pos.add(9, 2, 6), ModMetaBlocks.PROTOSS_METAL_T1.getStateFromMeta(metaPrimColor));
		world.setBlockState(pos.add(10, 2, 6), ModMetaBlocks.PROTOSS_METAL_T1.getStateFromMeta(metaPrimColor));
		world.setBlockState(pos.add(11, 2, 6), ModMetaBlocks.PROTOSS_METAL_T1.getStateFromMeta(metaPrimColor));
		world.setBlockState(pos.add(12, 2, 6), ModMetaBlocks.PROTOSS_METAL_T1.getStateFromMeta(metaPrimColor));
		world.setBlockState(pos.add(13, 2, 6), ModMetaBlocks.PROTOSS_METAL_T1.getStateFromMeta(metaPrimColor));
		world.setBlockState(pos.add(14, 2, 6), Blocks.AIR.getDefaultState());
		world.setBlockState(pos.add(0, 2, 7), Blocks.AIR.getDefaultState());
		world.setBlockState(pos.add(1, 2, 7), ModMetaBlocks.PROTOSS_METAL_T1.getStateFromMeta(metaPrimColor));
		world.setBlockState(pos.add(2, 2, 7), ModMetaBlocks.PROTOSS_METAL_T1.getStateFromMeta(metaPrimColor));
		world.setBlockState(pos.add(3, 2, 7), ModMetaBlocks.PROTOSS_METAL_T1.getStateFromMeta(metaPrimColor));
		world.setBlockState(pos.add(4, 2, 7), ModMetaBlocks.PROTOSS_METAL_T1.getStateFromMeta(metaPrimColor));
		world.setBlockState(pos.add(5, 2, 7), ModMetaBlocks.PROTOSS_METAL_T1.getStateFromMeta(metaPrimColor));
		world.setBlockState(pos.add(6, 2, 7), ModMetaBlocks.PROTOSS_METAL_T1.getStateFromMeta(metaPrimColor));
		world.setBlockState(pos.add(7, 2, 7), ModMetaBlocks.PROTOSS_METAL_T1.getStateFromMeta(metaPrimColor));
		world.setBlockState(pos.add(8, 2, 7), ModMetaBlocks.PROTOSS_METAL_T1.getStateFromMeta(metaPrimColor));
		world.setBlockState(pos.add(9, 2, 7), ModMetaBlocks.PROTOSS_METAL_T1.getStateFromMeta(metaPrimColor));
		world.setBlockState(pos.add(10, 2, 7), ModMetaBlocks.PROTOSS_METAL_T1.getStateFromMeta(metaPrimColor));
		world.setBlockState(pos.add(11, 2, 7), ModMetaBlocks.PROTOSS_METAL_T1.getStateFromMeta(metaPrimColor));
		world.setBlockState(pos.add(12, 2, 7), ModMetaBlocks.PROTOSS_METAL_T1.getStateFromMeta(metaPrimColor));
		world.setBlockState(pos.add(13, 2, 7), ModMetaBlocks.PROTOSS_METAL_T1.getStateFromMeta(metaPrimColor));
		world.setBlockState(pos.add(14, 2, 7), Blocks.AIR.getDefaultState());
		world.setBlockState(pos.add(0, 2, 8), Blocks.AIR.getDefaultState());
		world.setBlockState(pos.add(1, 2, 8), ModMetaBlocks.PROTOSS_METAL_T1.getStateFromMeta(metaPrimColor));
		world.setBlockState(pos.add(2, 2, 8), ModMetaBlocks.PROTOSS_METAL_T1.getStateFromMeta(metaPrimColor));
		world.setBlockState(pos.add(3, 2, 8), ModMetaBlocks.PROTOSS_METAL_T1.getStateFromMeta(metaPrimColor));
		world.setBlockState(pos.add(4, 2, 8), ModMetaBlocks.PROTOSS_METAL_T1.getStateFromMeta(metaPrimColor));
		world.setBlockState(pos.add(5, 2, 8), ModMetaBlocks.PROTOSS_METAL_T1.getStateFromMeta(metaPrimColor));
		world.setBlockState(pos.add(6, 2, 8), ModMetaBlocks.PROTOSS_METAL_T1.getStateFromMeta(metaPrimColor));
		world.setBlockState(pos.add(7, 2, 8), ModMetaBlocks.PROTOSS_METAL_T1.getStateFromMeta(metaPrimColor));
		world.setBlockState(pos.add(8, 2, 8), ModMetaBlocks.PROTOSS_METAL_T1.getStateFromMeta(metaPrimColor));
		world.setBlockState(pos.add(9, 2, 8), ModMetaBlocks.PROTOSS_METAL_T1.getStateFromMeta(metaPrimColor));
		world.setBlockState(pos.add(10, 2, 8), ModMetaBlocks.PROTOSS_METAL_T1.getStateFromMeta(metaPrimColor));
		world.setBlockState(pos.add(11, 2, 8), ModMetaBlocks.PROTOSS_METAL_T1.getStateFromMeta(metaPrimColor));
		world.setBlockState(pos.add(12, 2, 8), ModMetaBlocks.PROTOSS_METAL_T1.getStateFromMeta(metaPrimColor));
		world.setBlockState(pos.add(13, 2, 8), Blocks.AIR.getDefaultState());
		world.setBlockState(pos.add(14, 2, 8), Blocks.AIR.getDefaultState());
		world.setBlockState(pos.add(0, 2, 9), Blocks.AIR.getDefaultState());
		world.setBlockState(pos.add(1, 2, 9), Blocks.AIR.getDefaultState());
		world.setBlockState(pos.add(2, 2, 9), ModMetaBlocks.PROTOSS_METAL_T1.getStateFromMeta(metaPrimColor));
		world.setBlockState(pos.add(3, 2, 9), ModMetaBlocks.PROTOSS_METAL_T1.getStateFromMeta(metaPrimColor));
		world.setBlockState(pos.add(4, 2, 9), ModMetaBlocks.PROTOSS_METAL_T1.getStateFromMeta(metaPrimColor));
		world.setBlockState(pos.add(5, 2, 9), ModMetaBlocks.PROTOSS_METAL_T1.getStateFromMeta(metaPrimColor));
		world.setBlockState(pos.add(6, 2, 9), ModMetaBlocks.PROTOSS_METAL_T1.getStateFromMeta(metaPrimColor));
		world.setBlockState(pos.add(7, 2, 9), ModMetaBlocks.PROTOSS_METAL_T1.getStateFromMeta(metaPrimColor));
		world.setBlockState(pos.add(8, 2, 9), ModMetaBlocks.PROTOSS_METAL_T1.getStateFromMeta(metaPrimColor));
		world.setBlockState(pos.add(9, 2, 9), ModMetaBlocks.PROTOSS_METAL_T1.getStateFromMeta(metaPrimColor));
		world.setBlockState(pos.add(10, 2, 9), ModMetaBlocks.PROTOSS_METAL_T1.getStateFromMeta(metaPrimColor));
		world.setBlockState(pos.add(11, 2, 9), ModMetaBlocks.PROTOSS_METAL_T1.getStateFromMeta(metaPrimColor));
		world.setBlockState(pos.add(12, 2, 9), ModMetaBlocks.PROTOSS_METAL_T1.getStateFromMeta(metaPrimColor));
		world.setBlockState(pos.add(13, 2, 9), ModMetaBlocks.PROTOSS_METAL_T1.getStateFromMeta(metaPrimColor));
		world.setBlockState(pos.add(14, 2, 9), Blocks.AIR.getDefaultState());
		world.setBlockState(pos.add(0, 2, 10), Blocks.AIR.getDefaultState());
		world.setBlockState(pos.add(1, 2, 10), ModMetaBlocks.PROTOSS_METAL_T1.getStateFromMeta(metaPrimColor));
		world.setBlockState(pos.add(2, 2, 10), ModMetaBlocks.PROTOSS_METAL_T1.getStateFromMeta(metaPrimColor));
		world.setBlockState(pos.add(3, 2, 10), ModMetaBlocks.PROTOSS_METAL_T1.getStateFromMeta(metaPrimColor));
		world.setBlockState(pos.add(4, 2, 10), ModMetaBlocks.PROTOSS_METAL_T1.getStateFromMeta(metaPrimColor));
		world.setBlockState(pos.add(5, 2, 10), ModMetaBlocks.PROTOSS_METAL_T1.getStateFromMeta(metaPrimColor));
		world.setBlockState(pos.add(6, 2, 10), ModMetaBlocks.PROTOSS_METAL_T1.getStateFromMeta(metaPrimColor));
		world.setBlockState(pos.add(7, 2, 10), ModMetaBlocks.PROTOSS_METAL_T1.getStateFromMeta(metaPrimColor));
		world.setBlockState(pos.add(8, 2, 10), ModMetaBlocks.PROTOSS_METAL_T1.getStateFromMeta(metaPrimColor));
		world.setBlockState(pos.add(9, 2, 10), ModMetaBlocks.PROTOSS_METAL_T1.getStateFromMeta(metaPrimColor));
		world.setBlockState(pos.add(10, 2, 10), ModMetaBlocks.PROTOSS_METAL_T1.getStateFromMeta(metaPrimColor));
		world.setBlockState(pos.add(11, 2, 10), ModMetaBlocks.PROTOSS_METAL_T1.getStateFromMeta(metaPrimColor));
		world.setBlockState(pos.add(12, 2, 10), ModMetaBlocks.PROTOSS_METAL_T1.getStateFromMeta(metaPrimColor));
		world.setBlockState(pos.add(13, 2, 10), ModMetaBlocks.PROTOSS_METAL_T1.getStateFromMeta(metaPrimColor));
		world.setBlockState(pos.add(14, 2, 10), Blocks.AIR.getDefaultState());
		world.setBlockState(pos.add(0, 2, 11), Blocks.AIR.getDefaultState());
		world.setBlockState(pos.add(1, 2, 11), ModMetaBlocks.PROTOSS_METAL_T1.getStateFromMeta(metaSecColor));
		world.setBlockState(pos.add(2, 2, 11), ModMetaBlocks.PROTOSS_METAL_T1.getStateFromMeta(metaPrimColor));
		world.setBlockState(pos.add(3, 2, 11), ModMetaBlocks.PROTOSS_METAL_T1.getStateFromMeta(metaPrimColor));
		world.setBlockState(pos.add(4, 2, 11), ModMetaBlocks.PROTOSS_METAL_T1.getStateFromMeta(metaPrimColor));
		world.setBlockState(pos.add(5, 2, 11), ModMetaBlocks.PROTOSS_METAL_T1.getStateFromMeta(metaPrimColor));
		world.setBlockState(pos.add(6, 2, 11), ModMetaBlocks.PROTOSS_METAL_T1.getStateFromMeta(metaPrimColor));
		world.setBlockState(pos.add(7, 2, 11), ModMetaBlocks.PROTOSS_METAL_T1.getStateFromMeta(metaPrimColor));
		world.setBlockState(pos.add(8, 2, 11), ModMetaBlocks.PROTOSS_METAL_T1.getStateFromMeta(metaPrimColor));
		world.setBlockState(pos.add(9, 2, 11), ModMetaBlocks.PROTOSS_METAL_T1.getStateFromMeta(metaPrimColor));
		world.setBlockState(pos.add(10, 2, 11), ModMetaBlocks.PROTOSS_METAL_T1.getStateFromMeta(metaPrimColor));
		world.setBlockState(pos.add(11, 2, 11), ModMetaBlocks.PROTOSS_METAL_T1.getStateFromMeta(metaPrimColor));
		world.setBlockState(pos.add(12, 2, 11), ModMetaBlocks.PROTOSS_METAL_T1.getStateFromMeta(metaPrimColor));
		world.setBlockState(pos.add(13, 2, 11), Blocks.AIR.getDefaultState());
		world.setBlockState(pos.add(14, 2, 11), Blocks.AIR.getDefaultState());
		world.setBlockState(pos.add(0, 2, 12), Blocks.AIR.getDefaultState());
		world.setBlockState(pos.add(1, 2, 12), ModMetaBlocks.PROTOSS_METAL_T1.getStateFromMeta(metaSecColor));
		world.setBlockState(pos.add(2, 2, 12), ModMetaBlocks.PROTOSS_METAL_T1.getStateFromMeta(metaSecColor));
		world.setBlockState(pos.add(3, 2, 12), ModMetaBlocks.PROTOSS_METAL_T1.getStateFromMeta(metaPrimColor));
		world.setBlockState(pos.add(4, 2, 12), ModMetaBlocks.PROTOSS_METAL_T1.getStateFromMeta(metaPrimColor));
		world.setBlockState(pos.add(5, 2, 12), ModMetaBlocks.PROTOSS_METAL_T1.getStateFromMeta(metaPrimColor));
		world.setBlockState(pos.add(6, 2, 12), ModMetaBlocks.PROTOSS_METAL_T1.getStateFromMeta(metaPrimColor));
		world.setBlockState(pos.add(7, 2, 12), ModMetaBlocks.PROTOSS_METAL_T1.getStateFromMeta(metaPrimColor));
		world.setBlockState(pos.add(8, 2, 12), ModMetaBlocks.PROTOSS_METAL_T1.getStateFromMeta(metaPrimColor));
		world.setBlockState(pos.add(9, 2, 12), ModMetaBlocks.PROTOSS_METAL_T1.getStateFromMeta(metaPrimColor));
		world.setBlockState(pos.add(10, 2, 12), ModMetaBlocks.PROTOSS_METAL_T1.getStateFromMeta(metaPrimColor));
		world.setBlockState(pos.add(11, 2, 12), ModMetaBlocks.PROTOSS_METAL_T1.getStateFromMeta(metaPrimColor));
		world.setBlockState(pos.add(12, 2, 12), ModMetaBlocks.PROTOSS_METAL_T1.getStateFromMeta(metaPrimColor));
		world.setBlockState(pos.add(13, 2, 12), ModMetaBlocks.PROTOSS_METAL_T1.getStateFromMeta(metaPrimColor));
		world.setBlockState(pos.add(14, 2, 12), Blocks.AIR.getDefaultState());
		world.setBlockState(pos.add(0, 2, 13), Blocks.AIR.getDefaultState());
		world.setBlockState(pos.add(1, 2, 13), Blocks.AIR.getDefaultState());
		world.setBlockState(pos.add(2, 2, 13), ModMetaBlocks.PROTOSS_METAL_T1.getStateFromMeta(metaSecColor));
		world.setBlockState(pos.add(3, 2, 13), ModMetaBlocks.PROTOSS_METAL_T1.getStateFromMeta(metaSecColor));
		world.setBlockState(pos.add(4, 2, 13), ModMetaBlocks.PROTOSS_METAL_T1.getStateFromMeta(metaPrimColor));
		world.setBlockState(pos.add(5, 2, 13), Blocks.AIR.getDefaultState());
		world.setBlockState(pos.add(6, 2, 13), ModMetaBlocks.PROTOSS_METAL_T1.getStateFromMeta(metaPrimColor));
		world.setBlockState(pos.add(7, 2, 13), ModMetaBlocks.PROTOSS_METAL_T1.getStateFromMeta(metaPrimColor));
		world.setBlockState(pos.add(8, 2, 13), Blocks.AIR.getDefaultState());
		world.setBlockState(pos.add(9, 2, 13), ModMetaBlocks.PROTOSS_METAL_T1.getStateFromMeta(metaPrimColor));
		world.setBlockState(pos.add(10, 2, 13), ModMetaBlocks.PROTOSS_METAL_T1.getStateFromMeta(metaPrimColor));
		world.setBlockState(pos.add(11, 2, 13), Blocks.AIR.getDefaultState());
		world.setBlockState(pos.add(12, 2, 13), ModMetaBlocks.PROTOSS_METAL_T1.getStateFromMeta(metaPrimColor));
		world.setBlockState(pos.add(13, 2, 13), ModMetaBlocks.PROTOSS_METAL_T1.getStateFromMeta(metaPrimColor));
		world.setBlockState(pos.add(14, 2, 13), Blocks.AIR.getDefaultState());
		world.setBlockState(pos.add(0, 2, 14), Blocks.AIR.getDefaultState());
		world.setBlockState(pos.add(1, 2, 14), Blocks.AIR.getDefaultState());
		world.setBlockState(pos.add(2, 2, 14), Blocks.AIR.getDefaultState());
		world.setBlockState(pos.add(3, 2, 14), Blocks.AIR.getDefaultState());
		world.setBlockState(pos.add(4, 2, 14), Blocks.AIR.getDefaultState());
		world.setBlockState(pos.add(5, 2, 14), Blocks.AIR.getDefaultState());
		world.setBlockState(pos.add(6, 2, 14), Blocks.AIR.getDefaultState());
		world.setBlockState(pos.add(7, 2, 14), Blocks.AIR.getDefaultState());
		world.setBlockState(pos.add(8, 2, 14), Blocks.AIR.getDefaultState());
		world.setBlockState(pos.add(9, 2, 14), Blocks.AIR.getDefaultState());
		world.setBlockState(pos.add(10, 2, 14), Blocks.AIR.getDefaultState());
		world.setBlockState(pos.add(11, 2, 14), Blocks.AIR.getDefaultState());
		world.setBlockState(pos.add(12, 2, 14), Blocks.AIR.getDefaultState());
		world.setBlockState(pos.add(13, 2, 14), Blocks.AIR.getDefaultState());
		world.setBlockState(pos.add(14, 2, 14), Blocks.AIR.getDefaultState());
		world.setBlockState(pos.add(0, 3, 0), ModMetaBlocks.PROTOSS_METAL_T1.getStateFromMeta(metaPrimColor));
		world.setBlockState(pos.add(1, 3, 0), ModMetaBlocks.PROTOSS_METAL_T1.getStateFromMeta(metaPrimColor));
		world.setBlockState(pos.add(2, 3, 0), Blocks.AIR.getDefaultState());
		world.setBlockState(pos.add(3, 3, 0), Blocks.AIR.getDefaultState());
		world.setBlockState(pos.add(4, 3, 0), Blocks.AIR.getDefaultState());
		world.setBlockState(pos.add(5, 3, 0), Blocks.AIR.getDefaultState());
		world.setBlockState(pos.add(6, 3, 0), Blocks.AIR.getDefaultState());
		world.setBlockState(pos.add(7, 3, 0), Blocks.AIR.getDefaultState());
		world.setBlockState(pos.add(8, 3, 0), Blocks.AIR.getDefaultState());
		world.setBlockState(pos.add(9, 3, 0), Blocks.AIR.getDefaultState());
		world.setBlockState(pos.add(10, 3, 0), Blocks.AIR.getDefaultState());
		world.setBlockState(pos.add(11, 3, 0), Blocks.AIR.getDefaultState());
		world.setBlockState(pos.add(12, 3, 0), Blocks.AIR.getDefaultState());
		world.setBlockState(pos.add(13, 3, 0), Blocks.AIR.getDefaultState());
		world.setBlockState(pos.add(14, 3, 0), Blocks.AIR.getDefaultState());
		world.setBlockState(pos.add(0, 3, 1), ModMetaBlocks.PROTOSS_METAL_T1.getStateFromMeta(metaPrimColor));
		world.setBlockState(pos.add(1, 3, 1), ModMetaBlocks.PROTOSS_METAL_T1.getStateFromMeta(metaSecColor));
		world.setBlockState(pos.add(2, 3, 1), ModMetaBlocks.PROTOSS_METAL_T1.getStateFromMeta(metaPrimColor));
		world.setBlockState(pos.add(3, 3, 1), Blocks.AIR.getDefaultState());
		world.setBlockState(pos.add(4, 3, 1), Blocks.AIR.getDefaultState());
		world.setBlockState(pos.add(5, 3, 1), Blocks.AIR.getDefaultState());
		world.setBlockState(pos.add(6, 3, 1), Blocks.AIR.getDefaultState());
		world.setBlockState(pos.add(7, 3, 1), Blocks.AIR.getDefaultState());
		world.setBlockState(pos.add(8, 3, 1), Blocks.AIR.getDefaultState());
		world.setBlockState(pos.add(9, 3, 1), Blocks.AIR.getDefaultState());
		world.setBlockState(pos.add(10, 3, 1), ModMetaBlocks.PROTOSS_METAL_T1.getStateFromMeta(metaSecColor));
		world.setBlockState(pos.add(11, 3, 1), Blocks.AIR.getDefaultState());
		world.setBlockState(pos.add(12, 3, 1), Blocks.AIR.getDefaultState());
		world.setBlockState(pos.add(13, 3, 1), Blocks.AIR.getDefaultState());
		world.setBlockState(pos.add(14, 3, 1), Blocks.AIR.getDefaultState());
		world.setBlockState(pos.add(0, 3, 2), Blocks.AIR.getDefaultState());
		world.setBlockState(pos.add(1, 3, 2), ModMetaBlocks.PROTOSS_METAL_T1.getStateFromMeta(metaPrimColor));
		world.setBlockState(pos.add(2, 3, 2), ModMetaBlocks.PROTOSS_METAL_T1.getStateFromMeta(metaPrimColor));
		world.setBlockState(pos.add(3, 3, 2), ModMetaBlocks.PROTOSS_METAL_T1.getStateFromMeta(metaPrimColor));
		world.setBlockState(pos.add(4, 3, 2), ModMetaBlocks.PROTOSS_METAL_T1.getStateFromMeta(metaPrimColor));
		world.setBlockState(pos.add(5, 3, 2), ModMetaBlocks.PROTOSS_METAL_T1.getStateFromMeta(metaPrimColor));
		world.setBlockState(pos.add(6, 3, 2), ModMetaBlocks.PROTOSS_METAL_T1.getStateFromMeta(metaPrimColor));
		world.setBlockState(pos.add(7, 3, 2), ModMetaBlocks.PROTOSS_METAL_T1.getStateFromMeta(metaPrimColor));
		world.setBlockState(pos.add(8, 3, 2), ModMetaBlocks.PROTOSS_METAL_T1.getStateFromMeta(metaPrimColor));
		world.setBlockState(pos.add(9, 3, 2), ModMetaBlocks.PROTOSS_METAL_T1.getStateFromMeta(metaPrimColor));
		world.setBlockState(pos.add(10, 3, 2), ModMetaBlocks.PROTOSS_METAL_T1.getStateFromMeta(metaPrimColor));
		world.setBlockState(pos.add(11, 3, 2), ModMetaBlocks.PROTOSS_METAL_T1.getStateFromMeta(metaPrimColor));
		world.setBlockState(pos.add(12, 3, 2), Blocks.AIR.getDefaultState());
		world.setBlockState(pos.add(13, 3, 2), Blocks.AIR.getDefaultState());
		world.setBlockState(pos.add(14, 3, 2), Blocks.AIR.getDefaultState());
		world.setBlockState(pos.add(0, 3, 3), Blocks.AIR.getDefaultState());
		world.setBlockState(pos.add(1, 3, 3), Blocks.AIR.getDefaultState());
		world.setBlockState(pos.add(2, 3, 3), ModMetaBlocks.PROTOSS_METAL_T1.getStateFromMeta(metaPrimColor));
		world.setBlockState(pos.add(3, 3, 3), ModMetaBlocks.PROTOSS_METAL_T1.getStateFromMeta(metaPrimColor));
		world.setBlockState(pos.add(4, 3, 3), ModMetaBlocks.PROTOSS_METAL_T1.getStateFromMeta(metaPrimColor));
		world.setBlockState(pos.add(5, 3, 3), ModMetaBlocks.PROTOSS_METAL_T1.getStateFromMeta(metaPrimColor));
		world.setBlockState(pos.add(6, 3, 3), ModMetaBlocks.PROTOSS_METAL_T1.getStateFromMeta(metaPrimColor));
		world.setBlockState(pos.add(7, 3, 3), ModMetaBlocks.PROTOSS_METAL_T1.getStateFromMeta(metaPrimColor));
		world.setBlockState(pos.add(8, 3, 3), ModMetaBlocks.PROTOSS_METAL_T1.getStateFromMeta(metaPrimColor));
		world.setBlockState(pos.add(9, 3, 3), ModMetaBlocks.PROTOSS_METAL_T1.getStateFromMeta(metaPrimColor));
		world.setBlockState(pos.add(10, 3, 3), ModMetaBlocks.PROTOSS_METAL_T1.getStateFromMeta(metaPrimColor));
		world.setBlockState(pos.add(11, 3, 3), ModMetaBlocks.PROTOSS_METAL_T1.getStateFromMeta(metaPrimColor));
		world.setBlockState(pos.add(12, 3, 3), ModMetaBlocks.PROTOSS_METAL_T1.getStateFromMeta(metaPrimColor));
		world.setBlockState(pos.add(13, 3, 3), Blocks.AIR.getDefaultState());
		world.setBlockState(pos.add(14, 3, 3), Blocks.AIR.getDefaultState());
		world.setBlockState(pos.add(0, 3, 4), Blocks.AIR.getDefaultState());
		world.setBlockState(pos.add(1, 3, 4), Blocks.AIR.getDefaultState());
		world.setBlockState(pos.add(2, 3, 4), ModMetaBlocks.PROTOSS_METAL_T1.getStateFromMeta(metaPrimColor));
		world.setBlockState(pos.add(3, 3, 4), ModMetaBlocks.PROTOSS_METAL_T1.getStateFromMeta(metaPrimColor));
		world.setBlockState(pos.add(4, 3, 4), ModMetaBlocks.PROTOSS_METAL_T1.getStateFromMeta(metaPrimColor));
		world.setBlockState(pos.add(5, 3, 4), ModMetaBlocks.PROTOSS_METAL_T1.getStateFromMeta(metaPrimColor));
		world.setBlockState(pos.add(6, 3, 4), ModMetaBlocks.PROTOSS_METAL_T1.getStateFromMeta(metaPrimColor));
		world.setBlockState(pos.add(7, 3, 4), ModMetaBlocks.PROTOSS_METAL_T1.getStateFromMeta(metaPrimColor));
		world.setBlockState(pos.add(8, 3, 4), ModMetaBlocks.PROTOSS_METAL_T1.getStateFromMeta(metaPrimColor));
		world.setBlockState(pos.add(9, 3, 4), ModMetaBlocks.PROTOSS_METAL_T1.getStateFromMeta(metaPrimColor));
		world.setBlockState(pos.add(10, 3, 4), ModMetaBlocks.PROTOSS_METAL_T1.getStateFromMeta(metaPrimColor));
		world.setBlockState(pos.add(11, 3, 4), ModMetaBlocks.PROTOSS_METAL_T1.getStateFromMeta(metaPrimColor));
		world.setBlockState(pos.add(12, 3, 4), ModMetaBlocks.PROTOSS_METAL_T1.getStateFromMeta(metaPrimColor));
		world.setBlockState(pos.add(13, 3, 4), ModMetaBlocks.PROTOSS_METAL_T1.getStateFromMeta(metaSecColor));
		world.setBlockState(pos.add(14, 3, 4), Blocks.AIR.getDefaultState());
		world.setBlockState(pos.add(0, 3, 5), Blocks.AIR.getDefaultState());
		world.setBlockState(pos.add(1, 3, 5), Blocks.AIR.getDefaultState());
		world.setBlockState(pos.add(2, 3, 5), ModMetaBlocks.PROTOSS_METAL_T1.getStateFromMeta(metaPrimColor));
		world.setBlockState(pos.add(3, 3, 5), ModMetaBlocks.PROTOSS_METAL_T1.getStateFromMeta(metaPrimColor));
		world.setBlockState(pos.add(4, 3, 5), ModMetaBlocks.PROTOSS_METAL_T1.getStateFromMeta(metaPrimColor));
		world.setBlockState(pos.add(5, 3, 5), ModMetaBlocks.PROTOSS_METAL_T1.getStateFromMeta(metaPrimColor));
		world.setBlockState(pos.add(6, 3, 5), ModMetaBlocks.PROTOSS_METAL_T1.getStateFromMeta(metaPrimColor));
		world.setBlockState(pos.add(7, 3, 5), ModMetaBlocks.PROTOSS_METAL_T1.getStateFromMeta(metaPrimColor));
		world.setBlockState(pos.add(8, 3, 5), ModMetaBlocks.PROTOSS_METAL_T1.getStateFromMeta(metaPrimColor));
		world.setBlockState(pos.add(9, 3, 5), ModMetaBlocks.PROTOSS_METAL_T1.getStateFromMeta(metaPrimColor));
		world.setBlockState(pos.add(10, 3, 5), ModMetaBlocks.PROTOSS_METAL_T1.getStateFromMeta(metaPrimColor));
		world.setBlockState(pos.add(11, 3, 5), ModMetaBlocks.PROTOSS_METAL_T1.getStateFromMeta(metaPrimColor));
		world.setBlockState(pos.add(12, 3, 5), ModMetaBlocks.PROTOSS_METAL_T1.getStateFromMeta(metaPrimColor));
		world.setBlockState(pos.add(13, 3, 5), Blocks.AIR.getDefaultState());
		world.setBlockState(pos.add(14, 3, 5), Blocks.AIR.getDefaultState());
		world.setBlockState(pos.add(0, 3, 6), Blocks.AIR.getDefaultState());
		world.setBlockState(pos.add(1, 3, 6), Blocks.AIR.getDefaultState());
		world.setBlockState(pos.add(2, 3, 6), ModMetaBlocks.PROTOSS_METAL_T1.getStateFromMeta(metaPrimColor));
		world.setBlockState(pos.add(3, 3, 6), ModMetaBlocks.PROTOSS_METAL_T1.getStateFromMeta(metaPrimColor));
		world.setBlockState(pos.add(4, 3, 6), ModMetaBlocks.PROTOSS_METAL_T1.getStateFromMeta(metaPrimColor));
		world.setBlockState(pos.add(5, 3, 6), ModMetaBlocks.PROTOSS_METAL_T1.getStateFromMeta(metaPrimColor));
		world.setBlockState(pos.add(6, 3, 6), ModMetaBlocks.PROTOSS_METAL_T1.getStateFromMeta(metaPrimColor));
		world.setBlockState(pos.add(7, 3, 6), ModMetaBlocks.PROTOSS_METAL_T1.getStateFromMeta(metaPrimColor));
		world.setBlockState(pos.add(8, 3, 6), ModMetaBlocks.PROTOSS_METAL_T1.getStateFromMeta(metaPrimColor));
		world.setBlockState(pos.add(9, 3, 6), ModMetaBlocks.PROTOSS_METAL_T1.getStateFromMeta(metaPrimColor));
		world.setBlockState(pos.add(10, 3, 6), ModMetaBlocks.PROTOSS_METAL_T1.getStateFromMeta(metaPrimColor));
		world.setBlockState(pos.add(11, 3, 6), ModMetaBlocks.PROTOSS_METAL_T1.getStateFromMeta(metaPrimColor));
		world.setBlockState(pos.add(12, 3, 6), ModMetaBlocks.PROTOSS_METAL_T1.getStateFromMeta(metaPrimColor));
		world.setBlockState(pos.add(13, 3, 6), Blocks.AIR.getDefaultState());
		world.setBlockState(pos.add(14, 3, 6), Blocks.AIR.getDefaultState());
		world.setBlockState(pos.add(0, 3, 7), Blocks.AIR.getDefaultState());
		world.setBlockState(pos.add(1, 3, 7), Blocks.AIR.getDefaultState());
		world.setBlockState(pos.add(2, 3, 7), ModMetaBlocks.PROTOSS_METAL_T1.getStateFromMeta(metaPrimColor));
		world.setBlockState(pos.add(3, 3, 7), ModMetaBlocks.PROTOSS_METAL_T1.getStateFromMeta(metaPrimColor));
		world.setBlockState(pos.add(4, 3, 7), ModMetaBlocks.PROTOSS_METAL_T1.getStateFromMeta(metaPrimColor));
		world.setBlockState(pos.add(5, 3, 7), ModMetaBlocks.PROTOSS_METAL_T1.getStateFromMeta(metaPrimColor));
		world.setBlockState(pos.add(6, 3, 7), ModMetaBlocks.PROTOSS_METAL_T1.getStateFromMeta(metaPrimColor));
		world.setBlockState(pos.add(7, 3, 7), ModMetaBlocks.PROTOSS_METAL_T1.getStateFromMeta(metaPrimColor));
		world.setBlockState(pos.add(8, 3, 7), ModMetaBlocks.PROTOSS_METAL_T1.getStateFromMeta(metaPrimColor));
		world.setBlockState(pos.add(9, 3, 7), ModMetaBlocks.PROTOSS_METAL_T1.getStateFromMeta(metaPrimColor));
		world.setBlockState(pos.add(10, 3, 7), ModMetaBlocks.PROTOSS_METAL_T1.getStateFromMeta(metaPrimColor));
		world.setBlockState(pos.add(11, 3, 7), ModMetaBlocks.PROTOSS_METAL_T1.getStateFromMeta(metaPrimColor));
		world.setBlockState(pos.add(12, 3, 7), ModMetaBlocks.PROTOSS_METAL_T1.getStateFromMeta(metaPrimColor));
		world.setBlockState(pos.add(13, 3, 7), Blocks.AIR.getDefaultState());
		world.setBlockState(pos.add(14, 3, 7), Blocks.AIR.getDefaultState());
		world.setBlockState(pos.add(0, 3, 8), Blocks.AIR.getDefaultState());
		world.setBlockState(pos.add(1, 3, 8), Blocks.AIR.getDefaultState());
		world.setBlockState(pos.add(2, 3, 8), ModMetaBlocks.PROTOSS_METAL_T1.getStateFromMeta(metaPrimColor));
		world.setBlockState(pos.add(3, 3, 8), ModMetaBlocks.PROTOSS_METAL_T1.getStateFromMeta(metaPrimColor));
		world.setBlockState(pos.add(4, 3, 8), ModMetaBlocks.PROTOSS_METAL_T1.getStateFromMeta(metaPrimColor));
		world.setBlockState(pos.add(5, 3, 8), ModMetaBlocks.PROTOSS_METAL_T1.getStateFromMeta(metaPrimColor));
		world.setBlockState(pos.add(6, 3, 8), ModMetaBlocks.PROTOSS_METAL_T1.getStateFromMeta(metaPrimColor));
		world.setBlockState(pos.add(7, 3, 8), ModMetaBlocks.PROTOSS_METAL_T1.getStateFromMeta(metaPrimColor));
		world.setBlockState(pos.add(8, 3, 8), ModMetaBlocks.PROTOSS_METAL_T1.getStateFromMeta(metaPrimColor));
		world.setBlockState(pos.add(9, 3, 8), ModMetaBlocks.PROTOSS_METAL_T1.getStateFromMeta(metaPrimColor));
		world.setBlockState(pos.add(10, 3, 8), ModMetaBlocks.PROTOSS_METAL_T1.getStateFromMeta(metaPrimColor));
		world.setBlockState(pos.add(11, 3, 8), ModMetaBlocks.PROTOSS_METAL_T1.getStateFromMeta(metaPrimColor));
		world.setBlockState(pos.add(12, 3, 8), ModMetaBlocks.PROTOSS_METAL_T1.getStateFromMeta(metaPrimColor));
		world.setBlockState(pos.add(13, 3, 8), Blocks.AIR.getDefaultState());
		world.setBlockState(pos.add(14, 3, 8), Blocks.AIR.getDefaultState());
		world.setBlockState(pos.add(0, 3, 9), Blocks.AIR.getDefaultState());
		world.setBlockState(pos.add(1, 3, 9), Blocks.AIR.getDefaultState());
		world.setBlockState(pos.add(2, 3, 9), ModMetaBlocks.PROTOSS_METAL_T1.getStateFromMeta(metaPrimColor));
		world.setBlockState(pos.add(3, 3, 9), ModMetaBlocks.PROTOSS_METAL_T1.getStateFromMeta(metaPrimColor));
		world.setBlockState(pos.add(4, 3, 9), ModMetaBlocks.PROTOSS_METAL_T1.getStateFromMeta(metaPrimColor));
		world.setBlockState(pos.add(5, 3, 9), ModMetaBlocks.PROTOSS_METAL_T1.getStateFromMeta(metaPrimColor));
		world.setBlockState(pos.add(6, 3, 9), ModMetaBlocks.PROTOSS_METAL_T1.getStateFromMeta(metaPrimColor));
		world.setBlockState(pos.add(7, 3, 9), ModMetaBlocks.PROTOSS_METAL_T1.getStateFromMeta(metaPrimColor));
		world.setBlockState(pos.add(8, 3, 9), ModMetaBlocks.PROTOSS_METAL_T1.getStateFromMeta(metaPrimColor));
		world.setBlockState(pos.add(9, 3, 9), ModMetaBlocks.PROTOSS_METAL_T1.getStateFromMeta(metaPrimColor));
		world.setBlockState(pos.add(10, 3, 9), ModMetaBlocks.PROTOSS_METAL_T1.getStateFromMeta(metaPrimColor));
		world.setBlockState(pos.add(11, 3, 9), ModMetaBlocks.PROTOSS_METAL_T1.getStateFromMeta(metaPrimColor));
		world.setBlockState(pos.add(12, 3, 9), ModMetaBlocks.PROTOSS_METAL_T1.getStateFromMeta(metaPrimColor));
		world.setBlockState(pos.add(13, 3, 9), Blocks.AIR.getDefaultState());
		world.setBlockState(pos.add(14, 3, 9), Blocks.AIR.getDefaultState());
		world.setBlockState(pos.add(0, 3, 10), Blocks.AIR.getDefaultState());
		world.setBlockState(pos.add(1, 3, 10), ModMetaBlocks.PROTOSS_METAL_T1.getStateFromMeta(metaSecColor));
		world.setBlockState(pos.add(2, 3, 10), ModMetaBlocks.PROTOSS_METAL_T1.getStateFromMeta(metaPrimColor));
		world.setBlockState(pos.add(3, 3, 10), ModMetaBlocks.PROTOSS_METAL_T1.getStateFromMeta(metaPrimColor));
		world.setBlockState(pos.add(4, 3, 10), ModMetaBlocks.PROTOSS_METAL_T1.getStateFromMeta(metaPrimColor));
		world.setBlockState(pos.add(5, 3, 10), ModMetaBlocks.PROTOSS_METAL_T1.getStateFromMeta(metaPrimColor));
		world.setBlockState(pos.add(6, 3, 10), ModMetaBlocks.PROTOSS_METAL_T1.getStateFromMeta(metaPrimColor));
		world.setBlockState(pos.add(7, 3, 10), ModMetaBlocks.PROTOSS_METAL_T1.getStateFromMeta(metaPrimColor));
		world.setBlockState(pos.add(8, 3, 10), ModMetaBlocks.PROTOSS_METAL_T1.getStateFromMeta(metaPrimColor));
		world.setBlockState(pos.add(9, 3, 10), ModMetaBlocks.PROTOSS_METAL_T1.getStateFromMeta(metaPrimColor));
		world.setBlockState(pos.add(10, 3, 10), ModMetaBlocks.PROTOSS_METAL_T1.getStateFromMeta(metaPrimColor));
		world.setBlockState(pos.add(11, 3, 10), ModMetaBlocks.PROTOSS_METAL_T1.getStateFromMeta(metaPrimColor));
		world.setBlockState(pos.add(12, 3, 10), ModMetaBlocks.PROTOSS_METAL_T1.getStateFromMeta(metaPrimColor));
		world.setBlockState(pos.add(13, 3, 10), Blocks.AIR.getDefaultState());
		world.setBlockState(pos.add(14, 3, 10), Blocks.AIR.getDefaultState());
		world.setBlockState(pos.add(0, 3, 11), Blocks.AIR.getDefaultState());
		world.setBlockState(pos.add(1, 3, 11), Blocks.AIR.getDefaultState());
		world.setBlockState(pos.add(2, 3, 11), ModMetaBlocks.PROTOSS_METAL_T1.getStateFromMeta(metaPrimColor));
		world.setBlockState(pos.add(3, 3, 11), ModMetaBlocks.PROTOSS_METAL_T1.getStateFromMeta(metaPrimColor));
		world.setBlockState(pos.add(4, 3, 11), ModMetaBlocks.PROTOSS_METAL_T1.getStateFromMeta(metaPrimColor));
		world.setBlockState(pos.add(5, 3, 11), ModMetaBlocks.PROTOSS_METAL_T1.getStateFromMeta(metaPrimColor));
		world.setBlockState(pos.add(6, 3, 11), ModMetaBlocks.PROTOSS_METAL_T1.getStateFromMeta(metaPrimColor));
		world.setBlockState(pos.add(7, 3, 11), ModMetaBlocks.PROTOSS_METAL_T1.getStateFromMeta(metaPrimColor));
		world.setBlockState(pos.add(8, 3, 11), ModMetaBlocks.PROTOSS_METAL_T1.getStateFromMeta(metaPrimColor));
		world.setBlockState(pos.add(9, 3, 11), ModMetaBlocks.PROTOSS_METAL_T1.getStateFromMeta(metaPrimColor));
		world.setBlockState(pos.add(10, 3, 11), ModMetaBlocks.PROTOSS_METAL_T1.getStateFromMeta(metaPrimColor));
		world.setBlockState(pos.add(11, 3, 11), ModMetaBlocks.PROTOSS_METAL_T1.getStateFromMeta(metaPrimColor));
		world.setBlockState(pos.add(12, 3, 11), ModMetaBlocks.PROTOSS_METAL_T1.getStateFromMeta(metaPrimColor));
		world.setBlockState(pos.add(13, 3, 11), Blocks.AIR.getDefaultState());
		world.setBlockState(pos.add(14, 3, 11), Blocks.AIR.getDefaultState());
		world.setBlockState(pos.add(0, 3, 12), Blocks.AIR.getDefaultState());
		world.setBlockState(pos.add(1, 3, 12), Blocks.AIR.getDefaultState());
		world.setBlockState(pos.add(2, 3, 12), Blocks.AIR.getDefaultState());
		world.setBlockState(pos.add(3, 3, 12), ModMetaBlocks.PROTOSS_METAL_T1.getStateFromMeta(metaPrimColor));
		world.setBlockState(pos.add(4, 3, 12), ModMetaBlocks.PROTOSS_METAL_T1.getStateFromMeta(metaPrimColor));
		world.setBlockState(pos.add(5, 3, 12), ModMetaBlocks.PROTOSS_METAL_T1.getStateFromMeta(metaPrimColor));
		world.setBlockState(pos.add(6, 3, 12), ModMetaBlocks.PROTOSS_METAL_T1.getStateFromMeta(metaPrimColor));
		world.setBlockState(pos.add(7, 3, 12), ModMetaBlocks.PROTOSS_METAL_T1.getStateFromMeta(metaPrimColor));
		world.setBlockState(pos.add(8, 3, 12), ModMetaBlocks.PROTOSS_METAL_T1.getStateFromMeta(metaPrimColor));
		world.setBlockState(pos.add(9, 3, 12), ModMetaBlocks.PROTOSS_METAL_T1.getStateFromMeta(metaPrimColor));
		world.setBlockState(pos.add(10, 3, 12), ModMetaBlocks.PROTOSS_METAL_T1.getStateFromMeta(metaPrimColor));
		world.setBlockState(pos.add(11, 3, 12), ModMetaBlocks.PROTOSS_METAL_T1.getStateFromMeta(metaPrimColor));
		world.setBlockState(pos.add(12, 3, 12), ModMetaBlocks.PROTOSS_METAL_T1.getStateFromMeta(metaPrimColor));
		world.setBlockState(pos.add(13, 3, 12), ModMetaBlocks.PROTOSS_METAL_T1.getStateFromMeta(metaPrimColor));
		world.setBlockState(pos.add(14, 3, 12), Blocks.AIR.getDefaultState());
		world.setBlockState(pos.add(0, 3, 13), Blocks.AIR.getDefaultState());
		world.setBlockState(pos.add(1, 3, 13), Blocks.AIR.getDefaultState());
		world.setBlockState(pos.add(2, 3, 13), Blocks.AIR.getDefaultState());
		world.setBlockState(pos.add(3, 3, 13), Blocks.AIR.getDefaultState());
		world.setBlockState(pos.add(4, 3, 13), ModMetaBlocks.PROTOSS_METAL_T1.getStateFromMeta(metaSecColor));
		world.setBlockState(pos.add(5, 3, 13), Blocks.AIR.getDefaultState());
		world.setBlockState(pos.add(6, 3, 13), Blocks.AIR.getDefaultState());
		world.setBlockState(pos.add(7, 3, 13), Blocks.AIR.getDefaultState());
		world.setBlockState(pos.add(8, 3, 13), Blocks.AIR.getDefaultState());
		world.setBlockState(pos.add(9, 3, 13), Blocks.AIR.getDefaultState());
		world.setBlockState(pos.add(10, 3, 13), Blocks.AIR.getDefaultState());
		world.setBlockState(pos.add(11, 3, 13), Blocks.AIR.getDefaultState());
		world.setBlockState(pos.add(12, 3, 13), ModMetaBlocks.PROTOSS_METAL_T1.getStateFromMeta(metaPrimColor));
		world.setBlockState(pos.add(13, 3, 13), ModMetaBlocks.PROTOSS_METAL_T1.getStateFromMeta(metaSecColor));
		world.setBlockState(pos.add(14, 3, 13), ModMetaBlocks.PROTOSS_METAL_T1.getStateFromMeta(metaPrimColor));
		world.setBlockState(pos.add(0, 3, 14), Blocks.AIR.getDefaultState());
		world.setBlockState(pos.add(1, 3, 14), Blocks.AIR.getDefaultState());
		world.setBlockState(pos.add(2, 3, 14), Blocks.AIR.getDefaultState());
		world.setBlockState(pos.add(3, 3, 14), Blocks.AIR.getDefaultState());
		world.setBlockState(pos.add(4, 3, 14), Blocks.AIR.getDefaultState());
		world.setBlockState(pos.add(5, 3, 14), Blocks.AIR.getDefaultState());
		world.setBlockState(pos.add(6, 3, 14), Blocks.AIR.getDefaultState());
		world.setBlockState(pos.add(7, 3, 14), Blocks.AIR.getDefaultState());
		world.setBlockState(pos.add(8, 3, 14), Blocks.AIR.getDefaultState());
		world.setBlockState(pos.add(9, 3, 14), Blocks.AIR.getDefaultState());
		world.setBlockState(pos.add(10, 3, 14), Blocks.AIR.getDefaultState());
		world.setBlockState(pos.add(11, 3, 14), Blocks.AIR.getDefaultState());
		world.setBlockState(pos.add(12, 3, 14), Blocks.AIR.getDefaultState());
		world.setBlockState(pos.add(13, 3, 14), ModMetaBlocks.PROTOSS_METAL_T1.getStateFromMeta(metaPrimColor));
		world.setBlockState(pos.add(14, 3, 14), ModMetaBlocks.PROTOSS_METAL_T1.getStateFromMeta(metaPrimColor));
		world.setBlockState(pos.add(0, 4, 0), Blocks.AIR.getDefaultState());
		world.setBlockState(pos.add(1, 4, 0), Blocks.AIR.getDefaultState());
		world.setBlockState(pos.add(2, 4, 0), Blocks.AIR.getDefaultState());
		world.setBlockState(pos.add(3, 4, 0), Blocks.AIR.getDefaultState());
		world.setBlockState(pos.add(4, 4, 0), Blocks.AIR.getDefaultState());
		world.setBlockState(pos.add(5, 4, 0), Blocks.AIR.getDefaultState());
		world.setBlockState(pos.add(6, 4, 0), Blocks.AIR.getDefaultState());
		world.setBlockState(pos.add(7, 4, 0), Blocks.AIR.getDefaultState());
		world.setBlockState(pos.add(8, 4, 0), Blocks.AIR.getDefaultState());
		world.setBlockState(pos.add(9, 4, 0), Blocks.AIR.getDefaultState());
		world.setBlockState(pos.add(10, 4, 0), Blocks.AIR.getDefaultState());
		world.setBlockState(pos.add(11, 4, 0), Blocks.AIR.getDefaultState());
		world.setBlockState(pos.add(12, 4, 0), Blocks.AIR.getDefaultState());
		world.setBlockState(pos.add(13, 4, 0), Blocks.AIR.getDefaultState());
		world.setBlockState(pos.add(14, 4, 0), Blocks.AIR.getDefaultState());
		world.setBlockState(pos.add(0, 4, 1), Blocks.AIR.getDefaultState());
		world.setBlockState(pos.add(1, 4, 1), Blocks.AIR.getDefaultState());
		world.setBlockState(pos.add(2, 4, 1), Blocks.AIR.getDefaultState());
		world.setBlockState(pos.add(3, 4, 1), Blocks.AIR.getDefaultState());
		world.setBlockState(pos.add(4, 4, 1), Blocks.AIR.getDefaultState());
		world.setBlockState(pos.add(5, 4, 1), Blocks.AIR.getDefaultState());
		world.setBlockState(pos.add(6, 4, 1), Blocks.AIR.getDefaultState());
		world.setBlockState(pos.add(7, 4, 1), Blocks.AIR.getDefaultState());
		world.setBlockState(pos.add(8, 4, 1), Blocks.AIR.getDefaultState());
		world.setBlockState(pos.add(9, 4, 1), Blocks.AIR.getDefaultState());
		world.setBlockState(pos.add(10, 4, 1), Blocks.AIR.getDefaultState());
		world.setBlockState(pos.add(11, 4, 1), Blocks.AIR.getDefaultState());
		world.setBlockState(pos.add(12, 4, 1), Blocks.AIR.getDefaultState());
		world.setBlockState(pos.add(13, 4, 1), Blocks.AIR.getDefaultState());
		world.setBlockState(pos.add(14, 4, 1), Blocks.AIR.getDefaultState());
		world.setBlockState(pos.add(0, 4, 2), Blocks.AIR.getDefaultState());
		world.setBlockState(pos.add(1, 4, 2), Blocks.AIR.getDefaultState());
		world.setBlockState(pos.add(2, 4, 2), ModMetaBlocks.PROTOSS_METAL_T1.getStateFromMeta(metaPrimColor));
		world.setBlockState(pos.add(3, 4, 2), ModMetaBlocks.PROTOSS_METAL_T1.getStateFromMeta(metaPrimColor));
		world.setBlockState(pos.add(4, 4, 2), ModMetaBlocks.PROTOSS_METAL_T1.getStateFromMeta(metaSecColor));
		world.setBlockState(pos.add(5, 4, 2), ModMetaBlocks.PROTOSS_METAL_T1.getStateFromMeta(metaPrimColor));
		world.setBlockState(pos.add(6, 4, 2), Blocks.AIR.getDefaultState());
		world.setBlockState(pos.add(7, 4, 2), Blocks.AIR.getDefaultState());
		world.setBlockState(pos.add(8, 4, 2), Blocks.AIR.getDefaultState());
		world.setBlockState(pos.add(9, 4, 2), Blocks.AIR.getDefaultState());
		world.setBlockState(pos.add(10, 4, 2), ModMetaBlocks.PROTOSS_METAL_T1.getStateFromMeta(metaPrimColor));
		world.setBlockState(pos.add(11, 4, 2), Blocks.AIR.getDefaultState());
		world.setBlockState(pos.add(12, 4, 2), Blocks.AIR.getDefaultState());
		world.setBlockState(pos.add(13, 4, 2), Blocks.AIR.getDefaultState());
		world.setBlockState(pos.add(14, 4, 2), Blocks.AIR.getDefaultState());
		world.setBlockState(pos.add(0, 4, 3), Blocks.AIR.getDefaultState());
		world.setBlockState(pos.add(1, 4, 3), Blocks.AIR.getDefaultState());
		world.setBlockState(pos.add(2, 4, 3), ModMetaBlocks.PROTOSS_METAL_T1.getStateFromMeta(metaPrimColor));
		world.setBlockState(pos.add(3, 4, 3), ModMetaBlocks.PROTOSS_METAL_T1.getStateFromMeta(metaPrimColor));
		world.setBlockState(pos.add(4, 4, 3), ModMetaBlocks.PROTOSS_METAL_T1.getStateFromMeta(metaPrimColor));
		world.setBlockState(pos.add(5, 4, 3), ModMetaBlocks.PROTOSS_METAL_T1.getStateFromMeta(metaPrimColor));
		world.setBlockState(pos.add(6, 4, 3), ModMetaBlocks.PROTOSS_METAL_T1.getStateFromMeta(metaPrimColor));
		world.setBlockState(pos.add(7, 4, 3), ModMetaBlocks.PROTOSS_METAL_T1.getStateFromMeta(metaPrimColor));
		world.setBlockState(pos.add(8, 4, 3), ModMetaBlocks.PROTOSS_METAL_T1.getStateFromMeta(metaPrimColor));
		world.setBlockState(pos.add(9, 4, 3), ModMetaBlocks.PROTOSS_METAL_T1.getStateFromMeta(metaPrimColor));
		world.setBlockState(pos.add(10, 4, 3), ModMetaBlocks.PROTOSS_METAL_T1.getStateFromMeta(metaPrimColor));
		world.setBlockState(pos.add(11, 4, 3), ModMetaBlocks.PROTOSS_METAL_T1.getStateFromMeta(metaSecColor));
		world.setBlockState(pos.add(12, 4, 3), Blocks.AIR.getDefaultState());
		world.setBlockState(pos.add(13, 4, 3), Blocks.AIR.getDefaultState());
		world.setBlockState(pos.add(14, 4, 3), Blocks.AIR.getDefaultState());
		world.setBlockState(pos.add(0, 4, 4), Blocks.AIR.getDefaultState());
		world.setBlockState(pos.add(1, 4, 4), Blocks.AIR.getDefaultState());
		world.setBlockState(pos.add(2, 4, 4), ModMetaBlocks.PROTOSS_METAL_T1.getStateFromMeta(metaSecColor));
		world.setBlockState(pos.add(3, 4, 4), ModMetaBlocks.PROTOSS_METAL_T1.getStateFromMeta(metaPrimColor));
		world.setBlockState(pos.add(4, 4, 4), ModMetaBlocks.PROTOSS_METAL_T1.getStateFromMeta(metaPrimColor));
		world.setBlockState(pos.add(5, 4, 4), ModMetaBlocks.PROTOSS_METAL_T1.getStateFromMeta(metaPrimColor));
		world.setBlockState(pos.add(6, 4, 4), ModMetaBlocks.PROTOSS_METAL_T1.getStateFromMeta(metaPrimColor));
		world.setBlockState(pos.add(7, 4, 4), ModMetaBlocks.PROTOSS_METAL_T1.getStateFromMeta(metaPrimColor));
		world.setBlockState(pos.add(8, 4, 4), ModMetaBlocks.PROTOSS_METAL_T1.getStateFromMeta(metaPrimColor));
		world.setBlockState(pos.add(9, 4, 4), ModMetaBlocks.PROTOSS_METAL_T1.getStateFromMeta(metaPrimColor));
		world.setBlockState(pos.add(10, 4, 4), ModMetaBlocks.PROTOSS_METAL_T1.getStateFromMeta(metaPrimColor));
		world.setBlockState(pos.add(11, 4, 4), ModMetaBlocks.PROTOSS_METAL_T1.getStateFromMeta(metaPrimColor));
		world.setBlockState(pos.add(12, 4, 4), ModMetaBlocks.PROTOSS_METAL_T1.getStateFromMeta(metaPrimColor));
		world.setBlockState(pos.add(13, 4, 4), Blocks.AIR.getDefaultState());
		world.setBlockState(pos.add(14, 4, 4), Blocks.AIR.getDefaultState());
		world.setBlockState(pos.add(0, 4, 5), Blocks.AIR.getDefaultState());
		world.setBlockState(pos.add(1, 4, 5), Blocks.AIR.getDefaultState());
		world.setBlockState(pos.add(2, 4, 5), ModMetaBlocks.PROTOSS_METAL_T1.getStateFromMeta(metaPrimColor));
		world.setBlockState(pos.add(3, 4, 5), ModMetaBlocks.PROTOSS_METAL_T1.getStateFromMeta(metaPrimColor));
		world.setBlockState(pos.add(4, 4, 5), ModMetaBlocks.PROTOSS_METAL_T1.getStateFromMeta(metaPrimColor));
		world.setBlockState(pos.add(5, 4, 5), ModMetaBlocks.PROTOSS_METAL_T1.getStateFromMeta(metaPrimColor));
		world.setBlockState(pos.add(6, 4, 5), ModMetaBlocks.PROTOSS_METAL_T1.getStateFromMeta(metaPrimColor));
		world.setBlockState(pos.add(7, 4, 5), ModMetaBlocks.PROTOSS_METAL_T1.getStateFromMeta(metaPrimColor));
		world.setBlockState(pos.add(8, 4, 5), ModMetaBlocks.PROTOSS_METAL_T1.getStateFromMeta(metaPrimColor));
		world.setBlockState(pos.add(9, 4, 5), ModMetaBlocks.PROTOSS_METAL_T1.getStateFromMeta(metaPrimColor));
		world.setBlockState(pos.add(10, 4, 5), ModMetaBlocks.PROTOSS_METAL_T1.getStateFromMeta(metaPrimColor));
		world.setBlockState(pos.add(11, 4, 5), ModMetaBlocks.PROTOSS_METAL_T1.getStateFromMeta(metaPrimColor));
		world.setBlockState(pos.add(12, 4, 5), Blocks.AIR.getDefaultState());
		world.setBlockState(pos.add(13, 4, 5), Blocks.AIR.getDefaultState());
		world.setBlockState(pos.add(14, 4, 5), Blocks.AIR.getDefaultState());
		world.setBlockState(pos.add(0, 4, 6), Blocks.AIR.getDefaultState());
		world.setBlockState(pos.add(1, 4, 6), Blocks.AIR.getDefaultState());
		world.setBlockState(pos.add(2, 4, 6), Blocks.AIR.getDefaultState());
		world.setBlockState(pos.add(3, 4, 6), ModMetaBlocks.PROTOSS_METAL_T1.getStateFromMeta(metaPrimColor));
		world.setBlockState(pos.add(4, 4, 6), ModMetaBlocks.PROTOSS_METAL_T1.getStateFromMeta(metaPrimColor));
		world.setBlockState(pos.add(5, 4, 6), ModMetaBlocks.PROTOSS_METAL_T1.getStateFromMeta(metaPrimColor));
		world.setBlockState(pos.add(6, 4, 6), ModMetaBlocks.PROTOSS_METAL_T1.getStateFromMeta(metaPrimColor));
		world.setBlockState(pos.add(7, 4, 6), ModMetaBlocks.PROTOSS_METAL_T1.getStateFromMeta(metaPrimColor));
		world.setBlockState(pos.add(8, 4, 6), ModMetaBlocks.PROTOSS_METAL_T1.getStateFromMeta(metaPrimColor));
		world.setBlockState(pos.add(9, 4, 6), ModMetaBlocks.PROTOSS_METAL_T1.getStateFromMeta(metaPrimColor));
		world.setBlockState(pos.add(10, 4, 6), ModMetaBlocks.PROTOSS_METAL_T1.getStateFromMeta(metaPrimColor));
		world.setBlockState(pos.add(11, 4, 6), ModMetaBlocks.PROTOSS_METAL_T1.getStateFromMeta(metaPrimColor));
		world.setBlockState(pos.add(12, 4, 6), Blocks.AIR.getDefaultState());
		world.setBlockState(pos.add(13, 4, 6), Blocks.AIR.getDefaultState());
		world.setBlockState(pos.add(14, 4, 6), Blocks.AIR.getDefaultState());
		world.setBlockState(pos.add(0, 4, 7), Blocks.AIR.getDefaultState());
		world.setBlockState(pos.add(1, 4, 7), Blocks.AIR.getDefaultState());
		world.setBlockState(pos.add(2, 4, 7), Blocks.AIR.getDefaultState());
		world.setBlockState(pos.add(3, 4, 7), ModMetaBlocks.PROTOSS_METAL_T1.getStateFromMeta(metaPrimColor));
		world.setBlockState(pos.add(4, 4, 7), ModMetaBlocks.PROTOSS_METAL_T1.getStateFromMeta(metaPrimColor));
		world.setBlockState(pos.add(5, 4, 7), ModMetaBlocks.PROTOSS_METAL_T1.getStateFromMeta(metaPrimColor));
		world.setBlockState(pos.add(6, 4, 7), ModMetaBlocks.PROTOSS_METAL_T1.getStateFromMeta(metaPrimColor));
		world.setBlockState(pos.add(7, 4, 7), ModMetaBlocks.PROTOSS_METAL_T1.getStateFromMeta(metaPrimColor));
		world.setBlockState(pos.add(8, 4, 7), ModMetaBlocks.PROTOSS_METAL_T1.getStateFromMeta(metaPrimColor));
		world.setBlockState(pos.add(9, 4, 7), ModMetaBlocks.PROTOSS_METAL_T1.getStateFromMeta(metaPrimColor));
		world.setBlockState(pos.add(10, 4, 7), ModMetaBlocks.PROTOSS_METAL_T1.getStateFromMeta(metaPrimColor));
		world.setBlockState(pos.add(11, 4, 7), ModMetaBlocks.PROTOSS_METAL_T1.getStateFromMeta(metaPrimColor));
		world.setBlockState(pos.add(12, 4, 7), Blocks.AIR.getDefaultState());
		world.setBlockState(pos.add(13, 4, 7), Blocks.AIR.getDefaultState());
		world.setBlockState(pos.add(14, 4, 7), Blocks.AIR.getDefaultState());
		world.setBlockState(pos.add(0, 4, 8), Blocks.AIR.getDefaultState());
		world.setBlockState(pos.add(1, 4, 8), Blocks.AIR.getDefaultState());
		world.setBlockState(pos.add(2, 4, 8), Blocks.AIR.getDefaultState());
		world.setBlockState(pos.add(3, 4, 8), ModMetaBlocks.PROTOSS_METAL_T1.getStateFromMeta(metaPrimColor));
		world.setBlockState(pos.add(4, 4, 8), ModMetaBlocks.PROTOSS_METAL_T1.getStateFromMeta(metaPrimColor));
		world.setBlockState(pos.add(5, 4, 8), ModMetaBlocks.PROTOSS_METAL_T1.getStateFromMeta(metaPrimColor));
		world.setBlockState(pos.add(6, 4, 8), ModMetaBlocks.PROTOSS_METAL_T1.getStateFromMeta(metaPrimColor));
		world.setBlockState(pos.add(7, 4, 8), ModMetaBlocks.PROTOSS_METAL_T1.getStateFromMeta(metaPrimColor));
		world.setBlockState(pos.add(8, 4, 8), ModMetaBlocks.PROTOSS_METAL_T1.getStateFromMeta(metaPrimColor));
		world.setBlockState(pos.add(9, 4, 8), ModMetaBlocks.PROTOSS_METAL_T1.getStateFromMeta(metaPrimColor));
		world.setBlockState(pos.add(10, 4, 8), ModMetaBlocks.PROTOSS_METAL_T1.getStateFromMeta(metaPrimColor));
		world.setBlockState(pos.add(11, 4, 8), ModMetaBlocks.PROTOSS_METAL_T1.getStateFromMeta(metaPrimColor));
		world.setBlockState(pos.add(12, 4, 8), Blocks.AIR.getDefaultState());
		world.setBlockState(pos.add(13, 4, 8), Blocks.AIR.getDefaultState());
		world.setBlockState(pos.add(14, 4, 8), Blocks.AIR.getDefaultState());
		world.setBlockState(pos.add(0, 4, 9), Blocks.AIR.getDefaultState());
		world.setBlockState(pos.add(1, 4, 9), Blocks.AIR.getDefaultState());
		world.setBlockState(pos.add(2, 4, 9), Blocks.AIR.getDefaultState());
		world.setBlockState(pos.add(3, 4, 9), ModMetaBlocks.PROTOSS_METAL_T1.getStateFromMeta(metaPrimColor));
		world.setBlockState(pos.add(4, 4, 9), ModMetaBlocks.PROTOSS_METAL_T1.getStateFromMeta(metaPrimColor));
		world.setBlockState(pos.add(5, 4, 9), ModMetaBlocks.PROTOSS_METAL_T1.getStateFromMeta(metaPrimColor));
		world.setBlockState(pos.add(6, 4, 9), ModMetaBlocks.PROTOSS_METAL_T1.getStateFromMeta(metaPrimColor));
		world.setBlockState(pos.add(7, 4, 9), ModMetaBlocks.PROTOSS_METAL_T1.getStateFromMeta(metaPrimColor));
		world.setBlockState(pos.add(8, 4, 9), ModMetaBlocks.PROTOSS_METAL_T1.getStateFromMeta(metaPrimColor));
		world.setBlockState(pos.add(9, 4, 9), ModMetaBlocks.PROTOSS_METAL_T1.getStateFromMeta(metaPrimColor));
		world.setBlockState(pos.add(10, 4, 9), ModMetaBlocks.PROTOSS_METAL_T1.getStateFromMeta(metaPrimColor));
		world.setBlockState(pos.add(11, 4, 9), ModMetaBlocks.PROTOSS_METAL_T1.getStateFromMeta(metaPrimColor));
		world.setBlockState(pos.add(12, 4, 9), ModMetaBlocks.PROTOSS_METAL_T1.getStateFromMeta(metaPrimColor));
		world.setBlockState(pos.add(13, 4, 9), Blocks.AIR.getDefaultState());
		world.setBlockState(pos.add(14, 4, 9), Blocks.AIR.getDefaultState());
		world.setBlockState(pos.add(0, 4, 10), Blocks.AIR.getDefaultState());
		world.setBlockState(pos.add(1, 4, 10), Blocks.AIR.getDefaultState());
		world.setBlockState(pos.add(2, 4, 10), ModMetaBlocks.PROTOSS_METAL_T1.getStateFromMeta(metaPrimColor));
		world.setBlockState(pos.add(3, 4, 10), ModMetaBlocks.PROTOSS_METAL_T1.getStateFromMeta(metaPrimColor));
		world.setBlockState(pos.add(4, 4, 10), ModMetaBlocks.PROTOSS_METAL_T1.getStateFromMeta(metaPrimColor));
		world.setBlockState(pos.add(5, 4, 10), ModMetaBlocks.PROTOSS_METAL_T1.getStateFromMeta(metaPrimColor));
		world.setBlockState(pos.add(6, 4, 10), ModMetaBlocks.PROTOSS_METAL_T1.getStateFromMeta(metaPrimColor));
		world.setBlockState(pos.add(7, 4, 10), ModMetaBlocks.PROTOSS_METAL_T1.getStateFromMeta(metaPrimColor));
		world.setBlockState(pos.add(8, 4, 10), ModMetaBlocks.PROTOSS_METAL_T1.getStateFromMeta(metaPrimColor));
		world.setBlockState(pos.add(9, 4, 10), ModMetaBlocks.PROTOSS_METAL_T1.getStateFromMeta(metaPrimColor));
		world.setBlockState(pos.add(10, 4, 10), ModMetaBlocks.PROTOSS_METAL_T1.getStateFromMeta(metaPrimColor));
		world.setBlockState(pos.add(11, 4, 10), ModMetaBlocks.PROTOSS_METAL_T1.getStateFromMeta(metaPrimColor));
		world.setBlockState(pos.add(12, 4, 10), ModMetaBlocks.PROTOSS_METAL_T1.getStateFromMeta(metaSecColor));
		world.setBlockState(pos.add(13, 4, 10), Blocks.AIR.getDefaultState());
		world.setBlockState(pos.add(14, 4, 10), Blocks.AIR.getDefaultState());
		world.setBlockState(pos.add(0, 4, 11), Blocks.AIR.getDefaultState());
		world.setBlockState(pos.add(1, 4, 11), Blocks.AIR.getDefaultState());
		world.setBlockState(pos.add(2, 4, 11), Blocks.AIR.getDefaultState());
		world.setBlockState(pos.add(3, 4, 11), ModMetaBlocks.PROTOSS_METAL_T1.getStateFromMeta(metaSecColor));
		world.setBlockState(pos.add(4, 4, 11), ModMetaBlocks.PROTOSS_METAL_T1.getStateFromMeta(metaPrimColor));
		world.setBlockState(pos.add(5, 4, 11), ModMetaBlocks.PROTOSS_METAL_T1.getStateFromMeta(metaPrimColor));
		world.setBlockState(pos.add(6, 4, 11), ModMetaBlocks.PROTOSS_METAL_T1.getStateFromMeta(metaPrimColor));
		world.setBlockState(pos.add(7, 4, 11), ModMetaBlocks.PROTOSS_METAL_T1.getStateFromMeta(metaPrimColor));
		world.setBlockState(pos.add(8, 4, 11), ModMetaBlocks.PROTOSS_METAL_T1.getStateFromMeta(metaPrimColor));
		world.setBlockState(pos.add(9, 4, 11), ModMetaBlocks.PROTOSS_METAL_T1.getStateFromMeta(metaPrimColor));
		world.setBlockState(pos.add(10, 4, 11), ModMetaBlocks.PROTOSS_METAL_T1.getStateFromMeta(metaPrimColor));
		world.setBlockState(pos.add(11, 4, 11), ModMetaBlocks.PROTOSS_METAL_T1.getStateFromMeta(metaPrimColor));
		world.setBlockState(pos.add(12, 4, 11), ModMetaBlocks.PROTOSS_METAL_T1.getStateFromMeta(metaPrimColor));
		world.setBlockState(pos.add(13, 4, 11), Blocks.AIR.getDefaultState());
		world.setBlockState(pos.add(14, 4, 11), Blocks.AIR.getDefaultState());
		world.setBlockState(pos.add(0, 4, 12), Blocks.AIR.getDefaultState());
		world.setBlockState(pos.add(1, 4, 12), Blocks.AIR.getDefaultState());
		world.setBlockState(pos.add(2, 4, 12), Blocks.AIR.getDefaultState());
		world.setBlockState(pos.add(3, 4, 12), Blocks.AIR.getDefaultState());
		world.setBlockState(pos.add(4, 4, 12), ModMetaBlocks.PROTOSS_METAL_T1.getStateFromMeta(metaPrimColor));
		world.setBlockState(pos.add(5, 4, 12), Blocks.AIR.getDefaultState());
		world.setBlockState(pos.add(6, 4, 12), Blocks.AIR.getDefaultState());
		world.setBlockState(pos.add(7, 4, 12), Blocks.AIR.getDefaultState());
		world.setBlockState(pos.add(8, 4, 12), Blocks.AIR.getDefaultState());
		world.setBlockState(pos.add(9, 4, 12), ModMetaBlocks.PROTOSS_METAL_T1.getStateFromMeta(metaPrimColor));
		world.setBlockState(pos.add(10, 4, 12), ModMetaBlocks.PROTOSS_METAL_T1.getStateFromMeta(metaSecColor));
		world.setBlockState(pos.add(11, 4, 12), ModMetaBlocks.PROTOSS_METAL_T1.getStateFromMeta(metaPrimColor));
		world.setBlockState(pos.add(12, 4, 12), ModMetaBlocks.PROTOSS_METAL_T1.getStateFromMeta(metaPrimColor));
		world.setBlockState(pos.add(13, 4, 12), Blocks.AIR.getDefaultState());
		world.setBlockState(pos.add(14, 4, 12), Blocks.AIR.getDefaultState());
		world.setBlockState(pos.add(0, 4, 13), Blocks.AIR.getDefaultState());
		world.setBlockState(pos.add(1, 4, 13), Blocks.AIR.getDefaultState());
		world.setBlockState(pos.add(2, 4, 13), Blocks.AIR.getDefaultState());
		world.setBlockState(pos.add(3, 4, 13), Blocks.AIR.getDefaultState());
		world.setBlockState(pos.add(4, 4, 13), Blocks.AIR.getDefaultState());
		world.setBlockState(pos.add(5, 4, 13), Blocks.AIR.getDefaultState());
		world.setBlockState(pos.add(6, 4, 13), Blocks.AIR.getDefaultState());
		world.setBlockState(pos.add(7, 4, 13), Blocks.AIR.getDefaultState());
		world.setBlockState(pos.add(8, 4, 13), Blocks.AIR.getDefaultState());
		world.setBlockState(pos.add(9, 4, 13), Blocks.AIR.getDefaultState());
		world.setBlockState(pos.add(10, 4, 13), Blocks.AIR.getDefaultState());
		world.setBlockState(pos.add(11, 4, 13), Blocks.AIR.getDefaultState());
		world.setBlockState(pos.add(12, 4, 13), Blocks.AIR.getDefaultState());
		world.setBlockState(pos.add(13, 4, 13), Blocks.AIR.getDefaultState());
		world.setBlockState(pos.add(14, 4, 13), Blocks.AIR.getDefaultState());
		world.setBlockState(pos.add(0, 4, 14), Blocks.AIR.getDefaultState());
		world.setBlockState(pos.add(1, 4, 14), Blocks.AIR.getDefaultState());
		world.setBlockState(pos.add(2, 4, 14), Blocks.AIR.getDefaultState());
		world.setBlockState(pos.add(3, 4, 14), Blocks.AIR.getDefaultState());
		world.setBlockState(pos.add(4, 4, 14), Blocks.AIR.getDefaultState());
		world.setBlockState(pos.add(5, 4, 14), Blocks.AIR.getDefaultState());
		world.setBlockState(pos.add(6, 4, 14), Blocks.AIR.getDefaultState());
		world.setBlockState(pos.add(7, 4, 14), Blocks.AIR.getDefaultState());
		world.setBlockState(pos.add(8, 4, 14), Blocks.AIR.getDefaultState());
		world.setBlockState(pos.add(9, 4, 14), Blocks.AIR.getDefaultState());
		world.setBlockState(pos.add(10, 4, 14), Blocks.AIR.getDefaultState());
		world.setBlockState(pos.add(11, 4, 14), Blocks.AIR.getDefaultState());
		world.setBlockState(pos.add(12, 4, 14), Blocks.AIR.getDefaultState());
		world.setBlockState(pos.add(13, 4, 14), Blocks.AIR.getDefaultState());
		world.setBlockState(pos.add(14, 4, 14), Blocks.AIR.getDefaultState());
		world.setBlockState(pos.add(0, 5, 0), Blocks.AIR.getDefaultState());
		world.setBlockState(pos.add(1, 5, 0), Blocks.AIR.getDefaultState());
		world.setBlockState(pos.add(2, 5, 0), Blocks.AIR.getDefaultState());
		world.setBlockState(pos.add(3, 5, 0), Blocks.AIR.getDefaultState());
		world.setBlockState(pos.add(4, 5, 0), Blocks.AIR.getDefaultState());
		world.setBlockState(pos.add(5, 5, 0), Blocks.AIR.getDefaultState());
		world.setBlockState(pos.add(6, 5, 0), Blocks.AIR.getDefaultState());
		world.setBlockState(pos.add(7, 5, 0), Blocks.AIR.getDefaultState());
		world.setBlockState(pos.add(8, 5, 0), Blocks.AIR.getDefaultState());
		world.setBlockState(pos.add(9, 5, 0), Blocks.AIR.getDefaultState());
		world.setBlockState(pos.add(10, 5, 0), Blocks.AIR.getDefaultState());
		world.setBlockState(pos.add(11, 5, 0), Blocks.AIR.getDefaultState());
		world.setBlockState(pos.add(12, 5, 0), Blocks.AIR.getDefaultState());
		world.setBlockState(pos.add(13, 5, 0), Blocks.AIR.getDefaultState());
		world.setBlockState(pos.add(14, 5, 0), Blocks.AIR.getDefaultState());
		world.setBlockState(pos.add(0, 5, 1), Blocks.AIR.getDefaultState());
		world.setBlockState(pos.add(1, 5, 1), Blocks.AIR.getDefaultState());
		world.setBlockState(pos.add(2, 5, 1), ModMetaBlocks.PROTOSS_METAL_T1.getStateFromMeta(metaPrimColor));
		world.setBlockState(pos.add(3, 5, 1), ModMetaBlocks.PROTOSS_METAL_T1.getStateFromMeta(metaPrimColor));
		world.setBlockState(pos.add(4, 5, 1), Blocks.AIR.getDefaultState());
		world.setBlockState(pos.add(5, 5, 1), Blocks.AIR.getDefaultState());
		world.setBlockState(pos.add(6, 5, 1), Blocks.AIR.getDefaultState());
		world.setBlockState(pos.add(7, 5, 1), Blocks.AIR.getDefaultState());
		world.setBlockState(pos.add(8, 5, 1), Blocks.AIR.getDefaultState());
		world.setBlockState(pos.add(9, 5, 1), Blocks.AIR.getDefaultState());
		world.setBlockState(pos.add(10, 5, 1), Blocks.AIR.getDefaultState());
		world.setBlockState(pos.add(11, 5, 1), Blocks.AIR.getDefaultState());
		world.setBlockState(pos.add(12, 5, 1), Blocks.AIR.getDefaultState());
		world.setBlockState(pos.add(13, 5, 1), Blocks.AIR.getDefaultState());
		world.setBlockState(pos.add(14, 5, 1), Blocks.AIR.getDefaultState());
		world.setBlockState(pos.add(0, 5, 2), Blocks.AIR.getDefaultState());
		world.setBlockState(pos.add(1, 5, 2), ModMetaBlocks.PROTOSS_METAL_T1.getStateFromMeta(metaPrimColor));
		world.setBlockState(pos.add(2, 5, 2), ModMetaBlocks.PROTOSS_METAL_T1.getStateFromMeta(metaPrimColor));
		world.setBlockState(pos.add(3, 5, 2), ModMetaBlocks.PROTOSS_METAL_T1.getStateFromMeta(metaPrimColor));
		world.setBlockState(pos.add(4, 5, 2), ModMetaBlocks.PROTOSS_METAL_T1.getStateFromMeta(metaPrimColor));
		world.setBlockState(pos.add(5, 5, 2), Blocks.AIR.getDefaultState());
		world.setBlockState(pos.add(6, 5, 2), Blocks.AIR.getDefaultState());
		world.setBlockState(pos.add(7, 5, 2), Blocks.AIR.getDefaultState());
		world.setBlockState(pos.add(8, 5, 2), Blocks.AIR.getDefaultState());
		world.setBlockState(pos.add(9, 5, 2), Blocks.AIR.getDefaultState());
		world.setBlockState(pos.add(10, 5, 2), Blocks.AIR.getDefaultState());
		world.setBlockState(pos.add(11, 5, 2), Blocks.AIR.getDefaultState());
		world.setBlockState(pos.add(12, 5, 2), Blocks.AIR.getDefaultState());
		world.setBlockState(pos.add(13, 5, 2), Blocks.AIR.getDefaultState());
		world.setBlockState(pos.add(14, 5, 2), Blocks.AIR.getDefaultState());
		world.setBlockState(pos.add(0, 5, 3), Blocks.AIR.getDefaultState());
		world.setBlockState(pos.add(1, 5, 3), ModMetaBlocks.PROTOSS_METAL_T1.getStateFromMeta(metaPrimColor));
		world.setBlockState(pos.add(2, 5, 3), ModMetaBlocks.PROTOSS_METAL_T1.getStateFromMeta(metaPrimColor));
		world.setBlockState(pos.add(3, 5, 3), chanBlock.getDefaultState());
		world.setBlockState(pos.add(4, 5, 3), Blocks.AIR.getDefaultState());
		world.setBlockState(pos.add(5, 5, 3), Blocks.AIR.getDefaultState());
		world.setBlockState(pos.add(6, 5, 3), Blocks.AIR.getDefaultState());
		world.setBlockState(pos.add(7, 5, 3), Blocks.AIR.getDefaultState());
		world.setBlockState(pos.add(8, 5, 3), Blocks.AIR.getDefaultState());
		world.setBlockState(pos.add(9, 5, 3), Blocks.AIR.getDefaultState());
		world.setBlockState(pos.add(10, 5, 3), Blocks.AIR.getDefaultState());
		world.setBlockState(pos.add(11, 5, 3), Blocks.AIR.getDefaultState());
		world.setBlockState(pos.add(12, 5, 3), Blocks.AIR.getDefaultState());
		world.setBlockState(pos.add(13, 5, 3), Blocks.AIR.getDefaultState());
		world.setBlockState(pos.add(14, 5, 3), Blocks.AIR.getDefaultState());
		world.setBlockState(pos.add(0, 5, 4), Blocks.AIR.getDefaultState());
		world.setBlockState(pos.add(1, 5, 4), Blocks.AIR.getDefaultState());
		world.setBlockState(pos.add(2, 5, 4), ModMetaBlocks.PROTOSS_METAL_T1.getStateFromMeta(metaPrimColor));
		world.setBlockState(pos.add(3, 5, 4), Blocks.AIR.getDefaultState());
		world.setBlockState(pos.add(4, 5, 4), Blocks.AIR.getDefaultState());
		world.setBlockState(pos.add(5, 5, 4), Blocks.AIR.getDefaultState());
		world.setBlockState(pos.add(6, 5, 4), Blocks.AIR.getDefaultState());
		world.setBlockState(pos.add(7, 5, 4), ModMetaBlocks.PROTOSS_METAL_T1.getStateFromMeta(metaPrimColor));
		world.setBlockState(pos.add(8, 5, 4), ModMetaBlocks.PROTOSS_METAL_T1.getStateFromMeta(metaSecColor));
		world.setBlockState(pos.add(9, 5, 4), ModMetaBlocks.PROTOSS_METAL_T1.getStateFromMeta(metaPrimColor));
		world.setBlockState(pos.add(10, 5, 4), Blocks.AIR.getDefaultState());
		world.setBlockState(pos.add(11, 5, 4), Blocks.AIR.getDefaultState());
		world.setBlockState(pos.add(12, 5, 4), Blocks.AIR.getDefaultState());
		world.setBlockState(pos.add(13, 5, 4), Blocks.AIR.getDefaultState());
		world.setBlockState(pos.add(14, 5, 4), Blocks.AIR.getDefaultState());
		world.setBlockState(pos.add(0, 5, 5), Blocks.AIR.getDefaultState());
		world.setBlockState(pos.add(1, 5, 5), Blocks.AIR.getDefaultState());
		world.setBlockState(pos.add(2, 5, 5), Blocks.AIR.getDefaultState());
		world.setBlockState(pos.add(3, 5, 5), Blocks.AIR.getDefaultState());
		world.setBlockState(pos.add(4, 5, 5), Blocks.AIR.getDefaultState());
		world.setBlockState(pos.add(5, 5, 5), stabBlock.getDefaultState());
		world.setBlockState(pos.add(6, 5, 5), ModMetaBlocks.PROTOSS_METAL_T1.getStateFromMeta(metaPrimColor));
		world.setBlockState(pos.add(7, 5, 5), ModMetaBlocks.PROTOSS_METAL_T1.getStateFromMeta(metaSecColor));
		world.setBlockState(pos.add(8, 5, 5), ModMetaBlocks.PROTOSS_METAL_T1.getStateFromMeta(metaPrimColor));
		world.setBlockState(pos.add(9, 5, 5), ModMetaBlocks.PROTOSS_METAL_T1.getStateFromMeta(metaPrimColor));
		world.setBlockState(pos.add(10, 5, 5), ModMetaBlocks.PROTOSS_METAL_T1.getStateFromMeta(metaPrimColor));
		world.setBlockState(pos.add(11, 5, 5), Blocks.AIR.getDefaultState());
		world.setBlockState(pos.add(12, 5, 5), Blocks.AIR.getDefaultState());
		world.setBlockState(pos.add(13, 5, 5), Blocks.AIR.getDefaultState());
		world.setBlockState(pos.add(14, 5, 5), Blocks.AIR.getDefaultState());
		world.setBlockState(pos.add(0, 5, 6), Blocks.AIR.getDefaultState());
		world.setBlockState(pos.add(1, 5, 6), Blocks.AIR.getDefaultState());
		world.setBlockState(pos.add(2, 5, 6), Blocks.AIR.getDefaultState());
		world.setBlockState(pos.add(3, 5, 6), Blocks.AIR.getDefaultState());
		world.setBlockState(pos.add(4, 5, 6), Blocks.AIR.getDefaultState());
		world.setBlockState(pos.add(5, 5, 6), ModMetaBlocks.PROTOSS_METAL_T1.getStateFromMeta(metaPrimColor));
		world.setBlockState(pos.add(6, 5, 6), ModMetaBlocks.PROTOSS_METAL_T1.getStateFromMeta(metaPrimColor));
		world.setBlockState(pos.add(7, 5, 6), ModMetaBlocks.PROTOSS_METAL_T1.getStateFromMeta(metaPrimColor));
		world.setBlockState(pos.add(8, 5, 6), ModMetaBlocks.PROTOSS_METAL_T1.getStateFromMeta(metaSecColor));
		world.setBlockState(pos.add(9, 5, 6), ModMetaBlocks.PROTOSS_METAL_T1.getStateFromMeta(metaPrimColor));
		world.setBlockState(pos.add(10, 5, 6), ModMetaBlocks.PROTOSS_METAL_T1.getStateFromMeta(metaSecColor));
		world.setBlockState(pos.add(11, 5, 6), Blocks.AIR.getDefaultState());
		world.setBlockState(pos.add(12, 5, 6), Blocks.AIR.getDefaultState());
		world.setBlockState(pos.add(13, 5, 6), Blocks.AIR.getDefaultState());
		world.setBlockState(pos.add(14, 5, 6), Blocks.AIR.getDefaultState());
		world.setBlockState(pos.add(0, 5, 7), Blocks.AIR.getDefaultState());
		world.setBlockState(pos.add(1, 5, 7), Blocks.AIR.getDefaultState());
		world.setBlockState(pos.add(2, 5, 7), Blocks.AIR.getDefaultState());
		world.setBlockState(pos.add(3, 5, 7), Blocks.AIR.getDefaultState());
		world.setBlockState(pos.add(4, 5, 7), ModMetaBlocks.PROTOSS_METAL_T1.getStateFromMeta(metaPrimColor));
		world.setBlockState(pos.add(5, 5, 7), ModMetaBlocks.PROTOSS_METAL_T1.getStateFromMeta(metaSecColor));
		world.setBlockState(pos.add(6, 5, 7), ModMetaBlocks.PROTOSS_METAL_T1.getStateFromMeta(metaPrimColor));
		world.setBlockState(pos.add(7, 5, 7), stabBlock.getDefaultState());
		world.setBlockState(pos.add(8, 5, 7), ModMetaBlocks.PROTOSS_METAL_T1.getStateFromMeta(metaPrimColor));
		world.setBlockState(pos.add(9, 5, 7), ModMetaBlocks.PROTOSS_METAL_T1.getStateFromMeta(metaSecColor));
		world.setBlockState(pos.add(10, 5, 7), ModMetaBlocks.PROTOSS_METAL_T1.getStateFromMeta(metaPrimColor));
		world.setBlockState(pos.add(11, 5, 7), Blocks.AIR.getDefaultState());
		world.setBlockState(pos.add(12, 5, 7), Blocks.AIR.getDefaultState());
		world.setBlockState(pos.add(13, 5, 7), Blocks.AIR.getDefaultState());
		world.setBlockState(pos.add(14, 5, 7), Blocks.AIR.getDefaultState());
		world.setBlockState(pos.add(0, 5, 8), Blocks.AIR.getDefaultState());
		world.setBlockState(pos.add(1, 5, 8), Blocks.AIR.getDefaultState());
		world.setBlockState(pos.add(2, 5, 8), Blocks.AIR.getDefaultState());
		world.setBlockState(pos.add(3, 5, 8), Blocks.AIR.getDefaultState());
		world.setBlockState(pos.add(4, 5, 8), ModMetaBlocks.PROTOSS_METAL_T1.getStateFromMeta(metaSecColor));
		world.setBlockState(pos.add(5, 5, 8), ModMetaBlocks.PROTOSS_METAL_T1.getStateFromMeta(metaPrimColor));
		world.setBlockState(pos.add(6, 5, 8), ModMetaBlocks.PROTOSS_METAL_T1.getStateFromMeta(metaSecColor));
		world.setBlockState(pos.add(7, 5, 8), ModMetaBlocks.PROTOSS_METAL_T1.getStateFromMeta(metaPrimColor));
		world.setBlockState(pos.add(8, 5, 8), ModMetaBlocks.PROTOSS_METAL_T1.getStateFromMeta(metaPrimColor));
		world.setBlockState(pos.add(9, 5, 8), ModMetaBlocks.PROTOSS_METAL_T1.getStateFromMeta(metaPrimColor));
		world.setBlockState(pos.add(10, 5, 8), Blocks.AIR.getDefaultState());
		world.setBlockState(pos.add(11, 5, 8), Blocks.AIR.getDefaultState());
		world.setBlockState(pos.add(12, 5, 8), Blocks.AIR.getDefaultState());
		world.setBlockState(pos.add(13, 5, 8), Blocks.AIR.getDefaultState());
		world.setBlockState(pos.add(14, 5, 8), Blocks.AIR.getDefaultState());
		world.setBlockState(pos.add(0, 5, 9), Blocks.AIR.getDefaultState());
		world.setBlockState(pos.add(1, 5, 9), Blocks.AIR.getDefaultState());
		world.setBlockState(pos.add(2, 5, 9), Blocks.AIR.getDefaultState());
		world.setBlockState(pos.add(3, 5, 9), Blocks.AIR.getDefaultState());
		world.setBlockState(pos.add(4, 5, 9), ModMetaBlocks.PROTOSS_METAL_T1.getStateFromMeta(metaPrimColor));
		world.setBlockState(pos.add(5, 5, 9), ModMetaBlocks.PROTOSS_METAL_T1.getStateFromMeta(metaPrimColor));
		world.setBlockState(pos.add(6, 5, 9), ModMetaBlocks.PROTOSS_METAL_T1.getStateFromMeta(metaPrimColor));
		world.setBlockState(pos.add(7, 5, 9), ModMetaBlocks.PROTOSS_METAL_T1.getStateFromMeta(metaSecColor));
		world.setBlockState(pos.add(8, 5, 9), ModMetaBlocks.PROTOSS_METAL_T1.getStateFromMeta(metaPrimColor));
		world.setBlockState(pos.add(9, 5, 9), stabBlock.getDefaultState());
		world.setBlockState(pos.add(10, 5, 9), Blocks.AIR.getDefaultState());
		world.setBlockState(pos.add(11, 5, 9), Blocks.AIR.getDefaultState());
		world.setBlockState(pos.add(12, 5, 9), Blocks.AIR.getDefaultState());
		world.setBlockState(pos.add(13, 5, 9), Blocks.AIR.getDefaultState());
