//Schematic to java Structure by jajo_11 | inspired by "MITHION'S .SCHEMATIC TO JAVA CONVERTINGTOOL"

package net.bvanseghi.starcraft.worldgen.structure;

import java.util.Random;

import net.bvanseghi.starcraft.blocks.ModBlocks;
import net.minecraft.block.Block;
import net.minecraft.block.material.Material;
import net.minecraft.init.Blocks;
import net.minecraft.world.World;
import net.minecraft.world.gen.feature.WorldGenerator;

public class StructureZergSpawningPool extends WorldGenerator {
	protected Block[] GetValidSpawnBlocks() {
		return new Block[] { ModBlocks.zergCreep, };
	}

	public boolean LocationIsValidSpawn(World world, int x, int y, int z) {
		int distanceToAir = 0;
		Block checkBlock = world.getBlock(x, y, z);

		while (checkBlock != Blocks.AIR) {
			distanceToAir++;
			checkBlock = world.getBlock(x, y + distanceToAir, z);
		}

		if (distanceToAir > 1) {
			return false;
		}

		y += distanceToAir - 1;

		Block block = world.getBlock(x, y, z);
		Block blockAbove = world.getBlock(x, y + 1, z);
		Block blockBelow = world.getBlock(x, y - 1, z);

		for (Block i : GetValidSpawnBlocks()) {
			if (blockAbove != Blocks.AIR) {
				return false;
			}
			if (block == i) {
				return true;
			} else if (block == Blocks.SNOW_LAYER && blockBelow == i) {
				return true;
			} else if (block.getMaterial() == Material.PLANTS && blockBelow == i) {
				return true;
			}
		}
		return false;
	}

	public boolean generate(World world, Random rand, int x, int y, int z) {
		int i = rand.nextInt(1);

		if (i == 0) {
			generate_r0(world, rand, x, y, z);
		}

		return true;

	}

	public boolean generate_r0(World world, Random rand, int x, int y, int z) {
		if (!LocationIsValidSpawn(world, x, y, z) || !LocationIsValidSpawn(world, x + 18, y, z)
				|| !LocationIsValidSpawn(world, x + 18, y, z + 20) || !LocationIsValidSpawn(world, x, y, z + 20)) {
			return false;
		}

		world.setBlock(x + 0, y + 0, z + 0, ModBlocks.zergCreep, 0, 3);
		world.setBlock(x + 1, y + 0, z + 0, ModBlocks.zergCreep, 0, 3);
		world.setBlock(x + 2, y + 0, z + 0, ModBlocks.zergCreep, 0, 3);
		world.setBlock(x + 3, y + 0, z + 0, ModBlocks.zergCreep, 0, 3);
		world.setBlock(x + 4, y + 0, z + 0, ModBlocks.zergCreep, 0, 3);
		world.setBlock(x + 5, y + 0, z + 0, ModBlocks.zergCreep, 0, 3);
		world.setBlock(x + 6, y + 0, z + 0, ModBlocks.zergCreep, 0, 3);
		world.setBlock(x + 7, y + 0, z + 0, ModBlocks.zergCreep, 0, 3);
		world.setBlock(x + 8, y + 0, z + 0, ModBlocks.zergCreep, 0, 3);
		world.setBlock(x + 9, y + 0, z + 0, ModBlocks.zergCreep, 0, 3);
		world.setBlock(x + 10, y + 0, z + 0, ModBlocks.zergCreep, 0, 3);
		world.setBlock(x + 11, y + 0, z + 0, ModBlocks.zergCreep, 0, 3);
		world.setBlock(x + 12, y + 0, z + 0, ModBlocks.zergCreep, 0, 3);
		world.setBlock(x + 13, y + 0, z + 0, ModBlocks.zergCreep, 0, 3);
		world.setBlock(x + 14, y + 0, z + 0, ModBlocks.zergCreep, 0, 3);
		world.setBlock(x + 15, y + 0, z + 0, ModBlocks.zergCreep, 0, 3);
		world.setBlock(x + 16, y + 0, z + 0, ModBlocks.zergCreep, 0, 3);
		world.setBlock(x + 17, y + 0, z + 0, ModBlocks.zergCreep, 0, 3);
		world.setBlock(x + 18, y + 0, z + 0, ModBlocks.zergCreep, 0, 3);
		world.setBlock(x + 0, y + 0, z + 1, ModBlocks.zergCreep, 0, 3);
		world.setBlock(x + 1, y + 0, z + 1, ModBlocks.zergCreep, 0, 3);
		world.setBlock(x + 2, y + 0, z + 1, ModBlocks.zergCreep, 0, 3);
		world.setBlock(x + 3, y + 0, z + 1, ModBlocks.zergCreep, 0, 3);
		world.setBlock(x + 4, y + 0, z + 1, ModBlocks.zergCreep, 0, 3);
		world.setBlock(x + 5, y + 0, z + 1, ModBlocks.zergCreep, 0, 3);
		world.setBlock(x + 6, y + 0, z + 1, ModBlocks.zergCreep, 0, 3);
		world.setBlock(x + 7, y + 0, z + 1, ModBlocks.zergCreep, 0, 3);
		world.setBlock(x + 8, y + 0, z + 1, ModBlocks.zergCreep, 0, 3);
		world.setBlock(x + 9, y + 0, z + 1, ModBlocks.zergCreep, 0, 3);
		world.setBlock(x + 10, y + 0, z + 1, ModBlocks.zergCreep, 0, 3);
		world.setBlock(x + 11, y + 0, z + 1, ModBlocks.zergCreep, 0, 3);
		world.setBlock(x + 12, y + 0, z + 1, ModBlocks.zergCreep, 0, 3);
		world.setBlock(x + 13, y + 0, z + 1, ModBlocks.zergCreep, 0, 3);
		world.setBlock(x + 14, y + 0, z + 1, ModBlocks.zergCreep, 0, 3);
		world.setBlock(x + 15, y + 0, z + 1, ModBlocks.zergCreep, 0, 3);
		world.setBlock(x + 16, y + 0, z + 1, ModBlocks.zergCreep, 0, 3);
		world.setBlock(x + 17, y + 0, z + 1, ModBlocks.zergCreep, 0, 3);
		world.setBlock(x + 18, y + 0, z + 1, ModBlocks.zergCreep, 0, 3);
		world.setBlock(x + 0, y + 0, z + 2, ModBlocks.zergCreep, 0, 3);
		world.setBlock(x + 1, y + 0, z + 2, ModBlocks.zergCreep, 0, 3);
		world.setBlock(x + 2, y + 0, z + 2, ModBlocks.zergCreep, 0, 3);
		world.setBlock(x + 3, y + 0, z + 2, ModBlocks.zergCreep, 0, 3);
		world.setBlock(x + 4, y + 0, z + 2, ModBlocks.zergCreep, 0, 3);
		world.setBlock(x + 5, y + 0, z + 2, ModBlocks.zergCreep, 0, 3);
		world.setBlock(x + 6, y + 0, z + 2, ModBlocks.zergCreep, 0, 3);
		world.setBlock(x + 7, y + 0, z + 2, ModBlocks.zergCreep, 0, 3);
		world.setBlock(x + 8, y + 0, z + 2, ModBlocks.zergCreep, 0, 3);
		world.setBlock(x + 9, y + 0, z + 2, ModBlocks.zergCreep, 0, 3);
		world.setBlock(x + 10, y + 0, z + 2, ModBlocks.zergCreep, 0, 3);
		world.setBlock(x + 11, y + 0, z + 2, ModBlocks.zergCreep, 0, 3);
		world.setBlock(x + 12, y + 0, z + 2, ModBlocks.zergCreep, 0, 3);
		world.setBlock(x + 13, y + 0, z + 2, ModBlocks.zergCreep, 0, 3);
		world.setBlock(x + 14, y + 0, z + 2, ModBlocks.zergCreep, 0, 3);
		world.setBlock(x + 15, y + 0, z + 2, ModBlocks.zergCreep, 0, 3);
		world.setBlock(x + 16, y + 0, z + 2, ModBlocks.zergCreep, 0, 3);
		world.setBlock(x + 17, y + 0, z + 2, ModBlocks.zergCreep, 0, 3);
		world.setBlock(x + 18, y + 0, z + 2, ModBlocks.zergCreep, 0, 3);
		world.setBlock(x + 0, y + 0, z + 3, ModBlocks.zergCreep, 0, 3);
		world.setBlock(x + 1, y + 0, z + 3, ModBlocks.zergCreep, 0, 3);
		world.setBlock(x + 2, y + 0, z + 3, ModBlocks.zergCreep, 0, 3);
		world.setBlock(x + 3, y + 0, z + 3, ModBlocks.zergCreep, 0, 3);
		world.setBlock(x + 4, y + 0, z + 3, ModBlocks.zergCreep, 0, 3);
		world.setBlock(x + 5, y + 0, z + 3, ModBlocks.zergCreep, 0, 3);
		world.setBlock(x + 6, y + 0, z + 3, ModBlocks.zergCreep, 0, 3);
		world.setBlock(x + 7, y + 0, z + 3, ModBlocks.zergCreep, 0, 3);
		world.setBlock(x + 8, y + 0, z + 3, ModBlocks.zergCreep, 0, 3);
		world.setBlock(x + 9, y + 0, z + 3, ModBlocks.zergCreep, 0, 3);
		world.setBlock(x + 10, y + 0, z + 3, ModBlocks.zergCreep, 0, 3);
		world.setBlock(x + 11, y + 0, z + 3, ModBlocks.zergCreep, 0, 3);
		world.setBlock(x + 12, y + 0, z + 3, ModBlocks.zergCreep, 0, 3);
		world.setBlock(x + 13, y + 0, z + 3, ModBlocks.zergCreep, 0, 3);
		world.setBlock(x + 14, y + 0, z + 3, ModBlocks.zergCreep, 0, 3);
		world.setBlock(x + 15, y + 0, z + 3, ModBlocks.zergCreep, 0, 3);
		world.setBlock(x + 16, y + 0, z + 3, ModBlocks.zergCreep, 0, 3);
		world.setBlock(x + 17, y + 0, z + 3, ModBlocks.zergCreep, 0, 3);
		world.setBlock(x + 18, y + 0, z + 3, ModBlocks.zergCreep, 0, 3);
		world.setBlock(x + 0, y + 0, z + 4, ModBlocks.zergCreep, 0, 3);
		world.setBlock(x + 1, y + 0, z + 4, ModBlocks.zergCreep, 0, 3);
		world.setBlock(x + 2, y + 0, z + 4, ModBlocks.zergCreep, 0, 3);
		world.setBlock(x + 3, y + 0, z + 4, ModBlocks.zergCreep, 0, 3);
		world.setBlock(x + 4, y + 0, z + 4, ModBlocks.zergCreep, 0, 3);
		world.setBlock(x + 5, y + 0, z + 4, ModBlocks.zergCreep, 0, 3);
		world.setBlock(x + 6, y + 0, z + 4, ModBlocks.zergCreep, 0, 3);
		world.setBlock(x + 7, y + 0, z + 4, ModBlocks.zergCreep, 0, 3);
		world.setBlock(x + 8, y + 0, z + 4, ModBlocks.zergCreep, 0, 3);
		world.setBlock(x + 9, y + 0, z + 4, ModBlocks.zergCreep, 0, 3);
		world.setBlock(x + 10, y + 0, z + 4, ModBlocks.zergCreep, 0, 3);
		world.setBlock(x + 11, y + 0, z + 4, ModBlocks.zergCreep, 0, 3);
		world.setBlock(x + 12, y + 0, z + 4, ModBlocks.zergCreep, 0, 3);
		world.setBlock(x + 13, y + 0, z + 4, ModBlocks.zergCreep, 0, 3);
		world.setBlock(x + 14, y + 0, z + 4, ModBlocks.zergCreep, 0, 3);
		world.setBlock(x + 15, y + 0, z + 4, ModBlocks.zergCreep, 0, 3);
		world.setBlock(x + 16, y + 0, z + 4, ModBlocks.zergCreep, 0, 3);
		world.setBlock(x + 17, y + 0, z + 4, ModBlocks.zergCreep, 0, 3);
		world.setBlock(x + 18, y + 0, z + 4, ModBlocks.zergCreep, 0, 3);
		world.setBlock(x + 0, y + 0, z + 5, ModBlocks.zergCreep, 0, 3);
		world.setBlock(x + 1, y + 0, z + 5, ModBlocks.zergCreep, 0, 3);
		world.setBlock(x + 2, y + 0, z + 5, ModBlocks.zergCreep, 0, 3);
		world.setBlock(x + 3, y + 0, z + 5, ModBlocks.zergCreep, 0, 3);
		world.setBlock(x + 4, y + 0, z + 5, ModBlocks.zergCreep, 0, 3);
		world.setBlock(x + 5, y + 0, z + 5, ModBlocks.zergCreep, 0, 3);
		world.setBlock(x + 6, y + 0, z + 5, ModBlocks.zergCreep, 0, 3);
		world.setBlock(x + 7, y + 0, z + 5, ModBlocks.zergCreep, 0, 3);
		world.setBlock(x + 8, y + 0, z + 5, ModBlocks.zergCreep, 0, 3);
		world.setBlock(x + 9, y + 0, z + 5, ModBlocks.zergCreep, 0, 3);
		world.setBlock(x + 10, y + 0, z + 5, ModBlocks.zergCreep, 0, 3);
		world.setBlock(x + 11, y + 0, z + 5, ModBlocks.zergCreep, 0, 3);
		world.setBlock(x + 12, y + 0, z + 5, ModBlocks.zergCreep, 0, 3);
		world.setBlock(x + 13, y + 0, z + 5, ModBlocks.zergCreep, 0, 3);
		world.setBlock(x + 14, y + 0, z + 5, ModBlocks.zergCreep, 0, 3);
		world.setBlock(x + 15, y + 0, z + 5, ModBlocks.zergCreep, 0, 3);
		world.setBlock(x + 16, y + 0, z + 5, ModBlocks.zergCreep, 0, 3);
		world.setBlock(x + 17, y + 0, z + 5, ModBlocks.zergCreep, 0, 3);
		world.setBlock(x + 18, y + 0, z + 5, ModBlocks.zergCreep, 0, 3);
		world.setBlock(x + 0, y + 0, z + 6, ModBlocks.zergCreep, 0, 3);
		world.setBlock(x + 1, y + 0, z + 6, ModBlocks.zergCreep, 0, 3);
		world.setBlock(x + 2, y + 0, z + 6, ModBlocks.zergCreep, 0, 3);
		world.setBlock(x + 3, y + 0, z + 6, ModBlocks.zergCreep, 0, 3);
		world.setBlock(x + 4, y + 0, z + 6, ModBlocks.zergCreep, 0, 3);
		world.setBlock(x + 5, y + 0, z + 6, ModBlocks.zergCreep, 0, 3);
		world.setBlock(x + 6, y + 0, z + 6, ModBlocks.zergCreep, 0, 3);
		world.setBlock(x + 7, y + 0, z + 6, ModBlocks.zergCreep, 0, 3);
		world.setBlock(x + 8, y + 0, z + 6, ModBlocks.zergCreep, 0, 3);
		world.setBlock(x + 9, y + 0, z + 6, ModBlocks.zergCreep, 0, 3);
		world.setBlock(x + 10, y + 0, z + 6, ModBlocks.zergCreep, 0, 3);
		world.setBlock(x + 11, y + 0, z + 6, ModBlocks.zergCreep, 0, 3);
		world.setBlock(x + 12, y + 0, z + 6, ModBlocks.zergCreep, 0, 3);
		world.setBlock(x + 13, y + 0, z + 6, ModBlocks.zergCreep, 0, 3);
		world.setBlock(x + 14, y + 0, z + 6, ModBlocks.zergCreep, 0, 3);
		world.setBlock(x + 15, y + 0, z + 6, ModBlocks.zergCreep, 0, 3);
		world.setBlock(x + 16, y + 0, z + 6, ModBlocks.zergCreep, 0, 3);
		world.setBlock(x + 17, y + 0, z + 6, ModBlocks.zergCreep, 0, 3);
		world.setBlock(x + 18, y + 0, z + 6, ModBlocks.zergCreep, 0, 3);
		world.setBlock(x + 0, y + 0, z + 7, ModBlocks.zergCreep, 0, 3);
		world.setBlock(x + 1, y + 0, z + 7, ModBlocks.zergCreep, 0, 3);
		world.setBlock(x + 2, y + 0, z + 7, ModBlocks.zergCreep, 0, 3);
		world.setBlock(x + 3, y + 0, z + 7, ModBlocks.zergCreep, 0, 3);
		world.setBlock(x + 4, y + 0, z + 7, ModBlocks.zergCreep, 0, 3);
		world.setBlock(x + 5, y + 0, z + 7, ModBlocks.zergCreep, 0, 3);
		world.setBlock(x + 6, y + 0, z + 7, ModBlocks.zergCreep, 0, 3);
		world.setBlock(x + 7, y + 0, z + 7, ModBlocks.zergCreep, 0, 3);
		world.setBlock(x + 8, y + 0, z + 7, ModBlocks.zergCreep, 0, 3);
		world.setBlock(x + 9, y + 0, z + 7, ModBlocks.zergCreep, 0, 3);
		world.setBlock(x + 10, y + 0, z + 7, ModBlocks.zergCreep, 0, 3);
		world.setBlock(x + 11, y + 0, z + 7, ModBlocks.zergCreep, 0, 3);
		world.setBlock(x + 12, y + 0, z + 7, ModBlocks.zergCreep, 0, 3);
		world.setBlock(x + 13, y + 0, z + 7, ModBlocks.zergCreep, 0, 3);
		world.setBlock(x + 14, y + 0, z + 7, ModBlocks.zergCreep, 0, 3);
		world.setBlock(x + 15, y + 0, z + 7, ModBlocks.zergCreep, 0, 3);
		world.setBlock(x + 16, y + 0, z + 7, ModBlocks.zergCreep, 0, 3);
		world.setBlock(x + 17, y + 0, z + 7, ModBlocks.zergCreep, 0, 3);
		world.setBlock(x + 18, y + 0, z + 7, ModBlocks.zergCreep, 0, 3);
		world.setBlock(x + 0, y + 0, z + 8, ModBlocks.zergCreep, 0, 3);
		world.setBlock(x + 1, y + 0, z + 8, ModBlocks.zergCreep, 0, 3);
		world.setBlock(x + 2, y + 0, z + 8, ModBlocks.zergCreep, 0, 3);
		world.setBlock(x + 3, y + 0, z + 8, ModBlocks.zergCreep, 0, 3);
		world.setBlock(x + 4, y + 0, z + 8, ModBlocks.zergCreep, 0, 3);
		world.setBlock(x + 5, y + 0, z + 8, ModBlocks.zergCreep, 0, 3);
		world.setBlock(x + 6, y + 0, z + 8, ModBlocks.zergCreep, 0, 3);
		world.setBlock(x + 7, y + 0, z + 8, ModBlocks.zergCreep, 0, 3);
		world.setBlock(x + 8, y + 0, z + 8, ModBlocks.zergCreep, 0, 3);
		world.setBlock(x + 9, y + 0, z + 8, ModBlocks.zergCreep, 0, 3);
		world.setBlock(x + 10, y + 0, z + 8, ModBlocks.zergCreep, 0, 3);
		world.setBlock(x + 11, y + 0, z + 8, ModBlocks.zergCreep, 0, 3);
		world.setBlock(x + 12, y + 0, z + 8, ModBlocks.zergCreep, 0, 3);
		world.setBlock(x + 13, y + 0, z + 8, ModBlocks.zergCreep, 0, 3);
		world.setBlock(x + 14, y + 0, z + 8, ModBlocks.zergCreep, 0, 3);
		world.setBlock(x + 15, y + 0, z + 8, ModBlocks.zergCreep, 0, 3);
		world.setBlock(x + 16, y + 0, z + 8, ModBlocks.zergCreep, 0, 3);
		world.setBlock(x + 17, y + 0, z + 8, ModBlocks.zergCreep, 0, 3);
		world.setBlock(x + 18, y + 0, z + 8, ModBlocks.zergCreep, 0, 3);
		world.setBlock(x + 0, y + 0, z + 9, ModBlocks.zergCreep, 0, 3);
		world.setBlock(x + 1, y + 0, z + 9, ModBlocks.zergCreep, 0, 3);
		world.setBlock(x + 2, y + 0, z + 9, ModBlocks.zergCreep, 0, 3);
		world.setBlock(x + 3, y + 0, z + 9, ModBlocks.zergCreep, 0, 3);
		world.setBlock(x + 4, y + 0, z + 9, ModBlocks.zergCreep, 0, 3);
		world.setBlock(x + 5, y + 0, z + 9, ModBlocks.zergCreep, 0, 3);
		world.setBlock(x + 6, y + 0, z + 9, ModBlocks.zergCreep, 0, 3);
		world.setBlock(x + 7, y + 0, z + 9, ModBlocks.zergCreep, 0, 3);
		world.setBlock(x + 8, y + 0, z + 9, ModBlocks.zergCreep, 0, 3);
		world.setBlock(x + 9, y + 0, z + 9, ModBlocks.zergCreep, 0, 3);
		world.setBlock(x + 10, y + 0, z + 9, ModBlocks.zergCreep, 0, 3);
		world.setBlock(x + 11, y + 0, z + 9, ModBlocks.zergCreep, 0, 3);
		world.setBlock(x + 12, y + 0, z + 9, ModBlocks.zergCreep, 0, 3);
		world.setBlock(x + 13, y + 0, z + 9, ModBlocks.zergCreep, 0, 3);
		world.setBlock(x + 14, y + 0, z + 9, ModBlocks.zergCreep, 0, 3);
		world.setBlock(x + 15, y + 0, z + 9, ModBlocks.zergCreep, 0, 3);
		world.setBlock(x + 16, y + 0, z + 9, ModBlocks.zergCreep, 0, 3);
		world.setBlock(x + 17, y + 0, z + 9, ModBlocks.zergCreep, 0, 3);
		world.setBlock(x + 18, y + 0, z + 9, ModBlocks.zergCreep, 0, 3);
		world.setBlock(x + 0, y + 0, z + 10, ModBlocks.zergCreep, 0, 3);
		world.setBlock(x + 1, y + 0, z + 10, ModBlocks.zergCreep, 0, 3);
		world.setBlock(x + 2, y + 0, z + 10, ModBlocks.zergCreep, 0, 3);
		world.setBlock(x + 3, y + 0, z + 10, ModBlocks.zergCreep, 0, 3);
		world.setBlock(x + 4, y + 0, z + 10, ModBlocks.zergCreep, 0, 3);
		world.setBlock(x + 5, y + 0, z + 10, ModBlocks.zergCreep, 0, 3);
		world.setBlock(x + 6, y + 0, z + 10, ModBlocks.zergCreep, 0, 3);
		world.setBlock(x + 7, y + 0, z + 10, ModBlocks.zergCreep, 0, 3);
		world.setBlock(x + 8, y + 0, z + 10, ModBlocks.zergCreep, 0, 3);
		world.setBlock(x + 9, y + 0, z + 10, ModBlocks.zergCreep, 0, 3);
		world.setBlock(x + 10, y + 0, z + 10, ModBlocks.zergCreep, 0, 3);
		world.setBlock(x + 11, y + 0, z + 10, ModBlocks.zergCreep, 0, 3);
		world.setBlock(x + 12, y + 0, z + 10, ModBlocks.zergCreep, 0, 3);
		world.setBlock(x + 13, y + 0, z + 10, ModBlocks.zergCreep, 0, 3);
		world.setBlock(x + 14, y + 0, z + 10, ModBlocks.zergCreep, 0, 3);
		world.setBlock(x + 15, y + 0, z + 10, ModBlocks.zergCreep, 0, 3);
		world.setBlock(x + 16, y + 0, z + 10, ModBlocks.zergCreep, 0, 3);
		world.setBlock(x + 17, y + 0, z + 10, ModBlocks.zergCreep, 0, 3);
		world.setBlock(x + 18, y + 0, z + 10, ModBlocks.zergCreep, 0, 3);
		world.setBlock(x + 0, y + 0, z + 11, ModBlocks.zergCreep, 0, 3);
		world.setBlock(x + 1, y + 0, z + 11, ModBlocks.zergCreep, 0, 3);
		world.setBlock(x + 2, y + 0, z + 11, ModBlocks.zergCreep, 0, 3);
		world.setBlock(x + 3, y + 0, z + 11, ModBlocks.zergCreep, 0, 3);
		world.setBlock(x + 4, y + 0, z + 11, ModBlocks.zergCreep, 0, 3);
		world.setBlock(x + 5, y + 0, z + 11, ModBlocks.zergCreep, 0, 3);
		world.setBlock(x + 6, y + 0, z + 11, ModBlocks.zergCreep, 0, 3);
		world.setBlock(x + 7, y + 0, z + 11, ModBlocks.zergCreep, 0, 3);
		world.setBlock(x + 8, y + 0, z + 11, ModBlocks.zergCreep, 0, 3);
		world.setBlock(x + 9, y + 0, z + 11, ModBlocks.zergCreep, 0, 3);
		world.setBlock(x + 10, y + 0, z + 11, ModBlocks.zergCreep, 0, 3);
		world.setBlock(x + 11, y + 0, z + 11, ModBlocks.zergCreep, 0, 3);
		world.setBlock(x + 12, y + 0, z + 11, ModBlocks.zergCreep, 0, 3);
		world.setBlock(x + 13, y + 0, z + 11, ModBlocks.zergCreep, 0, 3);
		world.setBlock(x + 14, y + 0, z + 11, ModBlocks.zergCreep, 0, 3);
		world.setBlock(x + 15, y + 0, z + 11, ModBlocks.zergCreep, 0, 3);
		world.setBlock(x + 16, y + 0, z + 11, ModBlocks.zergCreep, 0, 3);
		world.setBlock(x + 17, y + 0, z + 11, ModBlocks.zergCreep, 0, 3);
		world.setBlock(x + 18, y + 0, z + 11, ModBlocks.zergCreep, 0, 3);
		world.setBlock(x + 0, y + 0, z + 12, ModBlocks.zergCreep, 0, 3);
		world.setBlock(x + 1, y + 0, z + 12, ModBlocks.zergCreep, 0, 3);
		world.setBlock(x + 2, y + 0, z + 12, ModBlocks.zergCreep, 0, 3);
		world.setBlock(x + 3, y + 0, z + 12, ModBlocks.zergCreep, 0, 3);
		world.setBlock(x + 4, y + 0, z + 12, ModBlocks.zergCreep, 0, 3);
		world.setBlock(x + 5, y + 0, z + 12, ModBlocks.zergCreep, 0, 3);
		world.setBlock(x + 6, y + 0, z + 12, ModBlocks.zergCreep, 0, 3);
		world.setBlock(x + 7, y + 0, z + 12, ModBlocks.zergCreep, 0, 3);
		world.setBlock(x + 8, y + 0, z + 12, ModBlocks.zergCreep, 0, 3);
		world.setBlock(x + 9, y + 0, z + 12, ModBlocks.zergCreep, 0, 3);
		world.setBlock(x + 10, y + 0, z + 12, ModBlocks.zergCreep, 0, 3);
		world.setBlock(x + 11, y + 0, z + 12, ModBlocks.zergCreep, 0, 3);
		world.setBlock(x + 12, y + 0, z + 12, ModBlocks.zergCreep, 0, 3);
		world.setBlock(x + 13, y + 0, z + 12, ModBlocks.zergCreep, 0, 3);
		world.setBlock(x + 14, y + 0, z + 12, ModBlocks.zergCreep, 0, 3);
		world.setBlock(x + 15, y + 0, z + 12, ModBlocks.zergCreep, 0, 3);
		world.setBlock(x + 16, y + 0, z + 12, ModBlocks.zergCreep, 0, 3);
		world.setBlock(x + 17, y + 0, z + 12, ModBlocks.zergCreep, 0, 3);
		world.setBlock(x + 18, y + 0, z + 12, ModBlocks.zergCreep, 0, 3);
		world.setBlock(x + 0, y + 0, z + 13, ModBlocks.zergCreep, 0, 3);
		world.setBlock(x + 1, y + 0, z + 13, ModBlocks.zergCreep, 0, 3);
		world.setBlock(x + 2, y + 0, z + 13, ModBlocks.zergCreep, 0, 3);
		world.setBlock(x + 3, y + 0, z + 13, ModBlocks.zergCreep, 0, 3);
		world.setBlock(x + 4, y + 0, z + 13, ModBlocks.zergCreep, 0, 3);
		world.setBlock(x + 5, y + 0, z + 13, ModBlocks.zergCreep, 0, 3);
		world.setBlock(x + 6, y + 0, z + 13, ModBlocks.zergCreep, 0, 3);
		world.setBlock(x + 7, y + 0, z + 13, ModBlocks.zergCreep, 0, 3);
		world.setBlock(x + 8, y + 0, z + 13, ModBlocks.zergCreep, 0, 3);
		world.setBlock(x + 9, y + 0, z + 13, ModBlocks.zergCreep, 0, 3);
		world.setBlock(x + 10, y + 0, z + 13, ModBlocks.zergCreep, 0, 3);
		world.setBlock(x + 11, y + 0, z + 13, ModBlocks.zergCreep, 0, 3);
		world.setBlock(x + 12, y + 0, z + 13, ModBlocks.zergCreep, 0, 3);
		world.setBlock(x + 13, y + 0, z + 13, ModBlocks.zergCreep, 0, 3);
		world.setBlock(x + 14, y + 0, z + 13, ModBlocks.zergCreep, 0, 3);
		world.setBlock(x + 15, y + 0, z + 13, ModBlocks.zergCreep, 0, 3);
		world.setBlock(x + 16, y + 0, z + 13, ModBlocks.zergCreep, 0, 3);
		world.setBlock(x + 17, y + 0, z + 13, ModBlocks.zergCreep, 0, 3);
		world.setBlock(x + 18, y + 0, z + 13, ModBlocks.zergCreep, 0, 3);
		world.setBlock(x + 0, y + 0, z + 14, ModBlocks.zergCreep, 0, 3);
		world.setBlock(x + 1, y + 0, z + 14, ModBlocks.zergCreep, 0, 3);
		world.setBlock(x + 2, y + 0, z + 14, ModBlocks.zergCreep, 0, 3);
		world.setBlock(x + 3, y + 0, z + 14, ModBlocks.zergCreep, 0, 3);
		world.setBlock(x + 4, y + 0, z + 14, ModBlocks.zergCreep, 0, 3);
		world.setBlock(x + 5, y + 0, z + 14, ModBlocks.zergCreep, 0, 3);
		world.setBlock(x + 6, y + 0, z + 14, ModBlocks.zergCreep, 0, 3);
		world.setBlock(x + 7, y + 0, z + 14, ModBlocks.zergCreep, 0, 3);
		world.setBlock(x + 8, y + 0, z + 14, ModBlocks.zergCreep, 0, 3);
		world.setBlock(x + 9, y + 0, z + 14, ModBlocks.zergCreep, 0, 3);
		world.setBlock(x + 10, y + 0, z + 14, ModBlocks.zergCreep, 0, 3);
		world.setBlock(x + 11, y + 0, z + 14, ModBlocks.zergCreep, 0, 3);
		world.setBlock(x + 12, y + 0, z + 14, ModBlocks.zergCreep, 0, 3);
		world.setBlock(x + 13, y + 0, z + 14, ModBlocks.zergCreep, 0, 3);
		world.setBlock(x + 14, y + 0, z + 14, ModBlocks.zergCreep, 0, 3);
		world.setBlock(x + 15, y + 0, z + 14, ModBlocks.zergCreep, 0, 3);
		world.setBlock(x + 16, y + 0, z + 14, ModBlocks.zergCreep, 0, 3);
		world.setBlock(x + 17, y + 0, z + 14, ModBlocks.zergCreep, 0, 3);
		world.setBlock(x + 18, y + 0, z + 14, ModBlocks.zergCreep, 0, 3);
		world.setBlock(x + 0, y + 0, z + 15, ModBlocks.zergCreep, 0, 3);
		world.setBlock(x + 1, y + 0, z + 15, ModBlocks.zergCreep, 0, 3);
		world.setBlock(x + 2, y + 0, z + 15, ModBlocks.zergCreep, 0, 3);
		world.setBlock(x + 3, y + 0, z + 15, ModBlocks.zergCreep, 0, 3);
		world.setBlock(x + 4, y + 0, z + 15, ModBlocks.zergCreep, 0, 3);
		world.setBlock(x + 5, y + 0, z + 15, ModBlocks.zergCreep, 0, 3);
		world.setBlock(x + 6, y + 0, z + 15, ModBlocks.zergCreep, 0, 3);
		world.setBlock(x + 7, y + 0, z + 15, ModBlocks.zergCreep, 0, 3);
		world.setBlock(x + 8, y + 0, z + 15, ModBlocks.zergCreep, 0, 3);
		world.setBlock(x + 9, y + 0, z + 15, ModBlocks.zergCreep, 0, 3);
		world.setBlock(x + 10, y + 0, z + 15, ModBlocks.zergCreep, 0, 3);
		world.setBlock(x + 11, y + 0, z + 15, ModBlocks.zergCreep, 0, 3);
		world.setBlock(x + 12, y + 0, z + 15, ModBlocks.zergCreep, 0, 3);
		world.setBlock(x + 13, y + 0, z + 15, ModBlocks.zergCreep, 0, 3);
		world.setBlock(x + 14, y + 0, z + 15, ModBlocks.zergCreep, 0, 3);
		world.setBlock(x + 15, y + 0, z + 15, ModBlocks.zergCreep, 0, 3);
		world.setBlock(x + 16, y + 0, z + 15, ModBlocks.zergCreep, 0, 3);
		world.setBlock(x + 17, y + 0, z + 15, ModBlocks.zergCreep, 0, 3);
		world.setBlock(x + 18, y + 0, z + 15, ModBlocks.zergCreep, 0, 3);
		world.setBlock(x + 0, y + 0, z + 16, ModBlocks.zergCreep, 0, 3);
		world.setBlock(x + 1, y + 0, z + 16, ModBlocks.zergCreep, 0, 3);
		world.setBlock(x + 2, y + 0, z + 16, ModBlocks.zergCreep, 0, 3);
		world.setBlock(x + 3, y + 0, z + 16, ModBlocks.zergCreep, 0, 3);
		world.setBlock(x + 4, y + 0, z + 16, ModBlocks.zergCreep, 0, 3);
		world.setBlock(x + 5, y + 0, z + 16, ModBlocks.zergCreep, 0, 3);
		world.setBlock(x + 6, y + 0, z + 16, ModBlocks.zergCreep, 0, 3);
		world.setBlock(x + 7, y + 0, z + 16, ModBlocks.zergCreep, 0, 3);
		world.setBlock(x + 8, y + 0, z + 16, ModBlocks.zergCreep, 0, 3);
		world.setBlock(x + 9, y + 0, z + 16, ModBlocks.zergCreep, 0, 3);
		world.setBlock(x + 10, y + 0, z + 16, ModBlocks.zergCreep, 0, 3);
		world.setBlock(x + 11, y + 0, z + 16, ModBlocks.zergCreep, 0, 3);
		world.setBlock(x + 12, y + 0, z + 16, ModBlocks.zergCreep, 0, 3);
		world.setBlock(x + 13, y + 0, z + 16, ModBlocks.zergCreep, 0, 3);
		world.setBlock(x + 14, y + 0, z + 16, ModBlocks.zergCreep, 0, 3);
		world.setBlock(x + 15, y + 0, z + 16, ModBlocks.zergCreep, 0, 3);
		world.setBlock(x + 16, y + 0, z + 16, ModBlocks.zergCreep, 0, 3);
		world.setBlock(x + 17, y + 0, z + 16, ModBlocks.zergCreep, 0, 3);
		world.setBlock(x + 18, y + 0, z + 16, ModBlocks.zergCreep, 0, 3);
		world.setBlock(x + 0, y + 0, z + 17, ModBlocks.zergCreep, 0, 3);
		world.setBlock(x + 1, y + 0, z + 17, ModBlocks.zergCreep, 0, 3);
		world.setBlock(x + 2, y + 0, z + 17, ModBlocks.zergCreep, 0, 3);
		world.setBlock(x + 3, y + 0, z + 17, ModBlocks.zergCreep, 0, 3);
		world.setBlock(x + 4, y + 0, z + 17, ModBlocks.zergCreep, 0, 3);
		world.setBlock(x + 5, y + 0, z + 17, ModBlocks.zergCreep, 0, 3);
		world.setBlock(x + 6, y + 0, z + 17, ModBlocks.zergCreep, 0, 3);
		world.setBlock(x + 7, y + 0, z + 17, ModBlocks.zergCreep, 0, 3);
		world.setBlock(x + 8, y + 0, z + 17, ModBlocks.zergCreep, 0, 3);
		world.setBlock(x + 9, y + 0, z + 17, ModBlocks.zergCreep, 0, 3);
		world.setBlock(x + 10, y + 0, z + 17, ModBlocks.zergCreep, 0, 3);
		world.setBlock(x + 11, y + 0, z + 17, ModBlocks.zergCreep, 0, 3);
		world.setBlock(x + 12, y + 0, z + 17, ModBlocks.zergCreep, 0, 3);
		world.setBlock(x + 13, y + 0, z + 17, ModBlocks.zergCreep, 0, 3);
		world.setBlock(x + 14, y + 0, z + 17, ModBlocks.zergCreep, 0, 3);
		world.setBlock(x + 15, y + 0, z + 17, ModBlocks.zergCreep, 0, 3);
		world.setBlock(x + 16, y + 0, z + 17, ModBlocks.zergCreep, 0, 3);
		world.setBlock(x + 17, y + 0, z + 17, ModBlocks.zergCreep, 0, 3);
		world.setBlock(x + 18, y + 0, z + 17, ModBlocks.zergCreep, 0, 3);
		world.setBlock(x + 0, y + 0, z + 18, ModBlocks.zergCreep, 0, 3);
		world.setBlock(x + 1, y + 0, z + 18, ModBlocks.zergCreep, 0, 3);
		world.setBlock(x + 2, y + 0, z + 18, ModBlocks.zergCreep, 0, 3);
		world.setBlock(x + 3, y + 0, z + 18, ModBlocks.zergCreep, 0, 3);
		world.setBlock(x + 4, y + 0, z + 18, ModBlocks.zergCreep, 0, 3);
		world.setBlock(x + 5, y + 0, z + 18, ModBlocks.zergCreep, 0, 3);
		world.setBlock(x + 6, y + 0, z + 18, ModBlocks.zergCreep, 0, 3);
		world.setBlock(x + 7, y + 0, z + 18, ModBlocks.zergCreep, 0, 3);
		world.setBlock(x + 8, y + 0, z + 18, ModBlocks.zergCreep, 0, 3);
		world.setBlock(x + 9, y + 0, z + 18, ModBlocks.zergCreep, 0, 3);
		world.setBlock(x + 10, y + 0, z + 18, ModBlocks.zergCreep, 0, 3);
		world.setBlock(x + 11, y + 0, z + 18, ModBlocks.zergCreep, 0, 3);
		world.setBlock(x + 12, y + 0, z + 18, ModBlocks.zergCreep, 0, 3);
		world.setBlock(x + 13, y + 0, z + 18, ModBlocks.zergCreep, 0, 3);
		world.setBlock(x + 14, y + 0, z + 18, ModBlocks.zergCreep, 0, 3);
		world.setBlock(x + 15, y + 0, z + 18, ModBlocks.zergCreep, 0, 3);
		world.setBlock(x + 16, y + 0, z + 18, ModBlocks.zergCreep, 0, 3);
		world.setBlock(x + 17, y + 0, z + 18, ModBlocks.zergCreep, 0, 3);
		world.setBlock(x + 18, y + 0, z + 18, ModBlocks.zergCreep, 0, 3);
		world.setBlock(x + 0, y + 0, z + 19, ModBlocks.zergCreep, 0, 3);
		world.setBlock(x + 1, y + 0, z + 19, ModBlocks.zergCreep, 0, 3);
		world.setBlock(x + 2, y + 0, z + 19, ModBlocks.zergCreep, 0, 3);
		world.setBlock(x + 3, y + 0, z + 19, ModBlocks.zergCreep, 0, 3);
		world.setBlock(x + 4, y + 0, z + 19, ModBlocks.zergCreep, 0, 3);
		world.setBlock(x + 5, y + 0, z + 19, ModBlocks.zergCreep, 0, 3);
		world.setBlock(x + 6, y + 0, z + 19, ModBlocks.zergCreep, 0, 3);
		world.setBlock(x + 7, y + 0, z + 19, ModBlocks.zergCreep, 0, 3);
		world.setBlock(x + 8, y + 0, z + 19, ModBlocks.zergCreep, 0, 3);
		world.setBlock(x + 9, y + 0, z + 19, ModBlocks.zergCreep, 0, 3);
		world.setBlock(x + 10, y + 0, z + 19, ModBlocks.zergCreep, 0, 3);
		world.setBlock(x + 11, y + 0, z + 19, ModBlocks.zergCreep, 0, 3);
		world.setBlock(x + 12, y + 0, z + 19, ModBlocks.zergCreep, 0, 3);
		world.setBlock(x + 13, y + 0, z + 19, ModBlocks.zergCreep, 0, 3);
		world.setBlock(x + 14, y + 0, z + 19, ModBlocks.zergCreep, 0, 3);
		world.setBlock(x + 15, y + 0, z + 19, ModBlocks.zergCreep, 0, 3);
		world.setBlock(x + 16, y + 0, z + 19, ModBlocks.zergCreep, 0, 3);
		world.setBlock(x + 17, y + 0, z + 19, ModBlocks.zergCreep, 0, 3);
		world.setBlock(x + 18, y + 0, z + 19, ModBlocks.zergCreep, 0, 3);
		world.setBlock(x + 0, y + 0, z + 20, ModBlocks.zergCreep, 0, 3);
		world.setBlock(x + 1, y + 0, z + 20, ModBlocks.zergCreep, 0, 3);
		world.setBlock(x + 2, y + 0, z + 20, ModBlocks.zergCreep, 0, 3);
		world.setBlock(x + 3, y + 0, z + 20, ModBlocks.zergCreep, 0, 3);
		world.setBlock(x + 4, y + 0, z + 20, ModBlocks.zergCreep, 0, 3);
		world.setBlock(x + 5, y + 0, z + 20, ModBlocks.zergCreep, 0, 3);
		world.setBlock(x + 6, y + 0, z + 20, ModBlocks.zergCreep, 0, 3);
		world.setBlock(x + 7, y + 0, z + 20, ModBlocks.zergCreep, 0, 3);
		world.setBlock(x + 8, y + 0, z + 20, ModBlocks.zergCreep, 0, 3);
		world.setBlock(x + 9, y + 0, z + 20, ModBlocks.zergCreep, 0, 3);
		world.setBlock(x + 10, y + 0, z + 20, ModBlocks.zergCreep, 0, 3);
		world.setBlock(x + 11, y + 0, z + 20, ModBlocks.zergCreep, 0, 3);
		world.setBlock(x + 12, y + 0, z + 20, ModBlocks.zergCreep, 0, 3);
		world.setBlock(x + 13, y + 0, z + 20, ModBlocks.zergCreep, 0, 3);
		world.setBlock(x + 14, y + 0, z + 20, ModBlocks.zergCreep, 0, 3);
		world.setBlock(x + 15, y + 0, z + 20, ModBlocks.zergCreep, 0, 3);
		world.setBlock(x + 16, y + 0, z + 20, ModBlocks.zergCreep, 0, 3);
		world.setBlock(x + 17, y + 0, z + 20, ModBlocks.zergCreep, 0, 3);
		world.setBlock(x + 18, y + 0, z + 20, ModBlocks.zergCreep, 0, 3);
		world.setBlock(x + 0, y + 1, z + 0, Blocks.air, 0, 3);
		world.setBlock(x + 1, y + 1, z + 0, Blocks.air, 0, 3);
		world.setBlock(x + 2, y + 1, z + 0, Blocks.air, 0, 3);
		world.setBlock(x + 3, y + 1, z + 0, Blocks.air, 0, 3);
		world.setBlock(x + 4, y + 1, z + 0, Blocks.air, 0, 3);
		world.setBlock(x + 5, y + 1, z + 0, Blocks.air, 0, 3);
		world.setBlock(x + 6, y + 1, z + 0, Blocks.air, 0, 3);
		world.setBlock(x + 7, y + 1, z + 0, Blocks.air, 0, 3);
		world.setBlock(x + 8, y + 1, z + 0, Blocks.air, 0, 3);
		world.setBlock(x + 9, y + 1, z + 0, Blocks.air, 0, 3);
		world.setBlock(x + 10, y + 1, z + 0, Blocks.air, 0, 3);
		world.setBlock(x + 11, y + 1, z + 0, Blocks.air, 0, 3);
		world.setBlock(x + 12, y + 1, z + 0, Blocks.air, 0, 3);
		world.setBlock(x + 13, y + 1, z + 0, Blocks.air, 0, 3);
		world.setBlock(x + 14, y + 1, z + 0, Blocks.air, 0, 3);
		world.setBlock(x + 15, y + 1, z + 0, Blocks.air, 0, 3);
		world.setBlock(x + 16, y + 1, z + 0, Blocks.air, 0, 3);
		world.setBlock(x + 17, y + 1, z + 0, Blocks.air, 0, 3);
		world.setBlock(x + 18, y + 1, z + 0, Blocks.air, 0, 3);
		world.setBlock(x + 0, y + 1, z + 1, Blocks.air, 0, 3);
		world.setBlock(x + 1, y + 1, z + 1, Blocks.air, 0, 3);
		world.setBlock(x + 2, y + 1, z + 1, Blocks.air, 0, 3);
		world.setBlock(x + 3, y + 1, z + 1, Blocks.air, 0, 3);
		world.setBlock(x + 4, y + 1, z + 1, Blocks.air, 0, 3);
		world.setBlock(x + 5, y + 1, z + 1, Blocks.air, 0, 3);
		world.setBlock(x + 6, y + 1, z + 1, Blocks.air, 0, 3);
		world.setBlock(x + 7, y + 1, z + 1, Blocks.air, 0, 3);
		world.setBlock(x + 8, y + 1, z + 1, ModBlocks.zergStrucFlesh, 0, 3);
		world.setBlock(x + 9, y + 1, z + 1, Blocks.air, 0, 3);
		world.setBlock(x + 10, y + 1, z + 1, Blocks.air, 0, 3);
		world.setBlock(x + 11, y + 1, z + 1, Blocks.air, 0, 3);
		world.setBlock(x + 12, y + 1, z + 1, Blocks.air, 0, 3);
		world.setBlock(x + 13, y + 1, z + 1, Blocks.air, 0, 3);
		world.setBlock(x + 14, y + 1, z + 1, Blocks.air, 0, 3);
		world.setBlock(x + 15, y + 1, z + 1, Blocks.air, 0, 3);
		world.setBlock(x + 16, y + 1, z + 1, Blocks.air, 0, 3);
		world.setBlock(x + 17, y + 1, z + 1, Blocks.air, 0, 3);
		world.setBlock(x + 18, y + 1, z + 1, Blocks.air, 0, 3);
		world.setBlock(x + 0, y + 1, z + 2, Blocks.air, 0, 3);
		world.setBlock(x + 1, y + 1, z + 2, Blocks.air, 0, 3);
		world.setBlock(x + 2, y + 1, z + 2, Blocks.air, 0, 3);
		world.setBlock(x + 3, y + 1, z + 2, Blocks.air, 0, 3);
		world.setBlock(x + 4, y + 1, z + 2, Blocks.air, 0, 3);
		world.setBlock(x + 5, y + 1, z + 2, Blocks.air, 0, 3);
		world.setBlock(x + 6, y + 1, z + 2, Blocks.air, 0, 3);
		world.setBlock(x + 7, y + 1, z + 2, Blocks.air, 0, 3);
		world.setBlock(x + 8, y + 1, z + 2, Blocks.air, 0, 3);
		world.setBlock(x + 9, y + 1, z + 2, ModBlocks.zergStrucFlesh, 0, 3);
		world.setBlock(x + 10, y + 1, z + 2, Blocks.air, 0, 3);
		world.setBlock(x + 11, y + 1, z + 2, Blocks.air, 0, 3);
		world.setBlock(x + 12, y + 1, z + 2, Blocks.air, 0, 3);
		world.setBlock(x + 13, y + 1, z + 2, Blocks.air, 0, 3);
		world.setBlock(x + 14, y + 1, z + 2, Blocks.air, 0, 3);
		world.setBlock(x + 15, y + 1, z + 2, Blocks.air, 0, 3);
		world.setBlock(x + 16, y + 1, z + 2, Blocks.air, 0, 3);
		world.setBlock(x + 17, y + 1, z + 2, Blocks.air, 0, 3);
		world.setBlock(x + 18, y + 1, z + 2, Blocks.air, 0, 3);
		world.setBlock(x + 0, y + 1, z + 3, Blocks.air, 0, 3);
		world.setBlock(x + 1, y + 1, z + 3, ModBlocks.zergStrucFlesh, 0, 3);
		world.setBlock(x + 2, y + 1, z + 3, Blocks.air, 0, 3);
		world.setBlock(x + 3, y + 1, z + 3, Blocks.air, 0, 3);
		world.setBlock(x + 4, y + 1, z + 3, Blocks.air, 0, 3);
		world.setBlock(x + 5, y + 1, z + 3, Blocks.air, 0, 3);
		world.setBlock(x + 6, y + 1, z + 3, Blocks.air, 0, 3);
		world.setBlock(x + 7, y + 1, z + 3, Blocks.air, 0, 3);
		world.setBlock(x + 8, y + 1, z + 3, ModBlocks.zergStrucFlesh, 0, 3);
		world.setBlock(x + 9, y + 1, z + 3, ModBlocks.zergStrucFlesh, 0, 3);
		world.setBlock(x + 10, y + 1, z + 3, Blocks.air, 0, 3);
		world.setBlock(x + 11, y + 1, z + 3, Blocks.air, 0, 3);
		world.setBlock(x + 12, y + 1, z + 3, Blocks.air, 0, 3);
		world.setBlock(x + 13, y + 1, z + 3, Blocks.air, 0, 3);
		world.setBlock(x + 14, y + 1, z + 3, Blocks.air, 0, 3);
		world.setBlock(x + 15, y + 1, z + 3, Blocks.air, 0, 3);
		world.setBlock(x + 16, y + 1, z + 3, Blocks.air, 0, 3);
		world.setBlock(x + 17, y + 1, z + 3, Blocks.air, 0, 3);
		world.setBlock(x + 18, y + 1, z + 3, Blocks.air, 0, 3);
		world.setBlock(x + 0, y + 1, z + 4, Blocks.air, 0, 3);
		world.setBlock(x + 1, y + 1, z + 4, Blocks.air, 0, 3);
		world.setBlock(x + 2, y + 1, z + 4, ModBlocks.zergStrucFlesh, 0, 3);
		world.setBlock(x + 3, y + 1, z + 4, ModBlocks.zergStrucFlesh, 0, 3);
		world.setBlock(x + 4, y + 1, z + 4, Blocks.air, 0, 3);
		world.setBlock(x + 5, y + 1, z + 4, ModBlocks.zergStrucFlesh, 0, 3);
		world.setBlock(x + 6, y + 1, z + 4, ModBlocks.zergStrucFlesh, 0, 3);
		world.setBlock(x + 7, y + 1, z + 4, ModBlocks.zergStrucFlesh, 0, 3);
		world.setBlock(x + 8, y + 1, z + 4, ModBlocks.zergStrucFlesh, 0, 3);
		world.setBlock(x + 9, y + 1, z + 4, ModBlocks.zergStrucFlesh, 0, 3);
		world.setBlock(x + 10, y + 1, z + 4, ModBlocks.zergStrucFlesh, 0, 3);
		world.setBlock(x + 11, y + 1, z + 4, ModBlocks.zergStrucFlesh, 0, 3);
		world.setBlock(x + 12, y + 1, z + 4, Blocks.air, 0, 3);
		world.setBlock(x + 13, y + 1, z + 4, Blocks.air, 0, 3);
		world.setBlock(x + 14, y + 1, z + 4, ModBlocks.zergStrucFlesh, 0, 3);
		world.setBlock(x + 15, y + 1, z + 4, ModBlocks.zergStrucFlesh, 0, 3);
		world.setBlock(x + 16, y + 1, z + 4, Blocks.air, 0, 3);
		world.setBlock(x + 17, y + 1, z + 4, Blocks.air, 0, 3);
		world.setBlock(x + 18, y + 1, z + 4, Blocks.air, 0, 3);
		world.setBlock(x + 0, y + 1, z + 5, Blocks.air, 0, 3);
		world.setBlock(x + 1, y + 1, z + 5, Blocks.air, 0, 3);
		world.setBlock(x + 2, y + 1, z + 5, Blocks.air, 0, 3);
		world.setBlock(x + 3, y + 1, z + 5, Blocks.air, 0, 3);
		world.setBlock(x + 4, y + 1, z + 5, ModBlocks.zergStrucFlesh, 0, 3);
		world.setBlock(x + 5, y + 1, z + 5, ModBlocks.zergStrucFlesh, 0, 3);
		world.setBlock(x + 6, y + 1, z + 5, ModBlocks.zergStrucFlesh, 0, 3);
		world.setBlock(x + 7, y + 1, z + 5, ModBlocks.zergStrucFlesh, 0, 3);
		world.setBlock(x + 8, y + 1, z + 5, ModBlocks.zergStrucFlesh, 0, 3);
		world.setBlock(x + 9, y + 1, z + 5, ModBlocks.zergStrucFlesh, 0, 3);
		world.setBlock(x + 10, y + 1, z + 5, ModBlocks.zergStrucFlesh, 0, 3);
		world.setBlock(x + 11, y + 1, z + 5, ModBlocks.zergStrucFlesh, 0, 3);
		world.setBlock(x + 12, y + 1, z + 5, ModBlocks.zergStrucFlesh, 0, 3);
		world.setBlock(x + 13, y + 1, z + 5, ModBlocks.zergStrucFlesh, 0, 3);
		world.setBlock(x + 14, y + 1, z + 5, ModBlocks.zergStrucFlesh, 0, 3);
		world.setBlock(x + 15, y + 1, z + 5, Blocks.air, 0, 3);
		world.setBlock(x + 16, y + 1, z + 5, Blocks.air, 0, 3);
		world.setBlock(x + 17, y + 1, z + 5, Blocks.air, 0, 3);
		world.setBlock(x + 18, y + 1, z + 5, Blocks.air, 0, 3);
		world.setBlock(x + 0, y + 1, z + 6, Blocks.air, 0, 3);
		world.setBlock(x + 1, y + 1, z + 6, Blocks.air, 0, 3);
		world.setBlock(x + 2, y + 1, z + 6, Blocks.air, 0, 3);
		world.setBlock(x + 3, y + 1, z + 6, Blocks.air, 0, 3);
		world.setBlock(x + 4, y + 1, z + 6, ModBlocks.zergStrucFlesh, 0, 3);
		world.setBlock(x + 5, y + 1, z + 6, ModBlocks.zergStrucFlesh, 0, 3);
		world.setBlock(x + 6, y + 1, z + 6, ModBlocks.zergStrucFlesh, 0, 3);
		world.setBlock(x + 7, y + 1, z + 6, ModBlocks.zergStrucFlesh, 0, 3);
		world.setBlock(x + 8, y + 1, z + 6, ModBlocks.zergStrucFlesh, 0, 3);
		world.setBlock(x + 9, y + 1, z + 6, ModBlocks.zergStrucFlesh, 0, 3);
		world.setBlock(x + 10, y + 1, z + 6, ModBlocks.zergStrucFlesh, 0, 3);
		world.setBlock(x + 11, y + 1, z + 6, ModBlocks.zergStrucFlesh, 0, 3);
		world.setBlock(x + 12, y + 1, z + 6, ModBlocks.zergStrucFlesh, 0, 3);
		world.setBlock(x + 13, y + 1, z + 6, ModBlocks.zergStrucFlesh, 0, 3);
		world.setBlock(x + 14, y + 1, z + 6, Blocks.air, 0, 3);
		world.setBlock(x + 15, y + 1, z + 6, Blocks.air, 0, 3);
		world.setBlock(x + 16, y + 1, z + 6, Blocks.air, 0, 3);
		world.setBlock(x + 17, y + 1, z + 6, Blocks.air, 0, 3);
		world.setBlock(x + 18, y + 1, z + 6, Blocks.air, 0, 3);
		world.setBlock(x + 0, y + 1, z + 7, Blocks.air, 0, 3);
		world.setBlock(x + 1, y + 1, z + 7, Blocks.air, 0, 3);
		world.setBlock(x + 2, y + 1, z + 7, Blocks.air, 0, 3);
		world.setBlock(x + 3, y + 1, z + 7, Blocks.air, 0, 3);
		world.setBlock(x + 4, y + 1, z + 7, ModBlocks.zergStrucFlesh, 0, 3);
		world.setBlock(x + 5, y + 1, z + 7, ModBlocks.zergStrucFlesh, 0, 3);
		world.setBlock(x + 6, y + 1, z + 7, ModBlocks.zergStrucFlesh, 0, 3);
		world.setBlock(x + 7, y + 1, z + 7, ModBlocks.zergStrucFlesh, 0, 3);
		world.setBlock(x + 8, y + 1, z + 7, ModBlocks.zergStrucFlesh, 0, 3);
		world.setBlock(x + 9, y + 1, z + 7, ModBlocks.zergStrucFlesh, 0, 3);
		world.setBlock(x + 10, y + 1, z + 7, ModBlocks.zergStrucFlesh, 0, 3);
		world.setBlock(x + 11, y + 1, z + 7, ModBlocks.zergStrucFlesh, 0, 3);
		world.setBlock(x + 12, y + 1, z + 7, ModBlocks.zergStrucFlesh, 0, 3);
		world.setBlock(x + 13, y + 1, z + 7, ModBlocks.zergStrucFlesh, 0, 3);
		world.setBlock(x + 14, y + 1, z + 7, ModBlocks.zergStrucFlesh, 0, 3);
		world.setBlock(x + 15, y + 1, z + 7, Blocks.air, 0, 3);
		world.setBlock(x + 16, y + 1, z + 7, Blocks.air, 0, 3);
		world.setBlock(x + 17, y + 1, z + 7, Blocks.air, 0, 3);
		world.setBlock(x + 18, y + 1, z + 7, Blocks.air, 0, 3);
		world.setBlock(x + 0, y + 1, z + 8, Blocks.air, 0, 3);
		world.setBlock(x + 1, y + 1, z + 8, Blocks.air, 0, 3);
		world.setBlock(x + 2, y + 1, z + 8, Blocks.air, 0, 3);
		world.setBlock(x + 3, y + 1, z + 8, ModBlocks.zergStrucFlesh, 0, 3);
		world.setBlock(x + 4, y + 1, z + 8, ModBlocks.zergStrucFlesh, 0, 3);
		world.setBlock(x + 5, y + 1, z + 8, ModBlocks.zergStrucFlesh, 0, 3);
		world.setBlock(x + 6, y + 1, z + 8, ModBlocks.zergStrucFlesh, 0, 3);
		world.setBlock(x + 7, y + 1, z + 8, ModBlocks.zergStrucFlesh, 0, 3);
		world.setBlock(x + 8, y + 1, z + 8, ModBlocks.zergStrucFlesh, 0, 3);
		world.setBlock(x + 9, y + 1, z + 8, ModBlocks.zergStrucFlesh, 0, 3);
		world.setBlock(x + 10, y + 1, z + 8, ModBlocks.zergStrucFlesh, 0, 3);
		world.setBlock(x + 11, y + 1, z + 8, ModBlocks.zergStrucFlesh, 0, 3);
		world.setBlock(x + 12, y + 1, z + 8, ModBlocks.zergStrucFlesh, 0, 3);
		world.setBlock(x + 13, y + 1, z + 8, ModBlocks.zergStrucFlesh, 0, 3);
		world.setBlock(x + 14, y + 1, z + 8, ModBlocks.zergStrucFlesh, 0, 3);
		world.setBlock(x + 15, y + 1, z + 8, ModBlocks.zergStrucFlesh, 0, 3);
		world.setBlock(x + 16, y + 1, z + 8, Blocks.air, 0, 3);
		world.setBlock(x + 17, y + 1, z + 8, Blocks.air, 0, 3);
		world.setBlock(x + 18, y + 1, z + 8, Blocks.air, 0, 3);
		world.setBlock(x + 0, y + 1, z + 9, Blocks.air, 0, 3);
		world.setBlock(x + 1, y + 1, z + 9, Blocks.air, 0, 3);
		world.setBlock(x + 2, y + 1, z + 9, Blocks.air, 0, 3);
		world.setBlock(x + 3, y + 1, z + 9, ModBlocks.zergStrucFlesh, 0, 3);
		world.setBlock(x + 4, y + 1, z + 9, ModBlocks.zergStrucFlesh, 0, 3);
		world.setBlock(x + 5, y + 1, z + 9, ModBlocks.zergStrucFlesh, 0, 3);
		world.setBlock(x + 6, y + 1, z + 9, ModBlocks.zergStrucFlesh, 0, 3);
		world.setBlock(x + 7, y + 1, z + 9, ModBlocks.zergStrucFlesh, 0, 3);
		world.setBlock(x + 8, y + 1, z + 9, ModBlocks.zergStrucFlesh, 0, 3);
		world.setBlock(x + 9, y + 1, z + 9, ModBlocks.zergStrucFlesh, 0, 3);
		world.setBlock(x + 10, y + 1, z + 9, ModBlocks.zergStrucFlesh, 0, 3);
		world.setBlock(x + 11, y + 1, z + 9, ModBlocks.zergStrucFlesh, 0, 3);
		world.setBlock(x + 12, y + 1, z + 9, ModBlocks.zergStrucFlesh, 0, 3);
		world.setBlock(x + 13, y + 1, z + 9, ModBlocks.zergStrucFlesh, 0, 3);
		world.setBlock(x + 14, y + 1, z + 9, ModBlocks.zergStrucFlesh, 0, 3);
		world.setBlock(x + 15, y + 1, z + 9, ModBlocks.zergStrucFlesh, 0, 3);
		world.setBlock(x + 16, y + 1, z + 9, Blocks.air, 0, 3);
		world.setBlock(x + 17, y + 1, z + 9, Blocks.air, 0, 3);
		world.setBlock(x + 18, y + 1, z + 9, Blocks.air, 0, 3);
		world.setBlock(x + 0, y + 1, z + 10, Blocks.air, 0, 3);
		world.setBlock(x + 1, y + 1, z + 10, Blocks.air, 0, 3);
		world.setBlock(x + 2, y + 1, z + 10, Blocks.air, 0, 3);
		world.setBlock(x + 3, y + 1, z + 10, ModBlocks.zergStrucFlesh, 0, 3);
		world.setBlock(x + 4, y + 1, z + 10, ModBlocks.zergStrucFlesh, 0, 3);
		world.setBlock(x + 5, y + 1, z + 10, ModBlocks.zergStrucFlesh, 0, 3);
		world.setBlock(x + 6, y + 1, z + 10, ModBlocks.zergStrucFlesh, 0, 3);
		world.setBlock(x + 7, y + 1, z + 10, ModBlocks.zergStrucFlesh, 0, 3);
		world.setBlock(x + 8, y + 1, z + 10, ModBlocks.zergStrucFlesh, 0, 3);
		world.setBlock(x + 9, y + 1, z + 10, ModBlocks.zergStrucFlesh, 0, 3);
		world.setBlock(x + 10, y + 1, z + 10, ModBlocks.zergStrucFlesh, 0, 3);
		world.setBlock(x + 11, y + 1, z + 10, ModBlocks.zergStrucFlesh, 0, 3);
		world.setBlock(x + 12, y + 1, z + 10, ModBlocks.zergStrucFlesh, 0, 3);
		world.setBlock(x + 13, y + 1, z + 10, ModBlocks.zergStrucFlesh, 0, 3);
		world.setBlock(x + 14, y + 1, z + 10, ModBlocks.zergStrucFlesh, 0, 3);
		world.setBlock(x + 15, y + 1, z + 10, ModBlocks.zergStrucFlesh, 0, 3);
		world.setBlock(x + 16, y + 1, z + 10, Blocks.air, 0, 3);
		world.setBlock(x + 17, y + 1, z + 10, Blocks.air, 0, 3);
		world.setBlock(x + 18, y + 1, z + 10, Blocks.air, 0, 3);
		world.setBlock(x + 0, y + 1, z + 11, Blocks.air, 0, 3);
		world.setBlock(x + 1, y + 1, z + 11, Blocks.air, 0, 3);
		world.setBlock(x + 2, y + 1, z + 11, Blocks.air, 0, 3);
		world.setBlock(x + 3, y + 1, z + 11, ModBlocks.zergStrucFlesh, 0, 3);
		world.setBlock(x + 4, y + 1, z + 11, ModBlocks.zergStrucFlesh, 0, 3);
		world.setBlock(x + 5, y + 1, z + 11, ModBlocks.zergStrucFlesh, 0, 3);
		world.setBlock(x + 6, y + 1, z + 11, ModBlocks.zergStrucFlesh, 0, 3);
		world.setBlock(x + 7, y + 1, z + 11, ModBlocks.zergStrucFlesh, 0, 3);
		world.setBlock(x + 8, y + 1, z + 11, ModBlocks.zergStrucFlesh, 0, 3);
		world.setBlock(x + 9, y + 1, z + 11, ModBlocks.zergStrucFlesh, 0, 3);
		world.setBlock(x + 10, y + 1, z + 11, ModBlocks.zergStrucFlesh, 0, 3);
		world.setBlock(x + 11, y + 1, z + 11, ModBlocks.zergStrucFlesh, 0, 3);
		world.setBlock(x + 12, y + 1, z + 11, ModBlocks.zergStrucFlesh, 0, 3);
		world.setBlock(x + 13, y + 1, z + 11, ModBlocks.zergStrucFlesh, 0, 3);
		world.setBlock(x + 14, y + 1, z + 11, ModBlocks.zergStrucFlesh, 0, 3);
		world.setBlock(x + 15, y + 1, z + 11, ModBlocks.zergStrucFlesh, 0, 3);
		world.setBlock(x + 16, y + 1, z + 11, Blocks.air, 0, 3);
		world.setBlock(x + 17, y + 1, z + 11, Blocks.air, 0, 3);
		world.setBlock(x + 18, y + 1, z + 11, Blocks.air, 0, 3);
		world.setBlock(x + 0, y + 1, z + 12, Blocks.air, 0, 3);
		world.setBlock(x + 1, y + 1, z + 12, Blocks.air, 0, 3);
		world.setBlock(x + 2, y + 1, z + 12, Blocks.air, 0, 3);
		world.setBlock(x + 3, y + 1, z + 12, ModBlocks.zergStrucFlesh, 0, 3);
		world.setBlock(x + 4, y + 1, z + 12, ModBlocks.zergStrucFlesh, 0, 3);
		world.setBlock(x + 5, y + 1, z + 12, ModBlocks.zergStrucFlesh, 0, 3);
		world.setBlock(x + 6, y + 1, z + 12, ModBlocks.zergStrucFlesh, 0, 3);
		world.setBlock(x + 7, y + 1, z + 12, ModBlocks.zergStrucFlesh, 0, 3);
		world.setBlock(x + 8, y + 1, z + 12, ModBlocks.zergStrucFlesh, 0, 3);
		world.setBlock(x + 9, y + 1, z + 12, ModBlocks.zergStrucFlesh, 0, 3);
		world.setBlock(x + 10, y + 1, z + 12, ModBlocks.zergStrucFlesh, 0, 3);
		world.setBlock(x + 11, y + 1, z + 12, ModBlocks.zergStrucFlesh, 0, 3);
		world.setBlock(x + 12, y + 1, z + 12, ModBlocks.zergStrucFlesh, 0, 3);
		world.setBlock(x + 13, y + 1, z + 12, ModBlocks.zergStrucFlesh, 0, 3);
		world.setBlock(x + 14, y + 1, z + 12, ModBlocks.zergStrucFlesh, 0, 3);
		world.setBlock(x + 15, y + 1, z + 12, ModBlocks.zergStrucFlesh, 0, 3);
		world.setBlock(x + 16, y + 1, z + 12, Blocks.air, 0, 3);
		world.setBlock(x + 17, y + 1, z + 12, Blocks.air, 0, 3);
		world.setBlock(x + 18, y + 1, z + 12, Blocks.air, 0, 3);
		world.setBlock(x + 0, y + 1, z + 13, Blocks.air, 0, 3);
		world.setBlock(x + 1, y + 1, z + 13, Blocks.air, 0, 3);
		world.setBlock(x + 2, y + 1, z + 13, Blocks.air, 0, 3);
		world.setBlock(x + 3, y + 1, z + 13, ModBlocks.zergStrucFlesh, 0, 3);
		world.setBlock(x + 4, y + 1, z + 13, ModBlocks.zergStrucFlesh, 0, 3);
		world.setBlock(x + 5, y + 1, z + 13, ModBlocks.zergStrucFlesh, 0, 3);
		world.setBlock(x + 6, y + 1, z + 13, ModBlocks.zergStrucFlesh, 0, 3);
		world.setBlock(x + 7, y + 1, z + 13, ModBlocks.zergStrucFlesh, 0, 3);
		world.setBlock(x + 8, y + 1, z + 13, ModBlocks.zergStrucFlesh, 0, 3);
		world.setBlock(x + 9, y + 1, z + 13, ModBlocks.zergStrucFlesh, 0, 3);
		world.setBlock(x + 10, y + 1, z + 13, ModBlocks.zergStrucFlesh, 0, 3);
		world.setBlock(x + 11, y + 1, z + 13, ModBlocks.zergStrucFlesh, 0, 3);
		world.setBlock(x + 12, y + 1, z + 13, ModBlocks.zergStrucFlesh, 0, 3);
		world.setBlock(x + 13, y + 1, z + 13, ModBlocks.zergStrucFlesh, 0, 3);
		world.setBlock(x + 14, y + 1, z + 13, ModBlocks.zergStrucFlesh, 0, 3);
		world.setBlock(x + 15, y + 1, z + 13, ModBlocks.zergStrucFlesh, 0, 3);
		world.setBlock(x + 16, y + 1, z + 13, Blocks.air, 0, 3);
		world.setBlock(x + 17, y + 1, z + 13, Blocks.air, 0, 3);
		world.setBlock(x + 18, y + 1, z + 13, Blocks.air, 0, 3);
		world.setBlock(x + 0, y + 1, z + 14, Blocks.air, 0, 3);
		world.setBlock(x + 1, y + 1, z + 14, Blocks.air, 0, 3);
		world.setBlock(x + 2, y + 1, z + 14, Blocks.air, 0, 3);
		world.setBlock(x + 3, y + 1, z + 14, ModBlocks.zergStrucFlesh, 0, 3);
		world.setBlock(x + 4, y + 1, z + 14, ModBlocks.zergStrucFlesh, 0, 3);
		world.setBlock(x + 5, y + 1, z + 14, ModBlocks.zergStrucFlesh, 0, 3);
		world.setBlock(x + 6, y + 1, z + 14, ModBlocks.zergStrucFlesh, 0, 3);
		world.setBlock(x + 7, y + 1, z + 14, ModBlocks.zergStrucFlesh, 0, 3);
		world.setBlock(x + 8, y + 1, z + 14, ModBlocks.zergStrucFlesh, 0, 3);
		world.setBlock(x + 9, y + 1, z + 14, ModBlocks.zergStrucFlesh, 0, 3);
		world.setBlock(x + 10, y + 1, z + 14, ModBlocks.zergStrucFlesh, 0, 3);
		world.setBlock(x + 11, y + 1, z + 14, ModBlocks.zergStrucFlesh, 0, 3);
		world.setBlock(x + 12, y + 1, z + 14, ModBlocks.zergStrucFlesh, 0, 3);
		world.setBlock(x + 13, y + 1, z + 14, ModBlocks.zergStrucFlesh, 0, 3);
		world.setBlock(x + 14, y + 1, z + 14, ModBlocks.zergStrucFlesh, 0, 3);
		world.setBlock(x + 15, y + 1, z + 14, ModBlocks.zergStrucFlesh, 0, 3);
		world.setBlock(x + 16, y + 1, z + 14, Blocks.air, 0, 3);
		world.setBlock(x + 17, y + 1, z + 14, Blocks.air, 0, 3);
		world.setBlock(x + 18, y + 1, z + 14, Blocks.air, 0, 3);
		world.setBlock(x + 0, y + 1, z + 15, Blocks.air, 0, 3);
		world.setBlock(x + 1, y + 1, z + 15, Blocks.air, 0, 3);
		world.setBlock(x + 2, y + 1, z + 15, Blocks.air, 0, 3);
		world.setBlock(x + 3, y + 1, z + 15, ModBlocks.zergStrucFlesh, 0, 3);
		world.setBlock(x + 4, y + 1, z + 15, ModBlocks.zergStrucFlesh, 0, 3);
		world.setBlock(x + 5, y + 1, z + 15, ModBlocks.zergStrucFlesh, 0, 3);
		world.setBlock(x + 6, y + 1, z + 15, ModBlocks.zergStrucFlesh, 0, 3);
		world.setBlock(x + 7, y + 1, z + 15, ModBlocks.zergStrucFlesh, 0, 3);
		world.setBlock(x + 8, y + 1, z + 15, ModBlocks.zergStrucFlesh, 0, 3);
		world.setBlock(x + 9, y + 1, z + 15, ModBlocks.zergStrucFlesh, 0, 3);
		world.setBlock(x + 10, y + 1, z + 15, ModBlocks.zergStrucFlesh, 0, 3);
		world.setBlock(x + 11, y + 1, z + 15, ModBlocks.zergStrucFlesh, 0, 3);
		world.setBlock(x + 12, y + 1, z + 15, ModBlocks.zergStrucFlesh, 0, 3);
		world.setBlock(x + 13, y + 1, z + 15, ModBlocks.zergStrucFlesh, 0, 3);
		world.setBlock(x + 14, y + 1, z + 15, ModBlocks.zergStrucFlesh, 0, 3);
		world.setBlock(x + 15, y + 1, z + 15, ModBlocks.zergStrucFlesh, 0, 3);
		world.setBlock(x + 16, y + 1, z + 15, ModBlocks.zergStrucFlesh, 0, 3);
		world.setBlock(x + 17, y + 1, z + 15, Blocks.air, 0, 3);
		world.setBlock(x + 18, y + 1, z + 15, ModBlocks.zergStrucFlesh, 0, 3);
		world.setBlock(x + 0, y + 1, z + 16, Blocks.air, 0, 3);
		world.setBlock(x + 1, y + 1, z + 16, Blocks.air, 0, 3);
		world.setBlock(x + 2, y + 1, z + 16, ModBlocks.zergStrucFlesh, 0, 3);
		world.setBlock(x + 3, y + 1, z + 16, ModBlocks.zergStrucFlesh, 0, 3);
		world.setBlock(x + 4, y + 1, z + 16, ModBlocks.zergStrucFlesh, 0, 3);
		world.setBlock(x + 5, y + 1, z + 16, ModBlocks.zergStrucFlesh, 0, 3);
		world.setBlock(x + 6, y + 1, z + 16, ModBlocks.zergStrucFlesh, 0, 3);
		world.setBlock(x + 7, y + 1, z + 16, ModBlocks.zergStrucFlesh, 0, 3);
		world.setBlock(x + 8, y + 1, z + 16, ModBlocks.zergStrucFlesh, 0, 3);
		world.setBlock(x + 9, y + 1, z + 16, ModBlocks.zergStrucFlesh, 0, 3);
		world.setBlock(x + 10, y + 1, z + 16, ModBlocks.zergStrucFlesh, 0, 3);
		world.setBlock(x + 11, y + 1, z + 16, ModBlocks.zergStrucFlesh, 0, 3);
		world.setBlock(x + 12, y + 1, z + 16, ModBlocks.zergStrucFlesh, 0, 3);
		world.setBlock(x + 13, y + 1, z + 16, ModBlocks.zergStrucFlesh, 0, 3);
		world.setBlock(x + 14, y + 1, z + 16, ModBlocks.zergStrucFlesh, 0, 3);
		world.setBlock(x + 15, y + 1, z + 16, Blocks.air, 0, 3);
		world.setBlock(x + 16, y + 1, z + 16, ModBlocks.zergStrucFlesh, 0, 3);
		world.setBlock(x + 17, y + 1, z + 16, ModBlocks.zergStrucFlesh, 0, 3);
		world.setBlock(x + 18, y + 1, z + 16, Blocks.air, 0, 3);
		world.setBlock(x + 0, y + 1, z + 17, ModBlocks.zergStrucFlesh, 0, 3);
		world.setBlock(x + 1, y + 1, z + 17, ModBlocks.zergStrucFlesh, 0, 3);
		world.setBlock(x + 2, y + 1, z + 17, Blocks.air, 0, 3);
		world.setBlock(x + 3, y + 1, z + 17, ModBlocks.zergStrucFlesh, 0, 3);
		world.setBlock(x + 4, y + 1, z + 17, Blocks.air, 0, 3);
		world.setBlock(x + 5, y + 1, z + 17, Blocks.air, 0, 3);
		world.setBlock(x + 6, y + 1, z + 17, Blocks.air, 0, 3);
		world.setBlock(x + 7, y + 1, z + 17, Blocks.air, 0, 3);
		world.setBlock(x + 8, y + 1, z + 17, Blocks.air, 0, 3);
		world.setBlock(x + 9, y + 1, z + 17, Blocks.air, 0, 3);
		world.setBlock(x + 10, y + 1, z + 17, Blocks.air, 0, 3);
		world.setBlock(x + 11, y + 1, z + 17, Blocks.air, 0, 3);
		world.setBlock(x + 12, y + 1, z + 17, Blocks.air, 0, 3);
		world.setBlock(x + 13, y + 1, z + 17, Blocks.air, 0, 3);
		world.setBlock(x + 14, y + 1, z + 17, ModBlocks.zergStrucFlesh, 0, 3);
		world.setBlock(x + 15, y + 1, z + 17, Blocks.air, 0, 3);
		world.setBlock(x + 16, y + 1, z + 17, Blocks.air, 0, 3);
		world.setBlock(x + 17, y + 1, z + 17, Blocks.air, 0, 3);
		world.setBlock(x + 18, y + 1, z + 17, Blocks.air, 0, 3);
		world.setBlock(x + 0, y + 1, z + 18, Blocks.air, 0, 3);
		world.setBlock(x + 1, y + 1, z + 18, Blocks.air, 0, 3);
		world.setBlock(x + 2, y + 1, z + 18, Blocks.air, 0, 3);
		world.setBlock(x + 3, y + 1, z + 18, ModBlocks.zergStrucFlesh, 0, 3);
		world.setBlock(x + 4, y + 1, z + 18, Blocks.air, 0, 3);
		world.setBlock(x + 5, y + 1, z + 18, Blocks.air, 0, 3);
		world.setBlock(x + 6, y + 1, z + 18, Blocks.air, 0, 3);
		world.setBlock(x + 7, y + 1, z + 18, Blocks.air, 0, 3);
		world.setBlock(x + 8, y + 1, z + 18, Blocks.air, 0, 3);
		world.setBlock(x + 9, y + 1, z + 18, Blocks.air, 0, 3);
		world.setBlock(x + 10, y + 1, z + 18, Blocks.air, 0, 3);
		world.setBlock(x + 11, y + 1, z + 18, Blocks.air, 0, 3);
		world.setBlock(x + 12, y + 1, z + 18, Blocks.air, 0, 3);
		world.setBlock(x + 13, y + 1, z + 18, ModBlocks.zergStrucFlesh, 0, 3);
		world.setBlock(x + 14, y + 1, z + 18, Blocks.air, 0, 3);
		world.setBlock(x + 15, y + 1, z + 18, Blocks.air, 0, 3);
		world.setBlock(x + 16, y + 1, z + 18, Blocks.air, 0, 3);
		world.setBlock(x + 17, y + 1, z + 18, Blocks.air, 0, 3);
		world.setBlock(x + 18, y + 1, z + 18, Blocks.air, 0, 3);
		world.setBlock(x + 0, y + 1, z + 19, Blocks.air, 0, 3);
		world.setBlock(x + 1, y + 1, z + 19, Blocks.air, 0, 3);
		world.setBlock(x + 2, y + 1, z + 19, Blocks.air, 0, 3);
		world.setBlock(x + 3, y + 1, z + 19, Blocks.air, 0, 3);
		world.setBlock(x + 4, y + 1, z + 19, ModBlocks.zergStrucFlesh, 0, 3);
		world.setBlock(x + 5, y + 1, z + 19, Blocks.air, 0, 3);
		world.setBlock(x + 6, y + 1, z + 19, Blocks.air, 0, 3);
		world.setBlock(x + 7, y + 1, z + 19, Blocks.air, 0, 3);
		world.setBlock(x + 8, y + 1, z + 19, Blocks.air, 0, 3);
		world.setBlock(x + 9, y + 1, z + 19, Blocks.air, 0, 3);
		world.setBlock(x + 10, y + 1, z + 19, Blocks.air, 0, 3);
		world.setBlock(x + 11, y + 1, z + 19, Blocks.air, 0, 3);
		world.setBlock(x + 12, y + 1, z + 19, Blocks.air, 0, 3);
		world.setBlock(x + 13, y + 1, z + 19, Blocks.air, 0, 3);
		world.setBlock(x + 14, y + 1, z + 19, ModBlocks.zergStrucFlesh, 0, 3);
		world.setBlock(x + 15, y + 1, z + 19, Blocks.air, 0, 3);
		world.setBlock(x + 16, y + 1, z + 19, Blocks.air, 0, 3);
		world.setBlock(x + 17, y + 1, z + 19, Blocks.air, 0, 3);
		world.setBlock(x + 18, y + 1, z + 19, Blocks.air, 0, 3);
		world.setBlock(x + 0, y + 1, z + 20, Blocks.air, 0, 3);
		world.setBlock(x + 1, y + 1, z + 20, Blocks.air, 0, 3);
		world.setBlock(x + 2, y + 1, z + 20, Blocks.air, 0, 3);
		world.setBlock(x + 3, y + 1, z + 20, Blocks.air, 0, 3);
		world.setBlock(x + 4, y + 1, z + 20, Blocks.air, 0, 3);
		world.setBlock(x + 5, y + 1, z + 20, Blocks.air, 0, 3);
		world.setBlock(x + 6, y + 1, z + 20, Blocks.air, 0, 3);
		world.setBlock(x + 7, y + 1, z + 20, Blocks.air, 0, 3);
		world.setBlock(x + 8, y + 1, z + 20, Blocks.air, 0, 3);
		world.setBlock(x + 9, y + 1, z + 20, Blocks.air, 0, 3);
		world.setBlock(x + 10, y + 1, z + 20, Blocks.air, 0, 3);
		world.setBlock(x + 11, y + 1, z + 20, Blocks.air, 0, 3);
		world.setBlock(x + 12, y + 1, z + 20, Blocks.air, 0, 3);
		world.setBlock(x + 13, y + 1, z + 20, Blocks.air, 0, 3);
		world.setBlock(x + 14, y + 1, z + 20, Blocks.air, 0, 3);
		world.setBlock(x + 15, y + 1, z + 20, Blocks.air, 0, 3);
		world.setBlock(x + 16, y + 1, z + 20, Blocks.air, 0, 3);
		world.setBlock(x + 17, y + 1, z + 20, Blocks.air, 0, 3);
		world.setBlock(x + 18, y + 1, z + 20, Blocks.air, 0, 3);
		world.setBlock(x + 0, y + 2, z + 0, Blocks.air, 0, 3);
		world.setBlock(x + 1, y + 2, z + 0, Blocks.air, 0, 3);
		world.setBlock(x + 2, y + 2, z + 0, Blocks.air, 0, 3);
		world.setBlock(x + 3, y + 2, z + 0, Blocks.air, 0, 3);
		world.setBlock(x + 4, y + 2, z + 0, Blocks.air, 0, 3);
		world.setBlock(x + 5, y + 2, z + 0, Blocks.air, 0, 3);
		world.setBlock(x + 6, y + 2, z + 0, Blocks.air, 0, 3);
		world.setBlock(x + 7, y + 2, z + 0, Blocks.air, 0, 3);
		world.setBlock(x + 8, y + 2, z + 0, Blocks.air, 0, 3);
		world.setBlock(x + 9, y + 2, z + 0, Blocks.air, 0, 3);
		world.setBlock(x + 10, y + 2, z + 0, Blocks.air, 0, 3);
		world.setBlock(x + 11, y + 2, z + 0, Blocks.air, 0, 3);
		world.setBlock(x + 12, y + 2, z + 0, Blocks.air, 0, 3);
		world.setBlock(x + 13, y + 2, z + 0, Blocks.air, 0, 3);
		world.setBlock(x + 14, y + 2, z + 0, Blocks.air, 0, 3);
		world.setBlock(x + 15, y + 2, z + 0, Blocks.air, 0, 3);
		world.setBlock(x + 16, y + 2, z + 0, Blocks.air, 0, 3);
		world.setBlock(x + 17, y + 2, z + 0, Blocks.air, 0, 3);
		world.setBlock(x + 18, y + 2, z + 0, Blocks.air, 0, 3);
		world.setBlock(x + 0, y + 2, z + 1, Blocks.air, 0, 3);
		world.setBlock(x + 1, y + 2, z + 1, Blocks.air, 0, 3);
		world.setBlock(x + 2, y + 2, z + 1, Blocks.air, 0, 3);
		world.setBlock(x + 3, y + 2, z + 1, Blocks.air, 0, 3);
		world.setBlock(x + 4, y + 2, z + 1, Blocks.air, 0, 3);
		world.setBlock(x + 5, y + 2, z + 1, Blocks.air, 0, 3);
		world.setBlock(x + 6, y + 2, z + 1, Blocks.air, 0, 3);
		world.setBlock(x + 7, y + 2, z + 1, Blocks.air, 0, 3);
		world.setBlock(x + 8, y + 2, z + 1, Blocks.air, 0, 3);
		world.setBlock(x + 9, y + 2, z + 1, Blocks.air, 0, 3);
		world.setBlock(x + 10, y + 2, z + 1, Blocks.air, 0, 3);
		world.setBlock(x + 11, y + 2, z + 1, Blocks.air, 0, 3);
		world.setBlock(x + 12, y + 2, z + 1, Blocks.air, 0, 3);
		world.setBlock(x + 13, y + 2, z + 1, Blocks.air, 0, 3);
		world.setBlock(x + 14, y + 2, z + 1, Blocks.air, 0, 3);
		world.setBlock(x + 15, y + 2, z + 1, Blocks.air, 0, 3);
		world.setBlock(x + 16, y + 2, z + 1, Blocks.air, 0, 3);
		world.setBlock(x + 17, y + 2, z + 1, Blocks.air, 0, 3);
		world.setBlock(x + 18, y + 2, z + 1, Blocks.air, 0, 3);
		world.setBlock(x + 0, y + 2, z + 2, Blocks.air, 0, 3);
		world.setBlock(x + 1, y + 2, z + 2, Blocks.air, 0, 3);
		world.setBlock(x + 2, y + 2, z + 2, Blocks.air, 0, 3);
		world.setBlock(x + 3, y + 2, z + 2, Blocks.air, 0, 3);
		world.setBlock(x + 4, y + 2, z + 2, Blocks.air, 0, 3);
		world.setBlock(x + 5, y + 2, z + 2, Blocks.air, 0, 3);
		world.setBlock(x + 6, y + 2, z + 2, Blocks.air, 0, 3);
		world.setBlock(x + 7, y + 2, z + 2, Blocks.air, 0, 3);
		world.setBlock(x + 8, y + 2, z + 2, Blocks.air, 0, 3);
		world.setBlock(x + 9, y + 2, z + 2, Blocks.air, 0, 3);
		world.setBlock(x + 10, y + 2, z + 2, Blocks.air, 0, 3);
		world.setBlock(x + 11, y + 2, z + 2, Blocks.air, 0, 3);
		world.setBlock(x + 12, y + 2, z + 2, Blocks.air, 0, 3);
		world.setBlock(x + 13, y + 2, z + 2, Blocks.air, 0, 3);
		world.setBlock(x + 14, y + 2, z + 2, Blocks.air, 0, 3);
		world.setBlock(x + 15, y + 2, z + 2, Blocks.air, 0, 3);
		world.setBlock(x + 16, y + 2, z + 2, Blocks.air, 0, 3);
		world.setBlock(x + 17, y + 2, z + 2, Blocks.air, 0, 3);
		world.setBlock(x + 18, y + 2, z + 2, Blocks.air, 0, 3);
		world.setBlock(x + 0, y + 2, z + 3, Blocks.air, 0, 3);
		world.setBlock(x + 1, y + 2, z + 3, Blocks.air, 0, 3);
		world.setBlock(x + 2, y + 2, z + 3, Blocks.air, 0, 3);
		world.setBlock(x + 3, y + 2, z + 3, Blocks.air, 0, 3);
		world.setBlock(x + 4, y + 2, z + 3, Blocks.air, 0, 3);
		world.setBlock(x + 5, y + 2, z + 3, Blocks.air, 0, 3);
		world.setBlock(x + 6, y + 2, z + 3, Blocks.air, 0, 3);
		world.setBlock(x + 7, y + 2, z + 3, Blocks.air, 0, 3);
		world.setBlock(x + 8, y + 2, z + 3, Blocks.air, 0, 3);
		world.setBlock(x + 9, y + 2, z + 3, Blocks.air, 0, 3);
		world.setBlock(x + 10, y + 2, z + 3, Blocks.air, 0, 3);
		world.setBlock(x + 11, y + 2, z + 3, Blocks.air, 0, 3);
		world.setBlock(x + 12, y + 2, z + 3, Blocks.air, 0, 3);
		world.setBlock(x + 13, y + 2, z + 3, Blocks.air, 0, 3);
		world.setBlock(x + 14, y + 2, z + 3, Blocks.air, 0, 3);
		world.setBlock(x + 15, y + 2, z + 3, Blocks.air, 0, 3);
		world.setBlock(x + 16, y + 2, z + 3, Blocks.air, 0, 3);
		world.setBlock(x + 17, y + 2, z + 3, Blocks.air, 0, 3);
		world.setBlock(x + 18, y + 2, z + 3, Blocks.air, 0, 3);
		world.setBlock(x + 0, y + 2, z + 4, Blocks.air, 0, 3);
		world.setBlock(x + 1, y + 2, z + 4, Blocks.air, 0, 3);
		world.setBlock(x + 2, y + 2, z + 4, Blocks.air, 0, 3);
		world.setBlock(x + 3, y + 2, z + 4, Blocks.air, 0, 3);
		world.setBlock(x + 4, y + 2, z + 4, Blocks.air, 0, 3);
		world.setBlock(x + 5, y + 2, z + 4, Blocks.air, 0, 3);
		world.setBlock(x + 6, y + 2, z + 4, Blocks.air, 0, 3);
		world.setBlock(x + 7, y + 2, z + 4, Blocks.air, 0, 3);
		world.setBlock(x + 8, y + 2, z + 4, ModBlocks.zergStrucFlesh, 0, 3);
		world.setBlock(x + 9, y + 2, z + 4, Blocks.air, 0, 3);
		world.setBlock(x + 10, y + 2, z + 4, Blocks.air, 0, 3);
		world.setBlock(x + 11, y + 2, z + 4, Blocks.air, 0, 3);
		world.setBlock(x + 12, y + 2, z + 4, Blocks.air, 0, 3);
		world.setBlock(x + 13, y + 2, z + 4, Blocks.air, 0, 3);
		world.setBlock(x + 14, y + 2, z + 4, Blocks.air, 0, 3);
		world.setBlock(x + 15, y + 2, z + 4, Blocks.air, 0, 3);
		world.setBlock(x + 16, y + 2, z + 4, Blocks.air, 0, 3);
		world.setBlock(x + 17, y + 2, z + 4, Blocks.air, 0, 3);
		world.setBlock(x + 18, y + 2, z + 4, Blocks.air, 0, 3);
		world.setBlock(x + 0, y + 2, z + 5, Blocks.air, 0, 3);
		world.setBlock(x + 1, y + 2, z + 5, Blocks.air, 0, 3);
		world.setBlock(x + 2, y + 2, z + 5, Blocks.air, 0, 3);
		world.setBlock(x + 3, y + 2, z + 5, Blocks.air, 0, 3);
		world.setBlock(x + 4, y + 2, z + 5, Blocks.air, 0, 3);
		world.setBlock(x + 5, y + 2, z + 5, Blocks.air, 0, 3);
		world.setBlock(x + 6, y + 2, z + 5, ModBlocks.zergStrucFlesh, 0, 3);
		world.setBlock(x + 7, y + 2, z + 5, ModBlocks.zergStrucFlesh, 0, 3);
		world.setBlock(x + 8, y + 2, z + 5, ModBlocks.zergStrucFlesh, 0, 3);
		world.setBlock(x + 9, y + 2, z + 5, ModBlocks.zergStrucFlesh, 0, 3);
		world.setBlock(x + 10, y + 2, z + 5, ModBlocks.zergStrucFlesh, 0, 3);
		world.setBlock(x + 11, y + 2, z + 5, ModBlocks.zergStrucFlesh, 0, 3);
		world.setBlock(x + 12, y + 2, z + 5, ModBlocks.zergStrucFlesh, 0, 3);
		world.setBlock(x + 13, y + 2, z + 5, Blocks.air, 0, 3);
		world.setBlock(x + 14, y + 2, z + 5, Blocks.air, 0, 3);
		world.setBlock(x + 15, y + 2, z + 5, Blocks.air, 0, 3);
		world.setBlock(x + 16, y + 2, z + 5, Blocks.air, 0, 3);
		world.setBlock(x + 17, y + 2, z + 5, Blocks.air, 0, 3);
		world.setBlock(x + 18, y + 2, z + 5, Blocks.air, 0, 3);
		world.setBlock(x + 0, y + 2, z + 6, Blocks.air, 0, 3);
		world.setBlock(x + 1, y + 2, z + 6, Blocks.air, 0, 3);
		world.setBlock(x + 2, y + 2, z + 6, Blocks.air, 0, 3);
		world.setBlock(x + 3, y + 2, z + 6, Blocks.air, 0, 3);
		world.setBlock(x + 4, y + 2, z + 6, Blocks.air, 0, 3);
		world.setBlock(x + 5, y + 2, z + 6, ModBlocks.zergStrucFlesh, 0, 3);
		world.setBlock(x + 6, y + 2, z + 6, ModBlocks.zergStrucFlesh, 0, 3);
		world.setBlock(x + 7, y + 2, z + 6, ModBlocks.zergStrucFlesh, 0, 3);
		world.setBlock(x + 8, y + 2, z + 6, ModBlocks.zergStrucFlesh, 0, 3);
		world.setBlock(x + 9, y + 2, z + 6, ModBlocks.zergStrucFlesh, 0, 3);
		world.setBlock(x + 10, y + 2, z + 6, ModBlocks.zergStrucFlesh, 0, 3);
		world.setBlock(x + 11, y + 2, z + 6, ModBlocks.zergStrucFlesh, 0, 3);
		world.setBlock(x + 12, y + 2, z + 6, ModBlocks.zergStrucFlesh, 0, 3);
		world.setBlock(x + 13, y + 2, z + 6, ModBlocks.zergStrucFlesh, 0, 3);
		world.setBlock(x + 14, y + 2, z + 6, Blocks.air, 0, 3);
		world.setBlock(x + 15, y + 2, z + 6, Blocks.air, 0, 3);
		world.setBlock(x + 16, y + 2, z + 6, Blocks.air, 0, 3);
		world.setBlock(x + 17, y + 2, z + 6, Blocks.air, 0, 3);
		world.setBlock(x + 18, y + 2, z + 6, Blocks.air, 0, 3);
		world.setBlock(x + 0, y + 2, z + 7, Blocks.air, 0, 3);
		world.setBlock(x + 1, y + 2, z + 7, Blocks.air, 0, 3);
		world.setBlock(x + 2, y + 2, z + 7, Blocks.air, 0, 3);
		world.setBlock(x + 3, y + 2, z + 7, Blocks.air, 0, 3);
		world.setBlock(x + 4, y + 2, z + 7, Blocks.air, 0, 3);
		world.setBlock(x + 5, y + 2, z + 7, ModBlocks.zergStrucFlesh, 0, 3);
		world.setBlock(x + 6, y + 2, z + 7, ModBlocks.zergStrucFlesh, 0, 3);
		world.setBlock(x + 7, y + 2, z + 7, ModBlocks.zergStrucFlesh, 0, 3);
		world.setBlock(x + 8, y + 2, z + 7, ModBlocks.zergStrucFlesh, 0, 3);
		world.setBlock(x + 9, y + 2, z + 7, ModBlocks.zergStrucFlesh, 0, 3);
		world.setBlock(x + 10, y + 2, z + 7, ModBlocks.zergStrucFlesh, 0, 3);
		world.setBlock(x + 11, y + 2, z + 7, ModBlocks.zergStrucFlesh, 0, 3);
		world.setBlock(x + 12, y + 2, z + 7, ModBlocks.zergStrucFlesh, 0, 3);
		world.setBlock(x + 13, y + 2, z + 7, ModBlocks.zergStrucFlesh, 0, 3);
		world.setBlock(x + 14, y + 2, z + 7, Blocks.air, 0, 3);
		world.setBlock(x + 15, y + 2, z + 7, Blocks.air, 0, 3);
		world.setBlock(x + 16, y + 2, z + 7, Blocks.air, 0, 3);
		world.setBlock(x + 17, y + 2, z + 7, Blocks.air, 0, 3);
		world.setBlock(x + 18, y + 2, z + 7, Blocks.air, 0, 3);
		world.setBlock(x + 0, y + 2, z + 8, Blocks.air, 0, 3);
		world.setBlock(x + 1, y + 2, z + 8, Blocks.air, 0, 3);
		world.setBlock(x + 2, y + 2, z + 8, Blocks.air, 0, 3);
		world.setBlock(x + 3, y + 2, z + 8, Blocks.air, 0, 3);
		world.setBlock(x + 4, y + 2, z + 8, ModBlocks.zergStrucFlesh, 0, 3);
		world.setBlock(x + 5, y + 2, z + 8, ModBlocks.zergStrucFlesh, 0, 3);
		world.setBlock(x + 6, y + 2, z + 8, ModBlocks.zergStrucFlesh, 0, 3);
		world.setBlock(x + 7, y + 2, z + 8, ModBlocks.fluidAcid, 8, 3);
		world.setBlock(x + 8, y + 2, z + 8, ModBlocks.fluidAcid, 8, 3);
		world.setBlock(x + 9, y + 2, z + 8, ModBlocks.fluidAcid, 8, 3);
		world.setBlock(x + 10, y + 2, z + 8, ModBlocks.zergStrucFlesh, 0, 3);
		world.setBlock(x + 11, y + 2, z + 8, ModBlocks.zergStrucFlesh, 0, 3);
		world.setBlock(x + 12, y + 2, z + 8, ModBlocks.zergStrucFlesh, 0, 3);
		world.setBlock(x + 13, y + 2, z + 8, ModBlocks.zergStrucFlesh, 0, 3);
		world.setBlock(x + 14, y + 2, z + 8, ModBlocks.zergStrucFlesh, 0, 3);
		world.setBlock(x + 15, y + 2, z + 8, Blocks.air, 0, 3);
		world.setBlock(x + 16, y + 2, z + 8, Blocks.air, 0, 3);
		world.setBlock(x + 17, y + 2, z + 8, Blocks.air, 0, 3);
		world.setBlock(x + 18, y + 2, z + 8, Blocks.air, 0, 3);
		world.setBlock(x + 0, y + 2, z + 9, Blocks.air, 0, 3);
		world.setBlock(x + 1, y + 2, z + 9, Blocks.air, 0, 3);
		world.setBlock(x + 2, y + 2, z + 9, Blocks.air, 0, 3);
		world.setBlock(x + 3, y + 2, z + 9, Blocks.air, 0, 3);
		world.setBlock(x + 4, y + 2, z + 9, ModBlocks.zergStrucFlesh, 0, 3);
		world.setBlock(x + 5, y + 2, z + 9, ModBlocks.zergStrucFlesh, 0, 3);
		world.setBlock(x + 6, y + 2, z + 9, ModBlocks.zergStrucFlesh, 0, 3);
		world.setBlock(x + 7, y + 2, z + 9, ModBlocks.fluidAcid, 8, 3);
		world.setBlock(x + 8, y + 2, z + 9, ModBlocks.fluidAcid, 8, 3);
		world.setBlock(x + 9, y + 2, z + 9, ModBlocks.fluidAcid, 8, 3);
		world.setBlock(x + 10, y + 2, z + 9, ModBlocks.fluidAcid, 8, 3);
		world.setBlock(x + 11, y + 2, z + 9, ModBlocks.zergStrucFlesh, 0, 3);
		world.setBlock(x + 12, y + 2, z + 9, ModBlocks.zergStrucFlesh, 0, 3);
		world.setBlock(x + 13, y + 2, z + 9, ModBlocks.zergStrucFlesh, 0, 3);
		world.setBlock(x + 14, y + 2, z + 9, ModBlocks.zergStrucFlesh, 0, 3);
		world.setBlock(x + 15, y + 2, z + 9, Blocks.air, 0, 3);
		world.setBlock(x + 16, y + 2, z + 9, Blocks.air, 0, 3);
		world.setBlock(x + 17, y + 2, z + 9, Blocks.air, 0, 3);
		world.setBlock(x + 18, y + 2, z + 9, Blocks.air, 0, 3);
		world.setBlock(x + 0, y + 2, z + 10, Blocks.air, 0, 3);
		world.setBlock(x + 1, y + 2, z + 10, Blocks.air, 0, 3);
		world.setBlock(x + 2, y + 2, z + 10, Blocks.air, 0, 3);
		world.setBlock(x + 3, y + 2, z + 10, Blocks.air, 0, 3);
		world.setBlock(x + 4, y + 2, z + 10, ModBlocks.zergStrucFlesh, 0, 3);
		world.setBlock(x + 5, y + 2, z + 10, ModBlocks.zergStrucFlesh, 0, 3);
		world.setBlock(x + 6, y + 2, z + 10, ModBlocks.zergStrucFlesh, 0, 3);
		world.setBlock(x + 7, y + 2, z + 10, ModBlocks.fluidAcid, 8, 3);
		world.setBlock(x + 8, y + 2, z + 10, ModBlocks.fluidAcid, 8, 3);
		world.setBlock(x + 9, y + 2, z + 10, ModBlocks.fluidAcid, 8, 3);
		world.setBlock(x + 10, y + 2, z + 10, ModBlocks.fluidAcid, 8, 3);
		world.setBlock(x + 11, y + 2, z + 10, ModBlocks.fluidAcid, 8, 3);
		world.setBlock(x + 12, y + 2, z + 10, ModBlocks.zergStrucFlesh, 0, 3);
		world.setBlock(x + 13, y + 2, z + 10, ModBlocks.zergStrucFlesh, 0, 3);
		world.setBlock(x + 14, y + 2, z + 10, ModBlocks.zergStrucFlesh, 0, 3);
		world.setBlock(x + 15, y + 2, z + 10, Blocks.air, 0, 3);
		world.setBlock(x + 16, y + 2, z + 10, Blocks.air, 0, 3);
		world.setBlock(x + 17, y + 2, z + 10, Blocks.air, 0, 3);
		world.setBlock(x + 18, y + 2, z + 10, Blocks.air, 0, 3);
		world.setBlock(x + 0, y + 2, z + 11, Blocks.air, 0, 3);
		world.setBlock(x + 1, y + 2, z + 11, Blocks.air, 0, 3);
		world.setBlock(x + 2, y + 2, z + 11, Blocks.air, 0, 3);
		world.setBlock(x + 3, y + 2, z + 11, Blocks.air, 0, 3);
		world.setBlock(x + 4, y + 2, z + 11, ModBlocks.zergStrucFlesh, 0, 3);
		world.setBlock(x + 5, y + 2, z + 11, ModBlocks.zergStrucFlesh, 0, 3);
		world.setBlock(x + 6, y + 2, z + 11, ModBlocks.zergStrucFlesh, 0, 3);
		world.setBlock(x + 7, y + 2, z + 11, ModBlocks.zergStrucFlesh, 0, 3);
		world.setBlock(x + 8, y + 2, z + 11, ModBlocks.fluidAcid, 8, 3);
		world.setBlock(x + 9, y + 2, z + 11, ModBlocks.fluidAcid, 8, 3);
		world.setBlock(x + 10, y + 2, z + 11, ModBlocks.fluidAcid, 8, 3);
		world.setBlock(x + 11, y + 2, z + 11, ModBlocks.fluidAcid, 8, 3);
		world.setBlock(x + 12, y + 2, z + 11, ModBlocks.zergStrucFlesh, 0, 3);
		world.setBlock(x + 13, y + 2, z + 11, ModBlocks.zergStrucFlesh, 0, 3);
		world.setBlock(x + 14, y + 2, z + 11, ModBlocks.zergStrucFlesh, 0, 3);
		world.setBlock(x + 15, y + 2, z + 11, Blocks.air, 0, 3);
		world.setBlock(x + 16, y + 2, z + 11, Blocks.air, 0, 3);
		world.setBlock(x + 17, y + 2, z + 11, Blocks.air, 0, 3);
		world.setBlock(x + 18, y + 2, z + 11, Blocks.air, 0, 3);
		world.setBlock(x + 0, y + 2, z + 12, Blocks.air, 0, 3);
		world.setBlock(x + 1, y + 2, z + 12, Blocks.air, 0, 3);
		world.setBlock(x + 2, y + 2, z + 12, Blocks.air, 0, 3);
		world.setBlock(x + 3, y + 2, z + 12, Blocks.air, 0, 3);
		world.setBlock(x + 4, y + 2, z + 12, ModBlocks.zergStrucFlesh, 0, 3);
		world.setBlock(x + 5, y + 2, z + 12, ModBlocks.zergStrucFlesh, 0, 3);
		world.setBlock(x + 6, y + 2, z + 12, ModBlocks.zergStrucFlesh, 0, 3);
		world.setBlock(x + 7, y + 2, z + 12, ModBlocks.zergStrucFlesh, 0, 3);
		world.setBlock(x + 8, y + 2, z + 12, ModBlocks.zergStrucFlesh, 0, 3);
		world.setBlock(x + 9, y + 2, z + 12, ModBlocks.fluidAcid, 8, 3);
		world.setBlock(x + 10, y + 2, z + 12, ModBlocks.fluidAcid, 8, 3);
		world.setBlock(x + 11, y + 2, z + 12, ModBlocks.fluidAcid, 8, 3);
		world.setBlock(x + 12, y + 2, z + 12, ModBlocks.zergStrucFlesh, 0, 3);
		world.setBlock(x + 13, y + 2, z + 12, ModBlocks.zergStrucFlesh, 0, 3);
		world.setBlock(x + 14, y + 2, z + 12, ModBlocks.zergStrucFlesh, 0, 3);
		world.setBlock(x + 15, y + 2, z + 12, Blocks.air, 0, 3);
		world.setBlock(x + 16, y + 2, z + 12, Blocks.air, 0, 3);
		world.setBlock(x + 17, y + 2, z + 12, Blocks.air, 0, 3);
		world.setBlock(x + 18, y + 2, z + 12, Blocks.air, 0, 3);
		world.setBlock(x + 0, y + 2, z + 13, Blocks.air, 0, 3);
		world.setBlock(x + 1, y + 2, z + 13, Blocks.air, 0, 3);
		world.setBlock(x + 2, y + 2, z + 13, Blocks.air, 0, 3);
		world.setBlock(x + 3, y + 2, z + 13, Blocks.air, 0, 3);
		world.setBlock(x + 4, y + 2, z + 13, ModBlocks.zergStrucFlesh, 0, 3);
		world.setBlock(x + 5, y + 2, z + 13, ModBlocks.zergStrucFlesh, 0, 3);
		world.setBlock(x + 6, y + 2, z + 13, ModBlocks.zergStrucFlesh, 0, 3);
		world.setBlock(x + 7, y + 2, z + 13, ModBlocks.zergStrucFlesh, 0, 3);
		world.setBlock(x + 8, y + 2, z + 13, ModBlocks.zergStrucFlesh, 0, 3);
		world.setBlock(x + 9, y + 2, z + 13, ModBlocks.zergStrucFlesh, 0, 3);
		world.setBlock(x + 10, y + 2, z + 13, ModBlocks.zergStrucFlesh, 0, 3);
		world.setBlock(x + 11, y + 2, z + 13, ModBlocks.zergStrucFlesh, 0, 3);
		world.setBlock(x + 12, y + 2, z + 13, ModBlocks.zergStrucFlesh, 0, 3);
		world.setBlock(x + 13, y + 2, z + 13, ModBlocks.zergStrucFlesh, 0, 3);
		world.setBlock(x + 14, y + 2, z + 13, ModBlocks.zergStrucFlesh, 0, 3);
		world.setBlock(x + 15, y + 2, z + 13, Blocks.air, 0, 3);
		world.setBlock(x + 16, y + 2, z + 13, Blocks.air, 0, 3);
		world.setBlock(x + 17, y + 2, z + 13, Blocks.air, 0, 3);
		world.setBlock(x + 18, y + 2, z + 13, Blocks.air, 0, 3);
		world.setBlock(x + 0, y + 2, z + 14, Blocks.air, 0, 3);
		world.setBlock(x + 1, y + 2, z + 14, Blocks.air, 0, 3);
		world.setBlock(x + 2, y + 2, z + 14, Blocks.air, 0, 3);
		world.setBlock(x + 3, y + 2, z + 14, Blocks.air, 0, 3);
		world.setBlock(x + 4, y + 2, z + 14, ModBlocks.zergStrucFlesh, 0, 3);
		world.setBlock(x + 5, y + 2, z + 14, ModBlocks.zergStrucFlesh, 0, 3);
		world.setBlock(x + 6, y + 2, z + 14, ModBlocks.zergStrucFlesh, 0, 3);
		world.setBlock(x + 7, y + 2, z + 14, ModBlocks.zergStrucFlesh, 0, 3);
		world.setBlock(x + 8, y + 2, z + 14, ModBlocks.zergStrucFlesh, 0, 3);
		world.setBlock(x + 9, y + 2, z + 14, ModBlocks.zergStrucFlesh, 0, 3);
		world.setBlock(x + 10, y + 2, z + 14, ModBlocks.zergStrucFlesh, 0, 3);
		world.setBlock(x + 11, y + 2, z + 14, ModBlocks.zergStrucFlesh, 0, 3);
		world.setBlock(x + 12, y + 2, z + 14, ModBlocks.zergStrucFlesh, 0, 3);
		world.setBlock(x + 13, y + 2, z + 14, ModBlocks.zergStrucFlesh, 0, 3);
		world.setBlock(x + 14, y + 2, z + 14, ModBlocks.zergStrucFlesh, 0, 3);
		world.setBlock(x + 15, y + 2, z + 14, Blocks.air, 0, 3);
		world.setBlock(x + 16, y + 2, z + 14, Blocks.air, 0, 3);
		world.setBlock(x + 17, y + 2, z + 14, Blocks.air, 0, 3);
		world.setBlock(x + 18, y + 2, z + 14, Blocks.air, 0, 3);
		world.setBlock(x + 0, y + 2, z + 15, Blocks.air, 0, 3);
		world.setBlock(x + 1, y + 2, z + 15, Blocks.air, 0, 3);
		world.setBlock(x + 2, y + 2, z + 15, Blocks.air, 0, 3);
		world.setBlock(x + 3, y + 2, z + 15, Blocks.air, 0, 3);
		world.setBlock(x + 4, y + 2, z + 15, ModBlocks.zergStrucFlesh, 0, 3);
		world.setBlock(x + 5, y + 2, z + 15, ModBlocks.zergStrucFlesh, 0, 3);
		world.setBlock(x + 6, y + 2, z + 15, ModBlocks.zergStrucFlesh, 0, 3);
		world.setBlock(x + 7, y + 2, z + 15, ModBlocks.zergStrucFlesh, 0, 3);
		world.setBlock(x + 8, y + 2, z + 15, ModBlocks.zergStrucFlesh, 0, 3);
		world.setBlock(x + 9, y + 2, z + 15, ModBlocks.zergStrucFlesh, 0, 3);
		world.setBlock(x + 10, y + 2, z + 15, ModBlocks.zergStrucFlesh, 0, 3);
		world.setBlock(x + 11, y + 2, z + 15, ModBlocks.zergStrucFlesh, 0, 3);
		world.setBlock(x + 12, y + 2, z + 15, ModBlocks.zergStrucFlesh, 0, 3);
		world.setBlock(x + 13, y + 2, z + 15, ModBlocks.zergStrucFlesh, 0, 3);
		world.setBlock(x + 14, y + 2, z + 15, Blocks.air, 0, 3);
		world.setBlock(x + 15, y + 2, z + 15, Blocks.air, 0, 3);
		world.setBlock(x + 16, y + 2, z + 15, Blocks.air, 0, 3);
		world.setBlock(x + 17, y + 2, z + 15, Blocks.air, 0, 3);
		world.setBlock(x + 18, y + 2, z + 15, Blocks.air, 0, 3);
		world.setBlock(x + 0, y + 2, z + 16, Blocks.air, 0, 3);
		world.setBlock(x + 1, y + 2, z + 16, Blocks.air, 0, 3);
		world.setBlock(x + 2, y + 2, z + 16, Blocks.air, 0, 3);
		world.setBlock(x + 3, y + 2, z + 16, Blocks.air, 0, 3);
		world.setBlock(x + 4, y + 2, z + 16, Blocks.air, 0, 3);
		world.setBlock(x + 5, y + 2, z + 16, Blocks.air, 0, 3);
		world.setBlock(x + 6, y + 2, z + 16, Blocks.air, 0, 3);
		world.setBlock(x + 7, y + 2, z + 16, Blocks.air, 0, 3);
		world.setBlock(x + 8, y + 2, z + 16, Blocks.air, 0, 3);
		world.setBlock(x + 9, y + 2, z + 16, Blocks.air, 0, 3);
		world.setBlock(x + 10, y + 2, z + 16, Blocks.air, 0, 3);
		world.setBlock(x + 11, y + 2, z + 16, Blocks.air, 0, 3);
		world.setBlock(x + 12, y + 2, z + 16, Blocks.air, 0, 3);
		world.setBlock(x + 13, y + 2, z + 16, Blocks.air, 0, 3);
		world.setBlock(x + 14, y + 2, z + 16, Blocks.air, 0, 3);
		world.setBlock(x + 15, y + 2, z + 16, Blocks.air, 0, 3);
		world.setBlock(x + 16, y + 2, z + 16, Blocks.air, 0, 3);
		world.setBlock(x + 17, y + 2, z + 16, Blocks.air, 0, 3);
		world.setBlock(x + 18, y + 2, z + 16, Blocks.air, 0, 3);
		world.setBlock(x + 0, y + 2, z + 17, Blocks.air, 0, 3);
		world.setBlock(x + 1, y + 2, z + 17, Blocks.air, 0, 3);
		world.setBlock(x + 2, y + 2, z + 17, Blocks.air, 0, 3);
		world.setBlock(x + 3, y + 2, z + 17, Blocks.air, 0, 3);
		world.setBlock(x + 4, y + 2, z + 17, Blocks.air, 0, 3);
		world.setBlock(x + 5, y + 2, z + 17, Blocks.air, 0, 3);
		world.setBlock(x + 6, y + 2, z + 17, Blocks.air, 0, 3);
		world.setBlock(x + 7, y + 2, z + 17, Blocks.air, 0, 3);
		world.setBlock(x + 8, y + 2, z + 17, Blocks.air, 0, 3);
		world.setBlock(x + 9, y + 2, z + 17, Blocks.air, 0, 3);
		world.setBlock(x + 10, y + 2, z + 17, Blocks.air, 0, 3);
		world.setBlock(x + 11, y + 2, z + 17, Blocks.air, 0, 3);
		world.setBlock(x + 12, y + 2, z + 17, Blocks.air, 0, 3);
		world.setBlock(x + 13, y + 2, z + 17, Blocks.air, 0, 3);
		world.setBlock(x + 14, y + 2, z + 17, Blocks.air, 0, 3);
		world.setBlock(x + 15, y + 2, z + 17, Blocks.air, 0, 3);
		world.setBlock(x + 16, y + 2, z + 17, Blocks.air, 0, 3);
		world.setBlock(x + 17, y + 2, z + 17, Blocks.air, 0, 3);
		world.setBlock(x + 18, y + 2, z + 17, Blocks.air, 0, 3);
		world.setBlock(x + 0, y + 2, z + 18, Blocks.air, 0, 3);
		world.setBlock(x + 1, y + 2, z + 18, Blocks.air, 0, 3);
		world.setBlock(x + 2, y + 2, z + 18, Blocks.air, 0, 3);
		world.setBlock(x + 3, y + 2, z + 18, Blocks.air, 0, 3);
		world.setBlock(x + 4, y + 2, z + 18, Blocks.air, 0, 3);
		world.setBlock(x + 5, y + 2, z + 18, Blocks.air, 0, 3);
		world.setBlock(x + 6, y + 2, z + 18, Blocks.air, 0, 3);
		world.setBlock(x + 7, y + 2, z + 18, Blocks.air, 0, 3);
		world.setBlock(x + 8, y + 2, z + 18, Blocks.air, 0, 3);
		world.setBlock(x + 9, y + 2, z + 18, Blocks.air, 0, 3);
		world.setBlock(x + 10, y + 2, z + 18, Blocks.air, 0, 3);
		world.setBlock(x + 11, y + 2, z + 18, Blocks.air, 0, 3);
		world.setBlock(x + 12, y + 2, z + 18, Blocks.air, 0, 3);
		world.setBlock(x + 13, y + 2, z + 18, Blocks.air, 0, 3);
		world.setBlock(x + 14, y + 2, z + 18, Blocks.air, 0, 3);
		world.setBlock(x + 15, y + 2, z + 18, Blocks.air, 0, 3);
		world.setBlock(x + 16, y + 2, z + 18, Blocks.air, 0, 3);
		world.setBlock(x + 17, y + 2, z + 18, Blocks.air, 0, 3);
		world.setBlock(x + 18, y + 2, z + 18, Blocks.air, 0, 3);
		world.setBlock(x + 0, y + 2, z + 19, Blocks.air, 0, 3);
		world.setBlock(x + 1, y + 2, z + 19, Blocks.air, 0, 3);
		world.setBlock(x + 2, y + 2, z + 19, Blocks.air, 0, 3);
		world.setBlock(x + 3, y + 2, z + 19, Blocks.air, 0, 3);
		world.setBlock(x + 4, y + 2, z + 19, Blocks.air, 0, 3);
		world.setBlock(x + 5, y + 2, z + 19, Blocks.air, 0, 3);
		world.setBlock(x + 6, y + 2, z + 19, Blocks.air, 0, 3);
		world.setBlock(x + 7, y + 2, z + 19, Blocks.air, 0, 3);
		world.setBlock(x + 8, y + 2, z + 19, Blocks.air, 0, 3);
		world.setBlock(x + 9, y + 2, z + 19, Blocks.air, 0, 3);
		world.setBlock(x + 10, y + 2, z + 19, Blocks.air, 0, 3);
		world.setBlock(x + 11, y + 2, z + 19, Blocks.air, 0, 3);
		world.setBlock(x + 12, y + 2, z + 19, Blocks.air, 0, 3);
		world.setBlock(x + 13, y + 2, z + 19, Blocks.air, 0, 3);
		world.setBlock(x + 14, y + 2, z + 19, Blocks.air, 0, 3);
		world.setBlock(x + 15, y + 2, z + 19, Blocks.air, 0, 3);
		world.setBlock(x + 16, y + 2, z + 19, Blocks.air, 0, 3);
		world.setBlock(x + 17, y + 2, z + 19, Blocks.air, 0, 3);
		world.setBlock(x + 18, y + 2, z + 19, Blocks.air, 0, 3);
		world.setBlock(x + 0, y + 2, z + 20, Blocks.air, 0, 3);
		world.setBlock(x + 1, y + 2, z + 20, Blocks.air, 0, 3);
		world.setBlock(x + 2, y + 2, z + 20, Blocks.air, 0, 3);
		world.setBlock(x + 3, y + 2, z + 20, Blocks.air, 0, 3);
		world.setBlock(x + 4, y + 2, z + 20, Blocks.air, 0, 3);
		world.setBlock(x + 5, y + 2, z + 20, Blocks.air, 0, 3);
		world.setBlock(x + 6, y + 2, z + 20, Blocks.air, 0, 3);
		world.setBlock(x + 7, y + 2, z + 20, Blocks.air, 0, 3);
		world.setBlock(x + 8, y + 2, z + 20, Blocks.air, 0, 3);
		world.setBlock(x + 9, y + 2, z + 20, Blocks.air, 0, 3);
		world.setBlock(x + 10, y + 2, z + 20, Blocks.air, 0, 3);
		world.setBlock(x + 11, y + 2, z + 20, Blocks.air, 0, 3);
		world.setBlock(x + 12, y + 2, z + 20, Blocks.air, 0, 3);
		world.setBlock(x + 13, y + 2, z + 20, Blocks.air, 0, 3);
		world.setBlock(x + 14, y + 2, z + 20, Blocks.air, 0, 3);
		world.setBlock(x + 15, y + 2, z + 20, Blocks.air, 0, 3);
		world.setBlock(x + 16, y + 2, z + 20, Blocks.air, 0, 3);
		world.setBlock(x + 17, y + 2, z + 20, Blocks.air, 0, 3);
		world.setBlock(x + 18, y + 2, z + 20, Blocks.air, 0, 3);
		world.setBlock(x + 0, y + 3, z + 0, Blocks.air, 0, 3);
		world.setBlock(x + 1, y + 3, z + 0, Blocks.air, 0, 3);
		world.setBlock(x + 2, y + 3, z + 0, Blocks.air, 0, 3);
		world.setBlock(x + 3, y + 3, z + 0, Blocks.air, 0, 3);
		world.setBlock(x + 4, y + 3, z + 0, Blocks.air, 0, 3);
		world.setBlock(x + 5, y + 3, z + 0, Blocks.air, 0, 3);
		world.setBlock(x + 6, y + 3, z + 0, Blocks.air, 0, 3);
		world.setBlock(x + 7, y + 3, z + 0, Blocks.air, 0, 3);
		world.setBlock(x + 8, y + 3, z + 0, Blocks.air, 0, 3);
		world.setBlock(x + 9, y + 3, z + 0, Blocks.air, 0, 3);
		world.setBlock(x + 10, y + 3, z + 0, Blocks.air, 0, 3);
		world.setBlock(x + 11, y + 3, z + 0, Blocks.air, 0, 3);
		world.setBlock(x + 12, y + 3, z + 0, Blocks.air, 0, 3);
		world.setBlock(x + 13, y + 3, z + 0, Blocks.air, 0, 3);
		world.setBlock(x + 14, y + 3, z + 0, Blocks.air, 0, 3);
		world.setBlock(x + 15, y + 3, z + 0, Blocks.air, 0, 3);
		world.setBlock(x + 16, y + 3, z + 0, Blocks.air, 0, 3);
		world.setBlock(x + 17, y + 3, z + 0, Blocks.air, 0, 3);
		world.setBlock(x + 18, y + 3, z + 0, Blocks.air, 0, 3);
		world.setBlock(x + 0, y + 3, z + 1, Blocks.air, 0, 3);
		world.setBlock(x + 1, y + 3, z + 1, Blocks.air, 0, 3);
		world.setBlock(x + 2, y + 3, z + 1, Blocks.air, 0, 3);
		world.setBlock(x + 3, y + 3, z + 1, Blocks.air, 0, 3);
		world.setBlock(x + 4, y + 3, z + 1, Blocks.air, 0, 3);
		world.setBlock(x + 5, y + 3, z + 1, Blocks.air, 0, 3);
		world.setBlock(x + 6, y + 3, z + 1, Blocks.air, 0, 3);
		world.setBlock(x + 7, y + 3, z + 1, Blocks.air, 0, 3);
		world.setBlock(x + 8, y + 3, z + 1, Blocks.air, 0, 3);
		world.setBlock(x + 9, y + 3, z + 1, Blocks.air, 0, 3);
		world.setBlock(x + 10, y + 3, z + 1, Blocks.air, 0, 3);
		world.setBlock(x + 11, y + 3, z + 1, Blocks.air, 0, 3);
		world.setBlock(x + 12, y + 3, z + 1, Blocks.air, 0, 3);
		world.setBlock(x + 13, y + 3, z + 1, Blocks.air, 0, 3);
		world.setBlock(x + 14, y + 3, z + 1, Blocks.air, 0, 3);
		world.setBlock(x + 15, y + 3, z + 1, Blocks.air, 0, 3);
		world.setBlock(x + 16, y + 3, z + 1, Blocks.air, 0, 3);
		world.setBlock(x + 17, y + 3, z + 1, Blocks.air, 0, 3);
		world.setBlock(x + 18, y + 3, z + 1, Blocks.air, 0, 3);
		world.setBlock(x + 0, y + 3, z + 2, Blocks.air, 0, 3);
		world.setBlock(x + 1, y + 3, z + 2, Blocks.air, 0, 3);
		world.setBlock(x + 2, y + 3, z + 2, Blocks.air, 0, 3);
		world.setBlock(x + 3, y + 3, z + 2, Blocks.air, 0, 3);
		world.setBlock(x + 4, y + 3, z + 2, Blocks.air, 0, 3);
		world.setBlock(x + 5, y + 3, z + 2, Blocks.air, 0, 3);
		world.setBlock(x + 6, y + 3, z + 2, Blocks.air, 0, 3);
		world.setBlock(x + 7, y + 3, z + 2, Blocks.air, 0, 3);
		world.setBlock(x + 8, y + 3, z + 2, Blocks.air, 0, 3);
		world.setBlock(x + 9, y + 3, z + 2, Blocks.air, 0, 3);
		world.setBlock(x + 10, y + 3, z + 2, Blocks.air, 0, 3);
		world.setBlock(x + 11, y + 3, z + 2, Blocks.air, 0, 3);
		world.setBlock(x + 12, y + 3, z + 2, Blocks.air, 0, 3);
		world.setBlock(x + 13, y + 3, z + 2, Blocks.air, 0, 3);
		world.setBlock(x + 14, y + 3, z + 2, Blocks.air, 0, 3);
		world.setBlock(x + 15, y + 3, z + 2, Blocks.air, 0, 3);
		world.setBlock(x + 16, y + 3, z + 2, Blocks.air, 0, 3);
		world.setBlock(x + 17, y + 3, z + 2, Blocks.air, 0, 3);
		world.setBlock(x + 18, y + 3, z + 2, Blocks.air, 0, 3);
		world.setBlock(x + 0, y + 3, z + 3, Blocks.air, 0, 3);
		world.setBlock(x + 1, y + 3, z + 3, Blocks.air, 0, 3);
		world.setBlock(x + 2, y + 3, z + 3, Blocks.air, 0, 3);
		world.setBlock(x + 3, y + 3, z + 3, Blocks.air, 0, 3);
		world.setBlock(x + 4, y + 3, z + 3, Blocks.air, 0, 3);
		world.setBlock(x + 5, y + 3, z + 3, Blocks.air, 0, 3);
		world.setBlock(x + 6, y + 3, z + 3, Blocks.air, 0, 3);
		world.setBlock(x + 7, y + 3, z + 3, Blocks.air, 0, 3);
		world.setBlock(x + 8, y + 3, z + 3, Blocks.air, 0, 3);
		world.setBlock(x + 9, y + 3, z + 3, Blocks.air, 0, 3);
		world.setBlock(x + 10, y + 3, z + 3, Blocks.air, 0, 3);
		world.setBlock(x + 11, y + 3, z + 3, Blocks.air, 0, 3);
		world.setBlock(x + 12, y + 3, z + 3, Blocks.air, 0, 3);
		world.setBlock(x + 13, y + 3, z + 3, Blocks.air, 0, 3);
		world.setBlock(x + 14, y + 3, z + 3, Blocks.air, 0, 3);
		world.setBlock(x + 15, y + 3, z + 3, Blocks.air, 0, 3);
		world.setBlock(x + 16, y + 3, z + 3, Blocks.air, 0, 3);
		world.setBlock(x + 17, y + 3, z + 3, Blocks.air, 0, 3);
		world.setBlock(x + 18, y + 3, z + 3, Blocks.air, 0, 3);
		world.setBlock(x + 0, y + 3, z + 4, Blocks.air, 0, 3);
		world.setBlock(x + 1, y + 3, z + 4, Blocks.air, 0, 3);
		world.setBlock(x + 2, y + 3, z + 4, Blocks.air, 0, 3);
		world.setBlock(x + 3, y + 3, z + 4, Blocks.air, 0, 3);
		world.setBlock(x + 4, y + 3, z + 4, Blocks.air, 0, 3);
		world.setBlock(x + 5, y + 3, z + 4, Blocks.air, 0, 3);
		world.setBlock(x + 6, y + 3, z + 4, Blocks.air, 0, 3);
		world.setBlock(x + 7, y + 3, z + 4, Blocks.air, 0, 3);
		world.setBlock(x + 8, y + 3, z + 4, Blocks.air, 0, 3);
		world.setBlock(x + 9, y + 3, z + 4, Blocks.air, 0, 3);
		world.setBlock(x + 10, y + 3, z + 4, Blocks.air, 0, 3);
		world.setBlock(x + 11, y + 3, z + 4, Blocks.air, 0, 3);
		world.setBlock(x + 12, y + 3, z + 4, Blocks.air, 0, 3);
		world.setBlock(x + 13, y + 3, z + 4, Blocks.air, 0, 3);
		world.setBlock(x + 14, y + 3, z + 4, Blocks.air, 0, 3);
		world.setBlock(x + 15, y + 3, z + 4, Blocks.air, 0, 3);
		world.setBlock(x + 16, y + 3, z + 4, Blocks.air, 0, 3);
		world.setBlock(x + 17, y + 3, z + 4, Blocks.air, 0, 3);
		world.setBlock(x + 18, y + 3, z + 4, Blocks.air, 0, 3);
		world.setBlock(x + 0, y + 3, z + 5, Blocks.air, 0, 3);
		world.setBlock(x + 1, y + 3, z + 5, Blocks.air, 0, 3);
		world.setBlock(x + 2, y + 3, z + 5, Blocks.air, 0, 3);
		world.setBlock(x + 3, y + 3, z + 5, Blocks.air, 0, 3);
		world.setBlock(x + 4, y + 3, z + 5, Blocks.air, 0, 3);
		world.setBlock(x + 5, y + 3, z + 5, Blocks.air, 0, 3);
		world.setBlock(x + 6, y + 3, z + 5, Blocks.air, 0, 3);
		world.setBlock(x + 7, y + 3, z + 5, ModBlocks.zergStrucFlesh, 0, 3);
		world.setBlock(x + 8, y + 3, z + 5, ModBlocks.zergStrucFlesh, 0, 3);
		world.setBlock(x + 9, y + 3, z + 5, ModBlocks.zergStrucFlesh, 0, 3);
		world.setBlock(x + 10, y + 3, z + 5, ModBlocks.zergStrucFlesh, 0, 3);
		world.setBlock(x + 11, y + 3, z + 5, ModBlocks.zergStrucFlesh, 0, 3);
		world.setBlock(x + 12, y + 3, z + 5, Blocks.air, 0, 3);
		world.setBlock(x + 13, y + 3, z + 5, Blocks.air, 0, 3);
		world.setBlock(x + 14, y + 3, z + 5, Blocks.air, 0, 3);
		world.setBlock(x + 15, y + 3, z + 5, Blocks.air, 0, 3);
		world.setBlock(x + 16, y + 3, z + 5, Blocks.air, 0, 3);
		world.setBlock(x + 17, y + 3, z + 5, Blocks.air, 0, 3);
		world.setBlock(x + 18, y + 3, z + 5, Blocks.air, 0, 3);
		world.setBlock(x + 0, y + 3, z + 6, Blocks.air, 0, 3);
		world.setBlock(x + 1, y + 3, z + 6, Blocks.air, 0, 3);
		world.setBlock(x + 2, y + 3, z + 6, Blocks.air, 0, 3);
		world.setBlock(x + 3, y + 3, z + 6, Blocks.air, 0, 3);
		world.setBlock(x + 4, y + 3, z + 6, Blocks.air, 0, 3);
		world.setBlock(x + 5, y + 3, z + 6, ModBlocks.zergStrucFlesh, 0, 3);
		world.setBlock(x + 6, y + 3, z + 6, ModBlocks.zergStrucFlesh, 0, 3);
		world.setBlock(x + 7, y + 3, z + 6, ModBlocks.zergStrucFlesh, 0, 3);
		world.setBlock(x + 8, y + 3, z + 6, ModBlocks.zergStrucFlesh, 0, 3);
		world.setBlock(x + 9, y + 3, z + 6, ModBlocks.zergStrucFlesh, 0, 3);
		world.setBlock(x + 10, y + 3, z + 6, ModBlocks.zergStrucFlesh, 0, 3);
		world.setBlock(x + 11, y + 3, z + 6, ModBlocks.zergStrucFlesh, 0, 3);
		world.setBlock(x + 12, y + 3, z + 6, ModBlocks.zergStrucFlesh, 0, 3);
		world.setBlock(x + 13, y + 3, z + 6, Blocks.air, 0, 3);
		world.setBlock(x + 14, y + 3, z + 6, Blocks.air, 0, 3);
		world.setBlock(x + 15, y + 3, z + 6, Blocks.air, 0, 3);
		world.setBlock(x + 16, y + 3, z + 6, Blocks.air, 0, 3);
		world.setBlock(x + 17, y + 3, z + 6, Blocks.air, 0, 3);
		world.setBlock(x + 18, y + 3, z + 6, Blocks.air, 0, 3);
		world.setBlock(x + 0, y + 3, z + 7, Blocks.air, 0, 3);
		world.setBlock(x + 1, y + 3, z + 7, Blocks.air, 0, 3);
		world.setBlock(x + 2, y + 3, z + 7, Blocks.air, 0, 3);
		world.setBlock(x + 3, y + 3, z + 7, Blocks.air, 0, 3);
		world.setBlock(x + 4, y + 3, z + 7, Blocks.air, 0, 3);
		world.setBlock(x + 5, y + 3, z + 7, ModBlocks.zergStrucFlesh, 0, 3);
		world.setBlock(x + 6, y + 3, z + 7, ModBlocks.zergStrucFlesh, 0, 3);
		world.setBlock(x + 7, y + 3, z + 7, ModBlocks.zergStrucFlesh, 0, 3);
		world.setBlock(x + 8, y + 3, z + 7, ModBlocks.zergStrucFlesh, 0, 3);
		world.setBlock(x + 9, y + 3, z + 7, ModBlocks.zergStrucFlesh, 0, 3);
		world.setBlock(x + 10, y + 3, z + 7, ModBlocks.zergStrucFlesh, 0, 3);
		world.setBlock(x + 11, y + 3, z + 7, ModBlocks.zergStrucFlesh, 0, 3);
		world.setBlock(x + 12, y + 3, z + 7, ModBlocks.zergStrucFlesh, 0, 3);
		world.setBlock(x + 13, y + 3, z + 7, ModBlocks.zergStrucFlesh, 0, 3);
		world.setBlock(x + 14, y + 3, z + 7, Blocks.air, 0, 3);
		world.setBlock(x + 15, y + 3, z + 7, Blocks.air, 0, 3);
		world.setBlock(x + 16, y + 3, z + 7, Blocks.air, 0, 3);
		world.setBlock(x + 17, y + 3, z + 7, Blocks.air, 0, 3);
		world.setBlock(x + 18, y + 3, z + 7, Blocks.air, 0, 3);
		world.setBlock(x + 0, y + 3, z + 8, Blocks.air, 0, 3);
		world.setBlock(x + 1, y + 3, z + 8, Blocks.air, 0, 3);
		world.setBlock(x + 2, y + 3, z + 8, Blocks.air, 0, 3);
		world.setBlock(x + 3, y + 3, z + 8, Blocks.air, 0, 3);
		world.setBlock(x + 4, y + 3, z + 8, ModBlocks.zergStrucFlesh, 0, 3);
		world.setBlock(x + 5, y + 3, z + 8, ModBlocks.zergStrucFlesh, 0, 3);
		world.setBlock(x + 6, y + 3, z + 8, ModBlocks.zergStrucFlesh, 0, 3);
		world.setBlock(x + 7, y + 3, z + 8, ModBlocks.fluidAcid, 0, 3);
		world.setBlock(x + 8, y + 3, z + 8, ModBlocks.fluidAcid, 0, 3);
		world.setBlock(x + 9, y + 3, z + 8, ModBlocks.fluidAcid, 0, 3);
		world.setBlock(x + 10, y + 3, z + 8, ModBlocks.fluidAcid, 0, 3);
		world.setBlock(x + 11, y + 3, z + 8, ModBlocks.zergStrucFlesh, 0, 3);
		world.setBlock(x + 12, y + 3, z + 8, ModBlocks.zergStrucFlesh, 0, 3);
		world.setBlock(x + 13, y + 3, z + 8, ModBlocks.zergStrucFlesh, 0, 3);
		world.setBlock(x + 14, y + 3, z + 8, ModBlocks.zergStrucFlesh, 0, 3);
		world.setBlock(x + 15, y + 3, z + 8, Blocks.air, 0, 3);
		world.setBlock(x + 16, y + 3, z + 8, Blocks.air, 0, 3);
		world.setBlock(x + 17, y + 3, z + 8, Blocks.air, 0, 3);
		world.setBlock(x + 18, y + 3, z + 8, Blocks.air, 0, 3);
		world.setBlock(x + 0, y + 3, z + 9, Blocks.air, 0, 3);
		world.setBlock(x + 1, y + 3, z + 9, Blocks.air, 0, 3);
		world.setBlock(x + 2, y + 3, z + 9, Blocks.air, 0, 3);
		world.setBlock(x + 3, y + 3, z + 9, Blocks.air, 0, 3);
		world.setBlock(x + 4, y + 3, z + 9, ModBlocks.zergStrucFlesh, 0, 3);
		world.setBlock(x + 5, y + 3, z + 9, ModBlocks.zergStrucFlesh, 0, 3);
		world.setBlock(x + 6, y + 3, z + 9, ModBlocks.zergStrucFlesh, 0, 3);
		world.setBlock(x + 7, y + 3, z + 9, ModBlocks.fluidAcid, 0, 3);
		world.setBlock(x + 8, y + 3, z + 9, ModBlocks.fluidAcid, 0, 3);
		world.setBlock(x + 9, y + 3, z + 9, ModBlocks.fluidAcid, 0, 3);
		world.setBlock(x + 10, y + 3, z + 9, ModBlocks.fluidAcid, 0, 3);
		world.setBlock(x + 11, y + 3, z + 9, ModBlocks.fluidAcid, 0, 3);
		world.setBlock(x + 12, y + 3, z + 9, ModBlocks.zergStrucFlesh, 0, 3);
		world.setBlock(x + 13, y + 3, z + 9, ModBlocks.zergStrucFlesh, 0, 3);
		world.setBlock(x + 14, y + 3, z + 9, ModBlocks.zergStrucFlesh, 0, 3);
		world.setBlock(x + 15, y + 3, z + 9, Blocks.air, 0, 3);
		world.setBlock(x + 16, y + 3, z + 9, Blocks.air, 0, 3);
		world.setBlock(x + 17, y + 3, z + 9, Blocks.air, 0, 3);
		world.setBlock(x + 18, y + 3, z + 9, Blocks.air, 0, 3);
		world.setBlock(x + 0, y + 3, z + 10, Blocks.air, 0, 3);
		world.setBlock(x + 1, y + 3, z + 10, Blocks.air, 0, 3);
		world.setBlock(x + 2, y + 3, z + 10, Blocks.air, 0, 3);
		world.setBlock(x + 3, y + 3, z + 10, Blocks.air, 0, 3);
		world.setBlock(x + 4, y + 3, z + 10, ModBlocks.zergStrucFlesh, 0, 3);
		world.setBlock(x + 5, y + 3, z + 10, ModBlocks.zergStrucFlesh, 0, 3);
		world.setBlock(x + 6, y + 3, z + 10, ModBlocks.zergStrucFlesh, 0, 3);
		world.setBlock(x + 7, y + 3, z + 10, ModBlocks.fluidAcid, 0, 3);
		world.setBlock(x + 8, y + 3, z + 10, ModBlocks.fluidAcid, 0, 3);
		world.setBlock(x + 9, y + 3, z + 10, ModBlocks.fluidAcid, 0, 3);
		world.setBlock(x + 10, y + 3, z + 10, ModBlocks.fluidAcid, 0, 3);
		world.setBlock(x + 11, y + 3, z + 10, ModBlocks.fluidAcid, 0, 3);
		world.setBlock(x + 12, y + 3, z + 10, ModBlocks.zergStrucFlesh, 0, 3);
		world.setBlock(x + 13, y + 3, z + 10, ModBlocks.zergStrucFlesh, 0, 3);
		world.setBlock(x + 14, y + 3, z + 10, ModBlocks.zergStrucFlesh, 0, 3);
		world.setBlock(x + 15, y + 3, z + 10, Blocks.air, 0, 3);
		world.setBlock(x + 16, y + 3, z + 10, Blocks.air, 0, 3);
		world.setBlock(x + 17, y + 3, z + 10, Blocks.air, 0, 3);
		world.setBlock(x + 18, y + 3, z + 10, Blocks.air, 0, 3);
		world.setBlock(x + 0, y + 3, z + 11, Blocks.air, 0, 3);
		world.setBlock(x + 1, y + 3, z + 11, Blocks.air, 0, 3);
		world.setBlock(x + 2, y + 3, z + 11, Blocks.air, 0, 3);
		world.setBlock(x + 3, y + 3, z + 11, Blocks.air, 0, 3);
		world.setBlock(x + 4, y + 3, z + 11, ModBlocks.zergStrucFlesh, 0, 3);
		world.setBlock(x + 5, y + 3, z + 11, ModBlocks.zergStrucFlesh, 0, 3);
		world.setBlock(x + 6, y + 3, z + 11, ModBlocks.zergStrucFlesh, 0, 3);
		world.setBlock(x + 7, y + 3, z + 11, ModBlocks.fluidAcid, 0, 3);
		world.setBlock(x + 8, y + 3, z + 11, ModBlocks.fluidAcid, 0, 3);
		world.setBlock(x + 9, y + 3, z + 11, ModBlocks.fluidAcid, 0, 3);
		world.setBlock(x + 10, y + 3, z + 11, ModBlocks.fluidAcid, 0, 3);
		world.setBlock(x + 11, y + 3, z + 11, ModBlocks.fluidAcid, 0, 3);
		world.setBlock(x + 12, y + 3, z + 11, ModBlocks.zergStrucFlesh, 0, 3);
		world.setBlock(x + 13, y + 3, z + 11, ModBlocks.zergStrucFlesh, 0, 3);
		world.setBlock(x + 14, y + 3, z + 11, ModBlocks.zergStrucFlesh, 0, 3);
		world.setBlock(x + 15, y + 3, z + 11, Blocks.air, 0, 3);
		world.setBlock(x + 16, y + 3, z + 11, Blocks.air, 0, 3);
		world.setBlock(x + 17, y + 3, z + 11, Blocks.air, 0, 3);
		world.setBlock(x + 18, y + 3, z + 11, Blocks.air, 0, 3);
		world.setBlock(x + 0, y + 3, z + 12, Blocks.air, 0, 3);
		world.setBlock(x + 1, y + 3, z + 12, Blocks.air, 0, 3);
		world.setBlock(x + 2, y + 3, z + 12, Blocks.air, 0, 3);
		world.setBlock(x + 3, y + 3, z + 12, Blocks.air, 0, 3);
		world.setBlock(x + 4, y + 3, z + 12, ModBlocks.zergStrucFlesh, 0, 3);
		world.setBlock(x + 5, y + 3, z + 12, ModBlocks.zergStrucFlesh, 0, 3);
		world.setBlock(x + 6, y + 3, z + 12, ModBlocks.zergStrucFlesh, 0, 3);
		world.setBlock(x + 7, y + 3, z + 12, ModBlocks.zergStrucFlesh, 0, 3);
		world.setBlock(x + 8, y + 3, z + 12, ModBlocks.fluidAcid, 0, 3);
		world.setBlock(x + 9, y + 3, z + 12, ModBlocks.fluidAcid, 0, 3);
		world.setBlock(x + 10, y + 3, z + 12, ModBlocks.fluidAcid, 0, 3);
		world.setBlock(x + 11, y + 3, z + 12, ModBlocks.fluidAcid, 0, 3);
		world.setBlock(x + 12, y + 3, z + 12, ModBlocks.zergStrucFlesh, 0, 3);
		world.setBlock(x + 13, y + 3, z + 12, ModBlocks.keratinChunk, 0, 3);
		world.setBlock(x + 14, y + 3, z + 12, ModBlocks.zergStrucFlesh, 0, 3);
		world.setBlock(x + 15, y + 3, z + 12, Blocks.air, 0, 3);
		world.setBlock(x + 16, y + 3, z + 12, Blocks.air, 0, 3);
		world.setBlock(x + 17, y + 3, z + 12, Blocks.air, 0, 3);
		world.setBlock(x + 18, y + 3, z + 12, Blocks.air, 0, 3);
		world.setBlock(x + 0, y + 3, z + 13, Blocks.air, 0, 3);
		world.setBlock(x + 1, y + 3, z + 13, Blocks.air, 0, 3);
		world.setBlock(x + 2, y + 3, z + 13, Blocks.air, 0, 3);
		world.setBlock(x + 3, y + 3, z + 13, Blocks.air, 0, 3);
		world.setBlock(x + 4, y + 3, z + 13, ModBlocks.zergStrucFlesh, 0, 3);
		world.setBlock(x + 5, y + 3, z + 13, ModBlocks.zergStrucFlesh, 0, 3);
		world.setBlock(x + 6, y + 3, z + 13, ModBlocks.zergStrucFlesh, 0, 3);
		world.setBlock(x + 7, y + 3, z + 13, ModBlocks.zergStrucFlesh, 0, 3);
		world.setBlock(x + 8, y + 3, z + 13, ModBlocks.zergStrucFlesh, 0, 3);
		world.setBlock(x + 9, y + 3, z + 13, ModBlocks.zergStrucFlesh, 0, 3);
		world.setBlock(x + 10, y + 3, z + 13, ModBlocks.zergStrucFlesh, 0, 3);
		world.setBlock(x + 11, y + 3, z + 13, ModBlocks.zergStrucFlesh, 0, 3);
		world.setBlock(x + 12, y + 3, z + 13, ModBlocks.zergStrucFlesh, 0, 3);
		world.setBlock(x + 13, y + 3, z + 13, ModBlocks.keratinChunk, 0, 3);
		world.setBlock(x + 14, y + 3, z + 13, ModBlocks.zergStrucFlesh, 0, 3);
		world.setBlock(x + 15, y + 3, z + 13, Blocks.air, 0, 3);
		world.setBlock(x + 16, y + 3, z + 13, Blocks.air, 0, 3);
		world.setBlock(x + 17, y + 3, z + 13, Blocks.air, 0, 3);
		world.setBlock(x + 18, y + 3, z + 13, Blocks.air, 0, 3);
		world.setBlock(x + 0, y + 3, z + 14, Blocks.air, 0, 3);
		world.setBlock(x + 1, y + 3, z + 14, Blocks.air, 0, 3);
		world.setBlock(x + 2, y + 3, z + 14, Blocks.air, 0, 3);
		world.setBlock(x + 3, y + 3, z + 14, Blocks.air, 0, 3);
		world.setBlock(x + 4, y + 3, z + 14, ModBlocks.zergStrucFlesh, 0, 3);
		world.setBlock(x + 5, y + 3, z + 14, ModBlocks.zergStrucFlesh, 0, 3);
		world.setBlock(x + 6, y + 3, z + 14, ModBlocks.zergStrucFlesh, 0, 3);
		world.setBlock(x + 7, y + 3, z + 14, ModBlocks.zergStrucFlesh, 0, 3);
		world.setBlock(x + 8, y + 3, z + 14, ModBlocks.zergStrucFlesh, 0, 3);
		world.setBlock(x + 9, y + 3, z + 14, ModBlocks.zergStrucFlesh, 0, 3);
		world.setBlock(x + 10, y + 3, z + 14, ModBlocks.zergStrucFlesh, 0, 3);
		world.setBlock(x + 11, y + 3, z + 14, ModBlocks.zergStrucFlesh, 0, 3);
		world.setBlock(x + 12, y + 3, z + 14, ModBlocks.keratinChunk, 0, 3);
		world.setBlock(x + 13, y + 3, z + 14, ModBlocks.zergStrucFlesh, 0, 3);
		world.setBlock(x + 14, y + 3, z + 14, ModBlocks.zergStrucFlesh, 0, 3);
		world.setBlock(x + 15, y + 3, z + 14, Blocks.air, 0, 3);
		world.setBlock(x + 16, y + 3, z + 14, Blocks.air, 0, 3);
		world.setBlock(x + 17, y + 3, z + 14, Blocks.air, 0, 3);
		world.setBlock(x + 18, y + 3, z + 14, Blocks.air, 0, 3);
		world.setBlock(x + 0, y + 3, z + 15, Blocks.air, 0, 3);
		world.setBlock(x + 1, y + 3, z + 15, Blocks.air, 0, 3);
		world.setBlock(x + 2, y + 3, z + 15, Blocks.air, 0, 3);
		world.setBlock(x + 3, y + 3, z + 15, Blocks.air, 0, 3);
		world.setBlock(x + 4, y + 3, z + 15, Blocks.air, 0, 3);
		world.setBlock(x + 5, y + 3, z + 15, ModBlocks.zergStrucFlesh, 0, 3);
		world.setBlock(x + 6, y + 3, z + 15, ModBlocks.zergStrucFlesh, 0, 3);
		world.setBlock(x + 7, y + 3, z + 15, ModBlocks.zergStrucFlesh, 0, 3);
		world.setBlock(x + 8, y + 3, z + 15, ModBlocks.zergStrucFlesh, 0, 3);
		world.setBlock(x + 9, y + 3, z + 15, ModBlocks.zergStrucFlesh, 0, 3);
		world.setBlock(x + 10, y + 3, z + 15, ModBlocks.zergStrucFlesh, 0, 3);
		world.setBlock(x + 11, y + 3, z + 15, ModBlocks.zergStrucFlesh, 0, 3);
		world.setBlock(x + 12, y + 3, z + 15, ModBlocks.zergStrucFlesh, 0, 3);
		world.setBlock(x + 13, y + 3, z + 15, ModBlocks.zergStrucFlesh, 0, 3);
		world.setBlock(x + 14, y + 3, z + 15, Blocks.air, 0, 3);
		world.setBlock(x + 15, y + 3, z + 15, Blocks.air, 0, 3);
		world.setBlock(x + 16, y + 3, z + 15, Blocks.air, 0, 3);
		world.setBlock(x + 17, y + 3, z + 15, Blocks.air, 0, 3);

		generate_r02(world, rand, x, y, z);
		return true;

	}

	public boolean generate_r02(World world, Random rand, int x, int y, int z) {

		world.setBlock(x + 18, y + 3, z + 15, Blocks.AIR, 0, 3);
		world.setBlock(x + 0, y + 3, z + 16, Blocks.air, 0, 3);
		world.setBlock(x + 1, y + 3, z + 16, Blocks.air, 0, 3);
		world.setBlock(x + 2, y + 3, z + 16, Blocks.air, 0, 3);
		world.setBlock(x + 3, y + 3, z + 16, Blocks.air, 0, 3);
		world.setBlock(x + 4, y + 3, z + 16, Blocks.air, 0, 3);
		world.setBlock(x + 5, y + 3, z + 16, Blocks.air, 0, 3);
		world.setBlock(x + 6, y + 3, z + 16, Blocks.air, 0, 3);
		world.setBlock(x + 7, y + 3, z + 16, Blocks.air, 0, 3);
		world.setBlock(x + 8, y + 3, z + 16, Blocks.air, 0, 3);
		world.setBlock(x + 9, y + 3, z + 16, Blocks.air, 0, 3);
		world.setBlock(x + 10, y + 3, z + 16, Blocks.air, 0, 3);
		world.setBlock(x + 11, y + 3, z + 16, Blocks.air, 0, 3);
		world.setBlock(x + 12, y + 3, z + 16, Blocks.air, 0, 3);
		world.setBlock(x + 13, y + 3, z + 16, Blocks.air, 0, 3);
		world.setBlock(x + 14, y + 3, z + 16, Blocks.air, 0, 3);
		world.setBlock(x + 15, y + 3, z + 16, Blocks.air, 0, 3);
		world.setBlock(x + 16, y + 3, z + 16, Blocks.air, 0, 3);
		world.setBlock(x + 17, y + 3, z + 16, Blocks.air, 0, 3);
		world.setBlock(x + 18, y + 3, z + 16, Blocks.air, 0, 3);
		world.setBlock(x + 0, y + 3, z + 17, Blocks.air, 0, 3);
		world.setBlock(x + 1, y + 3, z + 17, Blocks.air, 0, 3);
		world.setBlock(x + 2, y + 3, z + 17, Blocks.air, 0, 3);
		world.setBlock(x + 3, y + 3, z + 17, Blocks.air, 0, 3);
		world.setBlock(x + 4, y + 3, z + 17, Blocks.air, 0, 3);
		world.setBlock(x + 5, y + 3, z + 17, Blocks.air, 0, 3);
		world.setBlock(x + 6, y + 3, z + 17, Blocks.air, 0, 3);
		world.setBlock(x + 7, y + 3, z + 17, Blocks.air, 0, 3);
		world.setBlock(x + 8, y + 3, z + 17, Blocks.air, 0, 3);
		world.setBlock(x + 9, y + 3, z + 17, Blocks.air, 0, 3);
		world.setBlock(x + 10, y + 3, z + 17, Blocks.air, 0, 3);
		world.setBlock(x + 11, y + 3, z + 17, Blocks.air, 0, 3);
		world.setBlock(x + 12, y + 3, z + 17, Blocks.air, 0, 3);
		world.setBlock(x + 13, y + 3, z + 17, Blocks.air, 0, 3);
		world.setBlock(x + 14, y + 3, z + 17, Blocks.air, 0, 3);
