package net.bvanseghi.starcraft.worldgen.structure;

import java.util.Random;

import net.bvanseghi.starcraft.blocks.ModBlocks;
import net.minecraft.block.Block;
import net.minecraft.block.material.Material;
import net.minecraft.init.Blocks;
import net.minecraft.util.math.BlockPos;
import net.minecraft.world.World;
import net.minecraft.world.gen.feature.WorldGenerator;

public class StructureProtossWarpGateTemplate extends WorldGenerator {
	protected Block[] getValidSpawnBlocks() {
		return new Block[] { ModBlocks.ASH_CHAR, ModBlocks.STONE_CHAR, ModBlocks.ASH_CHAR, Blocks.GRAVEL, ModBlocks.SAND_SHAKURAS, ModBlocks.STONE_SHAKURAS };
	}
	
	public int metaDim;
	public int metaPrimColor;
	public int metaSecColor;
	public Block dimBlock;
	public Block chanBlock;
	public Block stabBlock;

	int x = 0;
	int y = 0;
	int z = 0;

	public boolean LocationIsValidSpawn(World world, BlockPos pos) {
		int distanceToAir = 0;
		Block checkBlock = world.getBlockState(pos).getBlock();

		while (checkBlock != Blocks.AIR) {
			distanceToAir++;
			checkBlock = world.getBlockState(pos.add(x, y + distanceToAir, z)).getBlock();
		}

		if (distanceToAir > 1) {
			return false;
		}

		y += distanceToAir - 1;
		
		Block block = world.getBlockState(pos).getBlock();
		Material m = block.getBlockState().getBaseState().getMaterial();
		Block blockAbove = world.getBlockState(pos.up()).getBlock();
		Block blockBelow = world.getBlockState(pos.down()).getBlock();

		for (Block i : getValidSpawnBlocks()) {
			if (blockAbove != Blocks.AIR) {
				return false;
			}
			if (block == i) {
				return true;
			} else if (block == Blocks.SNOW_LAYER && blockBelow == i) {
				return true;
			} else if (m == Material.PLANTS && blockBelow == i) {
				world.getBlockState(pos).getMaterial();
				return true;
			}
		}
		return false;
	}
	
	public boolean generate(World world, Random rand, BlockPos pos) {
		int i = rand.nextInt(1);

		if (i == 0) {
			generate_r0(world, rand, pos);
		}

		return true;

	}
	
	public boolean generate(int metaDim, int metaPrimColor, int metaSecColor, World world, Random rand, BlockPos pos) {
		this.metaDim = metaDim;
		this.metaPrimColor = metaPrimColor;
		this.metaSecColor = metaSecColor;
		
		if(metaDim == 0) {
			dimBlock = ModBlocks.WARPGATE_WORMHOLE_OVERWORLD;
		}else if(metaDim == 1) {
			dimBlock = ModBlocks.WARPGATE_WORMHOLE_CHAR;
		}else if(metaDim == 2) {
			dimBlock = ModBlocks.WARPGATE_WORMHOLE_SHAKURAS;
		}else {
			dimBlock = ModBlocks.WARPGATE_WORMHOLE_OVERWORLD;
		}
		
		if(metaPrimColor == 1) {
			stabBlock = ModBlocks.PROTOSS_DARK_ENERGY_STABILIZER;
			chanBlock = ModBlocks.PROTOSS_DARK_ENERGY_CHANNEL;
		}else {
			stabBlock = ModBlocks.PROTOSS_ENERGY_STABILIZER;
			chanBlock = ModBlocks.PROTOSS_ENERGY_CHANNEL;
		}
		
		int i = rand.nextInt(1);
		if (i == 0) {
			generate_r0(world, rand, pos);
		}
		return true;

	}

	public boolean generate_r0(World world, Random rand, BlockPos pos) {
		if (!LocationIsValidSpawn(world, pos.add(x, y, z)) || !LocationIsValidSpawn(world, pos.add(x + 14, y, z))
				|| !LocationIsValidSpawn(world, pos.add(x + 14, y, z + 14)) || !LocationIsValidSpawn(world, pos.add(x, y, z + 14))) {
			return false;
		}

		world.setBlockState(pos.add(x, y + 1, z), Blocks.AIR.getDefaultState());
		world.setBlockState(pos.add(x + 1, y + 1, z), Blocks.AIR.getDefaultState());
		world.setBlockState(pos.add(x + 2, y + 1, z), Blocks.AIR.getDefaultState());
		world.setBlockState(pos.add(x + 3, y + 1, z), Blocks.AIR.getDefaultState());
		world.setBlockState(pos.add(x + 4, y + 1, z), Blocks.AIR.getDefaultState());
		world.setBlockState(pos.add(x + 5, y + 1, z), Blocks.AIR.getDefaultState());
		world.setBlockState(pos.add(x + 6, y + 1, z), Blocks.AIR.getDefaultState());
		world.setBlockState(pos.add(x + 7, y + 1, z), Blocks.AIR.getDefaultState());
		world.setBlockState(pos.add(x + 8, y + 1, z), Blocks.AIR.getDefaultState());
		world.setBlockState(pos.add(x + 9, y + 1, z), Blocks.AIR.getDefaultState());
		world.setBlockState(pos.add(x + 10, y + 1, z), Blocks.AIR.getDefaultState());
		world.setBlockState(pos.add(x + 11, y + 1, z), Blocks.AIR.getDefaultState());
		world.setBlockState(pos.add(x + 12, y + 1, z), Blocks.AIR.getDefaultState());
		world.setBlockState(pos.add(x + 13, y + 1, z), Blocks.AIR.getDefaultState());
		world.setBlockState(pos.add(x + 14, y + 1, z), Blocks.AIR.getDefaultState());
		world.setBlockState(pos.add(x, y + 1, z + 1), Blocks.AIR.getDefaultState());
		world.setBlockState(pos.add(x + 1, y + 1, z + 1), ModBlocks.PROTOSS_METAL.getStateFromMeta(metaPrimColor));
		world.setBlockState(pos.add(x + 2, y + 1, z + 1), ModBlocks.PROTOSS_METAL.getStateFromMeta(metaPrimColor));
		world.setBlockState(pos.add(x + 3, y + 1, z + 1), Blocks.AIR.getDefaultState());
		world.setBlockState(pos.add(x + 4, y + 1, z + 1), ModBlocks.PROTOSS_METAL.getStateFromMeta(metaPrimColor));
		world.setBlockState(pos.add(x + 5, y + 1, z + 1), ModBlocks.PROTOSS_METAL.getStateFromMeta(metaPrimColor));
		world.setBlockState(pos.add(x + 6, y + 1, z + 1), Blocks.AIR.getDefaultState());
		world.setBlockState(pos.add(x + 7, y + 1, z + 1), ModBlocks.PROTOSS_METAL.getStateFromMeta(metaPrimColor));
		world.setBlockState(pos.add(x + 8, y + 1, z + 1), ModBlocks.PROTOSS_METAL.getStateFromMeta(metaPrimColor));
		world.setBlockState(pos.add(x + 9, y + 1, z + 1), Blocks.AIR.getDefaultState());
		world.setBlockState(pos.add(x + 10, y + 1, z + 1), ModBlocks.PROTOSS_METAL.getStateFromMeta(metaPrimColor));
		world.setBlockState(pos.add(x + 11, y + 1, z + 1), ModBlocks.PROTOSS_METAL.getStateFromMeta(metaPrimColor));
		world.setBlockState(pos.add(x + 12, y + 1, z + 1), ModBlocks.PROTOSS_METAL.getStateFromMeta(metaPrimColor));
		world.setBlockState(pos.add(x + 13, y + 1, z + 1), ModBlocks.PROTOSS_METAL.getStateFromMeta(metaPrimColor));
		world.setBlockState(pos.add(x + 14, y + 1, z + 1), Blocks.AIR.getDefaultState());
		world.setBlockState(pos.add(x, y + 1, z + 2), Blocks.AIR.getDefaultState());
		world.setBlockState(pos.add(x + 1, y + 1, z + 2), ModBlocks.PROTOSS_METAL.getStateFromMeta(metaPrimColor));
		world.setBlockState(pos.add(x + 2, y + 1, z + 2), ModBlocks.PROTOSS_METAL.getStateFromMeta(metaPrimColor));
		world.setBlockState(pos.add(x + 3, y + 1, z + 2), ModBlocks.PROTOSS_METAL.getStateFromMeta(metaPrimColor));
		world.setBlockState(pos.add(x + 4, y + 1, z + 2), ModBlocks.PROTOSS_METAL.getStateFromMeta(metaPrimColor));
		world.setBlockState(pos.add(x + 5, y + 1, z + 2), ModBlocks.PROTOSS_METAL.getStateFromMeta(metaPrimColor));
		world.setBlockState(pos.add(x + 6, y + 1, z + 2), ModBlocks.PROTOSS_METAL.getStateFromMeta(metaPrimColor));
		world.setBlockState(pos.add(x + 7, y + 1, z + 2), ModBlocks.PROTOSS_METAL.getStateFromMeta(metaPrimColor));
		world.setBlockState(pos.add(x + 8, y + 1, z + 2), ModBlocks.PROTOSS_METAL.getStateFromMeta(metaPrimColor));
		world.setBlockState(pos.add(x + 9, y + 1, z + 2), ModBlocks.PROTOSS_METAL.getStateFromMeta(metaPrimColor));
		world.setBlockState(pos.add(x + 10, y + 1, z + 2), ModBlocks.PROTOSS_METAL.getStateFromMeta(metaPrimColor));
		world.setBlockState(pos.add(x + 11, y + 1, z + 2), ModBlocks.PROTOSS_METAL.getStateFromMeta(metaPrimColor));
		world.setBlockState(pos.add(x + 12, y + 1, z + 2), ModBlocks.PROTOSS_METAL.getStateFromMeta(metaPrimColor));
		world.setBlockState(pos.add(x + 13, y + 1, z + 2), ModBlocks.PROTOSS_METAL.getStateFromMeta(metaPrimColor));
		world.setBlockState(pos.add(x + 14, y + 1, z + 2), Blocks.AIR.getDefaultState());
		world.setBlockState(pos.add(x, y + 1, z + 3), Blocks.AIR.getDefaultState());
		world.setBlockState(pos.add(x + 1, y + 1, z + 3), Blocks.AIR.getDefaultState());
		world.setBlockState(pos.add(x + 2, y + 1, z + 3), ModBlocks.PROTOSS_METAL.getStateFromMeta(metaPrimColor));
		world.setBlockState(pos.add(x + 3, y + 1, z + 3), ModBlocks.PROTOSS_METAL.getStateFromMeta(metaPrimColor));
		world.setBlockState(pos.add(x + 4, y + 1, z + 3), ModBlocks.PROTOSS_METAL.getStateFromMeta(metaPrimColor));
		world.setBlockState(pos.add(x + 5, y + 1, z + 3), ModBlocks.PROTOSS_METAL.getStateFromMeta(metaPrimColor));
		world.setBlockState(pos.add(x + 6, y + 1, z + 3), ModBlocks.PROTOSS_METAL.getStateFromMeta(metaPrimColor));
		world.setBlockState(pos.add(x + 7, y + 1, z + 3), ModBlocks.PROTOSS_METAL.getStateFromMeta(metaPrimColor));
		world.setBlockState(pos.add(x + 8, y + 1, z + 3), ModBlocks.PROTOSS_METAL.getStateFromMeta(metaPrimColor));
		world.setBlockState(pos.add(x + 9, y + 1, z + 3), ModBlocks.PROTOSS_METAL.getStateFromMeta(metaPrimColor));
		world.setBlockState(pos.add(x + 10, y + 1, z + 3), ModBlocks.PROTOSS_METAL.getStateFromMeta(metaPrimColor));
		world.setBlockState(pos.add(x + 11, y + 1, z + 3), ModBlocks.PROTOSS_METAL.getStateFromMeta(metaPrimColor));
		world.setBlockState(pos.add(x + 12, y + 1, z + 3), ModBlocks.PROTOSS_METAL.getStateFromMeta(metaPrimColor));
		world.setBlockState(pos.add(x + 13, y + 1, z + 3), ModBlocks.PROTOSS_METAL.getStateFromMeta(metaPrimColor));
		world.setBlockState(pos.add(x + 14, y + 1, z + 3), Blocks.AIR.getDefaultState());
		world.setBlockState(pos.add(x, y + 1, z + 4), Blocks.AIR.getDefaultState());
		world.setBlockState(pos.add(x + 1, y + 1, z + 4), ModBlocks.PROTOSS_METAL.getStateFromMeta(metaPrimColor));
		world.setBlockState(pos.add(x + 2, y + 1, z + 4), ModBlocks.PROTOSS_METAL.getStateFromMeta(metaPrimColor));
		world.setBlockState(pos.add(x + 3, y + 1, z + 4), ModBlocks.PROTOSS_METAL.getStateFromMeta(metaPrimColor));
		world.setBlockState(pos.add(x + 4, y + 1, z + 4), ModBlocks.PROTOSS_METAL.getStateFromMeta(metaPrimColor));
		world.setBlockState(pos.add(x + 5, y + 1, z + 4), ModBlocks.PROTOSS_METAL.getStateFromMeta(metaPrimColor));
		world.setBlockState(pos.add(x + 6, y + 1, z + 4), ModBlocks.PROTOSS_METAL.getStateFromMeta(metaPrimColor));
		world.setBlockState(pos.add(x + 7, y + 1, z + 4), ModBlocks.PROTOSS_METAL.getStateFromMeta(metaPrimColor));
		world.setBlockState(pos.add(x + 8, y + 1, z + 4), ModBlocks.PROTOSS_METAL.getStateFromMeta(metaPrimColor));
		world.setBlockState(pos.add(x + 9, y + 1, z + 4), ModBlocks.PROTOSS_METAL.getStateFromMeta(metaPrimColor));
		world.setBlockState(pos.add(x + 10, y + 1, z + 4), ModBlocks.PROTOSS_METAL.getStateFromMeta(metaPrimColor));
		world.setBlockState(pos.add(x + 11, y + 1, z + 4), ModBlocks.PROTOSS_METAL.getStateFromMeta(metaPrimColor));
		world.setBlockState(pos.add(x + 12, y + 1, z + 4), ModBlocks.PROTOSS_METAL.getStateFromMeta(metaPrimColor));
		world.setBlockState(pos.add(x + 13, y + 1, z + 4), ModBlocks.PROTOSS_METAL.getStateFromMeta(metaPrimColor));
		world.setBlockState(pos.add(x + 14, y + 1, z + 4), Blocks.AIR.getDefaultState());
		world.setBlockState(pos.add(x, y + 1, z + 5), Blocks.AIR.getDefaultState());
		world.setBlockState(pos.add(x + 1, y + 1, z + 5), ModBlocks.PROTOSS_METAL.getStateFromMeta(metaPrimColor));
		world.setBlockState(pos.add(x + 2, y + 1, z + 5), ModBlocks.PROTOSS_METAL.getStateFromMeta(metaPrimColor));
		world.setBlockState(pos.add(x + 3, y + 1, z + 5), ModBlocks.PROTOSS_METAL.getStateFromMeta(metaPrimColor));
		world.setBlockState(pos.add(x + 4, y + 1, z + 5), ModBlocks.PROTOSS_METAL.getStateFromMeta(metaPrimColor));
		world.setBlockState(pos.add(x + 5, y + 1, z + 5), ModBlocks.PROTOSS_METAL.getStateFromMeta(metaPrimColor));
		world.setBlockState(pos.add(x + 6, y + 1, z + 5), ModBlocks.PROTOSS_METAL.getStateFromMeta(metaPrimColor));
		world.setBlockState(pos.add(x + 7, y + 1, z + 5), ModBlocks.PROTOSS_METAL.getStateFromMeta(metaPrimColor));
		world.setBlockState(pos.add(x + 8, y + 1, z + 5), ModBlocks.PROTOSS_METAL.getStateFromMeta(metaPrimColor));
		world.setBlockState(pos.add(x + 9, y + 1, z + 5), ModBlocks.PROTOSS_METAL.getStateFromMeta(metaPrimColor));
		world.setBlockState(pos.add(x + 10, y + 1, z + 5), ModBlocks.PROTOSS_METAL.getStateFromMeta(metaPrimColor));
		world.setBlockState(pos.add(x + 11, y + 1, z + 5), ModBlocks.PROTOSS_METAL.getStateFromMeta(metaPrimColor));
		world.setBlockState(pos.add(x + 12, y + 1, z + 5), ModBlocks.PROTOSS_METAL.getStateFromMeta(metaPrimColor));
		world.setBlockState(pos.add(x + 13, y + 1, z + 5), Blocks.AIR.getDefaultState());
		world.setBlockState(pos.add(x + 14, y + 1, z + 5), Blocks.AIR.getDefaultState());
		world.setBlockState(pos.add(x, y + 1, z + 6), Blocks.AIR.getDefaultState());
		world.setBlockState(pos.add(x + 1, y + 1, z + 6), Blocks.AIR.getDefaultState());
		world.setBlockState(pos.add(x + 2, y + 1, z + 6), ModBlocks.PROTOSS_METAL.getStateFromMeta(metaPrimColor));
		world.setBlockState(pos.add(x + 3, y + 1, z + 6), ModBlocks.PROTOSS_METAL.getStateFromMeta(metaPrimColor));
		world.setBlockState(pos.add(x + 4, y + 1, z + 6), ModBlocks.PROTOSS_METAL.getStateFromMeta(metaPrimColor));
		world.setBlockState(pos.add(x + 5, y + 1, z + 6), ModBlocks.PROTOSS_METAL.getStateFromMeta(metaPrimColor));
		world.setBlockState(pos.add(x + 6, y + 1, z + 6), ModBlocks.PROTOSS_METAL.getStateFromMeta(metaPrimColor));
		world.setBlockState(pos.add(x + 7, y + 1, z + 6), ModBlocks.PROTOSS_METAL.getStateFromMeta(metaPrimColor));
		world.setBlockState(pos.add(x + 8, y + 1, z + 6), ModBlocks.PROTOSS_METAL.getStateFromMeta(metaPrimColor));
		world.setBlockState(pos.add(x + 9, y + 1, z + 6), ModBlocks.PROTOSS_METAL.getStateFromMeta(metaPrimColor));
		world.setBlockState(pos.add(x + 10, y + 1, z + 6), ModBlocks.PROTOSS_METAL.getStateFromMeta(metaPrimColor));
		world.setBlockState(pos.add(x + 11, y + 1, z + 6), ModBlocks.PROTOSS_METAL.getStateFromMeta(metaPrimColor));
		world.setBlockState(pos.add(x + 12, y + 1, z + 6), ModBlocks.PROTOSS_METAL.getStateFromMeta(metaPrimColor));
		world.setBlockState(pos.add(x + 13, y + 1, z + 6), ModBlocks.PROTOSS_METAL.getStateFromMeta(metaPrimColor));
		world.setBlockState(pos.add(x + 14, y + 1, z + 6), Blocks.AIR.getDefaultState());
		world.setBlockState(pos.add(x, y + 1, z + 7), Blocks.AIR.getDefaultState());
		world.setBlockState(pos.add(x + 1, y + 1, z + 7), ModBlocks.PROTOSS_METAL.getStateFromMeta(metaPrimColor));
		world.setBlockState(pos.add(x + 2, y + 1, z + 7), ModBlocks.PROTOSS_METAL.getStateFromMeta(metaPrimColor));
		world.setBlockState(pos.add(x + 3, y + 1, z + 7), ModBlocks.PROTOSS_METAL.getStateFromMeta(metaPrimColor));
		world.setBlockState(pos.add(x + 4, y + 1, z + 7), ModBlocks.PROTOSS_METAL.getStateFromMeta(metaPrimColor));
		world.setBlockState(pos.add(x + 5, y + 1, z + 7), ModBlocks.PROTOSS_METAL.getStateFromMeta(metaPrimColor));
		world.setBlockState(pos.add(x + 6, y + 1, z + 7), ModBlocks.PROTOSS_METAL.getStateFromMeta(metaPrimColor));
		world.setBlockState(pos.add(x + 7, y + 1, z + 7), ModBlocks.PROTOSS_METAL.getStateFromMeta(metaPrimColor));
		world.setBlockState(pos.add(x + 8, y + 1, z + 7), ModBlocks.PROTOSS_METAL.getStateFromMeta(metaPrimColor));
		world.setBlockState(pos.add(x + 9, y + 1, z + 7), ModBlocks.PROTOSS_METAL.getStateFromMeta(metaPrimColor));
		world.setBlockState(pos.add(x + 10, y + 1, z + 7), ModBlocks.PROTOSS_METAL.getStateFromMeta(metaPrimColor));
		world.setBlockState(pos.add(x + 11, y + 1, z + 7), ModBlocks.PROTOSS_METAL.getStateFromMeta(metaPrimColor));
		world.setBlockState(pos.add(x + 12, y + 1, z + 7), ModBlocks.PROTOSS_METAL.getStateFromMeta(metaPrimColor));
		world.setBlockState(pos.add(x + 13, y + 1, z + 7), ModBlocks.PROTOSS_METAL.getStateFromMeta(metaPrimColor));
		world.setBlockState(pos.add(x + 14, y + 1, z + 7), Blocks.AIR.getDefaultState());
		world.setBlockState(pos.add(x, y + 1, z + 8), Blocks.AIR.getDefaultState());
		world.setBlockState(pos.add(x + 1, y + 1, z + 8), ModBlocks.PROTOSS_METAL.getStateFromMeta(metaPrimColor));
		world.setBlockState(pos.add(x + 2, y + 1, z + 8), ModBlocks.PROTOSS_METAL.getStateFromMeta(metaPrimColor));
		world.setBlockState(pos.add(x + 3, y + 1, z + 8), ModBlocks.PROTOSS_METAL.getStateFromMeta(metaPrimColor));
		world.setBlockState(pos.add(x + 4, y + 1, z + 8), ModBlocks.PROTOSS_METAL.getStateFromMeta(metaPrimColor));
		world.setBlockState(pos.add(x + 5, y + 1, z + 8), ModBlocks.PROTOSS_METAL.getStateFromMeta(metaPrimColor));
		world.setBlockState(pos.add(x + 6, y + 1, z + 8), ModBlocks.PROTOSS_METAL.getStateFromMeta(metaPrimColor));
		world.setBlockState(pos.add(x + 7, y + 1, z + 8), ModBlocks.PROTOSS_METAL.getStateFromMeta(metaPrimColor));
		world.setBlockState(pos.add(x + 8, y + 1, z + 8), ModBlocks.PROTOSS_METAL.getStateFromMeta(metaPrimColor));
		world.setBlockState(pos.add(x + 9, y + 1, z + 8), ModBlocks.PROTOSS_METAL.getStateFromMeta(metaPrimColor));
		world.setBlockState(pos.add(x + 10, y + 1, z + 8), ModBlocks.PROTOSS_METAL.getStateFromMeta(metaPrimColor));
		world.setBlockState(pos.add(x + 11, y + 1, z + 8), ModBlocks.PROTOSS_METAL.getStateFromMeta(metaPrimColor));
		world.setBlockState(pos.add(x + 12, y + 1, z + 8), ModBlocks.PROTOSS_METAL.getStateFromMeta(metaPrimColor));
		world.setBlockState(pos.add(x + 13, y + 1, z + 8), Blocks.AIR.getDefaultState());
		world.setBlockState(pos.add(x + 14, y + 1, z + 8), Blocks.AIR.getDefaultState());
		world.setBlockState(pos.add(x, y + 1, z + 9), Blocks.AIR.getDefaultState());
		world.setBlockState(pos.add(x + 1, y + 1, z + 9), Blocks.AIR.getDefaultState());
		world.setBlockState(pos.add(x + 2, y + 1, z + 9), ModBlocks.PROTOSS_METAL.getStateFromMeta(metaPrimColor));
		world.setBlockState(pos.add(x + 3, y + 1, z + 9), ModBlocks.PROTOSS_METAL.getStateFromMeta(metaPrimColor));
		world.setBlockState(pos.add(x + 4, y + 1, z + 9), ModBlocks.PROTOSS_METAL.getStateFromMeta(metaPrimColor));
		world.setBlockState(pos.add(x + 5, y + 1, z + 9), ModBlocks.PROTOSS_METAL.getStateFromMeta(metaPrimColor));
		world.setBlockState(pos.add(x + 6, y + 1, z + 9), ModBlocks.PROTOSS_METAL.getStateFromMeta(metaPrimColor));
		world.setBlockState(pos.add(x + 7, y + 1, z + 9), ModBlocks.PROTOSS_METAL.getStateFromMeta(metaPrimColor));
		world.setBlockState(pos.add(x + 8, y + 1, z + 9), ModBlocks.PROTOSS_METAL.getStateFromMeta(metaPrimColor));
		world.setBlockState(pos.add(x + 9, y + 1, z + 9), ModBlocks.PROTOSS_METAL.getStateFromMeta(metaPrimColor));
		world.setBlockState(pos.add(x + 10, y + 1, z + 9), ModBlocks.PROTOSS_METAL.getStateFromMeta(metaPrimColor));
		world.setBlockState(pos.add(x + 11, y + 1, z + 9), ModBlocks.PROTOSS_METAL.getStateFromMeta(metaPrimColor));
		world.setBlockState(pos.add(x + 12, y + 1, z + 9), ModBlocks.PROTOSS_METAL.getStateFromMeta(metaPrimColor));
		world.setBlockState(pos.add(x + 13, y + 1, z + 9), ModBlocks.PROTOSS_METAL.getStateFromMeta(metaPrimColor));
		world.setBlockState(pos.add(x + 14, y + 1, z + 9), Blocks.AIR.getDefaultState());
		world.setBlockState(pos.add(x, y + 1, z + 10), Blocks.AIR.getDefaultState());
		world.setBlockState(pos.add(x + 1, y + 1, z + 10), ModBlocks.PROTOSS_METAL.getStateFromMeta(metaPrimColor));
		world.setBlockState(pos.add(x + 2, y + 1, z + 10), ModBlocks.PROTOSS_METAL.getStateFromMeta(metaPrimColor));
		world.setBlockState(pos.add(x + 3, y + 1, z + 10), ModBlocks.PROTOSS_METAL.getStateFromMeta(metaPrimColor));
		world.setBlockState(pos.add(x + 4, y + 1, z + 10), ModBlocks.PROTOSS_METAL.getStateFromMeta(metaPrimColor));
		world.setBlockState(pos.add(x + 5, y + 1, z + 10), ModBlocks.PROTOSS_METAL.getStateFromMeta(metaPrimColor));
		world.setBlockState(pos.add(x + 6, y + 1, z + 10), ModBlocks.PROTOSS_METAL.getStateFromMeta(metaPrimColor));
		world.setBlockState(pos.add(x + 7, y + 1, z + 10), ModBlocks.PROTOSS_METAL.getStateFromMeta(metaPrimColor));
		world.setBlockState(pos.add(x + 8, y + 1, z + 10), ModBlocks.PROTOSS_METAL.getStateFromMeta(metaPrimColor));
		world.setBlockState(pos.add(x + 9, y + 1, z + 10), ModBlocks.PROTOSS_METAL.getStateFromMeta(metaPrimColor));
		world.setBlockState(pos.add(x + 10, y + 1, z + 10), ModBlocks.PROTOSS_METAL.getStateFromMeta(metaPrimColor));
		world.setBlockState(pos.add(x + 11, y + 1, z + 10), ModBlocks.PROTOSS_METAL.getStateFromMeta(metaPrimColor));
		world.setBlockState(pos.add(x + 12, y + 1, z + 10), ModBlocks.PROTOSS_METAL.getStateFromMeta(metaPrimColor));
		world.setBlockState(pos.add(x + 13, y + 1, z + 10), ModBlocks.PROTOSS_METAL.getStateFromMeta(metaPrimColor));
		world.setBlockState(pos.add(x + 14, y + 1, z + 10), Blocks.AIR.getDefaultState());
		world.setBlockState(pos.add(x, y + 1, z + 11), Blocks.AIR.getDefaultState());
		world.setBlockState(pos.add(x + 1, y + 1, z + 11), ModBlocks.PROTOSS_METAL.getStateFromMeta(metaPrimColor));
		world.setBlockState(pos.add(x + 2, y + 1, z + 11), ModBlocks.PROTOSS_METAL.getStateFromMeta(metaPrimColor));
		world.setBlockState(pos.add(x + 3, y + 1, z + 11), ModBlocks.PROTOSS_METAL.getStateFromMeta(metaPrimColor));
		world.setBlockState(pos.add(x + 4, y + 1, z + 11), ModBlocks.PROTOSS_METAL.getStateFromMeta(metaPrimColor));
		world.setBlockState(pos.add(x + 5, y + 1, z + 11), ModBlocks.PROTOSS_METAL.getStateFromMeta(metaPrimColor));
		world.setBlockState(pos.add(x + 6, y + 1, z + 11), ModBlocks.PROTOSS_METAL.getStateFromMeta(metaPrimColor));
		world.setBlockState(pos.add(x + 7, y + 1, z + 11), ModBlocks.PROTOSS_METAL.getStateFromMeta(metaPrimColor));
		world.setBlockState(pos.add(x + 8, y + 1, z + 11), ModBlocks.PROTOSS_METAL.getStateFromMeta(metaPrimColor));
		world.setBlockState(pos.add(x + 9, y + 1, z + 11), ModBlocks.PROTOSS_METAL.getStateFromMeta(metaPrimColor));
		world.setBlockState(pos.add(x + 10, y + 1, z + 11), ModBlocks.PROTOSS_METAL.getStateFromMeta(metaPrimColor));
		world.setBlockState(pos.add(x + 11, y + 1, z + 11), ModBlocks.PROTOSS_METAL.getStateFromMeta(metaPrimColor));
		world.setBlockState(pos.add(x + 12, y + 1, z + 11), ModBlocks.PROTOSS_METAL.getStateFromMeta(metaPrimColor));
		world.setBlockState(pos.add(x + 13, y + 1, z + 11), Blocks.AIR.getDefaultState());
		world.setBlockState(pos.add(x + 14, y + 1, z + 11), Blocks.AIR.getDefaultState());
		world.setBlockState(pos.add(x, y + 1, z + 12), Blocks.AIR.getDefaultState());
		world.setBlockState(pos.add(x + 1, y + 1, z + 12), ModBlocks.PROTOSS_METAL.getStateFromMeta(metaPrimColor));
		world.setBlockState(pos.add(x + 2, y + 1, z + 12), ModBlocks.PROTOSS_METAL.getStateFromMeta(metaPrimColor));
		world.setBlockState(pos.add(x + 3, y + 1, z + 12), ModBlocks.PROTOSS_METAL.getStateFromMeta(metaPrimColor));
		world.setBlockState(pos.add(x + 4, y + 1, z + 12), ModBlocks.PROTOSS_METAL.getStateFromMeta(metaPrimColor));
		world.setBlockState(pos.add(x + 5, y + 1, z + 12), ModBlocks.PROTOSS_METAL.getStateFromMeta(metaPrimColor));
		world.setBlockState(pos.add(x + 6, y + 1, z + 12), ModBlocks.PROTOSS_METAL.getStateFromMeta(metaPrimColor));
		world.setBlockState(pos.add(x + 7, y + 1, z + 12), ModBlocks.PROTOSS_METAL.getStateFromMeta(metaPrimColor));
		world.setBlockState(pos.add(x + 8, y + 1, z + 12), ModBlocks.PROTOSS_METAL.getStateFromMeta(metaPrimColor));
		world.setBlockState(pos.add(x + 9, y + 1, z + 12), ModBlocks.PROTOSS_METAL.getStateFromMeta(metaPrimColor));
		world.setBlockState(pos.add(x + 10, y + 1, z + 12), ModBlocks.PROTOSS_METAL.getStateFromMeta(metaPrimColor));
		world.setBlockState(pos.add(x + 11, y + 1, z + 12), ModBlocks.PROTOSS_METAL.getStateFromMeta(metaPrimColor));
		world.setBlockState(pos.add(x + 12, y + 1, z + 12), ModBlocks.PROTOSS_METAL.getStateFromMeta(metaPrimColor));
		world.setBlockState(pos.add(x + 13, y + 1, z + 12), ModBlocks.PROTOSS_METAL.getStateFromMeta(metaPrimColor));
		world.setBlockState(pos.add(x + 14, y + 1, z + 12), Blocks.AIR.getDefaultState());
		world.setBlockState(pos.add(x, y + 1, z + 13), Blocks.AIR.getDefaultState());
		world.setBlockState(pos.add(x + 1, y + 1, z + 13), ModBlocks.PROTOSS_METAL.getStateFromMeta(metaPrimColor));
		world.setBlockState(pos.add(x + 2, y + 1, z + 13), ModBlocks.PROTOSS_METAL.getStateFromMeta(metaPrimColor));
		world.setBlockState(pos.add(x + 3, y + 1, z + 13), ModBlocks.PROTOSS_METAL.getStateFromMeta(metaPrimColor));
		world.setBlockState(pos.add(x + 4, y + 1, z + 13), ModBlocks.PROTOSS_METAL.getStateFromMeta(metaPrimColor));
		world.setBlockState(pos.add(x + 5, y + 1, z + 13), Blocks.AIR.getDefaultState());
		world.setBlockState(pos.add(x + 6, y + 1, z + 13), ModBlocks.PROTOSS_METAL.getStateFromMeta(metaPrimColor));
		world.setBlockState(pos.add(x + 7, y + 1, z + 13), ModBlocks.PROTOSS_METAL.getStateFromMeta(metaPrimColor));
		world.setBlockState(pos.add(x + 8, y + 1, z + 13), Blocks.AIR.getDefaultState());
		world.setBlockState(pos.add(x + 9, y + 1, z + 13), ModBlocks.PROTOSS_METAL.getStateFromMeta(metaPrimColor));
		world.setBlockState(pos.add(x + 10, y + 1, z + 13), ModBlocks.PROTOSS_METAL.getStateFromMeta(metaPrimColor));
		world.setBlockState(pos.add(x + 11, y + 1, z + 13), Blocks.AIR.getDefaultState());
		world.setBlockState(pos.add(x + 12, y + 1, z + 13), ModBlocks.PROTOSS_METAL.getStateFromMeta(metaPrimColor));
		world.setBlockState(pos.add(x + 13, y + 1, z + 13), ModBlocks.PROTOSS_METAL.getStateFromMeta(metaPrimColor));
		world.setBlockState(pos.add(x + 14, y + 1, z + 13), Blocks.AIR.getDefaultState());
		world.setBlockState(pos.add(x, y + 1, z + 14), Blocks.AIR.getDefaultState());
		world.setBlockState(pos.add(x + 1, y + 1, z + 14), Blocks.AIR.getDefaultState());
		world.setBlockState(pos.add(x + 2, y + 1, z + 14), Blocks.AIR.getDefaultState());
		world.setBlockState(pos.add(x + 3, y + 1, z + 14), Blocks.AIR.getDefaultState());
		world.setBlockState(pos.add(x + 4, y + 1, z + 14), Blocks.AIR.getDefaultState());
		world.setBlockState(pos.add(x + 5, y + 1, z + 14), Blocks.AIR.getDefaultState());
		world.setBlockState(pos.add(x + 6, y + 1, z + 14), Blocks.AIR.getDefaultState());
		world.setBlockState(pos.add(x + 7, y + 1, z + 14), Blocks.AIR.getDefaultState());
		world.setBlockState(pos.add(x + 8, y + 1, z + 14), Blocks.AIR.getDefaultState());
		world.setBlockState(pos.add(x + 9, y + 1, z + 14), Blocks.AIR.getDefaultState());
		world.setBlockState(pos.add(x + 10, y + 1, z + 14), Blocks.AIR.getDefaultState());
		world.setBlockState(pos.add(x + 11, y + 1, z + 14), Blocks.AIR.getDefaultState());
		world.setBlockState(pos.add(x + 12, y + 1, z + 14), Blocks.AIR.getDefaultState());
		world.setBlockState(pos.add(x + 13, y + 1, z + 14), Blocks.AIR.getDefaultState());
		world.setBlockState(pos.add(x + 14, y + 1, z + 14), Blocks.AIR.getDefaultState());
		world.setBlockState(pos.add(x, y + 2, z), Blocks.AIR.getDefaultState());
		world.setBlockState(pos.add(x + 1, y + 2, z), Blocks.AIR.getDefaultState());
		world.setBlockState(pos.add(x + 2, y + 2, z), Blocks.AIR.getDefaultState());
		world.setBlockState(pos.add(x + 3, y + 2, z), Blocks.AIR.getDefaultState());
		world.setBlockState(pos.add(x + 4, y + 2, z), Blocks.AIR.getDefaultState());
		world.setBlockState(pos.add(x + 5, y + 2, z), Blocks.AIR.getDefaultState());
		world.setBlockState(pos.add(x + 6, y + 2, z), Blocks.AIR.getDefaultState());
		world.setBlockState(pos.add(x + 7, y + 2, z), Blocks.AIR.getDefaultState());
		world.setBlockState(pos.add(x + 8, y + 2, z), Blocks.AIR.getDefaultState());
		world.setBlockState(pos.add(x + 9, y + 2, z), Blocks.AIR.getDefaultState());
		world.setBlockState(pos.add(x + 10, y + 2, z), Blocks.AIR.getDefaultState());
		world.setBlockState(pos.add(x + 11, y + 2, z), Blocks.AIR.getDefaultState());
		world.setBlockState(pos.add(x + 12, y + 2, z), Blocks.AIR.getDefaultState());
		world.setBlockState(pos.add(x + 13, y + 2, z), Blocks.AIR.getDefaultState());
		world.setBlockState(pos.add(x + 14, y + 2, z), Blocks.AIR.getDefaultState());
		world.setBlockState(pos.add(x, y + 2, z + 1), Blocks.AIR.getDefaultState());
		world.setBlockState(pos.add(x + 1, y + 2, z + 1), ModBlocks.PROTOSS_METAL.getStateFromMeta(metaPrimColor));
		world.setBlockState(pos.add(x + 2, y + 2, z + 1), ModBlocks.PROTOSS_METAL.getStateFromMeta(metaPrimColor));
		world.setBlockState(pos.add(x + 3, y + 2, z + 1), Blocks.AIR.getDefaultState());
		world.setBlockState(pos.add(x + 4, y + 2, z + 1), ModBlocks.PROTOSS_METAL.getStateFromMeta(metaPrimColor));
		world.setBlockState(pos.add(x + 5, y + 2, z + 1), ModBlocks.PROTOSS_METAL.getStateFromMeta(metaPrimColor));
		world.setBlockState(pos.add(x + 6, y + 2, z + 1), Blocks.AIR.getDefaultState());
		world.setBlockState(pos.add(x + 7, y + 2, z + 1), ModBlocks.PROTOSS_METAL.getStateFromMeta(metaPrimColor));
		world.setBlockState(pos.add(x + 8, y + 2, z + 1), ModBlocks.PROTOSS_METAL.getStateFromMeta(metaPrimColor));
		world.setBlockState(pos.add(x + 9, y + 2, z + 1), Blocks.AIR.getDefaultState());
		world.setBlockState(pos.add(x + 10, y + 2, z + 1), ModBlocks.PROTOSS_METAL.getStateFromMeta(metaPrimColor));
		world.setBlockState(pos.add(x + 11, y + 2, z + 1), ModBlocks.PROTOSS_METAL.getStateFromMeta(metaSecColor));
		world.setBlockState(pos.add(x + 12, y + 2, z + 1), ModBlocks.PROTOSS_METAL.getStateFromMeta(metaSecColor));
		world.setBlockState(pos.add(x + 13, y + 2, z + 1), Blocks.AIR.getDefaultState());
		world.setBlockState(pos.add(x + 14, y + 2, z + 1), Blocks.AIR.getDefaultState());
		world.setBlockState(pos.add(x, y + 2, z + 2), Blocks.AIR.getDefaultState());
		world.setBlockState(pos.add(x + 1, y + 2, z + 2), ModBlocks.PROTOSS_METAL.getStateFromMeta(metaPrimColor));
		world.setBlockState(pos.add(x + 2, y + 2, z + 2), ModBlocks.PROTOSS_METAL.getStateFromMeta(metaPrimColor));
		world.setBlockState(pos.add(x + 3, y + 2, z + 2), ModBlocks.PROTOSS_METAL.getStateFromMeta(metaPrimColor));
		world.setBlockState(pos.add(x + 4, y + 2, z + 2), ModBlocks.PROTOSS_METAL.getStateFromMeta(metaPrimColor));
		world.setBlockState(pos.add(x + 5, y + 2, z + 2), ModBlocks.PROTOSS_METAL.getStateFromMeta(metaPrimColor));
		world.setBlockState(pos.add(x + 6, y + 2, z + 2), ModBlocks.PROTOSS_METAL.getStateFromMeta(metaPrimColor));
		world.setBlockState(pos.add(x + 7, y + 2, z + 2), ModBlocks.PROTOSS_METAL.getStateFromMeta(metaPrimColor));
		world.setBlockState(pos.add(x + 8, y + 2, z + 2), ModBlocks.PROTOSS_METAL.getStateFromMeta(metaPrimColor));
		world.setBlockState(pos.add(x + 9, y + 2, z + 2), ModBlocks.PROTOSS_METAL.getStateFromMeta(metaPrimColor));
		world.setBlockState(pos.add(x + 10, y + 2, z + 2), ModBlocks.PROTOSS_METAL.getStateFromMeta(metaPrimColor));
		world.setBlockState(pos.add(x + 11, y + 2, z + 2), ModBlocks.PROTOSS_METAL.getStateFromMeta(metaPrimColor));
		world.setBlockState(pos.add(x + 12, y + 2, z + 2), ModBlocks.PROTOSS_METAL.getStateFromMeta(metaSecColor));
		world.setBlockState(pos.add(x + 13, y + 2, z + 2), ModBlocks.PROTOSS_METAL.getStateFromMeta(metaSecColor));
		world.setBlockState(pos.add(x + 14, y + 2, z + 2), Blocks.AIR.getDefaultState());
		world.setBlockState(pos.add(x, y + 2, z + 3), Blocks.AIR.getDefaultState());
		world.setBlockState(pos.add(x + 1, y + 2, z + 3), Blocks.AIR.getDefaultState());
		world.setBlockState(pos.add(x + 2, y + 2, z + 3), ModBlocks.PROTOSS_METAL.getStateFromMeta(metaPrimColor));
		world.setBlockState(pos.add(x + 3, y + 2, z + 3), ModBlocks.PROTOSS_METAL.getStateFromMeta(metaPrimColor));
		world.setBlockState(pos.add(x + 4, y + 2, z + 3), ModBlocks.PROTOSS_METAL.getStateFromMeta(metaPrimColor));
		world.setBlockState(pos.add(x + 5, y + 2, z + 3), ModBlocks.PROTOSS_METAL.getStateFromMeta(metaPrimColor));
		world.setBlockState(pos.add(x + 6, y + 2, z + 3), ModBlocks.PROTOSS_METAL.getStateFromMeta(metaPrimColor));
		world.setBlockState(pos.add(x + 7, y + 2, z + 3), ModBlocks.PROTOSS_METAL.getStateFromMeta(metaPrimColor));
		world.setBlockState(pos.add(x + 8, y + 2, z + 3), ModBlocks.PROTOSS_METAL.getStateFromMeta(metaPrimColor));
		world.setBlockState(pos.add(x + 9, y + 2, z + 3), ModBlocks.PROTOSS_METAL.getStateFromMeta(metaPrimColor));
		world.setBlockState(pos.add(x + 10, y + 2, z + 3), ModBlocks.PROTOSS_METAL.getStateFromMeta(metaPrimColor));
		world.setBlockState(pos.add(x + 11, y + 2, z + 3), ModBlocks.PROTOSS_METAL.getStateFromMeta(metaPrimColor));
		world.setBlockState(pos.add(x + 12, y + 2, z + 3), ModBlocks.PROTOSS_METAL.getStateFromMeta(metaPrimColor));
		world.setBlockState(pos.add(x + 13, y + 2, z + 3), ModBlocks.PROTOSS_METAL.getStateFromMeta(metaSecColor));
		world.setBlockState(pos.add(x + 14, y + 2, z + 3), Blocks.AIR.getDefaultState());
		world.setBlockState(pos.add(x, y + 2, z + 4), Blocks.AIR.getDefaultState());
		world.setBlockState(pos.add(x + 1, y + 2, z + 4), ModBlocks.PROTOSS_METAL.getStateFromMeta(metaPrimColor));
		world.setBlockState(pos.add(x + 2, y + 2, z + 4), ModBlocks.PROTOSS_METAL.getStateFromMeta(metaPrimColor));
		world.setBlockState(pos.add(x + 3, y + 2, z + 4), ModBlocks.PROTOSS_METAL.getStateFromMeta(metaPrimColor));
		world.setBlockState(pos.add(x + 4, y + 2, z + 4), ModBlocks.PROTOSS_METAL.getStateFromMeta(metaPrimColor));
		world.setBlockState(pos.add(x + 5, y + 2, z + 4), ModBlocks.PROTOSS_METAL.getStateFromMeta(metaPrimColor));
		world.setBlockState(pos.add(x + 6, y + 2, z + 4), ModBlocks.PROTOSS_METAL.getStateFromMeta(metaPrimColor));
		world.setBlockState(pos.add(x + 7, y + 2, z + 4), ModBlocks.PROTOSS_METAL.getStateFromMeta(metaPrimColor));
		world.setBlockState(pos.add(x + 8, y + 2, z + 4), ModBlocks.PROTOSS_METAL.getStateFromMeta(metaPrimColor));
		world.setBlockState(pos.add(x + 9, y + 2, z + 4), ModBlocks.PROTOSS_METAL.getStateFromMeta(metaPrimColor));
		world.setBlockState(pos.add(x + 10, y + 2, z + 4), ModBlocks.PROTOSS_METAL.getStateFromMeta(metaPrimColor));
		world.setBlockState(pos.add(x + 11, y + 2, z + 4), ModBlocks.PROTOSS_METAL.getStateFromMeta(metaPrimColor));
		world.setBlockState(pos.add(x + 12, y + 2, z + 4), ModBlocks.PROTOSS_METAL.getStateFromMeta(metaPrimColor));
		world.setBlockState(pos.add(x + 13, y + 2, z + 4), ModBlocks.PROTOSS_METAL.getStateFromMeta(metaPrimColor));
		world.setBlockState(pos.add(x + 14, y + 2, z + 4), Blocks.AIR.getDefaultState());
		world.setBlockState(pos.add(x, y + 2, z + 5), Blocks.AIR.getDefaultState());
		world.setBlockState(pos.add(x + 1, y + 2, z + 5), ModBlocks.PROTOSS_METAL.getStateFromMeta(metaPrimColor));
		world.setBlockState(pos.add(x + 2, y + 2, z + 5), ModBlocks.PROTOSS_METAL.getStateFromMeta(metaPrimColor));
		world.setBlockState(pos.add(x + 3, y + 2, z + 5), ModBlocks.PROTOSS_METAL.getStateFromMeta(metaPrimColor));
		world.setBlockState(pos.add(x + 4, y + 2, z + 5), ModBlocks.PROTOSS_METAL.getStateFromMeta(metaPrimColor));
		world.setBlockState(pos.add(x + 5, y + 2, z + 5), ModBlocks.PROTOSS_METAL.getStateFromMeta(metaPrimColor));
		world.setBlockState(pos.add(x + 6, y + 2, z + 5), ModBlocks.PROTOSS_METAL.getStateFromMeta(metaPrimColor));
		world.setBlockState(pos.add(x + 7, y + 2, z + 5), ModBlocks.PROTOSS_METAL.getStateFromMeta(metaPrimColor));
		world.setBlockState(pos.add(x + 8, y + 2, z + 5), ModBlocks.PROTOSS_METAL.getStateFromMeta(metaPrimColor));
		world.setBlockState(pos.add(x + 9, y + 2, z + 5), ModBlocks.PROTOSS_METAL.getStateFromMeta(metaPrimColor));
		world.setBlockState(pos.add(x + 10, y + 2, z + 5), ModBlocks.PROTOSS_METAL.getStateFromMeta(metaPrimColor));
		world.setBlockState(pos.add(x + 11, y + 2, z + 5), ModBlocks.PROTOSS_METAL.getStateFromMeta(metaPrimColor));
		world.setBlockState(pos.add(x + 12, y + 2, z + 5), ModBlocks.PROTOSS_METAL.getStateFromMeta(metaPrimColor));
		world.setBlockState(pos.add(x + 13, y + 2, z + 5), Blocks.AIR.getDefaultState());
		world.setBlockState(pos.add(x + 14, y + 2, z + 5), Blocks.AIR.getDefaultState());
		world.setBlockState(pos.add(x, y + 2, z + 6), Blocks.AIR.getDefaultState());
		world.setBlockState(pos.add(x + 1, y + 2, z + 6), Blocks.AIR.getDefaultState());
		world.setBlockState(pos.add(x + 2, y + 2, z + 6), ModBlocks.PROTOSS_METAL.getStateFromMeta(metaPrimColor));
		world.setBlockState(pos.add(x + 3, y + 2, z + 6), ModBlocks.PROTOSS_METAL.getStateFromMeta(metaPrimColor));
		world.setBlockState(pos.add(x + 4, y + 2, z + 6), ModBlocks.PROTOSS_METAL.getStateFromMeta(metaPrimColor));
		world.setBlockState(pos.add(x + 5, y + 2, z + 6), ModBlocks.PROTOSS_METAL.getStateFromMeta(metaPrimColor));
		world.setBlockState(pos.add(x + 6, y + 2, z + 6), ModBlocks.PROTOSS_METAL.getStateFromMeta(metaPrimColor));
		world.setBlockState(pos.add(x + 7, y + 2, z + 6), ModBlocks.PROTOSS_METAL.getStateFromMeta(metaPrimColor));
		world.setBlockState(pos.add(x + 8, y + 2, z + 6), ModBlocks.PROTOSS_METAL.getStateFromMeta(metaPrimColor));
		world.setBlockState(pos.add(x + 9, y + 2, z + 6), ModBlocks.PROTOSS_METAL.getStateFromMeta(metaPrimColor));
		world.setBlockState(pos.add(x + 10, y + 2, z + 6), ModBlocks.PROTOSS_METAL.getStateFromMeta(metaPrimColor));
		world.setBlockState(pos.add(x + 11, y + 2, z + 6), ModBlocks.PROTOSS_METAL.getStateFromMeta(metaPrimColor));
		world.setBlockState(pos.add(x + 12, y + 2, z + 6), ModBlocks.PROTOSS_METAL.getStateFromMeta(metaPrimColor));
		world.setBlockState(pos.add(x + 13, y + 2, z + 6), ModBlocks.PROTOSS_METAL.getStateFromMeta(metaPrimColor));
		world.setBlockState(pos.add(x + 14, y + 2, z + 6), Blocks.AIR.getDefaultState());
		world.setBlockState(pos.add(x, y + 2, z + 7), Blocks.AIR.getDefaultState());
		world.setBlockState(pos.add(x + 1, y + 2, z + 7), ModBlocks.PROTOSS_METAL.getStateFromMeta(metaPrimColor));
		world.setBlockState(pos.add(x + 2, y + 2, z + 7), ModBlocks.PROTOSS_METAL.getStateFromMeta(metaPrimColor));
		world.setBlockState(pos.add(x + 3, y + 2, z + 7), ModBlocks.PROTOSS_METAL.getStateFromMeta(metaPrimColor));
		world.setBlockState(pos.add(x + 4, y + 2, z + 7), ModBlocks.PROTOSS_METAL.getStateFromMeta(metaPrimColor));
		world.setBlockState(pos.add(x + 5, y + 2, z + 7), ModBlocks.PROTOSS_METAL.getStateFromMeta(metaPrimColor));
		world.setBlockState(pos.add(x + 6, y + 2, z + 7), ModBlocks.PROTOSS_METAL.getStateFromMeta(metaPrimColor));
		world.setBlockState(pos.add(x + 7, y + 2, z + 7), ModBlocks.PROTOSS_METAL.getStateFromMeta(metaPrimColor));
		world.setBlockState(pos.add(x + 8, y + 2, z + 7), ModBlocks.PROTOSS_METAL.getStateFromMeta(metaPrimColor));
		world.setBlockState(pos.add(x + 9, y + 2, z + 7), ModBlocks.PROTOSS_METAL.getStateFromMeta(metaPrimColor));
		world.setBlockState(pos.add(x + 10, y + 2, z + 7), ModBlocks.PROTOSS_METAL.getStateFromMeta(metaPrimColor));
		world.setBlockState(pos.add(x + 11, y + 2, z + 7), ModBlocks.PROTOSS_METAL.getStateFromMeta(metaPrimColor));
		world.setBlockState(pos.add(x + 12, y + 2, z + 7), ModBlocks.PROTOSS_METAL.getStateFromMeta(metaPrimColor));
		world.setBlockState(pos.add(x + 13, y + 2, z + 7), ModBlocks.PROTOSS_METAL.getStateFromMeta(metaPrimColor));
		world.setBlockState(pos.add(x + 14, y + 2, z + 7), Blocks.AIR.getDefaultState());
		world.setBlockState(pos.add(x, y + 2, z + 8), Blocks.AIR.getDefaultState());
		world.setBlockState(pos.add(x + 1, y + 2, z + 8), ModBlocks.PROTOSS_METAL.getStateFromMeta(metaPrimColor));
		world.setBlockState(pos.add(x + 2, y + 2, z + 8), ModBlocks.PROTOSS_METAL.getStateFromMeta(metaPrimColor));
		world.setBlockState(pos.add(x + 3, y + 2, z + 8), ModBlocks.PROTOSS_METAL.getStateFromMeta(metaPrimColor));
		world.setBlockState(pos.add(x + 4, y + 2, z + 8), ModBlocks.PROTOSS_METAL.getStateFromMeta(metaPrimColor));
		world.setBlockState(pos.add(x + 5, y + 2, z + 8), ModBlocks.PROTOSS_METAL.getStateFromMeta(metaPrimColor));
		world.setBlockState(pos.add(x + 6, y + 2, z + 8), ModBlocks.PROTOSS_METAL.getStateFromMeta(metaPrimColor));
		world.setBlockState(pos.add(x + 7, y + 2, z + 8), ModBlocks.PROTOSS_METAL.getStateFromMeta(metaPrimColor));
		world.setBlockState(pos.add(x + 8, y + 2, z + 8), ModBlocks.PROTOSS_METAL.getStateFromMeta(metaPrimColor));
		world.setBlockState(pos.add(x + 9, y + 2, z + 8), ModBlocks.PROTOSS_METAL.getStateFromMeta(metaPrimColor));
		world.setBlockState(pos.add(x + 10, y + 2, z + 8), ModBlocks.PROTOSS_METAL.getStateFromMeta(metaPrimColor));
		world.setBlockState(pos.add(x + 11, y + 2, z + 8), ModBlocks.PROTOSS_METAL.getStateFromMeta(metaPrimColor));
		world.setBlockState(pos.add(x + 12, y + 2, z + 8), ModBlocks.PROTOSS_METAL.getStateFromMeta(metaPrimColor));
		world.setBlockState(pos.add(x + 13, y + 2, z + 8), Blocks.AIR.getDefaultState());
		world.setBlockState(pos.add(x + 14, y + 2, z + 8), Blocks.AIR.getDefaultState());
		world.setBlockState(pos.add(x, y + 2, z + 9), Blocks.AIR.getDefaultState());
		world.setBlockState(pos.add(x + 1, y + 2, z + 9), Blocks.AIR.getDefaultState());
		world.setBlockState(pos.add(x + 2, y + 2, z + 9), ModBlocks.PROTOSS_METAL.getStateFromMeta(metaPrimColor));
		world.setBlockState(pos.add(x + 3, y + 2, z + 9), ModBlocks.PROTOSS_METAL.getStateFromMeta(metaPrimColor));
		world.setBlockState(pos.add(x + 4, y + 2, z + 9), ModBlocks.PROTOSS_METAL.getStateFromMeta(metaPrimColor));
		world.setBlockState(pos.add(x + 5, y + 2, z + 9), ModBlocks.PROTOSS_METAL.getStateFromMeta(metaPrimColor));
		world.setBlockState(pos.add(x + 6, y + 2, z + 9), ModBlocks.PROTOSS_METAL.getStateFromMeta(metaPrimColor));
		world.setBlockState(pos.add(x + 7, y + 2, z + 9), ModBlocks.PROTOSS_METAL.getStateFromMeta(metaPrimColor));
		world.setBlockState(pos.add(x + 8, y + 2, z + 9), ModBlocks.PROTOSS_METAL.getStateFromMeta(metaPrimColor));
		world.setBlockState(pos.add(x + 9, y + 2, z + 9), ModBlocks.PROTOSS_METAL.getStateFromMeta(metaPrimColor));
		world.setBlockState(pos.add(x + 10, y + 2, z + 9), ModBlocks.PROTOSS_METAL.getStateFromMeta(metaPrimColor));
		world.setBlockState(pos.add(x + 11, y + 2, z + 9), ModBlocks.PROTOSS_METAL.getStateFromMeta(metaPrimColor));
		world.setBlockState(pos.add(x + 12, y + 2, z + 9), ModBlocks.PROTOSS_METAL.getStateFromMeta(metaPrimColor));
		world.setBlockState(pos.add(x + 13, y + 2, z + 9), ModBlocks.PROTOSS_METAL.getStateFromMeta(metaPrimColor));
		world.setBlockState(pos.add(x + 14, y + 2, z + 9), Blocks.AIR.getDefaultState());
		world.setBlockState(pos.add(x, y + 2, z + 10), Blocks.AIR.getDefaultState());
		world.setBlockState(pos.add(x + 1, y + 2, z + 10), ModBlocks.PROTOSS_METAL.getStateFromMeta(metaPrimColor));
		world.setBlockState(pos.add(x + 2, y + 2, z + 10), ModBlocks.PROTOSS_METAL.getStateFromMeta(metaPrimColor));
		world.setBlockState(pos.add(x + 3, y + 2, z + 10), ModBlocks.PROTOSS_METAL.getStateFromMeta(metaPrimColor));
		world.setBlockState(pos.add(x + 4, y + 2, z + 10), ModBlocks.PROTOSS_METAL.getStateFromMeta(metaPrimColor));
		world.setBlockState(pos.add(x + 5, y + 2, z + 10), ModBlocks.PROTOSS_METAL.getStateFromMeta(metaPrimColor));
		world.setBlockState(pos.add(x + 6, y + 2, z + 10), ModBlocks.PROTOSS_METAL.getStateFromMeta(metaPrimColor));
		world.setBlockState(pos.add(x + 7, y + 2, z + 10), ModBlocks.PROTOSS_METAL.getStateFromMeta(metaPrimColor));
		world.setBlockState(pos.add(x + 8, y + 2, z + 10), ModBlocks.PROTOSS_METAL.getStateFromMeta(metaPrimColor));
		world.setBlockState(pos.add(x + 9, y + 2, z + 10), ModBlocks.PROTOSS_METAL.getStateFromMeta(metaPrimColor));
		world.setBlockState(pos.add(x + 10, y + 2, z + 10), ModBlocks.PROTOSS_METAL.getStateFromMeta(metaPrimColor));
		world.setBlockState(pos.add(x + 11, y + 2, z + 10), ModBlocks.PROTOSS_METAL.getStateFromMeta(metaPrimColor));
		world.setBlockState(pos.add(x + 12, y + 2, z + 10), ModBlocks.PROTOSS_METAL.getStateFromMeta(metaPrimColor));
		world.setBlockState(pos.add(x + 13, y + 2, z + 10), ModBlocks.PROTOSS_METAL.getStateFromMeta(metaPrimColor));
		world.setBlockState(pos.add(x + 14, y + 2, z + 10), Blocks.AIR.getDefaultState());
		world.setBlockState(pos.add(x, y + 2, z + 11), Blocks.AIR.getDefaultState());
		world.setBlockState(pos.add(x + 1, y + 2, z + 11), ModBlocks.PROTOSS_METAL.getStateFromMeta(metaSecColor));
		world.setBlockState(pos.add(x + 2, y + 2, z + 11), ModBlocks.PROTOSS_METAL.getStateFromMeta(metaPrimColor));
		world.setBlockState(pos.add(x + 3, y + 2, z + 11), ModBlocks.PROTOSS_METAL.getStateFromMeta(metaPrimColor));
		world.setBlockState(pos.add(x + 4, y + 2, z + 11), ModBlocks.PROTOSS_METAL.getStateFromMeta(metaPrimColor));
		world.setBlockState(pos.add(x + 5, y + 2, z + 11), ModBlocks.PROTOSS_METAL.getStateFromMeta(metaPrimColor));
		world.setBlockState(pos.add(x + 6, y + 2, z + 11), ModBlocks.PROTOSS_METAL.getStateFromMeta(metaPrimColor));
		world.setBlockState(pos.add(x + 7, y + 2, z + 11), ModBlocks.PROTOSS_METAL.getStateFromMeta(metaPrimColor));
		world.setBlockState(pos.add(x + 8, y + 2, z + 11), ModBlocks.PROTOSS_METAL.getStateFromMeta(metaPrimColor));
		world.setBlockState(pos.add(x + 9, y + 2, z + 11), ModBlocks.PROTOSS_METAL.getStateFromMeta(metaPrimColor));
		world.setBlockState(pos.add(x + 10, y + 2, z + 11), ModBlocks.PROTOSS_METAL.getStateFromMeta(metaPrimColor));
		world.setBlockState(pos.add(x + 11, y + 2, z + 11), ModBlocks.PROTOSS_METAL.getStateFromMeta(metaPrimColor));
		world.setBlockState(pos.add(x + 12, y + 2, z + 11), ModBlocks.PROTOSS_METAL.getStateFromMeta(metaPrimColor));
		world.setBlockState(pos.add(x + 13, y + 2, z + 11), Blocks.AIR.getDefaultState());
		world.setBlockState(pos.add(x + 14, y + 2, z + 11), Blocks.AIR.getDefaultState());
		world.setBlockState(pos.add(x, y + 2, z + 12), Blocks.AIR.getDefaultState());
		world.setBlockState(pos.add(x + 1, y + 2, z + 12), ModBlocks.PROTOSS_METAL.getStateFromMeta(metaSecColor));
		world.setBlockState(pos.add(x + 2, y + 2, z + 12), ModBlocks.PROTOSS_METAL.getStateFromMeta(metaSecColor));
		world.setBlockState(pos.add(x + 3, y + 2, z + 12), ModBlocks.PROTOSS_METAL.getStateFromMeta(metaPrimColor));
		world.setBlockState(pos.add(x + 4, y + 2, z + 12), ModBlocks.PROTOSS_METAL.getStateFromMeta(metaPrimColor));
		world.setBlockState(pos.add(x + 5, y + 2, z + 12), ModBlocks.PROTOSS_METAL.getStateFromMeta(metaPrimColor));
		world.setBlockState(pos.add(x + 6, y + 2, z + 12), ModBlocks.PROTOSS_METAL.getStateFromMeta(metaPrimColor));
		world.setBlockState(pos.add(x + 7, y + 2, z + 12), ModBlocks.PROTOSS_METAL.getStateFromMeta(metaPrimColor));
		world.setBlockState(pos.add(x + 8, y + 2, z + 12), ModBlocks.PROTOSS_METAL.getStateFromMeta(metaPrimColor));
		world.setBlockState(pos.add(x + 9, y + 2, z + 12), ModBlocks.PROTOSS_METAL.getStateFromMeta(metaPrimColor));
		world.setBlockState(pos.add(x + 10, y + 2, z + 12), ModBlocks.PROTOSS_METAL.getStateFromMeta(metaPrimColor));
		world.setBlockState(pos.add(x + 11, y + 2, z + 12), ModBlocks.PROTOSS_METAL.getStateFromMeta(metaPrimColor));
		world.setBlockState(pos.add(x + 12, y + 2, z + 12), ModBlocks.PROTOSS_METAL.getStateFromMeta(metaPrimColor));
		world.setBlockState(pos.add(x + 13, y + 2, z + 12), ModBlocks.PROTOSS_METAL.getStateFromMeta(metaPrimColor));
		world.setBlockState(pos.add(x + 14, y + 2, z + 12), Blocks.AIR.getDefaultState());
		world.setBlockState(pos.add(x, y + 2, z + 13), Blocks.AIR.getDefaultState());
		world.setBlockState(pos.add(x + 1, y + 2, z + 13), Blocks.AIR.getDefaultState());
		world.setBlockState(pos.add(x + 2, y + 2, z + 13), ModBlocks.PROTOSS_METAL.getStateFromMeta(metaSecColor));
		world.setBlockState(pos.add(x + 3, y + 2, z + 13), ModBlocks.PROTOSS_METAL.getStateFromMeta(metaSecColor));
		world.setBlockState(pos.add(x + 4, y + 2, z + 13), ModBlocks.PROTOSS_METAL.getStateFromMeta(metaPrimColor));
		world.setBlockState(pos.add(x + 5, y + 2, z + 13), Blocks.AIR.getDefaultState());
		world.setBlockState(pos.add(x + 6, y + 2, z + 13), ModBlocks.PROTOSS_METAL.getStateFromMeta(metaPrimColor));
		world.setBlockState(pos.add(x + 7, y + 2, z + 13), ModBlocks.PROTOSS_METAL.getStateFromMeta(metaPrimColor));
		world.setBlockState(pos.add(x + 8, y + 2, z + 13), Blocks.AIR.getDefaultState());
		world.setBlockState(pos.add(x + 9, y + 2, z + 13), ModBlocks.PROTOSS_METAL.getStateFromMeta(metaPrimColor));
		world.setBlockState(pos.add(x + 10, y + 2, z + 13), ModBlocks.PROTOSS_METAL.getStateFromMeta(metaPrimColor));
		world.setBlockState(pos.add(x + 11, y + 2, z + 13), Blocks.AIR.getDefaultState());
		world.setBlockState(pos.add(x + 12, y + 2, z + 13), ModBlocks.PROTOSS_METAL.getStateFromMeta(metaPrimColor));
		world.setBlockState(pos.add(x + 13, y + 2, z + 13), ModBlocks.PROTOSS_METAL.getStateFromMeta(metaPrimColor));
		world.setBlockState(pos.add(x + 14, y + 2, z + 13), Blocks.AIR.getDefaultState());
		world.setBlockState(pos.add(x, y + 2, z + 14), Blocks.AIR.getDefaultState());
		world.setBlockState(pos.add(x + 1, y + 2, z + 14), Blocks.AIR.getDefaultState());
		world.setBlockState(pos.add(x + 2, y + 2, z + 14), Blocks.AIR.getDefaultState());
		world.setBlockState(pos.add(x + 3, y + 2, z + 14), Blocks.AIR.getDefaultState());
		world.setBlockState(pos.add(x + 4, y + 2, z + 14), Blocks.AIR.getDefaultState());
		world.setBlockState(pos.add(x + 5, y + 2, z + 14), Blocks.AIR.getDefaultState());
		world.setBlockState(pos.add(x + 6, y + 2, z + 14), Blocks.AIR.getDefaultState());
		world.setBlockState(pos.add(x + 7, y + 2, z + 14), Blocks.AIR.getDefaultState());
		world.setBlockState(pos.add(x + 8, y + 2, z + 14), Blocks.AIR.getDefaultState());
		world.setBlockState(pos.add(x + 9, y + 2, z + 14), Blocks.AIR.getDefaultState());
		world.setBlockState(pos.add(x + 10, y + 2, z + 14), Blocks.AIR.getDefaultState());
		world.setBlockState(pos.add(x + 11, y + 2, z + 14), Blocks.AIR.getDefaultState());
		world.setBlockState(pos.add(x + 12, y + 2, z + 14), Blocks.AIR.getDefaultState());
		world.setBlockState(pos.add(x + 13, y + 2, z + 14), Blocks.AIR.getDefaultState());
		world.setBlockState(pos.add(x + 14, y + 2, z + 14), Blocks.AIR.getDefaultState());
		world.setBlockState(pos.add(x, y + 3, z), ModBlocks.PROTOSS_METAL.getStateFromMeta(metaPrimColor));
		world.setBlockState(pos.add(x + 1, y + 3, z), ModBlocks.PROTOSS_METAL.getStateFromMeta(metaPrimColor));
		world.setBlockState(pos.add(x + 2, y + 3, z), Blocks.AIR.getDefaultState());
		world.setBlockState(pos.add(x + 3, y + 3, z), Blocks.AIR.getDefaultState());
		world.setBlockState(pos.add(x + 4, y + 3, z), Blocks.AIR.getDefaultState());
		world.setBlockState(pos.add(x + 5, y + 3, z), Blocks.AIR.getDefaultState());
		world.setBlockState(pos.add(x + 6, y + 3, z), Blocks.AIR.getDefaultState());
		world.setBlockState(pos.add(x + 7, y + 3, z), Blocks.AIR.getDefaultState());
		world.setBlockState(pos.add(x + 8, y + 3, z), Blocks.AIR.getDefaultState());
		world.setBlockState(pos.add(x + 9, y + 3, z), Blocks.AIR.getDefaultState());
		world.setBlockState(pos.add(x + 10, y + 3, z), Blocks.AIR.getDefaultState());
		world.setBlockState(pos.add(x + 11, y + 3, z), Blocks.AIR.getDefaultState());
		world.setBlockState(pos.add(x + 12, y + 3, z), Blocks.AIR.getDefaultState());
		world.setBlockState(pos.add(x + 13, y + 3, z), Blocks.AIR.getDefaultState());
		world.setBlockState(pos.add(x + 14, y + 3, z), Blocks.AIR.getDefaultState());
		world.setBlockState(pos.add(x, y + 3, z + 1), ModBlocks.PROTOSS_METAL.getStateFromMeta(metaPrimColor));
		world.setBlockState(pos.add(x + 1, y + 3, z + 1), ModBlocks.PROTOSS_METAL.getStateFromMeta(metaSecColor));
		world.setBlockState(pos.add(x + 2, y + 3, z + 1), ModBlocks.PROTOSS_METAL.getStateFromMeta(metaPrimColor));
		world.setBlockState(pos.add(x + 3, y + 3, z + 1), Blocks.AIR.getDefaultState());
		world.setBlockState(pos.add(x + 4, y + 3, z + 1), Blocks.AIR.getDefaultState());
		world.setBlockState(pos.add(x + 5, y + 3, z + 1), Blocks.AIR.getDefaultState());
		world.setBlockState(pos.add(x + 6, y + 3, z + 1), Blocks.AIR.getDefaultState());
		world.setBlockState(pos.add(x + 7, y + 3, z + 1), Blocks.AIR.getDefaultState());
		world.setBlockState(pos.add(x + 8, y + 3, z + 1), Blocks.AIR.getDefaultState());
		world.setBlockState(pos.add(x + 9, y + 3, z + 1), Blocks.AIR.getDefaultState());
		world.setBlockState(pos.add(x + 10, y + 3, z + 1), ModBlocks.PROTOSS_METAL.getStateFromMeta(metaSecColor));
		world.setBlockState(pos.add(x + 11, y + 3, z + 1), Blocks.AIR.getDefaultState());
		world.setBlockState(pos.add(x + 12, y + 3, z + 1), Blocks.AIR.getDefaultState());
		world.setBlockState(pos.add(x + 13, y + 3, z + 1), Blocks.AIR.getDefaultState());
		world.setBlockState(pos.add(x + 14, y + 3, z + 1), Blocks.AIR.getDefaultState());
		world.setBlockState(pos.add(x, y + 3, z + 2), Blocks.AIR.getDefaultState());
		world.setBlockState(pos.add(x + 1, y + 3, z + 2), ModBlocks.PROTOSS_METAL.getStateFromMeta(metaPrimColor));
		world.setBlockState(pos.add(x + 2, y + 3, z + 2), ModBlocks.PROTOSS_METAL.getStateFromMeta(metaPrimColor));
		world.setBlockState(pos.add(x + 3, y + 3, z + 2), ModBlocks.PROTOSS_METAL.getStateFromMeta(metaPrimColor));
		world.setBlockState(pos.add(x + 4, y + 3, z + 2), ModBlocks.PROTOSS_METAL.getStateFromMeta(metaPrimColor));
		world.setBlockState(pos.add(x + 5, y + 3, z + 2), ModBlocks.PROTOSS_METAL.getStateFromMeta(metaPrimColor));
		world.setBlockState(pos.add(x + 6, y + 3, z + 2), ModBlocks.PROTOSS_METAL.getStateFromMeta(metaPrimColor));
		world.setBlockState(pos.add(x + 7, y + 3, z + 2), ModBlocks.PROTOSS_METAL.getStateFromMeta(metaPrimColor));
		world.setBlockState(pos.add(x + 8, y + 3, z + 2), ModBlocks.PROTOSS_METAL.getStateFromMeta(metaPrimColor));
		world.setBlockState(pos.add(x + 9, y + 3, z + 2), ModBlocks.PROTOSS_METAL.getStateFromMeta(metaPrimColor));
		world.setBlockState(pos.add(x + 10, y + 3, z + 2), ModBlocks.PROTOSS_METAL.getStateFromMeta(metaPrimColor));
		world.setBlockState(pos.add(x + 11, y + 3, z + 2), ModBlocks.PROTOSS_METAL.getStateFromMeta(metaPrimColor));
		world.setBlockState(pos.add(x + 12, y + 3, z + 2), Blocks.AIR.getDefaultState());
		world.setBlockState(pos.add(x + 13, y + 3, z + 2), Blocks.AIR.getDefaultState());
		world.setBlockState(pos.add(x + 14, y + 3, z + 2), Blocks.AIR.getDefaultState());
		world.setBlockState(pos.add(x, y + 3, z + 3), Blocks.AIR.getDefaultState());
		world.setBlockState(pos.add(x + 1, y + 3, z + 3), Blocks.AIR.getDefaultState());
		world.setBlockState(pos.add(x + 2, y + 3, z + 3), ModBlocks.PROTOSS_METAL.getStateFromMeta(metaPrimColor));
		world.setBlockState(pos.add(x + 3, y + 3, z + 3), ModBlocks.PROTOSS_METAL.getStateFromMeta(metaPrimColor));
		world.setBlockState(pos.add(x + 4, y + 3, z + 3), ModBlocks.PROTOSS_METAL.getStateFromMeta(metaPrimColor));
		world.setBlockState(pos.add(x + 5, y + 3, z + 3), ModBlocks.PROTOSS_METAL.getStateFromMeta(metaPrimColor));
		world.setBlockState(pos.add(x + 6, y + 3, z + 3), ModBlocks.PROTOSS_METAL.getStateFromMeta(metaPrimColor));
		world.setBlockState(pos.add(x + 7, y + 3, z + 3), ModBlocks.PROTOSS_METAL.getStateFromMeta(metaPrimColor));
		world.setBlockState(pos.add(x + 8, y + 3, z + 3), ModBlocks.PROTOSS_METAL.getStateFromMeta(metaPrimColor));
		world.setBlockState(pos.add(x + 9, y + 3, z + 3), ModBlocks.PROTOSS_METAL.getStateFromMeta(metaPrimColor));
		world.setBlockState(pos.add(x + 10, y + 3, z + 3), ModBlocks.PROTOSS_METAL.getStateFromMeta(metaPrimColor));
		world.setBlockState(pos.add(x + 11, y + 3, z + 3), ModBlocks.PROTOSS_METAL.getStateFromMeta(metaPrimColor));
		world.setBlockState(pos.add(x + 12, y + 3, z + 3), ModBlocks.PROTOSS_METAL.getStateFromMeta(metaPrimColor));
		world.setBlockState(pos.add(x + 13, y + 3, z + 3), Blocks.AIR.getDefaultState());
		world.setBlockState(pos.add(x + 14, y + 3, z + 3), Blocks.AIR.getDefaultState());
		world.setBlockState(pos.add(x, y + 3, z + 4), Blocks.AIR.getDefaultState());
		world.setBlockState(pos.add(x + 1, y + 3, z + 4), Blocks.AIR.getDefaultState());
		world.setBlockState(pos.add(x + 2, y + 3, z + 4), ModBlocks.PROTOSS_METAL.getStateFromMeta(metaPrimColor));
		world.setBlockState(pos.add(x + 3, y + 3, z + 4), ModBlocks.PROTOSS_METAL.getStateFromMeta(metaPrimColor));
		world.setBlockState(pos.add(x + 4, y + 3, z + 4), ModBlocks.PROTOSS_METAL.getStateFromMeta(metaPrimColor));
		world.setBlockState(pos.add(x + 5, y + 3, z + 4), ModBlocks.PROTOSS_METAL.getStateFromMeta(metaPrimColor));
		world.setBlockState(pos.add(x + 6, y + 3, z + 4), ModBlocks.PROTOSS_METAL.getStateFromMeta(metaPrimColor));
		world.setBlockState(pos.add(x + 7, y + 3, z + 4), ModBlocks.PROTOSS_METAL.getStateFromMeta(metaPrimColor));
		world.setBlockState(pos.add(x + 8, y + 3, z + 4), ModBlocks.PROTOSS_METAL.getStateFromMeta(metaPrimColor));
		world.setBlockState(pos.add(x + 9, y + 3, z + 4), ModBlocks.PROTOSS_METAL.getStateFromMeta(metaPrimColor));
		world.setBlockState(pos.add(x + 10, y + 3, z + 4), ModBlocks.PROTOSS_METAL.getStateFromMeta(metaPrimColor));
		world.setBlockState(pos.add(x + 11, y + 3, z + 4), ModBlocks.PROTOSS_METAL.getStateFromMeta(metaPrimColor));
		world.setBlockState(pos.add(x + 12, y + 3, z + 4), ModBlocks.PROTOSS_METAL.getStateFromMeta(metaPrimColor));
		world.setBlockState(pos.add(x + 13, y + 3, z + 4), ModBlocks.PROTOSS_METAL.getStateFromMeta(metaSecColor));
		world.setBlockState(pos.add(x + 14, y + 3, z + 4), Blocks.AIR.getDefaultState());
		world.setBlockState(pos.add(x, y + 3, z + 5), Blocks.AIR.getDefaultState());
		world.setBlockState(pos.add(x + 1, y + 3, z + 5), Blocks.AIR.getDefaultState());
		world.setBlockState(pos.add(x + 2, y + 3, z + 5), ModBlocks.PROTOSS_METAL.getStateFromMeta(metaPrimColor));
		world.setBlockState(pos.add(x + 3, y + 3, z + 5), ModBlocks.PROTOSS_METAL.getStateFromMeta(metaPrimColor));
		world.setBlockState(pos.add(x + 4, y + 3, z + 5), ModBlocks.PROTOSS_METAL.getStateFromMeta(metaPrimColor));
		world.setBlockState(pos.add(x + 5, y + 3, z + 5), ModBlocks.PROTOSS_METAL.getStateFromMeta(metaPrimColor));
		world.setBlockState(pos.add(x + 6, y + 3, z + 5), ModBlocks.PROTOSS_METAL.getStateFromMeta(metaPrimColor));
		world.setBlockState(pos.add(x + 7, y + 3, z + 5), ModBlocks.PROTOSS_METAL.getStateFromMeta(metaPrimColor));
		world.setBlockState(pos.add(x + 8, y + 3, z + 5), ModBlocks.PROTOSS_METAL.getStateFromMeta(metaPrimColor));
		world.setBlockState(pos.add(x + 9, y + 3, z + 5), ModBlocks.PROTOSS_METAL.getStateFromMeta(metaPrimColor));
		world.setBlockState(pos.add(x + 10, y + 3, z + 5), ModBlocks.PROTOSS_METAL.getStateFromMeta(metaPrimColor));
		world.setBlockState(pos.add(x + 11, y + 3, z + 5), ModBlocks.PROTOSS_METAL.getStateFromMeta(metaPrimColor));
		world.setBlockState(pos.add(x + 12, y + 3, z + 5), ModBlocks.PROTOSS_METAL.getStateFromMeta(metaPrimColor));
		world.setBlockState(pos.add(x + 13, y + 3, z + 5), Blocks.AIR.getDefaultState());
		world.setBlockState(pos.add(x + 14, y + 3, z + 5), Blocks.AIR.getDefaultState());
		world.setBlockState(pos.add(x, y + 3, z + 6), Blocks.AIR.getDefaultState());
		world.setBlockState(pos.add(x + 1, y + 3, z + 6), Blocks.AIR.getDefaultState());
		world.setBlockState(pos.add(x + 2, y + 3, z + 6), ModBlocks.PROTOSS_METAL.getStateFromMeta(metaPrimColor));
		world.setBlockState(pos.add(x + 3, y + 3, z + 6), ModBlocks.PROTOSS_METAL.getStateFromMeta(metaPrimColor));
		world.setBlockState(pos.add(x + 4, y + 3, z + 6), ModBlocks.PROTOSS_METAL.getStateFromMeta(metaPrimColor));
		world.setBlockState(pos.add(x + 5, y + 3, z + 6), ModBlocks.PROTOSS_METAL.getStateFromMeta(metaPrimColor));
		world.setBlockState(pos.add(x + 6, y + 3, z + 6), ModBlocks.PROTOSS_METAL.getStateFromMeta(metaPrimColor));
		world.setBlockState(pos.add(x + 7, y + 3, z + 6), ModBlocks.PROTOSS_METAL.getStateFromMeta(metaPrimColor));
		world.setBlockState(pos.add(x + 8, y + 3, z + 6), ModBlocks.PROTOSS_METAL.getStateFromMeta(metaPrimColor));
		world.setBlockState(pos.add(x + 9, y + 3, z + 6), ModBlocks.PROTOSS_METAL.getStateFromMeta(metaPrimColor));
		world.setBlockState(pos.add(x + 10, y + 3, z + 6), ModBlocks.PROTOSS_METAL.getStateFromMeta(metaPrimColor));
		world.setBlockState(pos.add(x + 11, y + 3, z + 6), ModBlocks.PROTOSS_METAL.getStateFromMeta(metaPrimColor));
		world.setBlockState(pos.add(x + 12, y + 3, z + 6), ModBlocks.PROTOSS_METAL.getStateFromMeta(metaPrimColor));
		world.setBlockState(pos.add(x + 13, y + 3, z + 6), Blocks.AIR.getDefaultState());
		world.setBlockState(pos.add(x + 14, y + 3, z + 6), Blocks.AIR.getDefaultState());
		world.setBlockState(pos.add(x, y + 3, z + 7), Blocks.AIR.getDefaultState());
		world.setBlockState(pos.add(x + 1, y + 3, z + 7), Blocks.AIR.getDefaultState());
		world.setBlockState(pos.add(x + 2, y + 3, z + 7), ModBlocks.PROTOSS_METAL.getStateFromMeta(metaPrimColor));
		world.setBlockState(pos.add(x + 3, y + 3, z + 7), ModBlocks.PROTOSS_METAL.getStateFromMeta(metaPrimColor));
		world.setBlockState(pos.add(x + 4, y + 3, z + 7), ModBlocks.PROTOSS_METAL.getStateFromMeta(metaPrimColor));
		world.setBlockState(pos.add(x + 5, y + 3, z + 7), ModBlocks.PROTOSS_METAL.getStateFromMeta(metaPrimColor));
		world.setBlockState(pos.add(x + 6, y + 3, z + 7), ModBlocks.PROTOSS_METAL.getStateFromMeta(metaPrimColor));
		world.setBlockState(pos.add(x + 7, y + 3, z + 7), ModBlocks.PROTOSS_METAL.getStateFromMeta(metaPrimColor));
		world.setBlockState(pos.add(x + 8, y + 3, z + 7), ModBlocks.PROTOSS_METAL.getStateFromMeta(metaPrimColor));
		world.setBlockState(pos.add(x + 9, y + 3, z + 7), ModBlocks.PROTOSS_METAL.getStateFromMeta(metaPrimColor));
		world.setBlockState(pos.add(x + 10, y + 3, z + 7), ModBlocks.PROTOSS_METAL.getStateFromMeta(metaPrimColor));
		world.setBlockState(pos.add(x + 11, y + 3, z + 7), ModBlocks.PROTOSS_METAL.getStateFromMeta(metaPrimColor));
		world.setBlockState(pos.add(x + 12, y + 3, z + 7), ModBlocks.PROTOSS_METAL.getStateFromMeta(metaPrimColor));
		world.setBlockState(pos.add(x + 13, y + 3, z + 7), Blocks.AIR.getDefaultState());
		world.setBlockState(pos.add(x + 14, y + 3, z + 7), Blocks.AIR.getDefaultState());
		world.setBlockState(pos.add(x, y + 3, z + 8), Blocks.AIR.getDefaultState());
		world.setBlockState(pos.add(x + 1, y + 3, z + 8), Blocks.AIR.getDefaultState());
		world.setBlockState(pos.add(x + 2, y + 3, z + 8), ModBlocks.PROTOSS_METAL.getStateFromMeta(metaPrimColor));
		world.setBlockState(pos.add(x + 3, y + 3, z + 8), ModBlocks.PROTOSS_METAL.getStateFromMeta(metaPrimColor));
		world.setBlockState(pos.add(x + 4, y + 3, z + 8), ModBlocks.PROTOSS_METAL.getStateFromMeta(metaPrimColor));
		world.setBlockState(pos.add(x + 5, y + 3, z + 8), ModBlocks.PROTOSS_METAL.getStateFromMeta(metaPrimColor));
		world.setBlockState(pos.add(x + 6, y + 3, z + 8), ModBlocks.PROTOSS_METAL.getStateFromMeta(metaPrimColor));
		world.setBlockState(pos.add(x + 7, y + 3, z + 8), ModBlocks.PROTOSS_METAL.getStateFromMeta(metaPrimColor));
		world.setBlockState(pos.add(x + 8, y + 3, z + 8), ModBlocks.PROTOSS_METAL.getStateFromMeta(metaPrimColor));
		world.setBlockState(pos.add(x + 9, y + 3, z + 8), ModBlocks.PROTOSS_METAL.getStateFromMeta(metaPrimColor));
		world.setBlockState(pos.add(x + 10, y + 3, z + 8), ModBlocks.PROTOSS_METAL.getStateFromMeta(metaPrimColor));
		world.setBlockState(pos.add(x + 11, y + 3, z + 8), ModBlocks.PROTOSS_METAL.getStateFromMeta(metaPrimColor));
		world.setBlockState(pos.add(x + 12, y + 3, z + 8), ModBlocks.PROTOSS_METAL.getStateFromMeta(metaPrimColor));
		world.setBlockState(pos.add(x + 13, y + 3, z + 8), Blocks.AIR.getDefaultState());
		world.setBlockState(pos.add(x + 14, y + 3, z + 8), Blocks.AIR.getDefaultState());
		world.setBlockState(pos.add(x, y + 3, z + 9), Blocks.AIR.getDefaultState());
		world.setBlockState(pos.add(x + 1, y + 3, z + 9), Blocks.AIR.getDefaultState());
		world.setBlockState(pos.add(x + 2, y + 3, z + 9), ModBlocks.PROTOSS_METAL.getStateFromMeta(metaPrimColor));
		world.setBlockState(pos.add(x + 3, y + 3, z + 9), ModBlocks.PROTOSS_METAL.getStateFromMeta(metaPrimColor));
		world.setBlockState(pos.add(x + 4, y + 3, z + 9), ModBlocks.PROTOSS_METAL.getStateFromMeta(metaPrimColor));
		world.setBlockState(pos.add(x + 5, y + 3, z + 9), ModBlocks.PROTOSS_METAL.getStateFromMeta(metaPrimColor));
		world.setBlockState(pos.add(x + 6, y + 3, z + 9), ModBlocks.PROTOSS_METAL.getStateFromMeta(metaPrimColor));
		world.setBlockState(pos.add(x + 7, y + 3, z + 9), ModBlocks.PROTOSS_METAL.getStateFromMeta(metaPrimColor));
		world.setBlockState(pos.add(x + 8, y + 3, z + 9), ModBlocks.PROTOSS_METAL.getStateFromMeta(metaPrimColor));
		world.setBlockState(pos.add(x + 9, y + 3, z + 9), ModBlocks.PROTOSS_METAL.getStateFromMeta(metaPrimColor));
		world.setBlockState(pos.add(x + 10, y + 3, z + 9), ModBlocks.PROTOSS_METAL.getStateFromMeta(metaPrimColor));
		world.setBlockState(pos.add(x + 11, y + 3, z + 9), ModBlocks.PROTOSS_METAL.getStateFromMeta(metaPrimColor));
		world.setBlockState(pos.add(x + 12, y + 3, z + 9), ModBlocks.PROTOSS_METAL.getStateFromMeta(metaPrimColor));
		world.setBlockState(pos.add(x + 13, y + 3, z + 9), Blocks.AIR.getDefaultState());
		world.setBlockState(pos.add(x + 14, y + 3, z + 9), Blocks.AIR.getDefaultState());
		world.setBlockState(pos.add(x, y + 3, z + 10), Blocks.AIR.getDefaultState());
		world.setBlockState(pos.add(x + 1, y + 3, z + 10), ModBlocks.PROTOSS_METAL.getStateFromMeta(metaSecColor));
		world.setBlockState(pos.add(x + 2, y + 3, z + 10), ModBlocks.PROTOSS_METAL.getStateFromMeta(metaPrimColor));
		world.setBlockState(pos.add(x + 3, y + 3, z + 10), ModBlocks.PROTOSS_METAL.getStateFromMeta(metaPrimColor));
		world.setBlockState(pos.add(x + 4, y + 3, z + 10), ModBlocks.PROTOSS_METAL.getStateFromMeta(metaPrimColor));
		world.setBlockState(pos.add(x + 5, y + 3, z + 10), ModBlocks.PROTOSS_METAL.getStateFromMeta(metaPrimColor));
		world.setBlockState(pos.add(x + 6, y + 3, z + 10), ModBlocks.PROTOSS_METAL.getStateFromMeta(metaPrimColor));
		world.setBlockState(pos.add(x + 7, y + 3, z + 10), ModBlocks.PROTOSS_METAL.getStateFromMeta(metaPrimColor));
		world.setBlockState(pos.add(x + 8, y + 3, z + 10), ModBlocks.PROTOSS_METAL.getStateFromMeta(metaPrimColor));
		world.setBlockState(pos.add(x + 9, y + 3, z + 10), ModBlocks.PROTOSS_METAL.getStateFromMeta(metaPrimColor));
		world.setBlockState(pos.add(x + 10, y + 3, z + 10), ModBlocks.PROTOSS_METAL.getStateFromMeta(metaPrimColor));
		world.setBlockState(pos.add(x + 11, y + 3, z + 10), ModBlocks.PROTOSS_METAL.getStateFromMeta(metaPrimColor));
		world.setBlockState(pos.add(x + 12, y + 3, z + 10), ModBlocks.PROTOSS_METAL.getStateFromMeta(metaPrimColor));
		world.setBlockState(pos.add(x + 13, y + 3, z + 10), Blocks.AIR.getDefaultState());
		world.setBlockState(pos.add(x + 14, y + 3, z + 10), Blocks.AIR.getDefaultState());
		world.setBlockState(pos.add(x, y + 3, z + 11), Blocks.AIR.getDefaultState());
		world.setBlockState(pos.add(x + 1, y + 3, z + 11), Blocks.AIR.getDefaultState());
		world.setBlockState(pos.add(x + 2, y + 3, z + 11), ModBlocks.PROTOSS_METAL.getStateFromMeta(metaPrimColor));
		world.setBlockState(pos.add(x + 3, y + 3, z + 11), ModBlocks.PROTOSS_METAL.getStateFromMeta(metaPrimColor));
		world.setBlockState(pos.add(x + 4, y + 3, z + 11), ModBlocks.PROTOSS_METAL.getStateFromMeta(metaPrimColor));
		world.setBlockState(pos.add(x + 5, y + 3, z + 11), ModBlocks.PROTOSS_METAL.getStateFromMeta(metaPrimColor));
		world.setBlockState(pos.add(x + 6, y + 3, z + 11), ModBlocks.PROTOSS_METAL.getStateFromMeta(metaPrimColor));
		world.setBlockState(pos.add(x + 7, y + 3, z + 11), ModBlocks.PROTOSS_METAL.getStateFromMeta(metaPrimColor));
		world.setBlockState(pos.add(x + 8, y + 3, z + 11), ModBlocks.PROTOSS_METAL.getStateFromMeta(metaPrimColor));
		world.setBlockState(pos.add(x + 9, y + 3, z + 11), ModBlocks.PROTOSS_METAL.getStateFromMeta(metaPrimColor));
		world.setBlockState(pos.add(x + 10, y + 3, z + 11), ModBlocks.PROTOSS_METAL.getStateFromMeta(metaPrimColor));
		world.setBlockState(pos.add(x + 11, y + 3, z + 11), ModBlocks.PROTOSS_METAL.getStateFromMeta(metaPrimColor));
		world.setBlockState(pos.add(x + 12, y + 3, z + 11), ModBlocks.PROTOSS_METAL.getStateFromMeta(metaPrimColor));
		world.setBlockState(pos.add(x + 13, y + 3, z + 11), Blocks.AIR.getDefaultState());
		world.setBlockState(pos.add(x + 14, y + 3, z + 11), Blocks.AIR.getDefaultState());
		world.setBlockState(pos.add(x, y + 3, z + 12), Blocks.AIR.getDefaultState());
		world.setBlockState(pos.add(x + 1, y + 3, z + 12), Blocks.AIR.getDefaultState());
		world.setBlockState(pos.add(x + 2, y + 3, z + 12), Blocks.AIR.getDefaultState());
		world.setBlockState(pos.add(x + 3, y + 3, z + 12), ModBlocks.PROTOSS_METAL.getStateFromMeta(metaPrimColor));
		world.setBlockState(pos.add(x + 4, y + 3, z + 12), ModBlocks.PROTOSS_METAL.getStateFromMeta(metaPrimColor));
		world.setBlockState(pos.add(x + 5, y + 3, z + 12), ModBlocks.PROTOSS_METAL.getStateFromMeta(metaPrimColor));
		world.setBlockState(pos.add(x + 6, y + 3, z + 12), ModBlocks.PROTOSS_METAL.getStateFromMeta(metaPrimColor));
		world.setBlockState(pos.add(x + 7, y + 3, z + 12), ModBlocks.PROTOSS_METAL.getStateFromMeta(metaPrimColor));
		world.setBlockState(pos.add(x + 8, y + 3, z + 12), ModBlocks.PROTOSS_METAL.getStateFromMeta(metaPrimColor));
		world.setBlockState(pos.add(x + 9, y + 3, z + 12), ModBlocks.PROTOSS_METAL.getStateFromMeta(metaPrimColor));
		world.setBlockState(pos.add(x + 10, y + 3, z + 12), ModBlocks.PROTOSS_METAL.getStateFromMeta(metaPrimColor));
		world.setBlockState(pos.add(x + 11, y + 3, z + 12), ModBlocks.PROTOSS_METAL.getStateFromMeta(metaPrimColor));
		world.setBlockState(pos.add(x + 12, y + 3, z + 12), ModBlocks.PROTOSS_METAL.getStateFromMeta(metaPrimColor));
		world.setBlockState(pos.add(x + 13, y + 3, z + 12), ModBlocks.PROTOSS_METAL.getStateFromMeta(metaPrimColor));
		world.setBlockState(pos.add(x + 14, y + 3, z + 12), Blocks.AIR.getDefaultState());
		world.setBlockState(pos.add(x, y + 3, z + 13), Blocks.AIR.getDefaultState());
		world.setBlockState(pos.add(x + 1, y + 3, z + 13), Blocks.AIR.getDefaultState());
		world.setBlockState(pos.add(x + 2, y + 3, z + 13), Blocks.AIR.getDefaultState());
		world.setBlockState(pos.add(x + 3, y + 3, z + 13), Blocks.AIR.getDefaultState());
		world.setBlockState(pos.add(x + 4, y + 3, z + 13), ModBlocks.PROTOSS_METAL.getStateFromMeta(metaSecColor));
		world.setBlockState(pos.add(x + 5, y + 3, z + 13), Blocks.AIR.getDefaultState());
		world.setBlockState(pos.add(x + 6, y + 3, z + 13), Blocks.AIR.getDefaultState());
		world.setBlockState(pos.add(x + 7, y + 3, z + 13), Blocks.AIR.getDefaultState());
		world.setBlockState(pos.add(x + 8, y + 3, z + 13), Blocks.AIR.getDefaultState());
		world.setBlockState(pos.add(x + 9, y + 3, z + 13), Blocks.AIR.getDefaultState());
		world.setBlockState(pos.add(x + 10, y + 3, z + 13), Blocks.AIR.getDefaultState());
		world.setBlockState(pos.add(x + 11, y + 3, z + 13), Blocks.AIR.getDefaultState());
		world.setBlockState(pos.add(x + 12, y + 3, z + 13), ModBlocks.PROTOSS_METAL.getStateFromMeta(metaPrimColor));
		world.setBlockState(pos.add(x + 13, y + 3, z + 13), ModBlocks.PROTOSS_METAL.getStateFromMeta(metaSecColor));
		world.setBlockState(pos.add(x + 14, y + 3, z + 13), ModBlocks.PROTOSS_METAL.getStateFromMeta(metaPrimColor));
		world.setBlockState(pos.add(x, y + 3, z + 14), Blocks.AIR.getDefaultState());
		world.setBlockState(pos.add(x + 1, y + 3, z + 14), Blocks.AIR.getDefaultState());
		world.setBlockState(pos.add(x + 2, y + 3, z + 14), Blocks.AIR.getDefaultState());
		world.setBlockState(pos.add(x + 3, y + 3, z + 14), Blocks.AIR.getDefaultState());
		world.setBlockState(pos.add(x + 4, y + 3, z + 14), Blocks.AIR.getDefaultState());
		world.setBlockState(pos.add(x + 5, y + 3, z + 14), Blocks.AIR.getDefaultState());
		world.setBlockState(pos.add(x + 6, y + 3, z + 14), Blocks.AIR.getDefaultState());
		world.setBlockState(pos.add(x + 7, y + 3, z + 14), Blocks.AIR.getDefaultState());
		world.setBlockState(pos.add(x + 8, y + 3, z + 14), Blocks.AIR.getDefaultState());
		world.setBlockState(pos.add(x + 9, y + 3, z + 14), Blocks.AIR.getDefaultState());
		world.setBlockState(pos.add(x + 10, y + 3, z + 14), Blocks.AIR.getDefaultState());
		world.setBlockState(pos.add(x + 11, y + 3, z + 14), Blocks.AIR.getDefaultState());
		world.setBlockState(pos.add(x + 12, y + 3, z + 14), Blocks.AIR.getDefaultState());
		world.setBlockState(pos.add(x + 13, y + 3, z + 14), ModBlocks.PROTOSS_METAL.getStateFromMeta(metaPrimColor));
		world.setBlockState(pos.add(x + 14, y + 3, z + 14), ModBlocks.PROTOSS_METAL.getStateFromMeta(metaPrimColor));
		world.setBlockState(pos.add(x, y + 4, z), Blocks.AIR.getDefaultState());
		world.setBlockState(pos.add(x + 1, y + 4, z), Blocks.AIR.getDefaultState());
		world.setBlockState(pos.add(x + 2, y + 4, z), Blocks.AIR.getDefaultState());
		world.setBlockState(pos.add(x + 3, y + 4, z), Blocks.AIR.getDefaultState());
		world.setBlockState(pos.add(x + 4, y + 4, z), Blocks.AIR.getDefaultState());
		world.setBlockState(pos.add(x + 5, y + 4, z), Blocks.AIR.getDefaultState());
		world.setBlockState(pos.add(x + 6, y + 4, z), Blocks.AIR.getDefaultState());
		world.setBlockState(pos.add(x + 7, y + 4, z), Blocks.AIR.getDefaultState());
		world.setBlockState(pos.add(x + 8, y + 4, z), Blocks.AIR.getDefaultState());
		world.setBlockState(pos.add(x + 9, y + 4, z), Blocks.AIR.getDefaultState());
		world.setBlockState(pos.add(x + 10, y + 4, z), Blocks.AIR.getDefaultState());
		world.setBlockState(pos.add(x + 11, y + 4, z), Blocks.AIR.getDefaultState());
		world.setBlockState(pos.add(x + 12, y + 4, z), Blocks.AIR.getDefaultState());
		world.setBlockState(pos.add(x + 13, y + 4, z), Blocks.AIR.getDefaultState());
		world.setBlockState(pos.add(x + 14, y + 4, z), Blocks.AIR.getDefaultState());
		world.setBlockState(pos.add(x, y + 4, z + 1), Blocks.AIR.getDefaultState());
		world.setBlockState(pos.add(x + 1, y + 4, z + 1), Blocks.AIR.getDefaultState());
		world.setBlockState(pos.add(x + 2, y + 4, z + 1), Blocks.AIR.getDefaultState());
		world.setBlockState(pos.add(x + 3, y + 4, z + 1), Blocks.AIR.getDefaultState());
		world.setBlockState(pos.add(x + 4, y + 4, z + 1), Blocks.AIR.getDefaultState());
		world.setBlockState(pos.add(x + 5, y + 4, z + 1), Blocks.AIR.getDefaultState());
		world.setBlockState(pos.add(x + 6, y + 4, z + 1), Blocks.AIR.getDefaultState());
		world.setBlockState(pos.add(x + 7, y + 4, z + 1), Blocks.AIR.getDefaultState());
		world.setBlockState(pos.add(x + 8, y + 4, z + 1), Blocks.AIR.getDefaultState());
		world.setBlockState(pos.add(x + 9, y + 4, z + 1), Blocks.AIR.getDefaultState());
		world.setBlockState(pos.add(x + 10, y + 4, z + 1), Blocks.AIR.getDefaultState());
		world.setBlockState(pos.add(x + 11, y + 4, z + 1), Blocks.AIR.getDefaultState());
		world.setBlockState(pos.add(x + 12, y + 4, z + 1), Blocks.AIR.getDefaultState());
		world.setBlockState(pos.add(x + 13, y + 4, z + 1), Blocks.AIR.getDefaultState());
		world.setBlockState(pos.add(x + 14, y + 4, z + 1), Blocks.AIR.getDefaultState());
		world.setBlockState(pos.add(x, y + 4, z + 2), Blocks.AIR.getDefaultState());
		world.setBlockState(pos.add(x + 1, y + 4, z + 2), Blocks.AIR.getDefaultState());
		world.setBlockState(pos.add(x + 2, y + 4, z + 2), ModBlocks.PROTOSS_METAL.getStateFromMeta(metaPrimColor));
		world.setBlockState(pos.add(x + 3, y + 4, z + 2), ModBlocks.PROTOSS_METAL.getStateFromMeta(metaPrimColor));
		world.setBlockState(pos.add(x + 4, y + 4, z + 2), ModBlocks.PROTOSS_METAL.getStateFromMeta(metaSecColor));
		world.setBlockState(pos.add(x + 5, y + 4, z + 2), ModBlocks.PROTOSS_METAL.getStateFromMeta(metaPrimColor));
		world.setBlockState(pos.add(x + 6, y + 4, z + 2), Blocks.AIR.getDefaultState());
		world.setBlockState(pos.add(x + 7, y + 4, z + 2), Blocks.AIR.getDefaultState());
		world.setBlockState(pos.add(x + 8, y + 4, z + 2), Blocks.AIR.getDefaultState());
		world.setBlockState(pos.add(x + 9, y + 4, z + 2), Blocks.AIR.getDefaultState());
		world.setBlockState(pos.add(x + 10, y + 4, z + 2), ModBlocks.PROTOSS_METAL.getStateFromMeta(metaPrimColor));
		world.setBlockState(pos.add(x + 11, y + 4, z + 2), Blocks.AIR.getDefaultState());
		world.setBlockState(pos.add(x + 12, y + 4, z + 2), Blocks.AIR.getDefaultState());
		world.setBlockState(pos.add(x + 13, y + 4, z + 2), Blocks.AIR.getDefaultState());
		world.setBlockState(pos.add(x + 14, y + 4, z + 2), Blocks.AIR.getDefaultState());
		world.setBlockState(pos.add(x, y + 4, z + 3), Blocks.AIR.getDefaultState());
		world.setBlockState(pos.add(x + 1, y + 4, z + 3), Blocks.AIR.getDefaultState());
		world.setBlockState(pos.add(x + 2, y + 4, z + 3), ModBlocks.PROTOSS_METAL.getStateFromMeta(metaPrimColor));
		world.setBlockState(pos.add(x + 3, y + 4, z + 3), ModBlocks.PROTOSS_METAL.getStateFromMeta(metaPrimColor));
		world.setBlockState(pos.add(x + 4, y + 4, z + 3), ModBlocks.PROTOSS_METAL.getStateFromMeta(metaPrimColor));
		world.setBlockState(pos.add(x + 5, y + 4, z + 3), ModBlocks.PROTOSS_METAL.getStateFromMeta(metaPrimColor));
		world.setBlockState(pos.add(x + 6, y + 4, z + 3), ModBlocks.PROTOSS_METAL.getStateFromMeta(metaPrimColor));
		world.setBlockState(pos.add(x + 7, y + 4, z + 3), ModBlocks.PROTOSS_METAL.getStateFromMeta(metaPrimColor));
		world.setBlockState(pos.add(x + 8, y + 4, z + 3), ModBlocks.PROTOSS_METAL.getStateFromMeta(metaPrimColor));
		world.setBlockState(pos.add(x + 9, y + 4, z + 3), ModBlocks.PROTOSS_METAL.getStateFromMeta(metaPrimColor));
		world.setBlockState(pos.add(x + 10, y + 4, z + 3), ModBlocks.PROTOSS_METAL.getStateFromMeta(metaPrimColor));
		world.setBlockState(pos.add(x + 11, y + 4, z + 3), ModBlocks.PROTOSS_METAL.getStateFromMeta(metaSecColor));
		world.setBlockState(pos.add(x + 12, y + 4, z + 3), Blocks.AIR.getDefaultState());
		world.setBlockState(pos.add(x + 13, y + 4, z + 3), Blocks.AIR.getDefaultState());
		world.setBlockState(pos.add(x + 14, y + 4, z + 3), Blocks.AIR.getDefaultState());
		world.setBlockState(pos.add(x, y + 4, z + 4), Blocks.AIR.getDefaultState());
		world.setBlockState(pos.add(x + 1, y + 4, z + 4), Blocks.AIR.getDefaultState());
		world.setBlockState(pos.add(x + 2, y + 4, z + 4), ModBlocks.PROTOSS_METAL.getStateFromMeta(metaSecColor));
		world.setBlockState(pos.add(x + 3, y + 4, z + 4), ModBlocks.PROTOSS_METAL.getStateFromMeta(metaPrimColor));
		world.setBlockState(pos.add(x + 4, y + 4, z + 4), ModBlocks.PROTOSS_METAL.getStateFromMeta(metaPrimColor));
		world.setBlockState(pos.add(x + 5, y + 4, z + 4), ModBlocks.PROTOSS_METAL.getStateFromMeta(metaPrimColor));
		world.setBlockState(pos.add(x + 6, y + 4, z + 4), ModBlocks.PROTOSS_METAL.getStateFromMeta(metaPrimColor));
		world.setBlockState(pos.add(x + 7, y + 4, z + 4), ModBlocks.PROTOSS_METAL.getStateFromMeta(metaPrimColor));
		world.setBlockState(pos.add(x + 8, y + 4, z + 4), ModBlocks.PROTOSS_METAL.getStateFromMeta(metaPrimColor));
		world.setBlockState(pos.add(x + 9, y + 4, z + 4), ModBlocks.PROTOSS_METAL.getStateFromMeta(metaPrimColor));
		world.setBlockState(pos.add(x + 10, y + 4, z + 4), ModBlocks.PROTOSS_METAL.getStateFromMeta(metaPrimColor));
		world.setBlockState(pos.add(x + 11, y + 4, z + 4), ModBlocks.PROTOSS_METAL.getStateFromMeta(metaPrimColor));
		world.setBlockState(pos.add(x + 12, y + 4, z + 4), ModBlocks.PROTOSS_METAL.getStateFromMeta(metaPrimColor));
		world.setBlockState(pos.add(x + 13, y + 4, z + 4), Blocks.AIR.getDefaultState());
		world.setBlockState(pos.add(x + 14, y + 4, z + 4), Blocks.AIR.getDefaultState());
		world.setBlockState(pos.add(x, y + 4, z + 5), Blocks.AIR.getDefaultState());
		world.setBlockState(pos.add(x + 1, y + 4, z + 5), Blocks.AIR.getDefaultState());
		world.setBlockState(pos.add(x + 2, y + 4, z + 5), ModBlocks.PROTOSS_METAL.getStateFromMeta(metaPrimColor));
		world.setBlockState(pos.add(x + 3, y + 4, z + 5), ModBlocks.PROTOSS_METAL.getStateFromMeta(metaPrimColor));
		world.setBlockState(pos.add(x + 4, y + 4, z + 5), ModBlocks.PROTOSS_METAL.getStateFromMeta(metaPrimColor));
		world.setBlockState(pos.add(x + 5, y + 4, z + 5), ModBlocks.PROTOSS_METAL.getStateFromMeta(metaPrimColor));
		world.setBlockState(pos.add(x + 6, y + 4, z + 5), ModBlocks.PROTOSS_METAL.getStateFromMeta(metaPrimColor));
		world.setBlockState(pos.add(x + 7, y + 4, z + 5), ModBlocks.PROTOSS_METAL.getStateFromMeta(metaPrimColor));
		world.setBlockState(pos.add(x + 8, y + 4, z + 5), ModBlocks.PROTOSS_METAL.getStateFromMeta(metaPrimColor));
		world.setBlockState(pos.add(x + 9, y + 4, z + 5), ModBlocks.PROTOSS_METAL.getStateFromMeta(metaPrimColor));
		world.setBlockState(pos.add(x + 10, y + 4, z + 5), ModBlocks.PROTOSS_METAL.getStateFromMeta(metaPrimColor));
		world.setBlockState(pos.add(x + 11, y + 4, z + 5), ModBlocks.PROTOSS_METAL.getStateFromMeta(metaPrimColor));
		world.setBlockState(pos.add(x + 12, y + 4, z + 5), Blocks.AIR.getDefaultState());
		world.setBlockState(pos.add(x + 13, y + 4, z + 5), Blocks.AIR.getDefaultState());
		world.setBlockState(pos.add(x + 14, y + 4, z + 5), Blocks.AIR.getDefaultState());
		world.setBlockState(pos.add(x, y + 4, z + 6), Blocks.AIR.getDefaultState());
		world.setBlockState(pos.add(x + 1, y + 4, z + 6), Blocks.AIR.getDefaultState());
		world.setBlockState(pos.add(x + 2, y + 4, z + 6), Blocks.AIR.getDefaultState());
		world.setBlockState(pos.add(x + 3, y + 4, z + 6), ModBlocks.PROTOSS_METAL.getStateFromMeta(metaPrimColor));
		world.setBlockState(pos.add(x + 4, y + 4, z + 6), ModBlocks.PROTOSS_METAL.getStateFromMeta(metaPrimColor));
		world.setBlockState(pos.add(x + 5, y + 4, z + 6), ModBlocks.PROTOSS_METAL.getStateFromMeta(metaPrimColor));
		world.setBlockState(pos.add(x + 6, y + 4, z + 6), ModBlocks.PROTOSS_METAL.getStateFromMeta(metaPrimColor));
		world.setBlockState(pos.add(x + 7, y + 4, z + 6), ModBlocks.PROTOSS_METAL.getStateFromMeta(metaPrimColor));
		world.setBlockState(pos.add(x + 8, y + 4, z + 6), ModBlocks.PROTOSS_METAL.getStateFromMeta(metaPrimColor));
		world.setBlockState(pos.add(x + 9, y + 4, z + 6), ModBlocks.PROTOSS_METAL.getStateFromMeta(metaPrimColor));
		world.setBlockState(pos.add(x + 10, y + 4, z + 6), ModBlocks.PROTOSS_METAL.getStateFromMeta(metaPrimColor));
		world.setBlockState(pos.add(x + 11, y + 4, z + 6), ModBlocks.PROTOSS_METAL.getStateFromMeta(metaPrimColor));
		world.setBlockState(pos.add(x + 12, y + 4, z + 6), Blocks.AIR.getDefaultState());
		world.setBlockState(pos.add(x + 13, y + 4, z + 6), Blocks.AIR.getDefaultState());
		world.setBlockState(pos.add(x + 14, y + 4, z + 6), Blocks.AIR.getDefaultState());
		world.setBlockState(pos.add(x, y + 4, z + 7), Blocks.AIR.getDefaultState());
		world.setBlockState(pos.add(x + 1, y + 4, z + 7), Blocks.AIR.getDefaultState());
		world.setBlockState(pos.add(x + 2, y + 4, z + 7), Blocks.AIR.getDefaultState());
		world.setBlockState(pos.add(x + 3, y + 4, z + 7), ModBlocks.PROTOSS_METAL.getStateFromMeta(metaPrimColor));
		world.setBlockState(pos.add(x + 4, y + 4, z + 7), ModBlocks.PROTOSS_METAL.getStateFromMeta(metaPrimColor));
		world.setBlockState(pos.add(x + 5, y + 4, z + 7), ModBlocks.PROTOSS_METAL.getStateFromMeta(metaPrimColor));
		world.setBlockState(pos.add(x + 6, y + 4, z + 7), ModBlocks.PROTOSS_METAL.getStateFromMeta(metaPrimColor));
		world.setBlockState(pos.add(x + 7, y + 4, z + 7), ModBlocks.PROTOSS_METAL.getStateFromMeta(metaPrimColor));
		world.setBlockState(pos.add(x + 8, y + 4, z + 7), ModBlocks.PROTOSS_METAL.getStateFromMeta(metaPrimColor));
		world.setBlockState(pos.add(x + 9, y + 4, z + 7), ModBlocks.PROTOSS_METAL.getStateFromMeta(metaPrimColor));
		world.setBlockState(pos.add(x + 10, y + 4, z + 7), ModBlocks.PROTOSS_METAL.getStateFromMeta(metaPrimColor));
		world.setBlockState(pos.add(x + 11, y + 4, z + 7), ModBlocks.PROTOSS_METAL.getStateFromMeta(metaPrimColor));
		world.setBlockState(pos.add(x + 12, y + 4, z + 7), Blocks.AIR.getDefaultState());
		world.setBlockState(pos.add(x + 13, y + 4, z + 7), Blocks.AIR.getDefaultState());
		world.setBlockState(pos.add(x + 14, y + 4, z + 7), Blocks.AIR.getDefaultState());
		world.setBlockState(pos.add(x, y + 4, z + 8), Blocks.AIR.getDefaultState());
		world.setBlockState(pos.add(x + 1, y + 4, z + 8), Blocks.AIR.getDefaultState());
		world.setBlockState(pos.add(x + 2, y + 4, z + 8), Blocks.AIR.getDefaultState());
		world.setBlockState(pos.add(x + 3, y + 4, z + 8), ModBlocks.PROTOSS_METAL.getStateFromMeta(metaPrimColor));
		world.setBlockState(pos.add(x + 4, y + 4, z + 8), ModBlocks.PROTOSS_METAL.getStateFromMeta(metaPrimColor));
		world.setBlockState(pos.add(x + 5, y + 4, z + 8), ModBlocks.PROTOSS_METAL.getStateFromMeta(metaPrimColor));
		world.setBlockState(pos.add(x + 6, y + 4, z + 8), ModBlocks.PROTOSS_METAL.getStateFromMeta(metaPrimColor));
		world.setBlockState(pos.add(x + 7, y + 4, z + 8), ModBlocks.PROTOSS_METAL.getStateFromMeta(metaPrimColor));
		world.setBlockState(pos.add(x + 8, y + 4, z + 8), ModBlocks.PROTOSS_METAL.getStateFromMeta(metaPrimColor));
		world.setBlockState(pos.add(x + 9, y + 4, z + 8), ModBlocks.PROTOSS_METAL.getStateFromMeta(metaPrimColor));
		world.setBlockState(pos.add(x + 10, y + 4, z + 8), ModBlocks.PROTOSS_METAL.getStateFromMeta(metaPrimColor));
		world.setBlockState(pos.add(x + 11, y + 4, z + 8), ModBlocks.PROTOSS_METAL.getStateFromMeta(metaPrimColor));
		world.setBlockState(pos.add(x + 12, y + 4, z + 8), Blocks.AIR.getDefaultState());
		world.setBlockState(pos.add(x + 13, y + 4, z + 8), Blocks.AIR.getDefaultState());
		world.setBlockState(pos.add(x + 14, y + 4, z + 8), Blocks.AIR.getDefaultState());
		world.setBlockState(pos.add(x, y + 4, z + 9), Blocks.AIR.getDefaultState());
		world.setBlockState(pos.add(x + 1, y + 4, z + 9), Blocks.AIR.getDefaultState());
		world.setBlockState(pos.add(x + 2, y + 4, z + 9), Blocks.AIR.getDefaultState());
		world.setBlockState(pos.add(x + 3, y + 4, z + 9), ModBlocks.PROTOSS_METAL.getStateFromMeta(metaPrimColor));
		world.setBlockState(pos.add(x + 4, y + 4, z + 9), ModBlocks.PROTOSS_METAL.getStateFromMeta(metaPrimColor));
		world.setBlockState(pos.add(x + 5, y + 4, z + 9), ModBlocks.PROTOSS_METAL.getStateFromMeta(metaPrimColor));
		world.setBlockState(pos.add(x + 6, y + 4, z + 9), ModBlocks.PROTOSS_METAL.getStateFromMeta(metaPrimColor));
		world.setBlockState(pos.add(x + 7, y + 4, z + 9), ModBlocks.PROTOSS_METAL.getStateFromMeta(metaPrimColor));
		world.setBlockState(pos.add(x + 8, y + 4, z + 9), ModBlocks.PROTOSS_METAL.getStateFromMeta(metaPrimColor));
		world.setBlockState(pos.add(x + 9, y + 4, z + 9), ModBlocks.PROTOSS_METAL.getStateFromMeta(metaPrimColor));
		world.setBlockState(pos.add(x + 10, y + 4, z + 9), ModBlocks.PROTOSS_METAL.getStateFromMeta(metaPrimColor));
		world.setBlockState(pos.add(x + 11, y + 4, z + 9), ModBlocks.PROTOSS_METAL.getStateFromMeta(metaPrimColor));
		world.setBlockState(pos.add(x + 12, y + 4, z + 9), ModBlocks.PROTOSS_METAL.getStateFromMeta(metaPrimColor));
		world.setBlockState(pos.add(x + 13, y + 4, z + 9), Blocks.AIR.getDefaultState());
		world.setBlockState(pos.add(x + 14, y + 4, z + 9), Blocks.AIR.getDefaultState());
		world.setBlockState(pos.add(x, y + 4, z + 10), Blocks.AIR.getDefaultState());
		world.setBlockState(pos.add(x + 1, y + 4, z + 10), Blocks.AIR.getDefaultState());
		world.setBlockState(pos.add(x + 2, y + 4, z + 10), ModBlocks.PROTOSS_METAL.getStateFromMeta(metaPrimColor));
		world.setBlockState(pos.add(x + 3, y + 4, z + 10), ModBlocks.PROTOSS_METAL.getStateFromMeta(metaPrimColor));
		world.setBlockState(pos.add(x + 4, y + 4, z + 10), ModBlocks.PROTOSS_METAL.getStateFromMeta(metaPrimColor));
		world.setBlockState(pos.add(x + 5, y + 4, z + 10), ModBlocks.PROTOSS_METAL.getStateFromMeta(metaPrimColor));
		world.setBlockState(pos.add(x + 6, y + 4, z + 10), ModBlocks.PROTOSS_METAL.getStateFromMeta(metaPrimColor));
		world.setBlockState(pos.add(x + 7, y + 4, z + 10), ModBlocks.PROTOSS_METAL.getStateFromMeta(metaPrimColor));
		world.setBlockState(pos.add(x + 8, y + 4, z + 10), ModBlocks.PROTOSS_METAL.getStateFromMeta(metaPrimColor));
		world.setBlockState(pos.add(x + 9, y + 4, z + 10), ModBlocks.PROTOSS_METAL.getStateFromMeta(metaPrimColor));
		world.setBlockState(pos.add(x + 10, y + 4, z + 10), ModBlocks.PROTOSS_METAL.getStateFromMeta(metaPrimColor));
		world.setBlockState(pos.add(x + 11, y + 4, z + 10), ModBlocks.PROTOSS_METAL.getStateFromMeta(metaPrimColor));
		world.setBlockState(pos.add(x + 12, y + 4, z + 10), ModBlocks.PROTOSS_METAL.getStateFromMeta(metaSecColor));
		world.setBlockState(pos.add(x + 13, y + 4, z + 10), Blocks.AIR.getDefaultState());
		world.setBlockState(pos.add(x + 14, y + 4, z + 10), Blocks.AIR.getDefaultState());
		world.setBlockState(pos.add(x, y + 4, z + 11), Blocks.AIR.getDefaultState());
		world.setBlockState(pos.add(x + 1, y + 4, z + 11), Blocks.AIR.getDefaultState());
		world.setBlockState(pos.add(x + 2, y + 4, z + 11), Blocks.AIR.getDefaultState());
		world.setBlockState(pos.add(x + 3, y + 4, z + 11), ModBlocks.PROTOSS_METAL.getStateFromMeta(metaSecColor));
		world.setBlockState(pos.add(x + 4, y + 4, z + 11), ModBlocks.PROTOSS_METAL.getStateFromMeta(metaPrimColor));
		world.setBlockState(pos.add(x + 5, y + 4, z + 11), ModBlocks.PROTOSS_METAL.getStateFromMeta(metaPrimColor));
		world.setBlockState(pos.add(x + 6, y + 4, z + 11), ModBlocks.PROTOSS_METAL.getStateFromMeta(metaPrimColor));
		world.setBlockState(pos.add(x + 7, y + 4, z + 11), ModBlocks.PROTOSS_METAL.getStateFromMeta(metaPrimColor));
		world.setBlockState(pos.add(x + 8, y + 4, z + 11), ModBlocks.PROTOSS_METAL.getStateFromMeta(metaPrimColor));
		world.setBlockState(pos.add(x + 9, y + 4, z + 11), ModBlocks.PROTOSS_METAL.getStateFromMeta(metaPrimColor));
		world.setBlockState(pos.add(x + 10, y + 4, z + 11), ModBlocks.PROTOSS_METAL.getStateFromMeta(metaPrimColor));
		world.setBlockState(pos.add(x + 11, y + 4, z + 11), ModBlocks.PROTOSS_METAL.getStateFromMeta(metaPrimColor));
		world.setBlockState(pos.add(x + 12, y + 4, z + 11), ModBlocks.PROTOSS_METAL.getStateFromMeta(metaPrimColor));
		world.setBlockState(pos.add(x + 13, y + 4, z + 11), Blocks.AIR.getDefaultState());
		world.setBlockState(pos.add(x + 14, y + 4, z + 11), Blocks.AIR.getDefaultState());
		world.setBlockState(pos.add(x, y + 4, z + 12), Blocks.AIR.getDefaultState());
		world.setBlockState(pos.add(x + 1, y + 4, z + 12), Blocks.AIR.getDefaultState());
		world.setBlockState(pos.add(x + 2, y + 4, z + 12), Blocks.AIR.getDefaultState());
		world.setBlockState(pos.add(x + 3, y + 4, z + 12), Blocks.AIR.getDefaultState());
		world.setBlockState(pos.add(x + 4, y + 4, z + 12), ModBlocks.PROTOSS_METAL.getStateFromMeta(metaPrimColor));
		world.setBlockState(pos.add(x + 5, y + 4, z + 12), Blocks.AIR.getDefaultState());
		world.setBlockState(pos.add(x + 6, y + 4, z + 12), Blocks.AIR.getDefaultState());
		world.setBlockState(pos.add(x + 7, y + 4, z + 12), Blocks.AIR.getDefaultState());
		world.setBlockState(pos.add(x + 8, y + 4, z + 12), Blocks.AIR.getDefaultState());
		world.setBlockState(pos.add(x + 9, y + 4, z + 12), ModBlocks.PROTOSS_METAL.getStateFromMeta(metaPrimColor));
		world.setBlockState(pos.add(x + 10, y + 4, z + 12), ModBlocks.PROTOSS_METAL.getStateFromMeta(metaSecColor));
		world.setBlockState(pos.add(x + 11, y + 4, z + 12), ModBlocks.PROTOSS_METAL.getStateFromMeta(metaPrimColor));
		world.setBlockState(pos.add(x + 12, y + 4, z + 12), ModBlocks.PROTOSS_METAL.getStateFromMeta(metaPrimColor));
		world.setBlockState(pos.add(x + 13, y + 4, z + 12), Blocks.AIR.getDefaultState());
		world.setBlockState(pos.add(x + 14, y + 4, z + 12), Blocks.AIR.getDefaultState());
		world.setBlockState(pos.add(x, y + 4, z + 13), Blocks.AIR.getDefaultState());
		world.setBlockState(pos.add(x + 1, y + 4, z + 13), Blocks.AIR.getDefaultState());
		world.setBlockState(pos.add(x + 2, y + 4, z + 13), Blocks.AIR.getDefaultState());
		world.setBlockState(pos.add(x + 3, y + 4, z + 13), Blocks.AIR.getDefaultState());
		world.setBlockState(pos.add(x + 4, y + 4, z + 13), Blocks.AIR.getDefaultState());
		world.setBlockState(pos.add(x + 5, y + 4, z + 13), Blocks.AIR.getDefaultState());
		world.setBlockState(pos.add(x + 6, y + 4, z + 13), Blocks.AIR.getDefaultState());
		world.setBlockState(pos.add(x + 7, y + 4, z + 13), Blocks.AIR.getDefaultState());
		world.setBlockState(pos.add(x + 8, y + 4, z + 13), Blocks.AIR.getDefaultState());
		world.setBlockState(pos.add(x + 9, y + 4, z + 13), Blocks.AIR.getDefaultState());
		world.setBlockState(pos.add(x + 10, y + 4, z + 13), Blocks.AIR.getDefaultState());
		world.setBlockState(pos.add(x + 11, y + 4, z + 13), Blocks.AIR.getDefaultState());
		world.setBlockState(pos.add(x + 12, y + 4, z + 13), Blocks.AIR.getDefaultState());
		world.setBlockState(pos.add(x + 13, y + 4, z + 13), Blocks.AIR.getDefaultState());
		world.setBlockState(pos.add(x + 14, y + 4, z + 13), Blocks.AIR.getDefaultState());
		world.setBlockState(pos.add(x, y + 4, z + 14), Blocks.AIR.getDefaultState());
		world.setBlockState(pos.add(x + 1, y + 4, z + 14), Blocks.AIR.getDefaultState());
		world.setBlockState(pos.add(x + 2, y + 4, z + 14), Blocks.AIR.getDefaultState());
		world.setBlockState(pos.add(x + 3, y + 4, z + 14), Blocks.AIR.getDefaultState());
		world.setBlockState(pos.add(x + 4, y + 4, z + 14), Blocks.AIR.getDefaultState());
		world.setBlockState(pos.add(x + 5, y + 4, z + 14), Blocks.AIR.getDefaultState());
		world.setBlockState(pos.add(x + 6, y + 4, z + 14), Blocks.AIR.getDefaultState());
		world.setBlockState(pos.add(x + 7, y + 4, z + 14), Blocks.AIR.getDefaultState());
		world.setBlockState(pos.add(x + 8, y + 4, z + 14), Blocks.AIR.getDefaultState());
		world.setBlockState(pos.add(x + 9, y + 4, z + 14), Blocks.AIR.getDefaultState());
		world.setBlockState(pos.add(x + 10, y + 4, z + 14), Blocks.AIR.getDefaultState());
		world.setBlockState(pos.add(x + 11, y + 4, z + 14), Blocks.AIR.getDefaultState());
		world.setBlockState(pos.add(x + 12, y + 4, z + 14), Blocks.AIR.getDefaultState());
		world.setBlockState(pos.add(x + 13, y + 4, z + 14), Blocks.AIR.getDefaultState());
		world.setBlockState(pos.add(x + 14, y + 4, z + 14), Blocks.AIR.getDefaultState());
		world.setBlockState(pos.add(x, y + 5, z), Blocks.AIR.getDefaultState());
		world.setBlockState(pos.add(x + 1, y + 5, z), Blocks.AIR.getDefaultState());
		world.setBlockState(pos.add(x + 2, y + 5, z), Blocks.AIR.getDefaultState());
		world.setBlockState(pos.add(x + 3, y + 5, z), Blocks.AIR.getDefaultState());
		world.setBlockState(pos.add(x + 4, y + 5, z), Blocks.AIR.getDefaultState());
		world.setBlockState(pos.add(x + 5, y + 5, z), Blocks.AIR.getDefaultState());
		world.setBlockState(pos.add(x + 6, y + 5, z), Blocks.AIR.getDefaultState());
		world.setBlockState(pos.add(x + 7, y + 5, z), Blocks.AIR.getDefaultState());
		world.setBlockState(pos.add(x + 8, y + 5, z), Blocks.AIR.getDefaultState());
		world.setBlockState(pos.add(x + 9, y + 5, z), Blocks.AIR.getDefaultState());
		world.setBlockState(pos.add(x + 10, y + 5, z), Blocks.AIR.getDefaultState());
		world.setBlockState(pos.add(x + 11, y + 5, z), Blocks.AIR.getDefaultState());
		world.setBlockState(pos.add(x + 12, y + 5, z), Blocks.AIR.getDefaultState());
		world.setBlockState(pos.add(x + 13, y + 5, z), Blocks.AIR.getDefaultState());
		world.setBlockState(pos.add(x + 14, y + 5, z), Blocks.AIR.getDefaultState());
		world.setBlockState(pos.add(x, y + 5, z + 1), Blocks.AIR.getDefaultState());
		world.setBlockState(pos.add(x + 1, y + 5, z + 1), Blocks.AIR.getDefaultState());
		world.setBlockState(pos.add(x + 2, y + 5, z + 1), ModBlocks.PROTOSS_METAL.getStateFromMeta(metaPrimColor));
		world.setBlockState(pos.add(x + 3, y + 5, z + 1), ModBlocks.PROTOSS_METAL.getStateFromMeta(metaPrimColor));
		world.setBlockState(pos.add(x + 4, y + 5, z + 1), Blocks.AIR.getDefaultState());
		world.setBlockState(pos.add(x + 5, y + 5, z + 1), Blocks.AIR.getDefaultState());
		world.setBlockState(pos.add(x + 6, y + 5, z + 1), Blocks.AIR.getDefaultState());
		world.setBlockState(pos.add(x + 7, y + 5, z + 1), Blocks.AIR.getDefaultState());
		world.setBlockState(pos.add(x + 8, y + 5, z + 1), Blocks.AIR.getDefaultState());
		world.setBlockState(pos.add(x + 9, y + 5, z + 1), Blocks.AIR.getDefaultState());
		world.setBlockState(pos.add(x + 10, y + 5, z + 1), Blocks.AIR.getDefaultState());
		world.setBlockState(pos.add(x + 11, y + 5, z + 1), Blocks.AIR.getDefaultState());
		world.setBlockState(pos.add(x + 12, y + 5, z + 1), Blocks.AIR.getDefaultState());
		world.setBlockState(pos.add(x + 13, y + 5, z + 1), Blocks.AIR.getDefaultState());
		world.setBlockState(pos.add(x + 14, y + 5, z + 1), Blocks.AIR.getDefaultState());
		world.setBlockState(pos.add(x, y + 5, z + 2), Blocks.AIR.getDefaultState());
		world.setBlockState(pos.add(x + 1, y + 5, z + 2), ModBlocks.PROTOSS_METAL.getStateFromMeta(metaPrimColor));
		world.setBlockState(pos.add(x + 2, y + 5, z + 2), ModBlocks.PROTOSS_METAL.getStateFromMeta(metaPrimColor));
		world.setBlockState(pos.add(x + 3, y + 5, z + 2), ModBlocks.PROTOSS_METAL.getStateFromMeta(metaPrimColor));
		world.setBlockState(pos.add(x + 4, y + 5, z + 2), ModBlocks.PROTOSS_METAL.getStateFromMeta(metaPrimColor));
		world.setBlockState(pos.add(x + 5, y + 5, z + 2), Blocks.AIR.getDefaultState());
		world.setBlockState(pos.add(x + 6, y + 5, z + 2), Blocks.AIR.getDefaultState());
		world.setBlockState(pos.add(x + 7, y + 5, z + 2), Blocks.AIR.getDefaultState());
		world.setBlockState(pos.add(x + 8, y + 5, z + 2), Blocks.AIR.getDefaultState());
		world.setBlockState(pos.add(x + 9, y + 5, z + 2), Blocks.AIR.getDefaultState());
		world.setBlockState(pos.add(x + 10, y + 5, z + 2), Blocks.AIR.getDefaultState());
		world.setBlockState(pos.add(x + 11, y + 5, z + 2), Blocks.AIR.getDefaultState());
		world.setBlockState(pos.add(x + 12, y + 5, z + 2), Blocks.AIR.getDefaultState());
		world.setBlockState(pos.add(x + 13, y + 5, z + 2), Blocks.AIR.getDefaultState());
		world.setBlockState(pos.add(x + 14, y + 5, z + 2), Blocks.AIR.getDefaultState());
		world.setBlockState(pos.add(x, y + 5, z + 3), Blocks.AIR.getDefaultState());
		world.setBlockState(pos.add(x + 1, y + 5, z + 3), ModBlocks.PROTOSS_METAL.getStateFromMeta(metaPrimColor));
		world.setBlockState(pos.add(x + 2, y + 5, z + 3), ModBlocks.PROTOSS_METAL.getStateFromMeta(metaPrimColor));
		world.setBlockState(pos.add(x + 3, y + 5, z + 3), chanBlock.getDefaultState());
		world.setBlockState(pos.add(x + 4, y + 5, z + 3), Blocks.AIR.getDefaultState());
		world.setBlockState(pos.add(x + 5, y + 5, z + 3), Blocks.AIR.getDefaultState());
		world.setBlockState(pos.add(x + 6, y + 5, z + 3), Blocks.AIR.getDefaultState());
		world.setBlockState(pos.add(x + 7, y + 5, z + 3), Blocks.AIR.getDefaultState());
		world.setBlockState(pos.add(x + 8, y + 5, z + 3), Blocks.AIR.getDefaultState());
		world.setBlockState(pos.add(x + 9, y + 5, z + 3), Blocks.AIR.getDefaultState());
		world.setBlockState(pos.add(x + 10, y + 5, z + 3), Blocks.AIR.getDefaultState());
		world.setBlockState(pos.add(x + 11, y + 5, z + 3), Blocks.AIR.getDefaultState());
		world.setBlockState(pos.add(x + 12, y + 5, z + 3), Blocks.AIR.getDefaultState());
		world.setBlockState(pos.add(x + 13, y + 5, z + 3), Blocks.AIR.getDefaultState());
		world.setBlockState(pos.add(x + 14, y + 5, z + 3), Blocks.AIR.getDefaultState());
		world.setBlockState(pos.add(x, y + 5, z + 4), Blocks.AIR.getDefaultState());
		world.setBlockState(pos.add(x + 1, y + 5, z + 4), Blocks.AIR.getDefaultState());
		world.setBlockState(pos.add(x + 2, y + 5, z + 4), ModBlocks.PROTOSS_METAL.getStateFromMeta(metaPrimColor));
		world.setBlockState(pos.add(x + 3, y + 5, z + 4), Blocks.AIR.getDefaultState());
		world.setBlockState(pos.add(x + 4, y + 5, z + 4), Blocks.AIR.getDefaultState());
		world.setBlockState(pos.add(x + 5, y + 5, z + 4), Blocks.AIR.getDefaultState());
		world.setBlockState(pos.add(x + 6, y + 5, z + 4), Blocks.AIR.getDefaultState());
		world.setBlockState(pos.add(x + 7, y + 5, z + 4), ModBlocks.PROTOSS_METAL.getStateFromMeta(metaPrimColor));
		world.setBlockState(pos.add(x + 8, y + 5, z + 4), ModBlocks.PROTOSS_METAL.getStateFromMeta(metaSecColor));
		world.setBlockState(pos.add(x + 9, y + 5, z + 4), ModBlocks.PROTOSS_METAL.getStateFromMeta(metaPrimColor));
		world.setBlockState(pos.add(x + 10, y + 5, z + 4), Blocks.AIR.getDefaultState());
		world.setBlockState(pos.add(x + 11, y + 5, z + 4), Blocks.AIR.getDefaultState());
		world.setBlockState(pos.add(x + 12, y + 5, z + 4), Blocks.AIR.getDefaultState());
		world.setBlockState(pos.add(x + 13, y + 5, z + 4), Blocks.AIR.getDefaultState());
		world.setBlockState(pos.add(x + 14, y + 5, z + 4), Blocks.AIR.getDefaultState());
		world.setBlockState(pos.add(x, y + 5, z + 5), Blocks.AIR.getDefaultState());
		world.setBlockState(pos.add(x + 1, y + 5, z + 5), Blocks.AIR.getDefaultState());
		world.setBlockState(pos.add(x + 2, y + 5, z + 5), Blocks.AIR.getDefaultState());
		world.setBlockState(pos.add(x + 3, y + 5, z + 5), Blocks.AIR.getDefaultState());
		world.setBlockState(pos.add(x + 4, y + 5, z + 5), Blocks.AIR.getDefaultState());
		world.setBlockState(pos.add(x + 5, y + 5, z + 5), stabBlock.getDefaultState());
		world.setBlockState(pos.add(x + 6, y + 5, z + 5), ModBlocks.PROTOSS_METAL.getStateFromMeta(metaPrimColor));
		world.setBlockState(pos.add(x + 7, y + 5, z + 5), ModBlocks.PROTOSS_METAL.getStateFromMeta(metaSecColor));
