package net.bvanseghi.starcraft.worldgen.structure;

import java.util.Random;

import net.bvanseghi.starcraft.blocks.ModBlocks;
import net.minecraft.block.Block;
import net.minecraft.block.material.Material;
import net.minecraft.init.Blocks;
import net.minecraft.world.World;
import net.minecraft.world.gen.feature.WorldGenerator;

public class StructureProtossDarkWarpGateChar extends WorldGenerator {
	protected Block[] getValidSpawnBlocks() {
		return new Block[] { Blocks.grass, Blocks.stone, Blocks.dirt, Blocks.gravel, ModBlocks.sandShakuras, ModBlocks.stoneShakuras };
	}

	public boolean locationIsValidSpawn(World world, int x, int y, int z) {
		int distanceToAir = 0;
		Block checkBlock = world.getBlock(x, y, z);

		while (checkBlock != Blocks.air) {
			distanceToAir++;
			checkBlock = world.getBlock(x, y + distanceToAir, z);
		}

		if (distanceToAir > 1) {
			return false;
		}

		y += distanceToAir - 1;

		Block block = world.getBlock(x, y, z);
		Block blockAbove = world.getBlock(x, y + 1, z);
		Block blockBelow = world.getBlock(x, y - 1, z);

		for (Block i : getValidSpawnBlocks()) {
			if (blockAbove != Blocks.air) {
				return false;
			}
			if (block == i) {
				return true;
			} else if (block == Blocks.snow_layer && blockBelow == i) {
				return true;
			} else if (block.getMaterial() == Material.plants && blockBelow == i) {
				return true;
			}
		}
		return false;
	}

	//Abstracted
	public boolean generate(World world, Random rand, int x, int y, int z) {
		int i = rand.nextInt(1);

		if (i == 0) {
			generator(world, x, y, z, (byte) 0); //how does do even
		}

		return true;
	}

	/**
	 * Calls the generators
	 * @param world the world
	 * @param x X coordinate
	 * @param y Y coordinate
	 * @param z Z coordinate
	 * @param metadata block metadata
	 */
	private void generator(World world, int x, int y, int z, byte metadata) {
		generatePart1(world, x, y, z, metadata);
	}
	
	public boolean generatePart1(World world, int x, int y, int z, byte metadata) {
		if (!locationIsValidSpawn(world, x, y, z) || !locationIsValidSpawn(world, x + 14, y, z)
				|| !locationIsValidSpawn(world, x + 14, y, z + 14) || !locationIsValidSpawn(world, x, y, z + 14)) {
			return false;
		}

		
		world.setBlock(x, y + 1, z, Blocks.air, 0, 3);
		world.setBlock(x + 1, y + 1, z, Blocks.air, 0, 3);
		world.setBlock(x + 2, y + 1, z, Blocks.air, 0, 3);
		world.setBlock(x + 3, y + 1, z, Blocks.air, 0, 3);
		world.setBlock(x + 4, y + 1, z, Blocks.air, 0, 3);
		world.setBlock(x + 5, y + 1, z, Blocks.air, 0, 3);
		world.setBlock(x + 6, y + 1, z, Blocks.air, 0, 3);
		world.setBlock(x + 7, y + 1, z, Blocks.air, 0, 3);
		world.setBlock(x + 8, y + 1, z, Blocks.air, 0, 3);
		world.setBlock(x + 9, y + 1, z, Blocks.air, 0, 3);
		world.setBlock(x + 10, y + 1, z, Blocks.air, 0, 3);
		world.setBlock(x + 11, y + 1, z, Blocks.air, 0, 3);
		world.setBlock(x + 12, y + 1, z, Blocks.air, 0, 3);
		world.setBlock(x + 13, y + 1, z, Blocks.air, 0, 3);
		world.setBlock(x + 14, y + 1, z, Blocks.air, 0, 3);
		world.setBlock(x, y + 1, z + 1, Blocks.air, 0, 3);
		world.setBlock(x + 1, y + 1, z + 1, ModBlocks.protossMetal, 1, 3);
		world.setBlock(x + 2, y + 1, z + 1, ModBlocks.protossMetal, 1, 3);
		world.setBlock(x + 3, y + 1, z + 1, Blocks.air, 0, 3);
		world.setBlock(x + 4, y + 1, z + 1, ModBlocks.protossMetal, 1, 3);
		world.setBlock(x + 5, y + 1, z + 1, ModBlocks.protossMetal, 1, 3);
		world.setBlock(x + 6, y + 1, z + 1, Blocks.air, 0, 3);
		world.setBlock(x + 7, y + 1, z + 1, ModBlocks.protossMetal, 1, 3);
		world.setBlock(x + 8, y + 1, z + 1, ModBlocks.protossMetal, 1, 3);
		world.setBlock(x + 9, y + 1, z + 1, Blocks.air, 0, 3);
		world.setBlock(x + 10, y + 1, z + 1, ModBlocks.protossMetal, 1, 3);
		world.setBlock(x + 11, y + 1, z + 1, ModBlocks.protossMetal, 1, 3);
		world.setBlock(x + 12, y + 1, z + 1, ModBlocks.protossMetal, 1, 3);
		world.setBlock(x + 13, y + 1, z + 1, ModBlocks.protossMetal, 1, 3);
		world.setBlock(x + 14, y + 1, z + 1, Blocks.air, 0, 3);
		world.setBlock(x, y + 1, z + 2, Blocks.air, 0, 3);
		world.setBlock(x + 1, y + 1, z + 2, ModBlocks.protossMetal, 1, 3);
		world.setBlock(x + 2, y + 1, z + 2, ModBlocks.protossMetal, 1, 3);
		world.setBlock(x + 3, y + 1, z + 2, ModBlocks.protossMetal, 1, 3);
		world.setBlock(x + 4, y + 1, z + 2, ModBlocks.protossMetal, 1, 3);
		world.setBlock(x + 5, y + 1, z + 2, ModBlocks.protossMetal, 1, 3);
		world.setBlock(x + 6, y + 1, z + 2, ModBlocks.protossMetal, 1, 3);
		world.setBlock(x + 7, y + 1, z + 2, ModBlocks.protossMetal, 1, 3);
		world.setBlock(x + 8, y + 1, z + 2, ModBlocks.protossMetal, 1, 3);
		world.setBlock(x + 9, y + 1, z + 2, ModBlocks.protossMetal, 1, 3);
		world.setBlock(x + 10, y + 1, z + 2, ModBlocks.protossMetal, 1, 3);
		world.setBlock(x + 11, y + 1, z + 2, ModBlocks.protossMetal, 1, 3);
		world.setBlock(x + 12, y + 1, z + 2, ModBlocks.protossMetal, 1, 3);
		world.setBlock(x + 13, y + 1, z + 2, ModBlocks.protossMetal, 1, 3);
		world.setBlock(x + 14, y + 1, z + 2, Blocks.air, 0, 3);
		world.setBlock(x, y + 1, z + 3, Blocks.air, 0, 3);
		world.setBlock(x + 1, y + 1, z + 3, Blocks.air, 0, 3);
		world.setBlock(x + 2, y + 1, z + 3, ModBlocks.protossMetal, 1, 3);
		world.setBlock(x + 3, y + 1, z + 3, ModBlocks.protossMetal, 1, 3);
		world.setBlock(x + 4, y + 1, z + 3, ModBlocks.protossMetal, 1, 3);
		world.setBlock(x + 5, y + 1, z + 3, ModBlocks.protossMetal, 1, 3);
		world.setBlock(x + 6, y + 1, z + 3, ModBlocks.protossMetal, 1, 3);
		world.setBlock(x + 7, y + 1, z + 3, ModBlocks.protossMetal, 1, 3);
		world.setBlock(x + 8, y + 1, z + 3, ModBlocks.protossMetal, 1, 3);
		world.setBlock(x + 9, y + 1, z + 3, ModBlocks.protossMetal, 1, 3);
		world.setBlock(x + 10, y + 1, z + 3, ModBlocks.protossMetal, 1, 3);
		world.setBlock(x + 11, y + 1, z + 3, ModBlocks.protossMetal, 1, 3);
		world.setBlock(x + 12, y + 1, z + 3, ModBlocks.protossMetal, 1, 3);
		world.setBlock(x + 13, y + 1, z + 3, ModBlocks.protossMetal, 1, 3);
		world.setBlock(x + 14, y + 1, z + 3, Blocks.air, 0, 3);
		world.setBlock(x, y + 1, z + 4, Blocks.air, 0, 3);
		world.setBlock(x + 1, y + 1, z + 4, ModBlocks.protossMetal, 1, 3);
		world.setBlock(x + 2, y + 1, z + 4, ModBlocks.protossMetal, 1, 3);
		world.setBlock(x + 3, y + 1, z + 4, ModBlocks.protossMetal, 1, 3);
		world.setBlock(x + 4, y + 1, z + 4, ModBlocks.protossMetal, 1, 3);
		world.setBlock(x + 5, y + 1, z + 4, ModBlocks.protossMetal, 1, 3);
		world.setBlock(x + 6, y + 1, z + 4, ModBlocks.protossMetal, 1, 3);
		world.setBlock(x + 7, y + 1, z + 4, ModBlocks.protossMetal, 1, 3);
		world.setBlock(x + 8, y + 1, z + 4, ModBlocks.protossMetal, 1, 3);
		world.setBlock(x + 9, y + 1, z + 4, ModBlocks.protossMetal, 1, 3);
		world.setBlock(x + 10, y + 1, z + 4, ModBlocks.protossMetal, 1, 3);
		world.setBlock(x + 11, y + 1, z + 4, ModBlocks.protossMetal, 1, 3);
		world.setBlock(x + 12, y + 1, z + 4, ModBlocks.protossMetal, 1, 3);
		world.setBlock(x + 13, y + 1, z + 4, ModBlocks.protossMetal, 1, 3);
		world.setBlock(x + 14, y + 1, z + 4, Blocks.air, 0, 3);
		world.setBlock(x, y + 1, z + 5, Blocks.air, 0, 3);
		world.setBlock(x + 1, y + 1, z + 5, ModBlocks.protossMetal, 1, 3);
		world.setBlock(x + 2, y + 1, z + 5, ModBlocks.protossMetal, 1, 3);
		world.setBlock(x + 3, y + 1, z + 5, ModBlocks.protossMetal, 1, 3);
		world.setBlock(x + 4, y + 1, z + 5, ModBlocks.protossMetal, 1, 3);
		world.setBlock(x + 5, y + 1, z + 5, ModBlocks.protossMetal, 1, 3);
		world.setBlock(x + 6, y + 1, z + 5, ModBlocks.protossMetal, 1, 3);
		world.setBlock(x + 7, y + 1, z + 5, ModBlocks.protossMetal, 1, 3);
		world.setBlock(x + 8, y + 1, z + 5, ModBlocks.protossMetal, 1, 3);
		world.setBlock(x + 9, y + 1, z + 5, ModBlocks.protossMetal, 1, 3);
		world.setBlock(x + 10, y + 1, z + 5, ModBlocks.protossMetal, 1, 3);
		world.setBlock(x + 11, y + 1, z + 5, ModBlocks.protossMetal, 1, 3);
		world.setBlock(x + 12, y + 1, z + 5, ModBlocks.protossMetal, 1, 3);
		world.setBlock(x + 13, y + 1, z + 5, Blocks.air, 0, 3);
		world.setBlock(x + 14, y + 1, z + 5, Blocks.air, 0, 3);
		world.setBlock(x, y + 1, z + 6, Blocks.air, 0, 3);
		world.setBlock(x + 1, y + 1, z + 6, Blocks.air, 0, 3);
		world.setBlock(x + 2, y + 1, z + 6, ModBlocks.protossMetal, 1, 3);
		world.setBlock(x + 3, y + 1, z + 6, ModBlocks.protossMetal, 1, 3);
		world.setBlock(x + 4, y + 1, z + 6, ModBlocks.protossMetal, 1, 3);
		world.setBlock(x + 5, y + 1, z + 6, ModBlocks.protossMetal, 1, 3);
		world.setBlock(x + 6, y + 1, z + 6, ModBlocks.protossMetal, 1, 3);
		world.setBlock(x + 7, y + 1, z + 6, ModBlocks.protossMetal, 1, 3);
		world.setBlock(x + 8, y + 1, z + 6, ModBlocks.protossMetal, 1, 3);
		world.setBlock(x + 9, y + 1, z + 6, ModBlocks.protossMetal, 1, 3);
		world.setBlock(x + 10, y + 1, z + 6, ModBlocks.protossMetal, 1, 3);
		world.setBlock(x + 11, y + 1, z + 6, ModBlocks.protossMetal, 1, 3);
		world.setBlock(x + 12, y + 1, z + 6, ModBlocks.protossMetal, 1, 3);
		world.setBlock(x + 13, y + 1, z + 6, ModBlocks.protossMetal, 1, 3);
		world.setBlock(x + 14, y + 1, z + 6, Blocks.air, 0, 3);
		world.setBlock(x, y + 1, z + 7, Blocks.air, 0, 3);
		world.setBlock(x + 1, y + 1, z + 7, ModBlocks.protossMetal, 1, 3);
		world.setBlock(x + 2, y + 1, z + 7, ModBlocks.protossMetal, 1, 3);
		world.setBlock(x + 3, y + 1, z + 7, ModBlocks.protossMetal, 1, 3);
		world.setBlock(x + 4, y + 1, z + 7, ModBlocks.protossMetal, 1, 3);
		world.setBlock(x + 5, y + 1, z + 7, ModBlocks.protossMetal, 1, 3);
		world.setBlock(x + 6, y + 1, z + 7, ModBlocks.protossMetal, 1, 3);
		world.setBlock(x + 7, y + 1, z + 7, ModBlocks.protossMetal, 1, 3);
		world.setBlock(x + 8, y + 1, z + 7, ModBlocks.protossMetal, 1, 3);
		world.setBlock(x + 9, y + 1, z + 7, ModBlocks.protossMetal, 1, 3);
		world.setBlock(x + 10, y + 1, z + 7, ModBlocks.protossMetal, 1, 3);
		world.setBlock(x + 11, y + 1, z + 7, ModBlocks.protossMetal, 1, 3);
		world.setBlock(x + 12, y + 1, z + 7, ModBlocks.protossMetal, 1, 3);
		world.setBlock(x + 13, y + 1, z + 7, ModBlocks.protossMetal, 1, 3);
		world.setBlock(x + 14, y + 1, z + 7, Blocks.air, 0, 3);
		world.setBlock(x, y + 1, z + 8, Blocks.air, 0, 3);
		world.setBlock(x + 1, y + 1, z + 8, ModBlocks.protossMetal, 1, 3);
		world.setBlock(x + 2, y + 1, z + 8, ModBlocks.protossMetal, 1, 3);
		world.setBlock(x + 3, y + 1, z + 8, ModBlocks.protossMetal, 1, 3);
		world.setBlock(x + 4, y + 1, z + 8, ModBlocks.protossMetal, 1, 3);
		world.setBlock(x + 5, y + 1, z + 8, ModBlocks.protossMetal, 1, 3);
		world.setBlock(x + 6, y + 1, z + 8, ModBlocks.protossMetal, 1, 3);
		world.setBlock(x + 7, y + 1, z + 8, ModBlocks.protossMetal, 1, 3);
		world.setBlock(x + 8, y + 1, z + 8, ModBlocks.protossMetal, 1, 3);
		world.setBlock(x + 9, y + 1, z + 8, ModBlocks.protossMetal, 1, 3);
		world.setBlock(x + 10, y + 1, z + 8, ModBlocks.protossMetal, 1, 3);
		world.setBlock(x + 11, y + 1, z + 8, ModBlocks.protossMetal, 1, 3);
		world.setBlock(x + 12, y + 1, z + 8, ModBlocks.protossMetal, 1, 3);
		world.setBlock(x + 13, y + 1, z + 8, Blocks.air, 0, 3);
		world.setBlock(x + 14, y + 1, z + 8, Blocks.air, 0, 3);
		world.setBlock(x, y + 1, z + 9, Blocks.air, 0, 3);
		world.setBlock(x + 1, y + 1, z + 9, Blocks.air, 0, 3);
		world.setBlock(x + 2, y + 1, z + 9, ModBlocks.protossMetal, 1, 3);
		world.setBlock(x + 3, y + 1, z + 9, ModBlocks.protossMetal, 1, 3);
		world.setBlock(x + 4, y + 1, z + 9, ModBlocks.protossMetal, 1, 3);
		world.setBlock(x + 5, y + 1, z + 9, ModBlocks.protossMetal, 1, 3);
		world.setBlock(x + 6, y + 1, z + 9, ModBlocks.protossMetal, 1, 3);
		world.setBlock(x + 7, y + 1, z + 9, ModBlocks.protossMetal, 1, 3);
		world.setBlock(x + 8, y + 1, z + 9, ModBlocks.protossMetal, 1, 3);
		world.setBlock(x + 9, y + 1, z + 9, ModBlocks.protossMetal, 1, 3);
		world.setBlock(x + 10, y + 1, z + 9, ModBlocks.protossMetal, 1, 3);
		world.setBlock(x + 11, y + 1, z + 9, ModBlocks.protossMetal, 1, 3);
		world.setBlock(x + 12, y + 1, z + 9, ModBlocks.protossMetal, 1, 3);
		world.setBlock(x + 13, y + 1, z + 9, ModBlocks.protossMetal, 1, 3);
		world.setBlock(x + 14, y + 1, z + 9, Blocks.air, 0, 3);
		world.setBlock(x, y + 1, z + 10, Blocks.air, 0, 3);
		world.setBlock(x + 1, y + 1, z + 10, ModBlocks.protossMetal, 1, 3);
		world.setBlock(x + 2, y + 1, z + 10, ModBlocks.protossMetal, 1, 3);
		world.setBlock(x + 3, y + 1, z + 10, ModBlocks.protossMetal, 1, 3);
		world.setBlock(x + 4, y + 1, z + 10, ModBlocks.protossMetal, 1, 3);
		world.setBlock(x + 5, y + 1, z + 10, ModBlocks.protossMetal, 1, 3);
		world.setBlock(x + 6, y + 1, z + 10, ModBlocks.protossMetal, 1, 3);
		world.setBlock(x + 7, y + 1, z + 10, ModBlocks.protossMetal, 1, 3);
		world.setBlock(x + 8, y + 1, z + 10, ModBlocks.protossMetal, 1, 3);
		world.setBlock(x + 9, y + 1, z + 10, ModBlocks.protossMetal, 1, 3);
		world.setBlock(x + 10, y + 1, z + 10, ModBlocks.protossMetal, 1, 3);
		world.setBlock(x + 11, y + 1, z + 10, ModBlocks.protossMetal, 1, 3);
		world.setBlock(x + 12, y + 1, z + 10, ModBlocks.protossMetal, 1, 3);
		world.setBlock(x + 13, y + 1, z + 10, ModBlocks.protossMetal, 1, 3);
		world.setBlock(x + 14, y + 1, z + 10, Blocks.air, 0, 3);
		world.setBlock(x, y + 1, z + 11, Blocks.air, 0, 3);
		world.setBlock(x + 1, y + 1, z + 11, ModBlocks.protossMetal, 1, 3);
		world.setBlock(x + 2, y + 1, z + 11, ModBlocks.protossMetal, 1, 3);
		world.setBlock(x + 3, y + 1, z + 11, ModBlocks.protossMetal, 1, 3);
		world.setBlock(x + 4, y + 1, z + 11, ModBlocks.protossMetal, 1, 3);
		world.setBlock(x + 5, y + 1, z + 11, ModBlocks.protossMetal, 1, 3);
		world.setBlock(x + 6, y + 1, z + 11, ModBlocks.protossMetal, 1, 3);
		world.setBlock(x + 7, y + 1, z + 11, ModBlocks.protossMetal, 1, 3);
		world.setBlock(x + 8, y + 1, z + 11, ModBlocks.protossMetal, 1, 3);
		world.setBlock(x + 9, y + 1, z + 11, ModBlocks.protossMetal, 1, 3);
		world.setBlock(x + 10, y + 1, z + 11, ModBlocks.protossMetal, 1, 3);
		world.setBlock(x + 11, y + 1, z + 11, ModBlocks.protossMetal, 1, 3);
		world.setBlock(x + 12, y + 1, z + 11, ModBlocks.protossMetal, 1, 3);
		world.setBlock(x + 13, y + 1, z + 11, Blocks.air, 0, 3);
		world.setBlock(x + 14, y + 1, z + 11, Blocks.air, 0, 3);
		world.setBlock(x, y + 1, z + 12, Blocks.air, 0, 3);
		world.setBlock(x + 1, y + 1, z + 12, ModBlocks.protossMetal, 1, 3);
		world.setBlock(x + 2, y + 1, z + 12, ModBlocks.protossMetal, 1, 3);
		world.setBlock(x + 3, y + 1, z + 12, ModBlocks.protossMetal, 1, 3);
		world.setBlock(x + 4, y + 1, z + 12, ModBlocks.protossMetal, 1, 3);
		world.setBlock(x + 5, y + 1, z + 12, ModBlocks.protossMetal, 1, 3);
		world.setBlock(x + 6, y + 1, z + 12, ModBlocks.protossMetal, 1, 3);
		world.setBlock(x + 7, y + 1, z + 12, ModBlocks.protossMetal, 1, 3);
		world.setBlock(x + 8, y + 1, z + 12, ModBlocks.protossMetal, 1, 3);
		world.setBlock(x + 9, y + 1, z + 12, ModBlocks.protossMetal, 1, 3);
		world.setBlock(x + 10, y + 1, z + 12, ModBlocks.protossMetal, 1, 3);
		world.setBlock(x + 11, y + 1, z + 12, ModBlocks.protossMetal, 1, 3);
		world.setBlock(x + 12, y + 1, z + 12, ModBlocks.protossMetal, 1, 3);
		world.setBlock(x + 13, y + 1, z + 12, ModBlocks.protossMetal, 1, 3);
		world.setBlock(x + 14, y + 1, z + 12, Blocks.air, 0, 3);
		world.setBlock(x, y + 1, z + 13, Blocks.air, 0, 3);
		world.setBlock(x + 1, y + 1, z + 13, ModBlocks.protossMetal, 1, 3);
		world.setBlock(x + 2, y + 1, z + 13, ModBlocks.protossMetal, 1, 3);
		world.setBlock(x + 3, y + 1, z + 13, ModBlocks.protossMetal, 1, 3);
		world.setBlock(x + 4, y + 1, z + 13, ModBlocks.protossMetal, 1, 3);
		world.setBlock(x + 5, y + 1, z + 13, Blocks.air, 0, 3);
		world.setBlock(x + 6, y + 1, z + 13, ModBlocks.protossMetal, 1, 3);
		world.setBlock(x + 7, y + 1, z + 13, ModBlocks.protossMetal, 1, 3);
		world.setBlock(x + 8, y + 1, z + 13, Blocks.air, 0, 3);
		world.setBlock(x + 9, y + 1, z + 13, ModBlocks.protossMetal, 1, 3);
		world.setBlock(x + 10, y + 1, z + 13, ModBlocks.protossMetal, 1, 3);
		world.setBlock(x + 11, y + 1, z + 13, Blocks.air, 0, 3);
		world.setBlock(x + 12, y + 1, z + 13, ModBlocks.protossMetal, 1, 3);
		world.setBlock(x + 13, y + 1, z + 13, ModBlocks.protossMetal, 1, 3);
		world.setBlock(x + 14, y + 1, z + 13, Blocks.air, 0, 3);
		world.setBlock(x, y + 1, z + 14, Blocks.air, 0, 3);
		world.setBlock(x + 1, y + 1, z + 14, Blocks.air, 0, 3);
		world.setBlock(x + 2, y + 1, z + 14, Blocks.air, 0, 3);
		world.setBlock(x + 3, y + 1, z + 14, Blocks.air, 0, 3);
		world.setBlock(x + 4, y + 1, z + 14, Blocks.air, 0, 3);
		world.setBlock(x + 5, y + 1, z + 14, Blocks.air, 0, 3);
		world.setBlock(x + 6, y + 1, z + 14, Blocks.air, 0, 3);
		world.setBlock(x + 7, y + 1, z + 14, Blocks.air, 0, 3);
		world.setBlock(x + 8, y + 1, z + 14, Blocks.air, 0, 3);
		world.setBlock(x + 9, y + 1, z + 14, Blocks.air, 0, 3);
		world.setBlock(x + 10, y + 1, z + 14, Blocks.air, 0, 3);
		world.setBlock(x + 11, y + 1, z + 14, Blocks.air, 0, 3);
		world.setBlock(x + 12, y + 1, z + 14, Blocks.air, 0, 3);
		world.setBlock(x + 13, y + 1, z + 14, Blocks.air, 0, 3);
		world.setBlock(x + 14, y + 1, z + 14, Blocks.air, 0, 3);
		world.setBlock(x, y + 2, z, Blocks.air, 0, 3);
		world.setBlock(x + 1, y + 2, z, Blocks.air, 0, 3);
		world.setBlock(x + 2, y + 2, z, Blocks.air, 0, 3);
		world.setBlock(x + 3, y + 2, z, Blocks.air, 0, 3);
		world.setBlock(x + 4, y + 2, z, Blocks.air, 0, 3);
		world.setBlock(x + 5, y + 2, z, Blocks.air, 0, 3);
		world.setBlock(x + 6, y + 2, z, Blocks.air, 0, 3);
		world.setBlock(x + 7, y + 2, z, Blocks.air, 0, 3);
		world.setBlock(x + 8, y + 2, z, Blocks.air, 0, 3);
		world.setBlock(x + 9, y + 2, z, Blocks.air, 0, 3);
		world.setBlock(x + 10, y + 2, z, Blocks.air, 0, 3);
		world.setBlock(x + 11, y + 2, z, Blocks.air, 0, 3);
		world.setBlock(x + 12, y + 2, z, Blocks.air, 0, 3);
		world.setBlock(x + 13, y + 2, z, Blocks.air, 0, 3);
		world.setBlock(x + 14, y + 2, z, Blocks.air, 0, 3);
		world.setBlock(x, y + 2, z + 1, Blocks.air, 0, 3);
		world.setBlock(x + 1, y + 2, z + 1, ModBlocks.protossMetal, 1, 3);
		world.setBlock(x + 2, y + 2, z + 1, ModBlocks.protossMetal, 1, 3);
		world.setBlock(x + 3, y + 2, z + 1, Blocks.air, 0, 3);
		world.setBlock(x + 4, y + 2, z + 1, ModBlocks.protossMetal, 1, 3);
		world.setBlock(x + 5, y + 2, z + 1, ModBlocks.protossMetal, 1, 3);
		world.setBlock(x + 6, y + 2, z + 1, Blocks.air, 0, 3);
		world.setBlock(x + 7, y + 2, z + 1, ModBlocks.protossMetal, 1, 3);
		world.setBlock(x + 8, y + 2, z + 1, ModBlocks.protossMetal, 1, 3);
		world.setBlock(x + 9, y + 2, z + 1, Blocks.air, 0, 3);
		world.setBlock(x + 10, y + 2, z + 1, ModBlocks.protossMetal, 1, 3);
		world.setBlock(x + 11, y + 2, z + 1, ModBlocks.protossMetal, 3, 3);
		world.setBlock(x + 12, y + 2, z + 1, ModBlocks.protossMetal, 3, 3);
		world.setBlock(x + 13, y + 2, z + 1, Blocks.air, 0, 3);
		world.setBlock(x + 14, y + 2, z + 1, Blocks.air, 0, 3);
		world.setBlock(x, y + 2, z + 2, Blocks.air, 0, 3);
		world.setBlock(x + 1, y + 2, z + 2, ModBlocks.protossMetal, 1, 3);
		world.setBlock(x + 2, y + 2, z + 2, ModBlocks.protossMetal, 1, 3);
		world.setBlock(x + 3, y + 2, z + 2, ModBlocks.protossMetal, 1, 3);
		world.setBlock(x + 4, y + 2, z + 2, ModBlocks.protossMetal, 1, 3);
		world.setBlock(x + 5, y + 2, z + 2, ModBlocks.protossMetal, 1, 3);
		world.setBlock(x + 6, y + 2, z + 2, ModBlocks.protossMetal, 1, 3);
		world.setBlock(x + 7, y + 2, z + 2, ModBlocks.protossMetal, 1, 3);
		world.setBlock(x + 8, y + 2, z + 2, ModBlocks.protossMetal, 1, 3);
		world.setBlock(x + 9, y + 2, z + 2, ModBlocks.protossMetal, 1, 3);
		world.setBlock(x + 10, y + 2, z + 2, ModBlocks.protossMetal, 1, 3);
		world.setBlock(x + 11, y + 2, z + 2, ModBlocks.protossMetal, 1, 3);
		world.setBlock(x + 12, y + 2, z + 2, ModBlocks.protossMetal, 3, 3);
		world.setBlock(x + 13, y + 2, z + 2, ModBlocks.protossMetal, 3, 3);
		world.setBlock(x + 14, y + 2, z + 2, Blocks.air, 0, 3);
		world.setBlock(x, y + 2, z + 3, Blocks.air, 0, 3);
		world.setBlock(x + 1, y + 2, z + 3, Blocks.air, 0, 3);
		world.setBlock(x + 2, y + 2, z + 3, ModBlocks.protossMetal, 1, 3);
		world.setBlock(x + 3, y + 2, z + 3, ModBlocks.protossMetal, 1, 3);
		world.setBlock(x + 4, y + 2, z + 3, ModBlocks.protossMetal, 1, 3);
		world.setBlock(x + 5, y + 2, z + 3, ModBlocks.protossMetal, 1, 3);
		world.setBlock(x + 6, y + 2, z + 3, ModBlocks.protossMetal, 1, 3);
		world.setBlock(x + 7, y + 2, z + 3, ModBlocks.protossMetal, 1, 3);
		world.setBlock(x + 8, y + 2, z + 3, ModBlocks.protossMetal, 1, 3);
		world.setBlock(x + 9, y + 2, z + 3, ModBlocks.protossMetal, 1, 3);
		world.setBlock(x + 10, y + 2, z + 3, ModBlocks.protossMetal, 1, 3);
		world.setBlock(x + 11, y + 2, z + 3, ModBlocks.protossMetal, 1, 3);
		world.setBlock(x + 12, y + 2, z + 3, ModBlocks.protossMetal, 1, 3);
		world.setBlock(x + 13, y + 2, z + 3, ModBlocks.protossMetal, 3, 3);
		world.setBlock(x + 14, y + 2, z + 3, Blocks.air, 0, 3);
		world.setBlock(x, y + 2, z + 4, Blocks.air, 0, 3);
		world.setBlock(x + 1, y + 2, z + 4, ModBlocks.protossMetal, 1, 3);
		world.setBlock(x + 2, y + 2, z + 4, ModBlocks.protossMetal, 1, 3);
		world.setBlock(x + 3, y + 2, z + 4, ModBlocks.protossMetal, 1, 3);
		world.setBlock(x + 4, y + 2, z + 4, ModBlocks.protossMetal, 1, 3);
		world.setBlock(x + 5, y + 2, z + 4, ModBlocks.protossMetal, 1, 3);
		world.setBlock(x + 6, y + 2, z + 4, ModBlocks.protossMetal, 1, 3);
		world.setBlock(x + 7, y + 2, z + 4, ModBlocks.protossMetal, 1, 3);
		world.setBlock(x + 8, y + 2, z + 4, ModBlocks.protossMetal, 1, 3);
		world.setBlock(x + 9, y + 2, z + 4, ModBlocks.protossMetal, 1, 3);
		world.setBlock(x + 10, y + 2, z + 4, ModBlocks.protossMetal, 1, 3);
		world.setBlock(x + 11, y + 2, z + 4, ModBlocks.protossMetal, 1, 3);
		world.setBlock(x + 12, y + 2, z + 4, ModBlocks.protossMetal, 1, 3);
		world.setBlock(x + 13, y + 2, z + 4, ModBlocks.protossMetal, 1, 3);
		world.setBlock(x + 14, y + 2, z + 4, Blocks.air, 0, 3);
		world.setBlock(x, y + 2, z + 5, Blocks.air, 0, 3);
		world.setBlock(x + 1, y + 2, z + 5, ModBlocks.protossMetal, 1, 3);
		world.setBlock(x + 2, y + 2, z + 5, ModBlocks.protossMetal, 1, 3);
		world.setBlock(x + 3, y + 2, z + 5, ModBlocks.protossMetal, 1, 3);
		world.setBlock(x + 4, y + 2, z + 5, ModBlocks.protossMetal, 1, 3);
		world.setBlock(x + 5, y + 2, z + 5, ModBlocks.protossMetal, 1, 3);
		world.setBlock(x + 6, y + 2, z + 5, ModBlocks.protossMetal, 1, 3);
		world.setBlock(x + 7, y + 2, z + 5, ModBlocks.protossMetal, 1, 3);
		world.setBlock(x + 8, y + 2, z + 5, ModBlocks.protossMetal, 1, 3);
		world.setBlock(x + 9, y + 2, z + 5, ModBlocks.protossMetal, 1, 3);
		world.setBlock(x + 10, y + 2, z + 5, ModBlocks.protossMetal, 1, 3);
		world.setBlock(x + 11, y + 2, z + 5, ModBlocks.protossMetal, 1, 3);
		world.setBlock(x + 12, y + 2, z + 5, ModBlocks.protossMetal, 1, 3);
		world.setBlock(x + 13, y + 2, z + 5, Blocks.air, 0, 3);
		world.setBlock(x + 14, y + 2, z + 5, Blocks.air, 0, 3);
		world.setBlock(x, y + 2, z + 6, Blocks.air, 0, 3);
		world.setBlock(x + 1, y + 2, z + 6, Blocks.air, 0, 3);
		world.setBlock(x + 2, y + 2, z + 6, ModBlocks.protossMetal, 1, 3);
		world.setBlock(x + 3, y + 2, z + 6, ModBlocks.protossMetal, 1, 3);
		world.setBlock(x + 4, y + 2, z + 6, ModBlocks.protossMetal, 1, 3);
		world.setBlock(x + 5, y + 2, z + 6, ModBlocks.protossMetal, 1, 3);
		world.setBlock(x + 6, y + 2, z + 6, ModBlocks.protossMetal, 1, 3);
		world.setBlock(x + 7, y + 2, z + 6, ModBlocks.protossMetal, 1, 3);
		world.setBlock(x + 8, y + 2, z + 6, ModBlocks.protossMetal, 1, 3);
		world.setBlock(x + 9, y + 2, z + 6, ModBlocks.protossMetal, 1, 3);
		world.setBlock(x + 10, y + 2, z + 6, ModBlocks.protossMetal, 1, 3);
		world.setBlock(x + 11, y + 2, z + 6, ModBlocks.protossMetal, 1, 3);
		world.setBlock(x + 12, y + 2, z + 6, ModBlocks.protossMetal, 1, 3);
		world.setBlock(x + 13, y + 2, z + 6, ModBlocks.protossMetal, 1, 3);
		world.setBlock(x + 14, y + 2, z + 6, Blocks.air, 0, 3);
		world.setBlock(x, y + 2, z + 7, Blocks.air, 0, 3);
		world.setBlock(x + 1, y + 2, z + 7, ModBlocks.protossMetal, 1, 3);
		world.setBlock(x + 2, y + 2, z + 7, ModBlocks.protossMetal, 1, 3);
		world.setBlock(x + 3, y + 2, z + 7, ModBlocks.protossMetal, 1, 3);
		world.setBlock(x + 4, y + 2, z + 7, ModBlocks.protossMetal, 1, 3);
		world.setBlock(x + 5, y + 2, z + 7, ModBlocks.protossMetal, 1, 3);
		world.setBlock(x + 6, y + 2, z + 7, ModBlocks.protossMetal, 1, 3);
		world.setBlock(x + 7, y + 2, z + 7, ModBlocks.protossMetal, 1, 3);
		world.setBlock(x + 8, y + 2, z + 7, ModBlocks.protossMetal, 1, 3);
		world.setBlock(x + 9, y + 2, z + 7, ModBlocks.protossMetal, 1, 3);
		world.setBlock(x + 10, y + 2, z + 7, ModBlocks.protossMetal, 1, 3);
		world.setBlock(x + 11, y + 2, z + 7, ModBlocks.protossMetal, 1, 3);
		world.setBlock(x + 12, y + 2, z + 7, ModBlocks.protossMetal, 1, 3);
		world.setBlock(x + 13, y + 2, z + 7, ModBlocks.protossMetal, 1, 3);
		world.setBlock(x + 14, y + 2, z + 7, Blocks.air, 0, 3);
		world.setBlock(x, y + 2, z + 8, Blocks.air, 0, 3);
		world.setBlock(x + 1, y + 2, z + 8, ModBlocks.protossMetal, 1, 3);
		world.setBlock(x + 2, y + 2, z + 8, ModBlocks.protossMetal, 1, 3);
		world.setBlock(x + 3, y + 2, z + 8, ModBlocks.protossMetal, 1, 3);
		world.setBlock(x + 4, y + 2, z + 8, ModBlocks.protossMetal, 1, 3);
		world.setBlock(x + 5, y + 2, z + 8, ModBlocks.protossMetal, 1, 3);
		world.setBlock(x + 6, y + 2, z + 8, ModBlocks.protossMetal, 1, 3);
		world.setBlock(x + 7, y + 2, z + 8, ModBlocks.protossMetal, 1, 3);
		world.setBlock(x + 8, y + 2, z + 8, ModBlocks.protossMetal, 1, 3);
		world.setBlock(x + 9, y + 2, z + 8, ModBlocks.protossMetal, 1, 3);
		world.setBlock(x + 10, y + 2, z + 8, ModBlocks.protossMetal, 1, 3);
		world.setBlock(x + 11, y + 2, z + 8, ModBlocks.protossMetal, 1, 3);
		world.setBlock(x + 12, y + 2, z + 8, ModBlocks.protossMetal, 1, 3);
		world.setBlock(x + 13, y + 2, z + 8, Blocks.air, 0, 3);
		world.setBlock(x + 14, y + 2, z + 8, Blocks.air, 0, 3);
		world.setBlock(x, y + 2, z + 9, Blocks.air, 0, 3);
		world.setBlock(x + 1, y + 2, z + 9, Blocks.air, 0, 3);
		world.setBlock(x + 2, y + 2, z + 9, ModBlocks.protossMetal, 1, 3);
		world.setBlock(x + 3, y + 2, z + 9, ModBlocks.protossMetal, 1, 3);
		world.setBlock(x + 4, y + 2, z + 9, ModBlocks.protossMetal, 1, 3);
		world.setBlock(x + 5, y + 2, z + 9, ModBlocks.protossMetal, 1, 3);
		world.setBlock(x + 6, y + 2, z + 9, ModBlocks.protossMetal, 1, 3);
		world.setBlock(x + 7, y + 2, z + 9, ModBlocks.protossMetal, 1, 3);
		world.setBlock(x + 8, y + 2, z + 9, ModBlocks.protossMetal, 1, 3);
		world.setBlock(x + 9, y + 2, z + 9, ModBlocks.protossMetal, 1, 3);
		world.setBlock(x + 10, y + 2, z + 9, ModBlocks.protossMetal, 1, 3);
		world.setBlock(x + 11, y + 2, z + 9, ModBlocks.protossMetal, 1, 3);
		world.setBlock(x + 12, y + 2, z + 9, ModBlocks.protossMetal, 1, 3);
		world.setBlock(x + 13, y + 2, z + 9, ModBlocks.protossMetal, 1, 3);
		world.setBlock(x + 14, y + 2, z + 9, Blocks.air, 0, 3);
		world.setBlock(x, y + 2, z + 10, Blocks.air, 0, 3);
		world.setBlock(x + 1, y + 2, z + 10, ModBlocks.protossMetal, 1, 3);
		world.setBlock(x + 2, y + 2, z + 10, ModBlocks.protossMetal, 1, 3);
		world.setBlock(x + 3, y + 2, z + 10, ModBlocks.protossMetal, 1, 3);
		world.setBlock(x + 4, y + 2, z + 10, ModBlocks.protossMetal, 1, 3);
		world.setBlock(x + 5, y + 2, z + 10, ModBlocks.protossMetal, 1, 3);
		world.setBlock(x + 6, y + 2, z + 10, ModBlocks.protossMetal, 1, 3);
		world.setBlock(x + 7, y + 2, z + 10, ModBlocks.protossMetal, 1, 3);
		world.setBlock(x + 8, y + 2, z + 10, ModBlocks.protossMetal, 1, 3);
		world.setBlock(x + 9, y + 2, z + 10, ModBlocks.protossMetal, 1, 3);
		world.setBlock(x + 10, y + 2, z + 10, ModBlocks.protossMetal, 1, 3);
		world.setBlock(x + 11, y + 2, z + 10, ModBlocks.protossMetal, 1, 3);
		world.setBlock(x + 12, y + 2, z + 10, ModBlocks.protossMetal, 1, 3);
		world.setBlock(x + 13, y + 2, z + 10, ModBlocks.protossMetal, 1, 3);
		world.setBlock(x + 14, y + 2, z + 10, Blocks.air, 0, 3);
		world.setBlock(x, y + 2, z + 11, Blocks.air, 0, 3);
		world.setBlock(x + 1, y + 2, z + 11, ModBlocks.protossMetal, 3, 3);
		world.setBlock(x + 2, y + 2, z + 11, ModBlocks.protossMetal, 1, 3);
		world.setBlock(x + 3, y + 2, z + 11, ModBlocks.protossMetal, 1, 3);
		world.setBlock(x + 4, y + 2, z + 11, ModBlocks.protossMetal, 1, 3);
		world.setBlock(x + 5, y + 2, z + 11, ModBlocks.protossMetal, 1, 3);
		world.setBlock(x + 6, y + 2, z + 11, ModBlocks.protossMetal, 1, 3);
		world.setBlock(x + 7, y + 2, z + 11, ModBlocks.protossMetal, 1, 3);
		world.setBlock(x + 8, y + 2, z + 11, ModBlocks.protossMetal, 1, 3);
		world.setBlock(x + 9, y + 2, z + 11, ModBlocks.protossMetal, 1, 3);
		world.setBlock(x + 10, y + 2, z + 11, ModBlocks.protossMetal, 1, 3);
		world.setBlock(x + 11, y + 2, z + 11, ModBlocks.protossMetal, 1, 3);
		world.setBlock(x + 12, y + 2, z + 11, ModBlocks.protossMetal, 1, 3);
		world.setBlock(x + 13, y + 2, z + 11, Blocks.air, 0, 3);
		world.setBlock(x + 14, y + 2, z + 11, Blocks.air, 0, 3);
		world.setBlock(x, y + 2, z + 12, Blocks.air, 0, 3);
		world.setBlock(x + 1, y + 2, z + 12, ModBlocks.protossMetal, 3, 3);
		world.setBlock(x + 2, y + 2, z + 12, ModBlocks.protossMetal, 3, 3);
		world.setBlock(x + 3, y + 2, z + 12, ModBlocks.protossMetal, 1, 3);
		world.setBlock(x + 4, y + 2, z + 12, ModBlocks.protossMetal, 1, 3);
		world.setBlock(x + 5, y + 2, z + 12, ModBlocks.protossMetal, 1, 3);
		world.setBlock(x + 6, y + 2, z + 12, ModBlocks.protossMetal, 1, 3);
		world.setBlock(x + 7, y + 2, z + 12, ModBlocks.protossMetal, 1, 3);
		world.setBlock(x + 8, y + 2, z + 12, ModBlocks.protossMetal, 1, 3);
		world.setBlock(x + 9, y + 2, z + 12, ModBlocks.protossMetal, 1, 3);
		world.setBlock(x + 10, y + 2, z + 12, ModBlocks.protossMetal, 1, 3);
		world.setBlock(x + 11, y + 2, z + 12, ModBlocks.protossMetal, 1, 3);
		world.setBlock(x + 12, y + 2, z + 12, ModBlocks.protossMetal, 1, 3);
		world.setBlock(x + 13, y + 2, z + 12, ModBlocks.protossMetal, 1, 3);
		world.setBlock(x + 14, y + 2, z + 12, Blocks.air, 0, 3);
		world.setBlock(x, y + 2, z + 13, Blocks.air, 0, 3);
		world.setBlock(x + 1, y + 2, z + 13, Blocks.air, 0, 3);
		world.setBlock(x + 2, y + 2, z + 13, ModBlocks.protossMetal, 3, 3);
		world.setBlock(x + 3, y + 2, z + 13, ModBlocks.protossMetal, 3, 3);
		world.setBlock(x + 4, y + 2, z + 13, ModBlocks.protossMetal, 1, 3);
		world.setBlock(x + 5, y + 2, z + 13, Blocks.air, 0, 3);
		world.setBlock(x + 6, y + 2, z + 13, ModBlocks.protossMetal, 1, 3);
		world.setBlock(x + 7, y + 2, z + 13, ModBlocks.protossMetal, 1, 3);
		world.setBlock(x + 8, y + 2, z + 13, Blocks.air, 0, 3);
		world.setBlock(x + 9, y + 2, z + 13, ModBlocks.protossMetal, 1, 3);
		world.setBlock(x + 10, y + 2, z + 13, ModBlocks.protossMetal, 1, 3);
		world.setBlock(x + 11, y + 2, z + 13, Blocks.air, 0, 3);
		world.setBlock(x + 12, y + 2, z + 13, ModBlocks.protossMetal, 1, 3);
		world.setBlock(x + 13, y + 2, z + 13, ModBlocks.protossMetal, 1, 3);
		world.setBlock(x + 14, y + 2, z + 13, Blocks.air, 0, 3);
		world.setBlock(x, y + 2, z + 14, Blocks.air, 0, 3);
		world.setBlock(x + 1, y + 2, z + 14, Blocks.air, 0, 3);
		world.setBlock(x + 2, y + 2, z + 14, Blocks.air, 0, 3);
		world.setBlock(x + 3, y + 2, z + 14, Blocks.air, 0, 3);
		world.setBlock(x + 4, y + 2, z + 14, Blocks.air, 0, 3);
		world.setBlock(x + 5, y + 2, z + 14, Blocks.air, 0, 3);
		world.setBlock(x + 6, y + 2, z + 14, Blocks.air, 0, 3);
		world.setBlock(x + 7, y + 2, z + 14, Blocks.air, 0, 3);
		world.setBlock(x + 8, y + 2, z + 14, Blocks.air, 0, 3);
		world.setBlock(x + 9, y + 2, z + 14, Blocks.air, 0, 3);
		world.setBlock(x + 10, y + 2, z + 14, Blocks.air, 0, 3);
		world.setBlock(x + 11, y + 2, z + 14, Blocks.air, 0, 3);
		world.setBlock(x + 12, y + 2, z + 14, Blocks.air, 0, 3);
		world.setBlock(x + 13, y + 2, z + 14, Blocks.air, 0, 3);
		world.setBlock(x + 14, y + 2, z + 14, Blocks.air, 0, 3);
		world.setBlock(x, y + 3, z, ModBlocks.protossMetal, 1, 3);
		world.setBlock(x + 1, y + 3, z, ModBlocks.protossMetal, 1, 3);
		world.setBlock(x + 2, y + 3, z, Blocks.air, 0, 3);
		world.setBlock(x + 3, y + 3, z, Blocks.air, 0, 3);
		world.setBlock(x + 4, y + 3, z, Blocks.air, 0, 3);
		world.setBlock(x + 5, y + 3, z, Blocks.air, 0, 3);
		world.setBlock(x + 6, y + 3, z, Blocks.air, 0, 3);
		world.setBlock(x + 7, y + 3, z, Blocks.air, 0, 3);
		world.setBlock(x + 8, y + 3, z, Blocks.air, 0, 3);
		world.setBlock(x + 9, y + 3, z, Blocks.air, 0, 3);
		world.setBlock(x + 10, y + 3, z, Blocks.air, 0, 3);
		world.setBlock(x + 11, y + 3, z, Blocks.air, 0, 3);
		world.setBlock(x + 12, y + 3, z, Blocks.air, 0, 3);
		world.setBlock(x + 13, y + 3, z, Blocks.air, 0, 3);
		world.setBlock(x + 14, y + 3, z, Blocks.air, 0, 3);
		world.setBlock(x, y + 3, z + 1, ModBlocks.protossMetal, 1, 3);
		world.setBlock(x + 1, y + 3, z + 1, ModBlocks.protossMetal, 3, 3);
		world.setBlock(x + 2, y + 3, z + 1, ModBlocks.protossMetal, 1, 3);
		world.setBlock(x + 3, y + 3, z + 1, Blocks.air, 0, 3);
		world.setBlock(x + 4, y + 3, z + 1, Blocks.air, 0, 3);
		world.setBlock(x + 5, y + 3, z + 1, Blocks.air, 0, 3);
		world.setBlock(x + 6, y + 3, z + 1, Blocks.air, 0, 3);
		world.setBlock(x + 7, y + 3, z + 1, Blocks.air, 0, 3);
		world.setBlock(x + 8, y + 3, z + 1, Blocks.air, 0, 3);
		world.setBlock(x + 9, y + 3, z + 1, Blocks.air, 0, 3);
		world.setBlock(x + 10, y + 3, z + 1, ModBlocks.protossMetal, 3, 3);
		world.setBlock(x + 11, y + 3, z + 1, Blocks.air, 0, 3);
		world.setBlock(x + 12, y + 3, z + 1, Blocks.air, 0, 3);
		world.setBlock(x + 13, y + 3, z + 1, Blocks.air, 0, 3);
		world.setBlock(x + 14, y + 3, z + 1, Blocks.air, 0, 3);
		world.setBlock(x, y + 3, z + 2, Blocks.air, 0, 3);
		world.setBlock(x + 1, y + 3, z + 2, ModBlocks.protossMetal, 1, 3);
		world.setBlock(x + 2, y + 3, z + 2, ModBlocks.protossMetal, 1, 3);
		world.setBlock(x + 3, y + 3, z + 2, ModBlocks.protossMetal, 1, 3);
		world.setBlock(x + 4, y + 3, z + 2, ModBlocks.protossMetal, 1, 3);
		world.setBlock(x + 5, y + 3, z + 2, ModBlocks.protossMetal, 1, 3);
		world.setBlock(x + 6, y + 3, z + 2, ModBlocks.protossMetal, 1, 3);
		world.setBlock(x + 7, y + 3, z + 2, ModBlocks.protossMetal, 1, 3);
		world.setBlock(x + 8, y + 3, z + 2, ModBlocks.protossMetal, 1, 3);
		world.setBlock(x + 9, y + 3, z + 2, ModBlocks.protossMetal, 1, 3);
		world.setBlock(x + 10, y + 3, z + 2, ModBlocks.protossMetal, 1, 3);
		world.setBlock(x + 11, y + 3, z + 2, ModBlocks.protossMetal, 1, 3);
		world.setBlock(x + 12, y + 3, z + 2, Blocks.air, 0, 3);
		world.setBlock(x + 13, y + 3, z + 2, Blocks.air, 0, 3);
		world.setBlock(x + 14, y + 3, z + 2, Blocks.air, 0, 3);
		world.setBlock(x, y + 3, z + 3, Blocks.air, 0, 3);
		world.setBlock(x + 1, y + 3, z + 3, Blocks.air, 0, 3);
		world.setBlock(x + 2, y + 3, z + 3, ModBlocks.protossMetal, 1, 3);
		world.setBlock(x + 3, y + 3, z + 3, ModBlocks.protossMetal, 1, 3);
		world.setBlock(x + 4, y + 3, z + 3, ModBlocks.protossMetal, 1, 3);
		world.setBlock(x + 5, y + 3, z + 3, ModBlocks.protossMetal, 1, 3);
		world.setBlock(x + 6, y + 3, z + 3, ModBlocks.protossMetal, 1, 3);
		world.setBlock(x + 7, y + 3, z + 3, ModBlocks.protossMetal, 1, 3);
		world.setBlock(x + 8, y + 3, z + 3, ModBlocks.protossMetal, 1, 3);
		world.setBlock(x + 9, y + 3, z + 3, ModBlocks.protossMetal, 1, 3);
		world.setBlock(x + 10, y + 3, z + 3, ModBlocks.protossMetal, 1, 3);
		world.setBlock(x + 11, y + 3, z + 3, ModBlocks.protossMetal, 1, 3);
		world.setBlock(x + 12, y + 3, z + 3, ModBlocks.protossMetal, 1, 3);
		world.setBlock(x + 13, y + 3, z + 3, Blocks.air, 0, 3);
		world.setBlock(x + 14, y + 3, z + 3, Blocks.air, 0, 3);
		world.setBlock(x, y + 3, z + 4, Blocks.air, 0, 3);
		world.setBlock(x + 1, y + 3, z + 4, Blocks.air, 0, 3);
		world.setBlock(x + 2, y + 3, z + 4, ModBlocks.protossMetal, 1, 3);
		world.setBlock(x + 3, y + 3, z + 4, ModBlocks.protossMetal, 1, 3);
		world.setBlock(x + 4, y + 3, z + 4, ModBlocks.protossMetal, 1, 3);
		world.setBlock(x + 5, y + 3, z + 4, ModBlocks.protossMetal, 1, 3);
		world.setBlock(x + 6, y + 3, z + 4, ModBlocks.protossMetal, 1, 3);
		world.setBlock(x + 7, y + 3, z + 4, ModBlocks.protossMetal, 1, 3);
		world.setBlock(x + 8, y + 3, z + 4, ModBlocks.protossMetal, 1, 3);
		world.setBlock(x + 9, y + 3, z + 4, ModBlocks.protossMetal, 1, 3);
		world.setBlock(x + 10, y + 3, z + 4, ModBlocks.protossMetal, 1, 3);
		world.setBlock(x + 11, y + 3, z + 4, ModBlocks.protossMetal, 1, 3);
		world.setBlock(x + 12, y + 3, z + 4, ModBlocks.protossMetal, 1, 3);
		world.setBlock(x + 13, y + 3, z + 4, ModBlocks.protossMetal, 3, 3);
		world.setBlock(x + 14, y + 3, z + 4, Blocks.air, 0, 3);
		world.setBlock(x, y + 3, z + 5, Blocks.air, 0, 3);
		world.setBlock(x + 1, y + 3, z + 5, Blocks.air, 0, 3);
		world.setBlock(x + 2, y + 3, z + 5, ModBlocks.protossMetal, 1, 3);
		world.setBlock(x + 3, y + 3, z + 5, ModBlocks.protossMetal, 1, 3);
		world.setBlock(x + 4, y + 3, z + 5, ModBlocks.protossMetal, 1, 3);
		world.setBlock(x + 5, y + 3, z + 5, ModBlocks.protossMetal, 1, 3);
		world.setBlock(x + 6, y + 3, z + 5, ModBlocks.protossMetal, 1, 3);
		world.setBlock(x + 7, y + 3, z + 5, ModBlocks.protossMetal, 1, 3);
		world.setBlock(x + 8, y + 3, z + 5, ModBlocks.protossMetal, 1, 3);
		world.setBlock(x + 9, y + 3, z + 5, ModBlocks.protossMetal, 1, 3);
		world.setBlock(x + 10, y + 3, z + 5, ModBlocks.protossMetal, 1, 3);
		world.setBlock(x + 11, y + 3, z + 5, ModBlocks.protossMetal, 1, 3);
		world.setBlock(x + 12, y + 3, z + 5, ModBlocks.protossMetal, 1, 3);
		world.setBlock(x + 13, y + 3, z + 5, Blocks.air, 0, 3);
		world.setBlock(x + 14, y + 3, z + 5, Blocks.air, 0, 3);
		world.setBlock(x, y + 3, z + 6, Blocks.air, 0, 3);
		world.setBlock(x + 1, y + 3, z + 6, Blocks.air, 0, 3);
		world.setBlock(x + 2, y + 3, z + 6, ModBlocks.protossMetal, 1, 3);
		world.setBlock(x + 3, y + 3, z + 6, ModBlocks.protossMetal, 1, 3);
		world.setBlock(x + 4, y + 3, z + 6, ModBlocks.protossMetal, 1, 3);
		world.setBlock(x + 5, y + 3, z + 6, ModBlocks.protossMetal, 1, 3);
		world.setBlock(x + 6, y + 3, z + 6, ModBlocks.protossMetal, 1, 3);
		world.setBlock(x + 7, y + 3, z + 6, ModBlocks.protossMetal, 1, 3);
		world.setBlock(x + 8, y + 3, z + 6, ModBlocks.protossMetal, 1, 3);
		world.setBlock(x + 9, y + 3, z + 6, ModBlocks.protossMetal, 1, 3);
		world.setBlock(x + 10, y + 3, z + 6, ModBlocks.protossMetal, 1, 3);
		world.setBlock(x + 11, y + 3, z + 6, ModBlocks.protossMetal, 1, 3);
		world.setBlock(x + 12, y + 3, z + 6, ModBlocks.protossMetal, 1, 3);
		world.setBlock(x + 13, y + 3, z + 6, Blocks.air, 0, 3);
		world.setBlock(x + 14, y + 3, z + 6, Blocks.air, 0, 3);
		world.setBlock(x, y + 3, z + 7, Blocks.air, 0, 3);
		world.setBlock(x + 1, y + 3, z + 7, Blocks.air, 0, 3);
		world.setBlock(x + 2, y + 3, z + 7, ModBlocks.protossMetal, 1, 3);
		world.setBlock(x + 3, y + 3, z + 7, ModBlocks.protossMetal, 1, 3);
		world.setBlock(x + 4, y + 3, z + 7, ModBlocks.protossMetal, 1, 3);
		world.setBlock(x + 5, y + 3, z + 7, ModBlocks.protossMetal, 1, 3);
		world.setBlock(x + 6, y + 3, z + 7, ModBlocks.protossMetal, 1, 3);
		world.setBlock(x + 7, y + 3, z + 7, ModBlocks.protossMetal, 1, 3);
		world.setBlock(x + 8, y + 3, z + 7, ModBlocks.protossMetal, 1, 3);
		world.setBlock(x + 9, y + 3, z + 7, ModBlocks.protossMetal, 1, 3);
		world.setBlock(x + 10, y + 3, z + 7, ModBlocks.protossMetal, 1, 3);
		world.setBlock(x + 11, y + 3, z + 7, ModBlocks.protossMetal, 1, 3);
		world.setBlock(x + 12, y + 3, z + 7, ModBlocks.protossMetal, 1, 3);
		world.setBlock(x + 13, y + 3, z + 7, Blocks.air, 0, 3);
		world.setBlock(x + 14, y + 3, z + 7, Blocks.air, 0, 3);
		world.setBlock(x, y + 3, z + 8, Blocks.air, 0, 3);
		world.setBlock(x + 1, y + 3, z + 8, Blocks.air, 0, 3);
		world.setBlock(x + 2, y + 3, z + 8, ModBlocks.protossMetal, 1, 3);
		world.setBlock(x + 3, y + 3, z + 8, ModBlocks.protossMetal, 1, 3);
		world.setBlock(x + 4, y + 3, z + 8, ModBlocks.protossMetal, 1, 3);
		world.setBlock(x + 5, y + 3, z + 8, ModBlocks.protossMetal, 1, 3);
		world.setBlock(x + 6, y + 3, z + 8, ModBlocks.protossMetal, 1, 3);
		world.setBlock(x + 7, y + 3, z + 8, ModBlocks.protossMetal, 1, 3);
		world.setBlock(x + 8, y + 3, z + 8, ModBlocks.protossMetal, 1, 3);
		world.setBlock(x + 9, y + 3, z + 8, ModBlocks.protossMetal, 1, 3);
		world.setBlock(x + 10, y + 3, z + 8, ModBlocks.protossMetal, 1, 3);
		world.setBlock(x + 11, y + 3, z + 8, ModBlocks.protossMetal, 1, 3);
		world.setBlock(x + 12, y + 3, z + 8, ModBlocks.protossMetal, 1, 3);
		world.setBlock(x + 13, y + 3, z + 8, Blocks.air, 0, 3);
		world.setBlock(x + 14, y + 3, z + 8, Blocks.air, 0, 3);
		world.setBlock(x, y + 3, z + 9, Blocks.air, 0, 3);
		world.setBlock(x + 1, y + 3, z + 9, Blocks.air, 0, 3);
		world.setBlock(x + 2, y + 3, z + 9, ModBlocks.protossMetal, 1, 3);
		world.setBlock(x + 3, y + 3, z + 9, ModBlocks.protossMetal, 1, 3);
		world.setBlock(x + 4, y + 3, z + 9, ModBlocks.protossMetal, 1, 3);
		world.setBlock(x + 5, y + 3, z + 9, ModBlocks.protossMetal, 1, 3);
		world.setBlock(x + 6, y + 3, z + 9, ModBlocks.protossMetal, 1, 3);
		world.setBlock(x + 7, y + 3, z + 9, ModBlocks.protossMetal, 1, 3);
		world.setBlock(x + 8, y + 3, z + 9, ModBlocks.protossMetal, 1, 3);
		world.setBlock(x + 9, y + 3, z + 9, ModBlocks.protossMetal, 1, 3);
		world.setBlock(x + 10, y + 3, z + 9, ModBlocks.protossMetal, 1, 3);
		world.setBlock(x + 11, y + 3, z + 9, ModBlocks.protossMetal, 1, 3);
		world.setBlock(x + 12, y + 3, z + 9, ModBlocks.protossMetal, 1, 3);
		world.setBlock(x + 13, y + 3, z + 9, Blocks.air, 0, 3);
		world.setBlock(x + 14, y + 3, z + 9, Blocks.air, 0, 3);
		world.setBlock(x, y + 3, z + 10, Blocks.air, 0, 3);
		world.setBlock(x + 1, y + 3, z + 10, ModBlocks.protossMetal, 3, 3);
		world.setBlock(x + 2, y + 3, z + 10, ModBlocks.protossMetal, 1, 3);
		world.setBlock(x + 3, y + 3, z + 10, ModBlocks.protossMetal, 1, 3);
		world.setBlock(x + 4, y + 3, z + 10, ModBlocks.protossMetal, 1, 3);
		world.setBlock(x + 5, y + 3, z + 10, ModBlocks.protossMetal, 1, 3);
		world.setBlock(x + 6, y + 3, z + 10, ModBlocks.protossMetal, 1, 3);
		world.setBlock(x + 7, y + 3, z + 10, ModBlocks.protossMetal, 1, 3);
		world.setBlock(x + 8, y + 3, z + 10, ModBlocks.protossMetal, 1, 3);
		world.setBlock(x + 9, y + 3, z + 10, ModBlocks.protossMetal, 1, 3);
		world.setBlock(x + 10, y + 3, z + 10, ModBlocks.protossMetal, 1, 3);
		world.setBlock(x + 11, y + 3, z + 10, ModBlocks.protossMetal, 1, 3);
		world.setBlock(x + 12, y + 3, z + 10, ModBlocks.protossMetal, 1, 3);
		world.setBlock(x + 13, y + 3, z + 10, Blocks.air, 0, 3);
		world.setBlock(x + 14, y + 3, z + 10, Blocks.air, 0, 3);
		world.setBlock(x, y + 3, z + 11, Blocks.air, 0, 3);
		world.setBlock(x + 1, y + 3, z + 11, Blocks.air, 0, 3);
		world.setBlock(x + 2, y + 3, z + 11, ModBlocks.protossMetal, 1, 3);
		world.setBlock(x + 3, y + 3, z + 11, ModBlocks.protossMetal, 1, 3);
		world.setBlock(x + 4, y + 3, z + 11, ModBlocks.protossMetal, 1, 3);
		world.setBlock(x + 5, y + 3, z + 11, ModBlocks.protossMetal, 1, 3);
		world.setBlock(x + 6, y + 3, z + 11, ModBlocks.protossMetal, 1, 3);
		world.setBlock(x + 7, y + 3, z + 11, ModBlocks.protossMetal, 1, 3);
		world.setBlock(x + 8, y + 3, z + 11, ModBlocks.protossMetal, 1, 3);
		world.setBlock(x + 9, y + 3, z + 11, ModBlocks.protossMetal, 1, 3);
		world.setBlock(x + 10, y + 3, z + 11, ModBlocks.protossMetal, 1, 3);
		world.setBlock(x + 11, y + 3, z + 11, ModBlocks.protossMetal, 1, 3);
		world.setBlock(x + 12, y + 3, z + 11, ModBlocks.protossMetal, 1, 3);
		world.setBlock(x + 13, y + 3, z + 11, Blocks.air, 0, 3);
		world.setBlock(x + 14, y + 3, z + 11, Blocks.air, 0, 3);
		world.setBlock(x, y + 3, z + 12, Blocks.air, 0, 3);
		world.setBlock(x + 1, y + 3, z + 12, Blocks.air, 0, 3);
		world.setBlock(x + 2, y + 3, z + 12, Blocks.air, 0, 3);
		world.setBlock(x + 3, y + 3, z + 12, ModBlocks.protossMetal, 1, 3);
		world.setBlock(x + 4, y + 3, z + 12, ModBlocks.protossMetal, 1, 3);
		world.setBlock(x + 5, y + 3, z + 12, ModBlocks.protossMetal, 1, 3);
		world.setBlock(x + 6, y + 3, z + 12, ModBlocks.protossMetal, 1, 3);
		world.setBlock(x + 7, y + 3, z + 12, ModBlocks.protossMetal, 1, 3);
		world.setBlock(x + 8, y + 3, z + 12, ModBlocks.protossMetal, 1, 3);
		world.setBlock(x + 9, y + 3, z + 12, ModBlocks.protossMetal, 1, 3);
		world.setBlock(x + 10, y + 3, z + 12, ModBlocks.protossMetal, 1, 3);
		world.setBlock(x + 11, y + 3, z + 12, ModBlocks.protossMetal, 1, 3);
		world.setBlock(x + 12, y + 3, z + 12, ModBlocks.protossMetal, 1, 3);
		world.setBlock(x + 13, y + 3, z + 12, ModBlocks.protossMetal, 1, 3);
		world.setBlock(x + 14, y + 3, z + 12, Blocks.air, 0, 3);
		world.setBlock(x, y + 3, z + 13, Blocks.air, 0, 3);
		world.setBlock(x + 1, y + 3, z + 13, Blocks.air, 0, 3);
		world.setBlock(x + 2, y + 3, z + 13, Blocks.air, 0, 3);
		world.setBlock(x + 3, y + 3, z + 13, Blocks.air, 0, 3);
		world.setBlock(x + 4, y + 3, z + 13, ModBlocks.protossMetal, 3, 3);
		world.setBlock(x + 5, y + 3, z + 13, Blocks.air, 0, 3);
		world.setBlock(x + 6, y + 3, z + 13, Blocks.air, 0, 3);
		world.setBlock(x + 7, y + 3, z + 13, Blocks.air, 0, 3);
		world.setBlock(x + 8, y + 3, z + 13, Blocks.air, 0, 3);
		world.setBlock(x + 9, y + 3, z + 13, Blocks.air, 0, 3);
		world.setBlock(x + 10, y + 3, z + 13, Blocks.air, 0, 3);
		world.setBlock(x + 11, y + 3, z + 13, Blocks.air, 0, 3);
		world.setBlock(x + 12, y + 3, z + 13, ModBlocks.protossMetal, 1, 3);
		world.setBlock(x + 13, y + 3, z + 13, ModBlocks.protossMetal, 3, 3);
		world.setBlock(x + 14, y + 3, z + 13, ModBlocks.protossMetal, 1, 3);
		world.setBlock(x, y + 3, z + 14, Blocks.air, 0, 3);
		world.setBlock(x + 1, y + 3, z + 14, Blocks.air, 0, 3);
		world.setBlock(x + 2, y + 3, z + 14, Blocks.air, 0, 3);
		world.setBlock(x + 3, y + 3, z + 14, Blocks.air, 0, 3);
		world.setBlock(x + 4, y + 3, z + 14, Blocks.air, 0, 3);
		world.setBlock(x + 5, y + 3, z + 14, Blocks.air, 0, 3);
		world.setBlock(x + 6, y + 3, z + 14, Blocks.air, 0, 3);
		world.setBlock(x + 7, y + 3, z + 14, Blocks.air, 0, 3);
		world.setBlock(x + 8, y + 3, z + 14, Blocks.air, 0, 3);
		world.setBlock(x + 9, y + 3, z + 14, Blocks.air, 0, 3);
		world.setBlock(x + 10, y + 3, z + 14, Blocks.air, 0, 3);
		world.setBlock(x + 11, y + 3, z + 14, Blocks.air, 0, 3);
		world.setBlock(x + 12, y + 3, z + 14, Blocks.air, 0, 3);
		world.setBlock(x + 13, y + 3, z + 14, ModBlocks.protossMetal, 1, 3);
		world.setBlock(x + 14, y + 3, z + 14, ModBlocks.protossMetal, 1, 3);
		world.setBlock(x, y + 4, z, Blocks.air, 0, 3);
		world.setBlock(x + 1, y + 4, z, Blocks.air, 0, 3);
		world.setBlock(x + 2, y + 4, z, Blocks.air, 0, 3);
		world.setBlock(x + 3, y + 4, z, Blocks.air, 0, 3);
		world.setBlock(x + 4, y + 4, z, Blocks.air, 0, 3);
		world.setBlock(x + 5, y + 4, z, Blocks.air, 0, 3);
		world.setBlock(x + 6, y + 4, z, Blocks.air, 0, 3);
		world.setBlock(x + 7, y + 4, z, Blocks.air, 0, 3);
		world.setBlock(x + 8, y + 4, z, Blocks.air, 0, 3);
		world.setBlock(x + 9, y + 4, z, Blocks.air, 0, 3);
		world.setBlock(x + 10, y + 4, z, Blocks.air, 0, 3);
		world.setBlock(x + 11, y + 4, z, Blocks.air, 0, 3);
		world.setBlock(x + 12, y + 4, z, Blocks.air, 0, 3);
		world.setBlock(x + 13, y + 4, z, Blocks.air, 0, 3);
		world.setBlock(x + 14, y + 4, z, Blocks.air, 0, 3);
		world.setBlock(x, y + 4, z + 1, Blocks.air, 0, 3);
		world.setBlock(x + 1, y + 4, z + 1, Blocks.air, 0, 3);
		world.setBlock(x + 2, y + 4, z + 1, Blocks.air, 0, 3);
		world.setBlock(x + 3, y + 4, z + 1, Blocks.air, 0, 3);
		world.setBlock(x + 4, y + 4, z + 1, Blocks.air, 0, 3);
		world.setBlock(x + 5, y + 4, z + 1, Blocks.air, 0, 3);
		world.setBlock(x + 6, y + 4, z + 1, Blocks.air, 0, 3);
		world.setBlock(x + 7, y + 4, z + 1, Blocks.air, 0, 3);
		world.setBlock(x + 8, y + 4, z + 1, Blocks.air, 0, 3);
		world.setBlock(x + 9, y + 4, z + 1, Blocks.air, 0, 3);
		world.setBlock(x + 10, y + 4, z + 1, Blocks.air, 0, 3);
		world.setBlock(x + 11, y + 4, z + 1, Blocks.air, 0, 3);
		world.setBlock(x + 12, y + 4, z + 1, Blocks.air, 0, 3);
		world.setBlock(x + 13, y + 4, z + 1, Blocks.air, 0, 3);
		world.setBlock(x + 14, y + 4, z + 1, Blocks.air, 0, 3);
		world.setBlock(x, y + 4, z + 2, Blocks.air, 0, 3);
		world.setBlock(x + 1, y + 4, z + 2, Blocks.air, 0, 3);
		world.setBlock(x + 2, y + 4, z + 2, ModBlocks.protossMetal, 1, 3);
		world.setBlock(x + 3, y + 4, z + 2, ModBlocks.protossMetal, 1, 3);
		world.setBlock(x + 4, y + 4, z + 2, ModBlocks.protossMetal, 3, 3);
		world.setBlock(x + 5, y + 4, z + 2, ModBlocks.protossMetal, 1, 3);
		world.setBlock(x + 6, y + 4, z + 2, Blocks.air, 0, 3);
		world.setBlock(x + 7, y + 4, z + 2, Blocks.air, 0, 3);
		world.setBlock(x + 8, y + 4, z + 2, Blocks.air, 0, 3);
		world.setBlock(x + 9, y + 4, z + 2, Blocks.air, 0, 3);
		world.setBlock(x + 10, y + 4, z + 2, ModBlocks.protossMetal, 1, 3);
		world.setBlock(x + 11, y + 4, z + 2, Blocks.air, 0, 3);
		world.setBlock(x + 12, y + 4, z + 2, Blocks.air, 0, 3);
		world.setBlock(x + 13, y + 4, z + 2, Blocks.air, 0, 3);
		world.setBlock(x + 14, y + 4, z + 2, Blocks.air, 0, 3);
		world.setBlock(x, y + 4, z + 3, Blocks.air, 0, 3);
		world.setBlock(x + 1, y + 4, z + 3, Blocks.air, 0, 3);
		world.setBlock(x + 2, y + 4, z + 3, ModBlocks.protossMetal, 1, 3);
		world.setBlock(x + 3, y + 4, z + 3, ModBlocks.protossMetal, 1, 3);
		world.setBlock(x + 4, y + 4, z + 3, ModBlocks.protossMetal, 1, 3);
		world.setBlock(x + 5, y + 4, z + 3, ModBlocks.protossMetal, 1, 3);
		world.setBlock(x + 6, y + 4, z + 3, ModBlocks.protossMetal, 1, 3);
		world.setBlock(x + 7, y + 4, z + 3, ModBlocks.protossMetal, 1, 3);
		world.setBlock(x + 8, y + 4, z + 3, ModBlocks.protossMetal, 1, 3);
		world.setBlock(x + 9, y + 4, z + 3, ModBlocks.protossMetal, 1, 3);
		world.setBlock(x + 10, y + 4, z + 3, ModBlocks.protossMetal, 1, 3);
		world.setBlock(x + 11, y + 4, z + 3, ModBlocks.protossMetal, 3, 3);
		world.setBlock(x + 12, y + 4, z + 3, Blocks.air, 0, 3);
		world.setBlock(x + 13, y + 4, z + 3, Blocks.air, 0, 3);
		world.setBlock(x + 14, y + 4, z + 3, Blocks.air, 0, 3);
		world.setBlock(x, y + 4, z + 4, Blocks.air, 0, 3);
		world.setBlock(x + 1, y + 4, z + 4, Blocks.air, 0, 3);
		world.setBlock(x + 2, y + 4, z + 4, ModBlocks.protossMetal, 3, 3);
		world.setBlock(x + 3, y + 4, z + 4, ModBlocks.protossMetal, 1, 3);
		world.setBlock(x + 4, y + 4, z + 4, ModBlocks.protossMetal, 1, 3);
		world.setBlock(x + 5, y + 4, z + 4, ModBlocks.protossMetal, 1, 3);
		world.setBlock(x + 6, y + 4, z + 4, ModBlocks.protossMetal, 1, 3);
		world.setBlock(x + 7, y + 4, z + 4, ModBlocks.protossMetal, 1, 3);
		world.setBlock(x + 8, y + 4, z + 4, ModBlocks.protossMetal, 1, 3);
		world.setBlock(x + 9, y + 4, z + 4, ModBlocks.protossMetal, 1, 3);
		world.setBlock(x + 10, y + 4, z + 4, ModBlocks.protossMetal, 1, 3);
		world.setBlock(x + 11, y + 4, z + 4, ModBlocks.protossMetal, 1, 3);
		world.setBlock(x + 12, y + 4, z + 4, ModBlocks.protossMetal, 1, 3);
		world.setBlock(x + 13, y + 4, z + 4, Blocks.air, 0, 3);
		world.setBlock(x + 14, y + 4, z + 4, Blocks.air, 0, 3);
		world.setBlock(x, y + 4, z + 5, Blocks.air, 0, 3);
		world.setBlock(x + 1, y + 4, z + 5, Blocks.air, 0, 3);
		world.setBlock(x + 2, y + 4, z + 5, ModBlocks.protossMetal, 1, 3);
		world.setBlock(x + 3, y + 4, z + 5, ModBlocks.protossMetal, 1, 3);
		world.setBlock(x + 4, y + 4, z + 5, ModBlocks.protossMetal, 1, 3);
		world.setBlock(x + 5, y + 4, z + 5, ModBlocks.protossMetal, 1, 3);
		world.setBlock(x + 6, y + 4, z + 5, ModBlocks.protossMetal, 1, 3);
		world.setBlock(x + 7, y + 4, z + 5, ModBlocks.protossMetal, 1, 3);
		world.setBlock(x + 8, y + 4, z + 5, ModBlocks.protossMetal, 1, 3);
		world.setBlock(x + 9, y + 4, z + 5, ModBlocks.protossMetal, 1, 3);
		world.setBlock(x + 10, y + 4, z + 5, ModBlocks.protossMetal, 1, 3);
		world.setBlock(x + 11, y + 4, z + 5, ModBlocks.protossMetal, 1, 3);
		world.setBlock(x + 12, y + 4, z + 5, Blocks.air, 0, 3);
		world.setBlock(x + 13, y + 4, z + 5, Blocks.air, 0, 3);
		world.setBlock(x + 14, y + 4, z + 5, Blocks.air, 0, 3);
		world.setBlock(x, y + 4, z + 6, Blocks.air, 0, 3);
		world.setBlock(x + 1, y + 4, z + 6, Blocks.air, 0, 3);
		world.setBlock(x + 2, y + 4, z + 6, Blocks.air, 0, 3);
		world.setBlock(x + 3, y + 4, z + 6, ModBlocks.protossMetal, 1, 3);
		world.setBlock(x + 4, y + 4, z + 6, ModBlocks.protossMetal, 1, 3);
		world.setBlock(x + 5, y + 4, z + 6, ModBlocks.protossMetal, 1, 3);
		world.setBlock(x + 6, y + 4, z + 6, ModBlocks.protossMetal, 1, 3);
		world.setBlock(x + 7, y + 4, z + 6, ModBlocks.protossMetal, 1, 3);
		world.setBlock(x + 8, y + 4, z + 6, ModBlocks.protossMetal, 1, 3);
		world.setBlock(x + 9, y + 4, z + 6, ModBlocks.protossMetal, 1, 3);
		world.setBlock(x + 10, y + 4, z + 6, ModBlocks.protossMetal, 1, 3);
		world.setBlock(x + 11, y + 4, z + 6, ModBlocks.protossMetal, 1, 3);
		world.setBlock(x + 12, y + 4, z + 6, Blocks.air, 0, 3);
		world.setBlock(x + 13, y + 4, z + 6, Blocks.air, 0, 3);
		world.setBlock(x + 14, y + 4, z + 6, Blocks.air, 0, 3);
		world.setBlock(x, y + 4, z + 7, Blocks.air, 0, 3);
		world.setBlock(x + 1, y + 4, z + 7, Blocks.air, 0, 3);
		world.setBlock(x + 2, y + 4, z + 7, Blocks.air, 0, 3);
		world.setBlock(x + 3, y + 4, z + 7, ModBlocks.protossMetal, 1, 3);
		world.setBlock(x + 4, y + 4, z + 7, ModBlocks.protossMetal, 1, 3);
		world.setBlock(x + 5, y + 4, z + 7, ModBlocks.protossMetal, 1, 3);
		world.setBlock(x + 6, y + 4, z + 7, ModBlocks.protossMetal, 1, 3);
		world.setBlock(x + 7, y + 4, z + 7, ModBlocks.protossMetal, 1, 3);
		world.setBlock(x + 8, y + 4, z + 7, ModBlocks.protossMetal, 1, 3);
		world.setBlock(x + 9, y + 4, z + 7, ModBlocks.protossMetal, 1, 3);
		world.setBlock(x + 10, y + 4, z + 7, ModBlocks.protossMetal, 1, 3);
		world.setBlock(x + 11, y + 4, z + 7, ModBlocks.protossMetal, 1, 3);
		world.setBlock(x + 12, y + 4, z + 7, Blocks.air, 0, 3);
		world.setBlock(x + 13, y + 4, z + 7, Blocks.air, 0, 3);
		world.setBlock(x + 14, y + 4, z + 7, Blocks.air, 0, 3);
		world.setBlock(x, y + 4, z + 8, Blocks.air, 0, 3);
		world.setBlock(x + 1, y + 4, z + 8, Blocks.air, 0, 3);
		world.setBlock(x + 2, y + 4, z + 8, Blocks.air, 0, 3);
		world.setBlock(x + 3, y + 4, z + 8, ModBlocks.protossMetal, 1, 3);
		world.setBlock(x + 4, y + 4, z + 8, ModBlocks.protossMetal, 1, 3);
		world.setBlock(x + 5, y + 4, z + 8, ModBlocks.protossMetal, 1, 3);
		world.setBlock(x + 6, y + 4, z + 8, ModBlocks.protossMetal, 1, 3);
		world.setBlock(x + 7, y + 4, z + 8, ModBlocks.protossMetal, 1, 3);
		world.setBlock(x + 8, y + 4, z + 8, ModBlocks.protossMetal, 1, 3);
		world.setBlock(x + 9, y + 4, z + 8, ModBlocks.protossMetal, 1, 3);
		world.setBlock(x + 10, y + 4, z + 8, ModBlocks.protossMetal, 1, 3);
		world.setBlock(x + 11, y + 4, z + 8, ModBlocks.protossMetal, 1, 3);
		world.setBlock(x + 12, y + 4, z + 8, Blocks.air, 0, 3);
		world.setBlock(x + 13, y + 4, z + 8, Blocks.air, 0, 3);
		world.setBlock(x + 14, y + 4, z + 8, Blocks.air, 0, 3);
		world.setBlock(x, y + 4, z + 9, Blocks.air, 0, 3);
		world.setBlock(x + 1, y + 4, z + 9, Blocks.air, 0, 3);
		world.setBlock(x + 2, y + 4, z + 9, Blocks.air, 0, 3);
		world.setBlock(x + 3, y + 4, z + 9, ModBlocks.protossMetal, 1, 3);
		world.setBlock(x + 4, y + 4, z + 9, ModBlocks.protossMetal, 1, 3);
		world.setBlock(x + 5, y + 4, z + 9, ModBlocks.protossMetal, 1, 3);
		world.setBlock(x + 6, y + 4, z + 9, ModBlocks.protossMetal, 1, 3);
		world.setBlock(x + 7, y + 4, z + 9, ModBlocks.protossMetal, 1, 3);
		world.setBlock(x + 8, y + 4, z + 9, ModBlocks.protossMetal, 1, 3);
		world.setBlock(x + 9, y + 4, z + 9, ModBlocks.protossMetal, 1, 3);
		world.setBlock(x + 10, y + 4, z + 9, ModBlocks.protossMetal, 1, 3);
		world.setBlock(x + 11, y + 4, z + 9, ModBlocks.protossMetal, 1, 3);
		world.setBlock(x + 12, y + 4, z + 9, ModBlocks.protossMetal, 1, 3);
		world.setBlock(x + 13, y + 4, z + 9, Blocks.air, 0, 3);
		world.setBlock(x + 14, y + 4, z + 9, Blocks.air, 0, 3);
		world.setBlock(x, y + 4, z + 10, Blocks.air, 0, 3);
		world.setBlock(x + 1, y + 4, z + 10, Blocks.air, 0, 3);
		world.setBlock(x + 2, y + 4, z + 10, ModBlocks.protossMetal, 1, 3);
		world.setBlock(x + 3, y + 4, z + 10, ModBlocks.protossMetal, 1, 3);
		world.setBlock(x + 4, y + 4, z + 10, ModBlocks.protossMetal, 1, 3);
		world.setBlock(x + 5, y + 4, z + 10, ModBlocks.protossMetal, 1, 3);
		world.setBlock(x + 6, y + 4, z + 10, ModBlocks.protossMetal, 1, 3);
		world.setBlock(x + 7, y + 4, z + 10, ModBlocks.protossMetal, 1, 3);
		world.setBlock(x + 8, y + 4, z + 10, ModBlocks.protossMetal, 1, 3);
		world.setBlock(x + 9, y + 4, z + 10, ModBlocks.protossMetal, 1, 3);
		world.setBlock(x + 10, y + 4, z + 10, ModBlocks.protossMetal, 1, 3);
		world.setBlock(x + 11, y + 4, z + 10, ModBlocks.protossMetal, 1, 3);
		world.setBlock(x + 12, y + 4, z + 10, ModBlocks.protossMetal, 3, 3);
		world.setBlock(x + 13, y + 4, z + 10, Blocks.air, 0, 3);
		world.setBlock(x + 14, y + 4, z + 10, Blocks.air, 0, 3);
		world.setBlock(x, y + 4, z + 11, Blocks.air, 0, 3);
		world.setBlock(x + 1, y + 4, z + 11, Blocks.air, 0, 3);
		world.setBlock(x + 2, y + 4, z + 11, Blocks.air, 0, 3);
		world.setBlock(x + 3, y + 4, z + 11, ModBlocks.protossMetal, 3, 3);
		world.setBlock(x + 4, y + 4, z + 11, ModBlocks.protossMetal, 1, 3);
		world.setBlock(x + 5, y + 4, z + 11, ModBlocks.protossMetal, 1, 3);
		world.setBlock(x + 6, y + 4, z + 11, ModBlocks.protossMetal, 1, 3);
		world.setBlock(x + 7, y + 4, z + 11, ModBlocks.protossMetal, 1, 3);
		world.setBlock(x + 8, y + 4, z + 11, ModBlocks.protossMetal, 1, 3);
		world.setBlock(x + 9, y + 4, z + 11, ModBlocks.protossMetal, 1, 3);
		world.setBlock(x + 10, y + 4, z + 11, ModBlocks.protossMetal, 1, 3);
		world.setBlock(x + 11, y + 4, z + 11, ModBlocks.protossMetal, 1, 3);
		world.setBlock(x + 12, y + 4, z + 11, ModBlocks.protossMetal, 1, 3);
		world.setBlock(x + 13, y + 4, z + 11, Blocks.air, 0, 3);
		world.setBlock(x + 14, y + 4, z + 11, Blocks.air, 0, 3);
		world.setBlock(x, y + 4, z + 12, Blocks.air, 0, 3);
		world.setBlock(x + 1, y + 4, z + 12, Blocks.air, 0, 3);
		world.setBlock(x + 2, y + 4, z + 12, Blocks.air, 0, 3);
		world.setBlock(x + 3, y + 4, z + 12, Blocks.air, 0, 3);
		world.setBlock(x + 4, y + 4, z + 12, ModBlocks.protossMetal, 1, 3);
		world.setBlock(x + 5, y + 4, z + 12, Blocks.air, 0, 3);
		world.setBlock(x + 6, y + 4, z + 12, Blocks.air, 0, 3);
		world.setBlock(x + 7, y + 4, z + 12, Blocks.air, 0, 3);
		world.setBlock(x + 8, y + 4, z + 12, Blocks.air, 0, 3);
		world.setBlock(x + 9, y + 4, z + 12, ModBlocks.protossMetal, 1, 3);
		world.setBlock(x + 10, y + 4, z + 12, ModBlocks.protossMetal, 3, 3);
		world.setBlock(x + 11, y + 4, z + 12, ModBlocks.protossMetal, 1, 3);
		world.setBlock(x + 12, y + 4, z + 12, ModBlocks.protossMetal, 1, 3);
		world.setBlock(x + 13, y + 4, z + 12, Blocks.air, 0, 3);
		world.setBlock(x + 14, y + 4, z + 12, Blocks.air, 0, 3);
		world.setBlock(x, y + 4, z + 13, Blocks.air, 0, 3);
		world.setBlock(x + 1, y + 4, z + 13, Blocks.air, 0, 3);
		world.setBlock(x + 2, y + 4, z + 13, Blocks.air, 0, 3);
		world.setBlock(x + 3, y + 4, z + 13, Blocks.air, 0, 3);
		world.setBlock(x + 4, y + 4, z + 13, Blocks.air, 0, 3);
		world.setBlock(x + 5, y + 4, z + 13, Blocks.air, 0, 3);
		world.setBlock(x + 6, y + 4, z + 13, Blocks.air, 0, 3);
		world.setBlock(x + 7, y + 4, z + 13, Blocks.air, 0, 3);
		world.setBlock(x + 8, y + 4, z + 13, Blocks.air, 0, 3);
		world.setBlock(x + 9, y + 4, z + 13, Blocks.air, 0, 3);
		world.setBlock(x + 10, y + 4, z + 13, Blocks.air, 0, 3);
		world.setBlock(x + 11, y + 4, z + 13, Blocks.air, 0, 3);
		world.setBlock(x + 12, y + 4, z + 13, Blocks.air, 0, 3);
		world.setBlock(x + 13, y + 4, z + 13, Blocks.air, 0, 3);
		world.setBlock(x + 14, y + 4, z + 13, Blocks.air, 0, 3);
		world.setBlock(x, y + 4, z + 14, Blocks.air, 0, 3);
		world.setBlock(x + 1, y + 4, z + 14, Blocks.air, 0, 3);
		world.setBlock(x + 2, y + 4, z + 14, Blocks.air, 0, 3);
		world.setBlock(x + 3, y + 4, z + 14, Blocks.air, 0, 3);
		world.setBlock(x + 4, y + 4, z + 14, Blocks.air, 0, 3);
		world.setBlock(x + 5, y + 4, z + 14, Blocks.air, 0, 3);
		world.setBlock(x + 6, y + 4, z + 14, Blocks.air, 0, 3);
		world.setBlock(x + 7, y + 4, z + 14, Blocks.air, 0, 3);
		world.setBlock(x + 8, y + 4, z + 14, Blocks.air, 0, 3);
		world.setBlock(x + 9, y + 4, z + 14, Blocks.air, 0, 3);
		world.setBlock(x + 10, y + 4, z + 14, Blocks.air, 0, 3);
		world.setBlock(x + 11, y + 4, z + 14, Blocks.air, 0, 3);
		world.setBlock(x + 12, y + 4, z + 14, Blocks.air, 0, 3);
		world.setBlock(x + 13, y + 4, z + 14, Blocks.air, 0, 3);
		world.setBlock(x + 14, y + 4, z + 14, Blocks.air, 0, 3);
		world.setBlock(x, y + 5, z, Blocks.air, 0, 3);
		world.setBlock(x + 1, y + 5, z, Blocks.air, 0, 3);
		world.setBlock(x + 2, y + 5, z, Blocks.air, 0, 3);
		world.setBlock(x + 3, y + 5, z, Blocks.air, 0, 3);
		world.setBlock(x + 4, y + 5, z, Blocks.air, 0, 3);
		world.setBlock(x + 5, y + 5, z, Blocks.air, 0, 3);
		world.setBlock(x + 6, y + 5, z, Blocks.air, 0, 3);
		world.setBlock(x + 7, y + 5, z, Blocks.air, 0, 3);
		world.setBlock(x + 8, y + 5, z, Blocks.air, 0, 3);
		world.setBlock(x + 9, y + 5, z, Blocks.air, 0, 3);
		world.setBlock(x + 10, y + 5, z, Blocks.air, 0, 3);
		world.setBlock(x + 11, y + 5, z, Blocks.air, 0, 3);
		world.setBlock(x + 12, y + 5, z, Blocks.air, 0, 3);
		world.setBlock(x + 13, y + 5, z, Blocks.air, 0, 3);
		world.setBlock(x + 14, y + 5, z, Blocks.air, 0, 3);
		world.setBlock(x, y + 5, z + 1, Blocks.air, 0, 3);
		world.setBlock(x + 1, y + 5, z + 1, Blocks.air, 0, 3);
		world.setBlock(x + 2, y + 5, z + 1, ModBlocks.protossMetal, 1, 3);
		world.setBlock(x + 3, y + 5, z + 1, ModBlocks.protossMetal, 1, 3);
		world.setBlock(x + 4, y + 5, z + 1, Blocks.air, 0, 3);
		world.setBlock(x + 5, y + 5, z + 1, Blocks.air, 0, 3);
		world.setBlock(x + 6, y + 5, z + 1, Blocks.air, 0, 3);
		world.setBlock(x + 7, y + 5, z + 1, Blocks.air, 0, 3);
		world.setBlock(x + 8, y + 5, z + 1, Blocks.air, 0, 3);
		world.setBlock(x + 9, y + 5, z + 1, Blocks.air, 0, 3);
		world.setBlock(x + 10, y + 5, z + 1, Blocks.air, 0, 3);
		world.setBlock(x + 11, y + 5, z + 1, Blocks.air, 0, 3);
		world.setBlock(x + 12, y + 5, z + 1, Blocks.air, 0, 3);
		world.setBlock(x + 13, y + 5, z + 1, Blocks.air, 0, 3);
		world.setBlock(x + 14, y + 5, z + 1, Blocks.air, 0, 3);
		world.setBlock(x, y + 5, z + 2, Blocks.air, 0, 3);
		world.setBlock(x + 1, y + 5, z + 2, ModBlocks.protossMetal, 1, 3);
		world.setBlock(x + 2, y + 5, z + 2, ModBlocks.protossMetal, 1, 3);
		world.setBlock(x + 3, y + 5, z + 2, ModBlocks.protossMetal, 1, 3);
		world.setBlock(x + 4, y + 5, z + 2, ModBlocks.protossMetal, 1, 3);
		world.setBlock(x + 5, y + 5, z + 2, Blocks.air, 0, 3);
		world.setBlock(x + 6, y + 5, z + 2, Blocks.air, 0, 3);
		world.setBlock(x + 7, y + 5, z + 2, Blocks.air, 0, 3);
		world.setBlock(x + 8, y + 5, z + 2, Blocks.air, 0, 3);
		world.setBlock(x + 9, y + 5, z + 2, Blocks.air, 0, 3);
		world.setBlock(x + 10, y + 5, z + 2, Blocks.air, 0, 3);
		world.setBlock(x + 11, y + 5, z + 2, Blocks.air, 0, 3);
		world.setBlock(x + 12, y + 5, z + 2, Blocks.air, 0, 3);
		world.setBlock(x + 13, y + 5, z + 2, Blocks.air, 0, 3);
		world.setBlock(x + 14, y + 5, z + 2, Blocks.air, 0, 3);
		world.setBlock(x, y + 5, z + 3, Blocks.air, 0, 3);
		world.setBlock(x + 1, y + 5, z + 3, ModBlocks.protossMetal, 1, 3);
		world.setBlock(x + 2, y + 5, z + 3, ModBlocks.protossMetal, 1, 3);
		world.setBlock(x + 3, y + 5, z + 3, ModBlocks.protossEnergyChannelDark, 0, 3);
		world.setBlock(x + 4, y + 5, z + 3, Blocks.air, 0, 3);
		world.setBlock(x + 5, y + 5, z + 3, Blocks.air, 0, 3);
		world.setBlock(x + 6, y + 5, z + 3, Blocks.air, 0, 3);
		world.setBlock(x + 7, y + 5, z + 3, Blocks.air, 0, 3);
		world.setBlock(x + 8, y + 5, z + 3, Blocks.air, 0, 3);
		world.setBlock(x + 9, y + 5, z + 3, Blocks.air, 0, 3);
		world.setBlock(x + 10, y + 5, z + 3, Blocks.air, 0, 3);
		world.setBlock(x + 11, y + 5, z + 3, Blocks.air, 0, 3);
		world.setBlock(x + 12, y + 5, z + 3, Blocks.air, 0, 3);
		world.setBlock(x + 13, y + 5, z + 3, Blocks.air, 0, 3);
		world.setBlock(x + 14, y + 5, z + 3, Blocks.air, 0, 3);
		world.setBlock(x, y + 5, z + 4, Blocks.air, 0, 3);
		world.setBlock(x + 1, y + 5, z + 4, Blocks.air, 0, 3);
		world.setBlock(x + 2, y + 5, z + 4, ModBlocks.protossMetal, 1, 3);
		world.setBlock(x + 3, y + 5, z + 4, Blocks.air, 0, 3);
		world.setBlock(x + 4, y + 5, z + 4, Blocks.air, 0, 3);
		world.setBlock(x + 5, y + 5, z + 4, Blocks.air, 0, 3);
		world.setBlock(x + 6, y + 5, z + 4, Blocks.air, 0, 3);
		world.setBlock(x + 7, y + 5, z + 4, ModBlocks.protossMetal, 1, 3);
		world.setBlock(x + 8, y + 5, z + 4, ModBlocks.protossMetal, 3, 3);
		world.setBlock(x + 9, y + 5, z + 4, ModBlocks.protossMetal, 1, 3);
		world.setBlock(x + 10, y + 5, z + 4, Blocks.air, 0, 3);
		world.setBlock(x + 11, y + 5, z + 4, Blocks.air, 0, 3);
		world.setBlock(x + 12, y + 5, z + 4, Blocks.air, 0, 3);
		world.setBlock(x + 13, y + 5, z + 4, Blocks.air, 0, 3);
		world.setBlock(x + 14, y + 5, z + 4, Blocks.air, 0, 3);
		world.setBlock(x, y + 5, z + 5, Blocks.air, 0, 3);
		world.setBlock(x + 1, y + 5, z + 5, Blocks.air, 0, 3);
		world.setBlock(x + 2, y + 5, z + 5, Blocks.air, 0, 3);
		world.setBlock(x + 3, y + 5, z + 5, Blocks.air, 0, 3);
		world.setBlock(x + 4, y + 5, z + 5, Blocks.air, 0, 3);
		world.setBlock(x + 5, y + 5, z + 5, ModBlocks.protossEnergyStabilizerDark, 0, 3);
		world.setBlock(x + 6, y + 5, z + 5, ModBlocks.protossMetal, 1, 3);
		world.setBlock(x + 7, y + 5, z + 5, ModBlocks.protossMetal, 3, 3);
		world.setBlock(x + 8, y + 5, z + 5, ModBlocks.protossMetal, 1, 3);
		world.setBlock(x + 9, y + 5, z + 5, ModBlocks.protossMetal, 1, 3);
		world.setBlock(x + 10, y + 5, z + 5, ModBlocks.protossMetal, 1, 3);
		world.setBlock(x + 11, y + 5, z + 5, Blocks.air, 0, 3);
		world.setBlock(x + 12, y + 5, z + 5, Blocks.air, 0, 3);
		world.setBlock(x + 13, y + 5, z + 5, Blocks.air, 0, 3);
		world.setBlock(x + 14, y + 5, z + 5, Blocks.air, 0, 3);
		world.setBlock(x, y + 5, z + 6, Blocks.air, 0, 3);
		world.setBlock(x + 1, y + 5, z + 6, Blocks.air, 0, 3);
		world.setBlock(x + 2, y + 5, z + 6, Blocks.air, 0, 3);
		world.setBlock(x + 3, y + 5, z + 6, Blocks.air, 0, 3);
		world.setBlock(x + 4, y + 5, z + 6, Blocks.air, 0, 3);
		world.setBlock(x + 5, y + 5, z + 6, ModBlocks.protossMetal, 1, 3);
		world.setBlock(x + 6, y + 5, z + 6, ModBlocks.protossMetal, 1, 3);
		world.setBlock(x + 7, y + 5, z + 6, ModBlocks.protossMetal, 1, 3);
		world.setBlock(x + 8, y + 5, z + 6, ModBlocks.protossMetal, 3, 3);
		world.setBlock(x + 9, y + 5, z + 6, ModBlocks.protossMetal, 1, 3);
		world.setBlock(x + 10, y + 5, z + 6, ModBlocks.protossMetal, 3, 3);
		world.setBlock(x + 11, y + 5, z + 6, Blocks.air, 0, 3);
		world.setBlock(x + 12, y + 5, z + 6, Blocks.air, 0, 3);
		world.setBlock(x + 13, y + 5, z + 6, Blocks.air, 0, 3);
		world.setBlock(x + 14, y + 5, z + 6, Blocks.air, 0, 3);
		world.setBlock(x, y + 5, z + 7, Blocks.air, 0, 3);
		world.setBlock(x + 1, y + 5, z + 7, Blocks.air, 0, 3);
		world.setBlock(x + 2, y + 5, z + 7, Blocks.air, 0, 3);
		world.setBlock(x + 3, y + 5, z + 7, Blocks.air, 0, 3);
		world.setBlock(x + 4, y + 5, z + 7, ModBlocks.protossMetal, 1, 3);
		world.setBlock(x + 5, y + 5, z + 7, ModBlocks.protossMetal, 3, 3);
		world.setBlock(x + 6, y + 5, z + 7, ModBlocks.protossMetal, 1, 3);
		world.setBlock(x + 7, y + 5, z + 7, ModBlocks.protossEnergyStabilizerDark, 0, 3);
		world.setBlock(x + 8, y + 5, z + 7, ModBlocks.protossMetal, 1, 3);
		world.setBlock(x + 9, y + 5, z + 7, ModBlocks.protossMetal, 3, 3);
		world.setBlock(x + 10, y + 5, z + 7, ModBlocks.protossMetal, 1, 3);
		world.setBlock(x + 11, y + 5, z + 7, Blocks.air, 0, 3);
		world.setBlock(x + 12, y + 5, z + 7, Blocks.air, 0, 3);
		world.setBlock(x + 13, y + 5, z + 7, Blocks.air, 0, 3);
		world.setBlock(x + 14, y + 5, z + 7, Blocks.air, 0, 3);
		world.setBlock(x, y + 5, z + 8, Blocks.air, 0, 3);
		world.setBlock(x + 1, y + 5, z + 8, Blocks.air, 0, 3);
		world.setBlock(x + 2, y + 5, z + 8, Blocks.air, 0, 3);
		world.setBlock(x + 3, y + 5, z + 8, Blocks.air, 0, 3);
		world.setBlock(x + 4, y + 5, z + 8, ModBlocks.protossMetal, 3, 3);
		world.setBlock(x + 5, y + 5, z + 8, ModBlocks.protossMetal, 1, 3);
		world.setBlock(x + 6, y + 5, z + 8, ModBlocks.protossMetal, 3, 3);
		world.setBlock(x + 7, y + 5, z + 8, ModBlocks.protossMetal, 1, 3);
		world.setBlock(x + 8, y + 5, z + 8, ModBlocks.protossMetal, 1, 3);
		world.setBlock(x + 9, y + 5, z + 8, ModBlocks.protossMetal, 1, 3);
		world.setBlock(x + 10, y + 5, z + 8, Blocks.air, 0, 3);
		world.setBlock(x + 11, y + 5, z + 8, Blocks.air, 0, 3);
		world.setBlock(x + 12, y + 5, z + 8, Blocks.air, 0, 3);
		world.setBlock(x + 13, y + 5, z + 8, Blocks.air, 0, 3);
		world.setBlock(x + 14, y + 5, z + 8, Blocks.air, 0, 3);
		world.setBlock(x, y + 5, z + 9, Blocks.air, 0, 3);
		world.setBlock(x + 1, y + 5, z + 9, Blocks.air, 0, 3);
		world.setBlock(x + 2, y + 5, z + 9, Blocks.air, 0, 3);
		world.setBlock(x + 3, y + 5, z + 9, Blocks.air, 0, 3);
		world.setBlock(x + 4, y + 5, z + 9, ModBlocks.protossMetal, 1, 3);
		world.setBlock(x + 5, y + 5, z + 9, ModBlocks.protossMetal, 1, 3);
		world.setBlock(x + 6, y + 5, z + 9, ModBlocks.protossMetal, 1, 3);
		world.setBlock(x + 7, y + 5, z + 9, ModBlocks.protossMetal, 3, 3);
		world.setBlock(x + 8, y + 5, z + 9, ModBlocks.protossMetal, 1, 3);
		world.setBlock(x + 9, y + 5, z + 9, ModBlocks.protossEnergyStabilizerDark, 0, 3);
		world.setBlock(x + 10, y + 5, z + 9, Blocks.air, 0, 3);
		world.setBlock(x + 11, y + 5, z + 9, Blocks.air, 0, 3);
		world.setBlock(x + 12, y + 5, z + 9, Blocks.air, 0, 3);
		world.setBlock(x + 13, y + 5, z + 9, Blocks.air, 0, 3);
		world.setBlock(x + 14, y + 5, z + 9, Blocks.air, 0, 3);
		world.setBlock(x, y + 5, z + 10, Blocks.air, 0, 3);
		world.setBlock(x + 1, y + 5, z + 10, Blocks.air, 0, 3);
		world.setBlock(x + 2, y + 5, z + 10, Blocks.air, 0, 3);
		world.setBlock(x + 3, y + 5, z + 10, Blocks.air, 0, 3);
		world.setBlock(x + 4, y + 5, z + 10, Blocks.air, 0, 3);
		world.setBlock(x + 5, y + 5, z + 10, ModBlocks.protossMetal, 1, 3);
		world.setBlock(x + 6, y + 5, z + 10, ModBlocks.protossMetal, 3, 3);
		world.setBlock(x + 7, y + 5, z + 10, ModBlocks.protossMetal, 1, 3);
		world.setBlock(x + 8, y + 5, z + 10, Blocks.air, 0, 3);
		world.setBlock(x + 9, y + 5, z + 10, Blocks.air, 0, 3);
		world.setBlock(x + 10, y + 5, z + 10, Blocks.air, 0, 3);
		world.setBlock(x + 11, y + 5, z + 10, Blocks.air, 0, 3);
		world.setBlock(x + 12, y + 5, z + 10, ModBlocks.protossMetal, 1, 3);
		world.setBlock(x + 13, y + 5, z + 10, Blocks.air, 0, 3);
		world.setBlock(x + 14, y + 5, z + 10, Blocks.air, 0, 3);
		world.setBlock(x, y + 5, z + 11, Blocks.air, 0, 3);
		world.setBlock(x + 1, y + 5, z + 11, Blocks.air, 0, 3);
		world.setBlock(x + 2, y + 5, z + 11, Blocks.air, 0, 3);
		world.setBlock(x + 3, y + 5, z + 11, Blocks.air, 0, 3);
		world.setBlock(x + 4, y + 5, z + 11, Blocks.air, 0, 3);
		world.setBlock(x + 5, y + 5, z + 11, Blocks.air, 0, 3);
		world.setBlock(x + 6, y + 5, z + 11, Blocks.air, 0, 3);
		world.setBlock(x + 7, y + 5, z + 11, Blocks.air, 0, 3);
		world.setBlock(x + 8, y + 5, z + 11, Blocks.air, 0, 3);
		world.setBlock(x + 9, y + 5, z + 11, Blocks.air, 0, 3);
		world.setBlock(x + 10, y + 5, z + 11, Blocks.air, 0, 3);
		world.setBlock(x + 11, y + 5, z + 11, ModBlocks.protossEnergyChannelDark, 0, 3);
		world.setBlock(x + 12, y + 5, z + 11, ModBlocks.protossMetal, 1, 3);
		world.setBlock(x + 13, y + 5, z + 11, ModBlocks.protossMetal, 1, 3);
		world.setBlock(x + 14, y + 5, z + 11, Blocks.air, 0, 3);
		world.setBlock(x, y + 5, z + 12, Blocks.air, 0, 3);
		world.setBlock(x + 1, y + 5, z + 12, Blocks.air, 0, 3);
		world.setBlock(x + 2, y + 5, z + 12, Blocks.air, 0, 3);
		world.setBlock(x + 3, y + 5, z + 12, Blocks.air, 0, 3);
		world.setBlock(x + 4, y + 5, z + 12, Blocks.air, 0, 3);
		world.setBlock(x + 5, y + 5, z + 12, Blocks.air, 0, 3);
		world.setBlock(x + 6, y + 5, z + 12, Blocks.air, 0, 3);
		world.setBlock(x + 7, y + 5, z + 12, Blocks.air, 0, 3);
		world.setBlock(x + 8, y + 5, z + 12, Blocks.air, 0, 3);
		world.setBlock(x + 9, y + 5, z + 12, Blocks.air, 0, 3);
		world.setBlock(x + 10, y + 5, z + 12, ModBlocks.protossMetal, 1, 3);
		world.setBlock(x + 11, y + 5, z + 12, ModBlocks.protossMetal, 1, 3);
		world.setBlock(x + 12, y + 5, z + 12, ModBlocks.protossMetal, 1, 3);
		world.setBlock(x + 13, y + 5, z + 12, ModBlocks.protossMetal, 1, 3);
		world.setBlock(x + 14, y + 5, z + 12, Blocks.air, 0, 3);
		world.setBlock(x, y + 5, z + 13, Blocks.air, 0, 3);
		world.setBlock(x + 1, y + 5, z + 13, Blocks.air, 0, 3);
		world.setBlock(x + 2, y + 5, z + 13, Blocks.air, 0, 3);
		world.setBlock(x + 3, y + 5, z + 13, Blocks.air, 0, 3);
		world.setBlock(x + 4, y + 5, z + 13, Blocks.air, 0, 3);
		world.setBlock(x + 5, y + 5, z + 13, Blocks.air, 0, 3);
		world.setBlock(x + 6, y + 5, z + 13, Blocks.air, 0, 3);
		world.setBlock(x + 7, y + 5, z + 13, Blocks.air, 0, 3);
		world.setBlock(x + 8, y + 5, z + 13, Blocks.air, 0, 3);
		world.setBlock(x + 9, y + 5, z + 13, Blocks.air, 0, 3);
		world.setBlock(x + 10, y + 5, z + 13, Blocks.air, 0, 3);
		world.setBlock(x + 11, y + 5, z + 13, ModBlocks.protossMetal, 1, 3);
		world.setBlock(x + 12, y + 5, z + 13, ModBlocks.protossMetal, 1, 3);
		world.setBlock(x + 13, y + 5, z + 13, Blocks.air, 0, 3);
		world.setBlock(x + 14, y + 5, z + 13, Blocks.air, 0, 3);
		world.setBlock(x, y + 5, z + 14, Blocks.air, 0, 3);
		world.setBlock(x + 1, y + 5, z + 14, Blocks.air, 0, 3);
		world.setBlock(x + 2, y + 5, z + 14, Blocks.air, 0, 3);
		world.setBlock(x + 3, y + 5, z + 14, Blocks.air, 0, 3);
		world.setBlock(x + 4, y + 5, z + 14, Blocks.air, 0, 3);
		world.setBlock(x + 5, y + 5, z + 14, Blocks.air, 0, 3);
		world.setBlock(x + 6, y + 5, z + 14, Blocks.air, 0, 3);
		world.setBlock(x + 7, y + 5, z + 14, Blocks.air, 0, 3);
		world.setBlock(x + 8, y + 5, z + 14, Blocks.air, 0, 3);
		world.setBlock(x + 9, y + 5, z + 14, Blocks.air, 0, 3);
		world.setBlock(x + 10, y + 5, z + 14, Blocks.air, 0, 3);
		world.setBlock(x + 11, y + 5, z + 14, Blocks.air, 0, 3);
		world.setBlock(x + 12, y + 5, z + 14, Blocks.air, 0, 3);
		world.setBlock(x + 13, y + 5, z + 14, Blocks.air, 0, 3);
		world.setBlock(x + 14, y + 5, z + 14, Blocks.air, 0, 3);
		world.setBlock(x, y + 6, z, Blocks.air, 0, 3);
		world.setBlock(x + 1, y + 6, z, Blocks.air, 0, 3);
		world.setBlock(x + 2, y + 6, z, Blocks.air, 0, 3);
		world.setBlock(x + 3, y + 6, z, Blocks.air, 0, 3);
		world.setBlock(x + 4, y + 6, z, Blocks.air, 0, 3);
		world.setBlock(x + 5, y + 6, z, Blocks.air, 0, 3);
		world.setBlock(x + 6, y + 6, z, Blocks.air, 0, 3);
		world.setBlock(x + 7, y + 6, z, Blocks.air, 0, 3);
		world.setBlock(x + 8, y + 6, z, Blocks.air, 0, 3);
		world.setBlock(x + 9, y + 6, z, Blocks.air, 0, 3);
		world.setBlock(x + 10, y + 6, z, Blocks.air, 0, 3);
		world.setBlock(x + 11, y + 6, z, Blocks.air, 0, 3);
		world.setBlock(x + 12, y + 6, z, Blocks.air, 0, 3);
		world.setBlock(x + 13, y + 6, z, Blocks.air, 0, 3);
		world.setBlock(x + 14, y + 6, z, Blocks.air, 0, 3);
		world.setBlock(x, y + 6, z + 1, Blocks.air, 0, 3);
		world.setBlock(x + 1, y + 6, z + 1, Blocks.air, 0, 3);
		world.setBlock(x + 2, y + 6, z + 1, ModBlocks.protossMetal, 1, 3);
		world.setBlock(x + 3, y + 6, z + 1, ModBlocks.protossMetal, 1, 3);
		world.setBlock(x + 4, y + 6, z + 1, Blocks.air, 0, 3);
		world.setBlock(x + 5, y + 6, z + 1, Blocks.air, 0, 3);
		world.setBlock(x + 6, y + 6, z + 1, Blocks.air, 0, 3);
		world.setBlock(x + 7, y + 6, z + 1, Blocks.air, 0, 3);
		world.setBlock(x + 8, y + 6, z + 1, Blocks.air, 0, 3);
		world.setBlock(x + 9, y + 6, z + 1, Blocks.air, 0, 3);
		world.setBlock(x + 10, y + 6, z + 1, Blocks.air, 0, 3);
		world.setBlock(x + 11, y + 6, z + 1, Blocks.air, 0, 3);
		world.setBlock(x + 12, y + 6, z + 1, Blocks.air, 0, 3);
		world.setBlock(x + 13, y + 6, z + 1, Blocks.air, 0, 3);
		world.setBlock(x + 14, y + 6, z + 1, Blocks.air, 0, 3);
		world.setBlock(x, y + 6, z + 2, Blocks.air, 0, 3);
		world.setBlock(x + 1, y + 6, z + 2, ModBlocks.protossMetal, 1, 3);
		world.setBlock(x + 2, y + 6, z + 2, ModBlocks.protossMetal, 1, 3);
		world.setBlock(x + 3, y + 6, z + 2, ModBlocks.protossMetal, 1, 3);
		world.setBlock(x + 4, y + 6, z + 2, Blocks.air, 0, 3);
		world.setBlock(x + 5, y + 6, z + 2, Blocks.air, 0, 3);
		world.setBlock(x + 6, y + 6, z + 2, Blocks.air, 0, 3);
		world.setBlock(x + 7, y + 6, z + 2, Blocks.air, 0, 3);
		world.setBlock(x + 8, y + 6, z + 2, Blocks.air, 0, 3);
		world.setBlock(x + 9, y + 6, z + 2, Blocks.air, 0, 3);
		world.setBlock(x + 10, y + 6, z + 2, Blocks.air, 0, 3);
		world.setBlock(x + 11, y + 6, z + 2, Blocks.air, 0, 3);
		world.setBlock(x + 12, y + 6, z + 2, Blocks.air, 0, 3);
		world.setBlock(x + 13, y + 6, z + 2, Blocks.air, 0, 3);
		world.setBlock(x + 14, y + 6, z + 2, Blocks.air, 0, 3);
		world.setBlock(x, y + 6, z + 3, Blocks.air, 0, 3);
		world.setBlock(x + 1, y + 6, z + 3, ModBlocks.protossMetal, 1, 3);
		world.setBlock(x + 2, y + 6, z + 3, ModBlocks.protossMetal, 1, 3);
		world.setBlock(x + 3, y + 6, z + 3, ModBlocks.protossEnergyChannelDark, 0, 3);
		world.setBlock(x + 4, y + 6, z + 3, Blocks.air, 0, 3);
		world.setBlock(x + 5, y + 6, z + 3, Blocks.air, 0, 3);
		world.setBlock(x + 6, y + 6, z + 3, Blocks.air, 0, 3);
		world.setBlock(x + 7, y + 6, z + 3, Blocks.air, 0, 3);
		world.setBlock(x + 8, y + 6, z + 3, Blocks.air, 0, 3);
		world.setBlock(x + 9, y + 6, z + 3, Blocks.air, 0, 3);
		world.setBlock(x + 10, y + 6, z + 3, Blocks.air, 0, 3);
		world.setBlock(x + 11, y + 6, z + 3, Blocks.air, 0, 3);
		world.setBlock(x + 12, y + 6, z + 3, Blocks.air, 0, 3);
		world.setBlock(x + 13, y + 6, z + 3, Blocks.air, 0, 3);
		world.setBlock(x + 14, y + 6, z + 3, Blocks.air, 0, 3);
		world.setBlock(x, y + 6, z + 4, Blocks.air, 0, 3);
		world.setBlock(x + 1, y + 6, z + 4, Blocks.air, 0, 3);
		world.setBlock(x + 2, y + 6, z + 4, Blocks.air, 0, 3);
		world.setBlock(x + 3, y + 6, z + 4, Blocks.air, 0, 3);
		world.setBlock(x + 4, y + 6, z + 4, Blocks.air, 0, 3);
		world.setBlock(x + 5, y + 6, z + 4, Blocks.air, 0, 3);
		world.setBlock(x + 6, y + 6, z + 4, Blocks.air, 0, 3);
		world.setBlock(x + 7, y + 6, z + 4, Blocks.air, 0, 3);
		world.setBlock(x + 8, y + 6, z + 4, Blocks.air, 0, 3);
		world.setBlock(x + 9, y + 6, z + 4, Blocks.air, 0, 3);
		world.setBlock(x + 10, y + 6, z + 4, Blocks.air, 0, 3);
		world.setBlock(x + 11, y + 6, z + 4, Blocks.air, 0, 3);
		world.setBlock(x + 12, y + 6, z + 4, Blocks.air, 0, 3);
		world.setBlock(x + 13, y + 6, z + 4, Blocks.air, 0, 3);
		world.setBlock(x + 14, y + 6, z + 4, Blocks.air, 0, 3);
		world.setBlock(x, y + 6, z + 5, Blocks.air, 0, 3);
		world.setBlock(x + 1, y + 6, z + 5, Blocks.air, 0, 3);
		world.setBlock(x + 2, y + 6, z + 5, Blocks.air, 0, 3);
		world.setBlock(x + 3, y + 6, z + 5, Blocks.air, 0, 3);
		world.setBlock(x + 4, y + 6, z + 5, Blocks.air, 0, 3);
		world.setBlock(x + 5, y + 6, z + 5, Blocks.air, 0, 3);
		world.setBlock(x + 6, y + 6, z + 5, Blocks.air, 0, 3);
		world.setBlock(x + 7, y + 6, z + 5, Blocks.air, 0, 3);
		world.setBlock(x + 8, y + 6, z + 5, Blocks.air, 0, 3);
		world.setBlock(x + 9, y + 6, z + 5, Blocks.air, 0, 3);
		world.setBlock(x + 10, y + 6, z + 5, Blocks.air, 0, 3);
		world.setBlock(x + 11, y + 6, z + 5, Blocks.air, 0, 3);
		world.setBlock(x + 12, y + 6, z + 5, Blocks.air, 0, 3);
		world.setBlock(x + 13, y + 6, z + 5, Blocks.air, 0, 3);
		world.setBlock(x + 14, y + 6, z + 5, Blocks.air, 0, 3);
		world.setBlock(x, y + 6, z + 6, Blocks.air, 0, 3);
		world.setBlock(x + 1, y + 6, z + 6, Blocks.air, 0, 3);
		world.setBlock(x + 2, y + 6, z + 6, Blocks.air, 0, 3);
		world.setBlock(x + 3, y + 6, z + 6, Blocks.air, 0, 3);
		world.setBlock(x + 4, y + 6, z + 6, Blocks.air, 0, 3);
		world.setBlock(x + 5, y + 6, z + 6, Blocks.air, 0, 3);
		world.setBlock(x + 6, y + 6, z + 6, Blocks.air, 0, 3);
		world.setBlock(x + 7, y + 6, z + 6, Blocks.air, 0, 3);
		world.setBlock(x + 8, y + 6, z + 6, Blocks.air, 0, 3);
		world.setBlock(x + 9, y + 6, z + 6, Blocks.air, 0, 3);
		world.setBlock(x + 10, y + 6, z + 6, Blocks.air, 0, 3);
		world.setBlock(x + 11, y + 6, z + 6, Blocks.air, 0, 3);
		world.setBlock(x + 12, y + 6, z + 6, Blocks.air, 0, 3);
		world.setBlock(x + 13, y + 6, z + 6, Blocks.air, 0, 3);
		world.setBlock(x + 14, y + 6, z + 6, Blocks.air, 0, 3);
		world.setBlock(x, y + 6, z + 7, Blocks.air, 0, 3);
		world.setBlock(x + 1, y + 6, z + 7, Blocks.air, 0, 3);
		world.setBlock(x + 2, y + 6, z + 7, Blocks.air, 0, 3);
		world.setBlock(x + 3, y + 6, z + 7, Blocks.air, 0, 3);
		world.setBlock(x + 4, y + 6, z + 7, Blocks.air, 0, 3);
		world.setBlock(x + 5, y + 6, z + 7, Blocks.air, 0, 3);
		world.setBlock(x + 6, y + 6, z + 7, Blocks.air, 0, 3);
		world.setBlock(x + 7, y + 6, z + 7, Blocks.air, 0, 3);
		world.setBlock(x + 8, y + 6, z + 7, Blocks.air, 0, 3);
		world.setBlock(x + 9, y + 6, z + 7, Blocks.air, 0, 3);
		world.setBlock(x + 10, y + 6, z + 7, Blocks.air, 0, 3);
		world.setBlock(x + 11, y + 6, z + 7, Blocks.air, 0, 3);
		world.setBlock(x + 12, y + 6, z + 7, Blocks.air, 0, 3);
		world.setBlock(x + 13, y + 6, z + 7, Blocks.air, 0, 3);
		world.setBlock(x + 14, y + 6, z + 7, Blocks.air, 0, 3);
		world.setBlock(x, y + 6, z + 8, Blocks.air, 0, 3);
		world.setBlock(x + 1, y + 6, z + 8, Blocks.air, 0, 3);
		world.setBlock(x + 2, y + 6, z + 8, Blocks.air, 0, 3);
		world.setBlock(x + 3, y + 6, z + 8, Blocks.air, 0, 3);
		world.setBlock(x + 4, y + 6, z + 8, Blocks.air, 0, 3);
		world.setBlock(x + 5, y + 6, z + 8, Blocks.air, 0, 3);
		world.setBlock(x + 6, y + 6, z + 8, Blocks.air, 0, 3);
		world.setBlock(x + 7, y + 6, z + 8, Blocks.air, 0, 3);
		world.setBlock(x + 8, y + 6, z + 8, Blocks.air, 0, 3);
		world.setBlock(x + 9, y + 6, z + 8, Blocks.air, 0, 3);
		world.setBlock(x + 10, y + 6, z + 8, Blocks.air, 0, 3);
		world.setBlock(x + 11, y + 6, z + 8, Blocks.air, 0, 3);
		world.setBlock(x + 12, y + 6, z + 8, Blocks.air, 0, 3);
		world.setBlock(x + 13, y + 6, z + 8, Blocks.air, 0, 3);
		world.setBlock(x + 14, y + 6, z + 8, Blocks.air, 0, 3);
		world.setBlock(x, y + 6, z + 9, Blocks.air, 0, 3);
		world.setBlock(x + 1, y + 6, z + 9, Blocks.air, 0, 3);
		world.setBlock(x + 2, y + 6, z + 9, Blocks.air, 0, 3);
		world.setBlock(x + 3, y + 6, z + 9, Blocks.air, 0, 3);
		world.setBlock(x + 4, y + 6, z + 9, Blocks.air, 0, 3);
		world.setBlock(x + 5, y + 6, z + 9, Blocks.air, 0, 3);
		world.setBlock(x + 6, y + 6, z + 9, Blocks.air, 0, 3);
		world.setBlock(x + 7, y + 6, z + 9, Blocks.air, 0, 3);
		world.setBlock(x + 8, y + 6, z + 9, Blocks.air, 0, 3);
		world.setBlock(x + 9, y + 6, z + 9, Blocks.air, 0, 3);
		world.setBlock(x + 10, y + 6, z + 9, Blocks.air, 0, 3);
		world.setBlock(x + 11, y + 6, z + 9, Blocks.air, 0, 3);
		world.setBlock(x + 12, y + 6, z + 9, Blocks.air, 0, 3);
		world.setBlock(x + 13, y + 6, z + 9, Blocks.air, 0, 3);
		world.setBlock(x + 14, y + 6, z + 9, Blocks.air, 0, 3);

		generate_r02(world, x, y, z);
		return true;

	}

	public boolean generate_r02(World world, int x, int y, int z) {

		world.setBlock(x, y + 6, z + 10, Blocks.air, 0, 3);
		world.setBlock(x + 1, y + 6, z + 10, Blocks.air, 0, 3);
		world.setBlock(x + 2, y + 6, z + 10, Blocks.air, 0, 3);
		world.setBlock(x + 3, y + 6, z + 10, Blocks.air, 0, 3);
		world.setBlock(x + 4, y + 6, z + 10, Blocks.air, 0, 3);
		world.setBlock(x + 5, y + 6, z + 10, Blocks.air, 0, 3);
		world.setBlock(x + 6, y + 6, z + 10, Blocks.air, 0, 3);
		world.setBlock(x + 7, y + 6, z + 10, Blocks.air, 0, 3);
		world.setBlock(x + 8, y + 6, z + 10, Blocks.air, 0, 3);
		world.setBlock(x + 9, y + 6, z + 10, Blocks.air, 0, 3);
		world.setBlock(x + 10, y + 6, z + 10, Blocks.air, 0, 3);
		world.setBlock(x + 11, y + 6, z + 10, Blocks.air, 0, 3);
		world.setBlock(x + 12, y + 6, z + 10, Blocks.air, 0, 3);
		world.setBlock(x + 13, y + 6, z + 10, Blocks.air, 0, 3);
		world.setBlock(x + 14, y + 6, z + 10, Blocks.air, 0, 3);
		world.setBlock(x, y + 6, z + 11, Blocks.air, 0, 3);
		world.setBlock(x + 1, y + 6, z + 11, Blocks.air, 0, 3);
		world.setBlock(x + 2, y + 6, z + 11, Blocks.air, 0, 3);
		world.setBlock(x + 3, y + 6, z + 11, Blocks.air, 0, 3);
		world.setBlock(x + 4, y + 6, z + 11, Blocks.air, 0, 3);
		world.setBlock(x + 5, y + 6, z + 11, Blocks.air, 0, 3);
		world.setBlock(x + 6, y + 6, z + 11, Blocks.air, 0, 3);
		world.setBlock(x + 7, y + 6, z + 11, Blocks.air, 0, 3);
		world.setBlock(x + 8, y + 6, z + 11, Blocks.air, 0, 3);
		world.setBlock(x + 9, y + 6, z + 11, Blocks.air, 0, 3);
		world.setBlock(x + 10, y + 6, z + 11, Blocks.air, 0, 3);
		world.setBlock(x + 11, y + 6, z + 11, ModBlocks.protossEnergyChannelDark, 0, 3);
		world.setBlock(x + 12, y + 6, z + 11, ModBlocks.protossMetal, 1, 3);
		world.setBlock(x + 13, y + 6, z + 11, ModBlocks.protossMetal, 1, 3);
		world.setBlock(x + 14, y + 6, z + 11, Blocks.air, 0, 3);
		world.setBlock(x, y + 6, z + 12, Blocks.air, 0, 3);
		world.setBlock(x + 1, y + 6, z + 12, Blocks.air, 0, 3);
		world.setBlock(x + 2, y + 6, z + 12, Blocks.air, 0, 3);
		world.setBlock(x + 3, y + 6, z + 12, Blocks.air, 0, 3);
		world.setBlock(x + 4, y + 6, z + 12, Blocks.air, 0, 3);
		world.setBlock(x + 5, y + 6, z + 12, Blocks.air, 0, 3);
		world.setBlock(x + 6, y + 6, z + 12, Blocks.air, 0, 3);
		world.setBlock(x + 7, y + 6, z + 12, Blocks.air, 0, 3);
		world.setBlock(x + 8, y + 6, z + 12, Blocks.air, 0, 3);
		world.setBlock(x + 9, y + 6, z + 12, Blocks.air, 0, 3);
		world.setBlock(x + 10, y + 6, z + 12, Blocks.air, 0, 3);
		world.setBlock(x + 11, y + 6, z + 12, ModBlocks.protossMetal, 1, 3);
		world.setBlock(x + 12, y + 6, z + 12, ModBlocks.protossMetal, 1, 3);
		world.setBlock(x + 13, y + 6, z + 12, ModBlocks.protossMetal, 1, 3);
		world.setBlock(x + 14, y + 6, z + 12, Blocks.air, 0, 3);
		world.setBlock(x, y + 6, z + 13, Blocks.air, 0, 3);
		world.setBlock(x + 1, y + 6, z + 13, Blocks.air, 0, 3);
		world.setBlock(x + 2, y + 6, z + 13, Blocks.air, 0, 3);
		world.setBlock(x + 3, y + 6, z + 13, Blocks.air, 0, 3);
		world.setBlock(x + 4, y + 6, z + 13, Blocks.air, 0, 3);
		world.setBlock(x + 5, y + 6, z + 13, Blocks.air, 0, 3);
		world.setBlock(x + 6, y + 6, z + 13, Blocks.air, 0, 3);
		world.setBlock(x + 7, y + 6, z + 13, Blocks.air, 0, 3);
		world.setBlock(x + 8, y + 6, z + 13, Blocks.air, 0, 3);
		world.setBlock(x + 9, y + 6, z + 13, Blocks.air, 0, 3);
		world.setBlock(x + 10, y + 6, z + 13, Blocks.air, 0, 3);
		world.setBlock(x + 11, y + 6, z + 13, ModBlocks.protossMetal, 1, 3);
		world.setBlock(x + 12, y + 6, z + 13, ModBlocks.protossMetal, 1, 3);
		world.setBlock(x + 13, y + 6, z + 13, Blocks.air, 0, 3);
		world.setBlock(x + 14, y + 6, z + 13, Blocks.air, 0, 3);
		world.setBlock(x, y + 6, z + 14, Blocks.air, 0, 3);
		world.setBlock(x + 1, y + 6, z + 14, Blocks.air, 0, 3);
		world.setBlock(x + 2, y + 6, z + 14, Blocks.air, 0, 3);
		world.setBlock(x + 3, y + 6, z + 14, Blocks.air, 0, 3);
		world.setBlock(x + 4, y + 6, z + 14, Blocks.air, 0, 3);
		world.setBlock(x + 5, y + 6, z + 14, Blocks.air, 0, 3);
		world.setBlock(x + 6, y + 6, z + 14, Blocks.air, 0, 3);
		world.setBlock(x + 7, y + 6, z + 14, Blocks.air, 0, 3);
		world.setBlock(x + 8, y + 6, z + 14, Blocks.air, 0, 3);
		world.setBlock(x + 9, y + 6, z + 14, Blocks.air, 0, 3);
		world.setBlock(x + 10, y + 6, z + 14, Blocks.air, 0, 3);
		world.setBlock(x + 11, y + 6, z + 14, Blocks.air, 0, 3);
		world.setBlock(x + 12, y + 6, z + 14, Blocks.air, 0, 3);
		world.setBlock(x + 13, y + 6, z + 14, Blocks.air, 0, 3);
		world.setBlock(x + 14, y + 6, z + 14, Blocks.air, 0, 3);
		world.setBlock(x, y + 7, z, Blocks.air, 0, 3);
		world.setBlock(x + 1, y + 7, z, Blocks.air, 0, 3);
		world.setBlock(x + 2, y + 7, z, Blocks.air, 0, 3);
		world.setBlock(x + 3, y + 7, z, Blocks.air, 0, 3);
		world.setBlock(x + 4, y + 7, z, Blocks.air, 0, 3);
		world.setBlock(x + 5, y + 7, z, Blocks.air, 0, 3);
		world.setBlock(x + 6, y + 7, z, Blocks.air, 0, 3);
		world.setBlock(x + 7, y + 7, z, Blocks.air, 0, 3);
		world.setBlock(x + 8, y + 7, z, Blocks.air, 0, 3);
		world.setBlock(x + 9, y + 7, z, Blocks.air, 0, 3);
		world.setBlock(x + 10, y + 7, z, Blocks.air, 0, 3);
		world.setBlock(x + 11, y + 7, z, Blocks.air, 0, 3);
		world.setBlock(x + 12, y + 7, z, Blocks.air, 0, 3);
		world.setBlock(x + 13, y + 7, z, Blocks.air, 0, 3);
		world.setBlock(x + 14, y + 7, z, Blocks.air, 0, 3);
		world.setBlock(x, y + 7, z + 1, Blocks.air, 0, 3);
		world.setBlock(x + 1, y + 7, z + 1, Blocks.air, 0, 3);
		world.setBlock(x + 2, y + 7, z + 1, ModBlocks.protossMetal, 1, 3);
		world.setBlock(x + 3, y + 7, z + 1, ModBlocks.protossMetal, 1, 3);
		world.setBlock(x + 4, y + 7, z + 1, Blocks.air, 0, 3);
		world.setBlock(x + 5, y + 7, z + 1, Blocks.air, 0, 3);
		world.setBlock(x + 6, y + 7, z + 1, Blocks.air, 0, 3);
		world.setBlock(x + 7, y + 7, z + 1, Blocks.air, 0, 3);
		world.setBlock(x + 8, y + 7, z + 1, Blocks.air, 0, 3);
		world.setBlock(x + 9, y + 7, z + 1, Blocks.air, 0, 3);
		world.setBlock(x + 10, y + 7, z + 1, Blocks.air, 0, 3);
		world.setBlock(x + 11, y + 7, z + 1, Blocks.air, 0, 3);
		world.setBlock(x + 12, y + 7, z + 1, Blocks.air, 0, 3);
		world.setBlock(x + 13, y + 7, z + 1, Blocks.air, 0, 3);
		world.setBlock(x + 14, y + 7, z + 1, Blocks.air, 0, 3);
		world.setBlock(x, y + 7, z + 2, Blocks.air, 0, 3);
		world.setBlock(x + 1, y + 7, z + 2, ModBlocks.protossMetal, 1, 3);
		world.setBlock(x + 2, y + 7, z + 2, ModBlocks.protossMetal, 1, 3);
		world.setBlock(x + 3, y + 7, z + 2, ModBlocks.protossMetal, 1, 3);
		world.setBlock(x + 4, y + 7, z + 2, Blocks.air, 0, 3);
		world.setBlock(x + 5, y + 7, z + 2, Blocks.air, 0, 3);
		world.setBlock(x + 6, y + 7, z + 2, Blocks.air, 0, 3);
		world.setBlock(x + 7, y + 7, z + 2, Blocks.air, 0, 3);
		world.setBlock(x + 8, y + 7, z + 2, Blocks.air, 0, 3);
		world.setBlock(x + 9, y + 7, z + 2, Blocks.air, 0, 3);
		world.setBlock(x + 10, y + 7, z + 2, Blocks.air, 0, 3);
		world.setBlock(x + 11, y + 7, z + 2, Blocks.air, 0, 3);
		world.setBlock(x + 12, y + 7, z + 2, Blocks.air, 0, 3);
		world.setBlock(x + 13, y + 7, z + 2, Blocks.air, 0, 3);
		world.setBlock(x + 14, y + 7, z + 2, Blocks.air, 0, 3);
		world.setBlock(x, y + 7, z + 3, Blocks.air, 0, 3);
		world.setBlock(x + 1, y + 7, z + 3, ModBlocks.protossMetal, 1, 3);
		world.setBlock(x + 2, y + 7, z + 3, ModBlocks.protossMetal, 1, 3);
		world.setBlock(x + 3, y + 7, z + 3, ModBlocks.protossEnergyChannelDark, 0, 3);
		world.setBlock(x + 4, y + 7, z + 3, Blocks.air, 0, 3);
		world.setBlock(x + 5, y + 7, z + 3, Blocks.air, 0, 3);
		world.setBlock(x + 6, y + 7, z + 3, Blocks.air, 0, 3);
		world.setBlock(x + 7, y + 7, z + 3, Blocks.air, 0, 3);
		world.setBlock(x + 8, y + 7, z + 3, Blocks.air, 0, 3);
		world.setBlock(x + 9, y + 7, z + 3, Blocks.air, 0, 3);
		world.setBlock(x + 10, y + 7, z + 3, Blocks.air, 0, 3);
		world.setBlock(x + 11, y + 7, z + 3, Blocks.air, 0, 3);
		world.setBlock(x + 12, y + 7, z + 3, Blocks.air, 0, 3);
		world.setBlock(x + 13, y + 7, z + 3, Blocks.air, 0, 3);
		world.setBlock(x + 14, y + 7, z + 3, Blocks.air, 0, 3);
		world.setBlock(x, y + 7, z + 4, Blocks.air, 0, 3);
		world.setBlock(x + 1, y + 7, z + 4, Blocks.air, 0, 3);
		world.setBlock(x + 2, y + 7, z + 4, Blocks.air, 0, 3);
		world.setBlock(x + 3, y + 7, z + 4, Blocks.air, 0, 3);
		world.setBlock(x + 4, y + 7, z + 4, Blocks.air, 0, 3);
		world.setBlock(x + 5, y + 7, z + 4, Blocks.air, 0, 3);
		world.setBlock(x + 6, y + 7, z + 4, Blocks.air, 0, 3);
		world.setBlock(x + 7, y + 7, z + 4, Blocks.air, 0, 3);
		world.setBlock(x + 8, y + 7, z + 4, Blocks.air, 0, 3);
		world.setBlock(x + 9, y + 7, z + 4, Blocks.air, 0, 3);
		world.setBlock(x + 10, y + 7, z + 4, Blocks.air, 0, 3);
		world.setBlock(x + 11, y + 7, z + 4, Blocks.air, 0, 3);
		world.setBlock(x + 12, y + 7, z + 4, Blocks.air, 0, 3);
		world.setBlock(x + 13, y + 7, z + 4, Blocks.air, 0, 3);
		world.setBlock(x + 14, y + 7, z + 4, Blocks.air, 0, 3);
		world.setBlock(x, y + 7, z + 5, Blocks.air, 0, 3);
		world.setBlock(x + 1, y + 7, z + 5, Blocks.air, 0, 3);
		world.setBlock(x + 2, y + 7, z + 5, Blocks.air, 0, 3);
		world.setBlock(x + 3, y + 7, z + 5, Blocks.air, 0, 3);
		world.setBlock(x + 4, y + 7, z + 5, Blocks.air, 0, 3);
		world.setBlock(x + 5, y + 7, z + 5, Blocks.air, 0, 3);
		world.setBlock(x + 6, y + 7, z + 5, Blocks.air, 0, 3);
		world.setBlock(x + 7, y + 7, z + 5, Blocks.air, 0, 3);
		world.setBlock(x + 8, y + 7, z + 5, Blocks.air, 0, 3);
		world.setBlock(x + 9, y + 7, z + 5, Blocks.air, 0, 3);
		world.setBlock(x + 10, y + 7, z + 5, Blocks.air, 0, 3);
		world.setBlock(x + 11, y + 7, z + 5, Blocks.air, 0, 3);
		world.setBlock(x + 12, y + 7, z + 5, Blocks.air, 0, 3);
		world.setBlock(x + 13, y + 7, z + 5, Blocks.air, 0, 3);
		world.setBlock(x + 14, y + 7, z + 5, Blocks.air, 0, 3);
		world.setBlock(x, y + 7, z + 6, Blocks.air, 0, 3);
		world.setBlock(x + 1, y + 7, z + 6, Blocks.air, 0, 3);
		world.setBlock(x + 2, y + 7, z + 6, Blocks.air, 0, 3);
		world.setBlock(x + 3, y + 7, z + 6, Blocks.air, 0, 3);
		world.setBlock(x + 4, y + 7, z + 6, Blocks.air, 0, 3);
		world.setBlock(x + 5, y + 7, z + 6, Blocks.air, 0, 3);
		world.setBlock(x + 6, y + 7, z + 6, Blocks.air, 0, 3);
		world.setBlock(x + 7, y + 7, z + 6, Blocks.air, 0, 3);
		world.setBlock(x + 8, y + 7, z + 6, Blocks.air, 0, 3);
		world.setBlock(x + 9, y + 7, z + 6, Blocks.air, 0, 3);
		world.setBlock(x + 10, y + 7, z + 6, Blocks.air, 0, 3);
		world.setBlock(x + 11, y + 7, z + 6, Blocks.air, 0, 3);
		world.setBlock(x + 12, y + 7, z + 6, Blocks.air, 0, 3);
		world.setBlock(x + 13, y + 7, z + 6, Blocks.air, 0, 3);
		world.setBlock(x + 14, y + 7, z + 6, Blocks.air, 0, 3);
		world.setBlock(x, y + 7, z + 7, Blocks.air, 0, 3);
		world.setBlock(x + 1, y + 7, z + 7, Blocks.air, 0, 3);
		world.setBlock(x + 2, y + 7, z + 7, Blocks.air, 0, 3);
		world.setBlock(x + 3, y + 7, z + 7, Blocks.air, 0, 3);
		world.setBlock(x + 4, y + 7, z + 7, Blocks.air, 0, 3);
		world.setBlock(x + 5, y + 7, z + 7, Blocks.air, 0, 3);
		world.setBlock(x + 6, y + 7, z + 7, Blocks.air, 0, 3);
		world.setBlock(x + 7, y + 7, z + 7, Blocks.air, 0, 3);
		world.setBlock(x + 8, y + 7, z + 7, Blocks.air, 0, 3);
		world.setBlock(x + 9, y + 7, z + 7, Blocks.air, 0, 3);
		world.setBlock(x + 10, y + 7, z + 7, Blocks.air, 0, 3);
		world.setBlock(x + 11, y + 7, z + 7, Blocks.air, 0, 3);
		world.setBlock(x + 12, y + 7, z + 7, Blocks.air, 0, 3);
		world.setBlock(x + 13, y + 7, z + 7, Blocks.air, 0, 3);
		world.setBlock(x + 14, y + 7, z + 7, Blocks.air, 0, 3);
		world.setBlock(x, y + 7, z + 8, Blocks.air, 0, 3);
		world.setBlock(x + 1, y + 7, z + 8, Blocks.air, 0, 3);
		world.setBlock(x + 2, y + 7, z + 8, Blocks.air, 0, 3);
		world.setBlock(x + 3, y + 7, z + 8, Blocks.air, 0, 3);
		world.setBlock(x + 4, y + 7, z + 8, Blocks.air, 0, 3);
		world.setBlock(x + 5, y + 7, z + 8, Blocks.air, 0, 3);
		world.setBlock(x + 6, y + 7, z + 8, Blocks.air, 0, 3);
		world.setBlock(x + 7, y + 7, z + 8, Blocks.air, 0, 3);
		world.setBlock(x + 8, y + 7, z + 8, Blocks.air, 0, 3);
		world.setBlock(x + 9, y + 7, z + 8, Blocks.air, 0, 3);
		world.setBlock(x + 10, y + 7, z + 8, Blocks.air, 0, 3);
		world.setBlock(x + 11, y + 7, z + 8, Blocks.air, 0, 3);
		world.setBlock(x + 12, y + 7, z + 8, Blocks.air, 0, 3);
		world.setBlock(x + 13, y + 7, z + 8, Blocks.air, 0, 3);
		world.setBlock(x + 14, y + 7, z + 8, Blocks.air, 0, 3);
		world.setBlock(x, y + 7, z + 9, Blocks.air, 0, 3);
		world.setBlock(x + 1, y + 7, z + 9, Blocks.air, 0, 3);
		world.setBlock(x + 2, y + 7, z + 9, Blocks.air, 0, 3);
		world.setBlock(x + 3, y + 7, z + 9, Blocks.air, 0, 3);
		world.setBlock(x + 4, y + 7, z + 9, Blocks.air, 0, 3);
		world.setBlock(x + 5, y + 7, z + 9, Blocks.air, 0, 3);
		world.setBlock(x + 6, y + 7, z + 9, Blocks.air, 0, 3);
		world.setBlock(x + 7, y + 7, z + 9, Blocks.air, 0, 3);
		world.setBlock(x + 8, y + 7, z + 9, Blocks.air, 0, 3);
		world.setBlock(x + 9, y + 7, z + 9, Blocks.air, 0, 3);
		world.setBlock(x + 10, y + 7, z + 9, Blocks.air, 0, 3);
		world.setBlock(x + 11, y + 7, z + 9, Blocks.air, 0, 3);
		world.setBlock(x + 12, y + 7, z + 9, Blocks.air, 0, 3);
		world.setBlock(x + 13, y + 7, z + 9, Blocks.air, 0, 3);
		world.setBlock(x + 14, y + 7, z + 9, Blocks.air, 0, 3);
		world.setBlock(x, y + 7, z + 10, Blocks.air, 0, 3);
		world.setBlock(x + 1, y + 7, z + 10, Blocks.air, 0, 3);
		world.setBlock(x + 2, y + 7, z + 10, Blocks.air, 0, 3);
		world.setBlock(x + 3, y + 7, z + 10, Blocks.air, 0, 3);
		world.setBlock(x + 4, y + 7, z + 10, Blocks.air, 0, 3);
		world.setBlock(x + 5, y + 7, z + 10, Blocks.air, 0, 3);
		world.setBlock(x + 6, y + 7, z + 10, Blocks.air, 0, 3);
		world.setBlock(x + 7, y + 7, z + 10, Blocks.air, 0, 3);
		world.setBlock(x + 8, y + 7, z + 10, Blocks.air, 0, 3);
		world.setBlock(x + 9, y + 7, z + 10, Blocks.air, 0, 3);
		world.setBlock(x + 10, y + 7, z + 10, Blocks.air, 0, 3);
		world.setBlock(x + 11, y + 7, z + 10, Blocks.air, 0, 3);
		world.setBlock(x + 12, y + 7, z + 10, Blocks.air, 0, 3);
		world.setBlock(x + 13, y + 7, z + 10, Blocks.air, 0, 3);
		world.setBlock(x + 14, y + 7, z + 10, Blocks.air, 0, 3);
		world.setBlock(x, y + 7, z + 11, Blocks.air, 0, 3);
		world.setBlock(x + 1, y + 7, z + 11, Blocks.air, 0, 3);
		world.setBlock(x + 2, y + 7, z + 11, Blocks.air, 0, 3);
		world.setBlock(x + 3, y + 7, z + 11, Blocks.air, 0, 3);
		world.setBlock(x + 4, y + 7, z + 11, Blocks.air, 0, 3);
		world.setBlock(x + 5, y + 7, z + 11, Blocks.air, 0, 3);
		world.setBlock(x + 6, y + 7, z + 11, Blocks.air, 0, 3);
		world.setBlock(x + 7, y + 7, z + 11, Blocks.air, 0, 3);
		world.setBlock(x + 8, y + 7, z + 11, Blocks.air, 0, 3);
		world.setBlock(x + 9, y + 7, z + 11, Blocks.air, 0, 3);
		world.setBlock(x + 10, y + 7, z + 11, Blocks.air, 0, 3);
		world.setBlock(x + 11, y + 7, z + 11, ModBlocks.protossEnergyChannelDark, 0, 3);
		world.setBlock(x + 12, y + 7, z + 11, ModBlocks.protossMetal, 1, 3);
		world.setBlock(x + 13, y + 7, z + 11, ModBlocks.protossMetal, 1, 3);
		world.setBlock(x + 14, y + 7, z + 11, Blocks.air, 0, 3);
		world.setBlock(x, y + 7, z + 12, Blocks.air, 0, 3);
		world.setBlock(x + 1, y + 7, z + 12, Blocks.air, 0, 3);
		world.setBlock(x + 2, y + 7, z + 12, Blocks.air, 0, 3);
		world.setBlock(x + 3, y + 7, z + 12, Blocks.air, 0, 3);
		world.setBlock(x + 4, y + 7, z + 12, Blocks.air, 0, 3);
		world.setBlock(x + 5, y + 7, z + 12, Blocks.air, 0, 3);
		world.setBlock(x + 6, y + 7, z + 12, Blocks.air, 0, 3);
		world.setBlock(x + 7, y + 7, z + 12, Blocks.air, 0, 3);
		world.setBlock(x + 8, y + 7, z + 12, Blocks.air, 0, 3);
		world.setBlock(x + 9, y + 7, z + 12, Blocks.air, 0, 3);
		world.setBlock(x + 10, y + 7, z + 12, Blocks.air, 0, 3);
		world.setBlock(x + 11, y + 7, z + 12, ModBlocks.protossMetal, 1, 3);
		world.setBlock(x + 12, y + 7, z + 12, ModBlocks.protossMetal, 1, 3);
		world.setBlock(x + 13, y + 7, z + 12, ModBlocks.protossMetal, 1, 3);
		world.setBlock(x + 14, y + 7, z + 12, Blocks.air, 0, 3);
		world.setBlock(x, y + 7, z + 13, Blocks.air, 0, 3);
		world.setBlock(x + 1, y + 7, z + 13, Blocks.air, 0, 3);
		world.setBlock(x + 2, y + 7, z + 13, Blocks.air, 0, 3);
		world.setBlock(x + 3, y + 7, z + 13, Blocks.air, 0, 3);
		world.setBlock(x + 4, y + 7, z + 13, Blocks.air, 0, 3);
		world.setBlock(x + 5, y + 7, z + 13, Blocks.air, 0, 3);
		world.setBlock(x + 6, y + 7, z + 13, Blocks.air, 0, 3);
		world.setBlock(x + 7, y + 7, z + 13, Blocks.air, 0, 3);
		world.setBlock(x + 8, y + 7, z + 13, Blocks.air, 0, 3);
		world.setBlock(x + 9, y + 7, z + 13, Blocks.air, 0, 3);
		world.setBlock(x + 10, y + 7, z + 13, Blocks.air, 0, 3);
		world.setBlock(x + 11, y + 7, z + 13, ModBlocks.protossMetal, 1, 3);
		world.setBlock(x + 12, y + 7, z + 13, ModBlocks.protossMetal, 1, 3);
		world.setBlock(x + 13, y + 7, z + 13, Blocks.air, 0, 3);
		world.setBlock(x + 14, y + 7, z + 13, Blocks.air, 0, 3);
		world.setBlock(x, y + 7, z + 14, Blocks.air, 0, 3);
		world.setBlock(x + 1, y + 7, z + 14, Blocks.air, 0, 3);
		world.setBlock(x + 2, y + 7, z + 14, Blocks.air, 0, 3);
		world.setBlock(x + 3, y + 7, z + 14, Blocks.air, 0, 3);
		world.setBlock(x + 4, y + 7, z + 14, Blocks.air, 0, 3);
		world.setBlock(x + 5, y + 7, z + 14, Blocks.air, 0, 3);
		world.setBlock(x + 6, y + 7, z + 14, Blocks.air, 0, 3);
		world.setBlock(x + 7, y + 7, z + 14, Blocks.air, 0, 3);
		world.setBlock(x + 8, y + 7, z + 14, Blocks.air, 0, 3);
		world.setBlock(x + 9, y + 7, z + 14, Blocks.air, 0, 3);
		world.setBlock(x + 10, y + 7, z + 14, Blocks.air, 0, 3);
		world.setBlock(x + 11, y + 7, z + 14, Blocks.air, 0, 3);
		world.setBlock(x + 12, y + 7, z + 14, Blocks.air, 0, 3);
		world.setBlock(x + 13, y + 7, z + 14, Blocks.air, 0, 3);
